Workbook

Sheet Policy_Decisions
A1: POLICY DECISIONS
A4: Policy | B4: Selected Decision | C4: Allowed Values | D4: Formula Impact | E4: Owner | F4: Status | G4: Comments
A5: Malus method | B5: Proportional | C5: Proportional | Percentage points | D5: Final Achievement = Gross x (1-Malus), or Gross-Malus | E5: HR / Compensation | F5: Validated
A6: Extra PCS treatment | B6: Additive | C6: Additive | Replacement | D6: Additive sums standard and extra PCS; Replacement keeps the higher PCS award | E6: Operations / HR | F6: Validated
A7: Target bonus rate basis | B7: Monthly | C7: Monthly | Annual | D7: Annual rates are divided by 12 before monthly payout calculation | E7: HR / Payroll | F7: Validated
A8: Proration denominator | B8: Calendar days | C8: Calendar days | Working days | Planned days | D8: Determines how Scheduled Days and Eligible Days must be populated | E8: HR / Payroll | F8: Validated
A9: Absence treatment | B9: KPI only | C9: KPI only | Eligibility only | Both | D9: Prevents unintended double reduction unless Both is explicitly approved | E9: HR / Operations | F9: Validated
A10: Achievement cap | B10: 1.3 | C10: 0% to 200% | D10: Caps Gross Achievement after KPI aggregation | E10: HR / Compensation | F10: Validated
A11: Rounding | B11: Centime | C11: Centime | Whole MAD | D11: Final Payout rounded to 2 decimals or 0 decimals | E11: Payroll | F11: To validate
A12: Employee eligibility | B12: Active eligible population | C12: Policy reference required | D12: Controls joiners, leavers, probation and exclusions | E12: HR | F12: To validate

Sheet Control_Checks
A1: CONTROL CHECKS
A4: Area | B4: Check | C4: Count / Value | D4: Expected | E4: Status | F4: Owner | G4: Evidence | H4: Comment
A5: Monetary inputs | B5: Missing currency | C5: =COUNTIFS(Raw_Data!A5:A206,"<>",Raw_Data!M5:M206,"") -> 0 | D5: 0 | E5: =IF(D5="INFO","INFO",IF(C5=D5,"OK","REVIEW")) -> OK | F5: WFM / HR
A6: Monetary inputs | B6: Currency different from MAD | C6: =COUNTIFS(Raw_Data!A5:A206,"<>",Raw_Data!M5:M206,"<>MAD") -> 0 | D6: 0 | E6: =IF(D6="INFO","INFO",IF(C6=D6,"OK","REVIEW")) -> OK | F6: WFM / HR
A7: Monetary inputs | B7: Missing salary/rate and override | C7: =SUMPRODUCT(--(Raw_Data!A5:A206<>""),--(Raw_Data!P5:P206=""),--((Raw_Data!N5:N206="")+(Raw_Data!O5:O206="")>0)) -> 0 | D7: 0 | E7: =IF(D7="INFO","INFO",IF(C7=D7,"OK","REVIEW")) -> OK | F7: WFM / HR
A8: Proration | B8: Missing or zero Scheduled Days | C8: =SUMPRODUCT(--(Raw_Data!A5:A206<>""),--((Raw_Data!R5:R206="")+(Raw_Data!R5:R206<=0)>0)) -> 0 | D8: 0 | E8: =IF(D8="INFO","INFO",IF(C8=D8,"OK","REVIEW")) -> OK | F8: WFM / HR
A9: Proration | B9: Eligible Days greater than Scheduled Days | C9: =SUMPRODUCT(--(Raw_Data!A5:A206<>""),--(Raw_Data!Q5:Q206>Raw_Data!R5:R206)) -> 0 | D9: 0 | E9: =IF(D9="INFO","INFO",IF(C9=D9,"OK","REVIEW")) -> OK | F9: WFM / HR
A10: Dashboard readiness | B10: Period different from 2026-07 | C10: =COUNTIFS(Raw_Data!A5:A206,"<>",Raw_Data!D5:D206,"<>2026-07") -> 0 | D10: 0 | E10: =IF(D10="INFO","INFO",IF(C10=D10,"OK","REVIEW")) -> OK | F10: WFM / HR
A11: Dashboard readiness | B11: LOB missing from KPI configuration | C11: =SUMPRODUCT(--(Raw_Data!$A$5:$A$206<>""),--(COUNTIF(KPI_Config!$A$5:$A$46,Raw_Data!$C$5:$C$206)=0)) -> 0 | D11: 0 | E11: =IF(D11="INFO","INFO",IF(C11=D11,"OK","REVIEW")) -> OK | F11: WFM / HR
A12: Dashboard readiness | B12: Duplicate Agent ID + Period | C12: =SUMPRODUCT((Raw_Data!A5:A206<>"")*(COUNTIFS(Raw_Data!A5:A206,Raw_Data!A5:A206,Raw_Data!D5:D206,Raw_Data!D5:D206)>1))/2 -> 0 | D12: 0 | E12: =IF(D12="INFO","INFO",IF(C12=D12,"OK","REVIEW")) -> OK | F12: WFM / HR
A13: Policy | B13: Policy decisions not validated | C13: =COUNTIF(Policy_Decisions!F5:F12,"<>Validated") -> 2 | D13: 0 | E13: =IF(D13="INFO","INFO",IF(C13=D13,"OK","REVIEW")) -> REVIEW | F13: WFM / HR
A14: Data status | B14: Synthetic demonstration records | C14: =COUNTIF(Raw_Data!S5:S206,"SYNTHETIC") -> 0 | D14: 0 | E14: =IF(D14="INFO","INFO",IF(C14=D14,"OK","REVIEW")) -> OK | F14: WFM / HR
A15: Roster mapping | B15: Agents without Team Lead mapping | C15: =COUNTIFS(Raw_Data!$A$5:$A$206,"<>",Raw_Data!$T$5:$T$206,"Unmapped") -> 0 | D15: 0 | E15: =IF(C15=D15,"OK","REVIEW") -> OK | F15: WFM / HR
A16: Information | B16: Total loaded records | C16: =COUNTA(Raw_Data!A5:A206) -> 167 | D16: INFO | E16: =IF(D15="INFO","INFO",IF(C15=D15,"OK","REVIEW")) -> OK | F16: WFM / HR
A17: Information | B17: Estimated final payout | C17: =SUM(Results!Y5:Y206) -> 143600 | D17: INFO | E17: =IF(D16="INFO","INFO",IF(C16=D16,"OK","REVIEW")) -> INFO | F17: WFM / HR

Sheet KPI_Config
A1: BONUS CONFIGURATION
A4: Population | B4: KPI | C4: Direction | D4: Tier 1 Bonus % | E4: Tier 1 Target | F4: Tier 2 Bonus % | G4: Tier 2 Target | I4: VOC Detractor Count | J4: Malus Impact
A5: Ford GER | B5: AHT | C5: L | D5: 0.15 | E5: 450 | F5: 0 | G5: 0 | I5: 0 | J5: 0
A6: Ford GER | B6: Productivity | C6: H | D6: 0.15 | E6: 7 | F6: 0 | G6: 0 | I6: 1 | J6: 0.1
A7: Ford GER | B7: PCS Score | C7: H | D7: 0.2 | E7: 4.3 | F7: 0.15 | G7: 4.1 | I7: 2 | J7: 0.2
A8: Ford GER | B8: PCS % (Participation) | C8: H | D8: 0.15 | E8: 0.5 | F8: 0.1 | G8: 0.4 | I8: 3 | J8: 0.5
A9: Ford GER | B9: QM | C9: H | D9: 0.2 | E9: 0.9 | F9: 0.15 | G9: 0.8 | I9: 4 | J9: 0.75
A10: Ford GER | B10: Abs% | C10: L | D10: 0.15 | E10: 0.05 | F10: 0 | G10: 0 | I10: 5 | J10: 1
A11: Ford GER | B11: Extra Bonus (PCS Score) | C11: H | D11: 0.3 | E11: 4.5 | F11: 0.2 | G11: 4.3
A12: Ford Dutch | B12: AHT | C12: L | D12: 0.15 | E12: 450 | F12: 0 | G12: 0 | I12: 0 | J12: 0
A13: Ford Dutch | B13: Productivity | C13: H | D13: 0.15 | E13: 7 | F13: 0 | G13: 0 | I13: 1 | J13: 0.1
A14: Ford Dutch | B14: PCS Score | C14: H | D14: 0.2 | E14: 4.3 | F14: 0.15 | G14: 4.1 | I14: 2 | J14: 0.2
A15: Ford Dutch | B15: PCS % (Participation) | C15: H | D15: 0.15 | E15: 0.5 | F15: 0.1 | G15: 0.4 | I15: 3 | J15: 0.5
A16: Ford Dutch | B16: QM | C16: H | D16: 0.2 | E16: 0.9 | F16: 0.15 | G16: 0.8 | I16: 4 | J16: 0.75
A17: Ford Dutch | B17: Abs% | C17: L | D17: 0.15 | E17: 0.05 | F17: 0 | G17: 0 | I17: 5 | J17: 1
A18: Ford Dutch | B18: Extra Bonus (PCS Score) | C18: H | D18: 0.3 | E18: 4.5 | F18: 0.2 | G18: 4.3
A19: OEM FR | B19: AHT | C19: L | D19: 0.15 | E19: 450 | F19: 0 | G19: 0 | I19: 0 | J19: 0
A20: OEM FR | B20: Productivity | C20: H | D20: 0.15 | E20: 7 | F20: 0 | G20: 0 | I20: 1 | J20: 0.1
A21: OEM FR | B21: PCS Score | C21: H | D21: 0.2 | E21: 4.3 | F21: 0.15 | G21: 4.1 | I21: 2 | J21: 0.2
A22: OEM FR | B22: PCS % (Participation) | C22: H | D22: 0.15 | E22: 0.5 | F22: 0.1 | G22: 0.4 | I22: 3 | J22: 0.5
A23: OEM FR | B23: QM | C23: H | D23: 0.2 | E23: 0.9 | F23: 0.15 | G23: 0.8 | I23: 4 | J23: 0.75
A24: OEM FR | B24: Abs% | C24: L | D24: 0.15 | E24: 0.05 | F24: 0 | G24: 0 | I24: 5 | J24: 1
A25: OEM FR | B25: Extra Bonus (PCS Score) | C25: H | D25: 0.3 | E25: 4.5 | F25: 0.2 | G25: 4.3
A26: RSA FR | B26: AHT | C26: L | D26: 0.15 | E26: 450 | F26: 0 | G26: 0 | I26: 0 | J26: 0
A27: RSA FR | B27: Productivity | C27: H | D27: 0.15 | E27: 7 | F27: 0 | G27: 0 | I27: 1 | J27: 0.1
A28: RSA FR | B28: PCS Score | C28: H | D28: 0.2 | E28: 4.3 | F28: 0.15 | G28: 4.1 | I28: 2 | J28: 0.2
A29: RSA FR | B29: PCS % (Participation) | C29: H | D29: 0.15 | E29: 0.5 | F29: 0.1 | G29: 0.4 | I29: 3 | J29: 0.5
A30: RSA FR | B30: QM | C30: H | D30: 0.2 | E30: 0.9 | F30: 0.15 | G30: 0.8 | I30: 4 | J30: 0.75
A31: RSA FR | B31: Abs% | C31: L | D31: 0.15 | E31: 0.05 | F31: 0 | G31: 0 | I31: 5 | J31: 1
A32: RSA FR | B32: Extra Bonus (PCS Score) | C32: H | D32: 0.3 | E32: 4.5 | F32: 0.2 | G32: 4.3
A33: RSA NL | B33: AHT | C33: L | D33: 0.15 | E33: 450 | F33: 0 | G33: 0 | I33: 0 | J33: 0
A34: RSA NL | B34: Productivity | C34: H | D34: 0.15 | E34: 7 | F34: 0 | G34: 0 | I34: 1 | J34: 0.1
A35: RSA NL | B35: PCS Score | C35: H | D35: 0.2 | E35: 4.3 | F35: 0.15 | G35: 4.1 | I35: 2 | J35: 0.2
A36: RSA NL | B36: PCS % (Participation) | C36: H | D36: 0.15 | E36: 0.5 | F36: 0.1 | G36: 0.4 | I36: 3 | J36: 0.5
A37: RSA NL | B37: QM | C37: H | D37: 0.2 | E37: 0.9 | F37: 0.15 | G37: 0.8 | I37: 4 | J37: 0.75
A38: RSA NL | B38: Abs% | C38: L | D38: 0.15 | E38: 0.05 | F38: 0 | G38: 0 | I38: 5 | J38: 1
A39: RSA NL | B39: Extra Bonus (PCS Score) | C39: H | D39: 0.3 | E39: 4.5 | F39: 0.2 | G39: 4.3
A40: RSA VL | B40: AHT | C40: L | D40: 0.15 | E40: 450 | F40: 0 | G40: 0 | I40: 0 | J40: 0
A41: RSA VL | B41: Productivity | C41: H | D41: 0.15 | E41: 7 | F41: 0 | G41: 0 | I41: 1 | J41: 0.1
A42: RSA VL | B42: PCS Score | C42: H | D42: 0.2 | E42: 4.3 | F42: 0.15 | G42: 4.1 | I42: 2 | J42: 0.2
...

Sheet Raw_Data
A1: RAW PERFORMANCE DATA
A4: Agent ID | B4: Agent Name | C4: Population | D4: Period | E4: AHT | F4: Productivity | G4: PCS Score | H4: PCS % Participation | I4: QM | J4: Abs% | K4: VOC Detractor Count | L4: Notes | M4: Currency | N4: Monthly Fixed Salary | O4: Target Bonus Rate | P4: Reference Bonus Override | Q4: Eligible Days | R4: Scheduled Days | S4: Data Status | T4: Team Lead | U4: Ops Manager
A5: 204341 | B5: Felhane Mohamed Amine | C5: Ford GER | D5: 2026-07 | E5: 451.41525 | F5: 7.3103422 | G5: 2.1538462 | H5: 0.091872792 | K5: 0 | M5: MAD | P5: 2000 | Q5: 31 | R5: 31 | S5: ICMP | T5: Grouh Jaouad | U5: Anas OUAKKAD
A6: 204342 | B6: Zekhnini Mustapha | C6: Ford GER | D6: 2026-07 | E6: 664.04077 | F6: 4.9695744 | G6: 4.7142857 | H6: 0.090128755 | K6: 0 | M6: MAD | P6: 2000 | Q6: 31 | R6: 31 | S6: ICMP | T6: Grouh Jaouad | U6: Anas OUAKKAD
A7: 204343 | B7: Talhajit Abdellah | C7: Ford GER | D7: 2026-07 | E7: 589.97174 | F7: 5.5934883 | G7: 1 | H7: 0.109375 | K7: 0 | M7: MAD | P7: 2000 | Q7: 31 | R7: 31 | S7: ICMP | T7: Grouh Jaouad | U7: Anas OUAKKAD
A8: 204344 | B8: AYMAZ Abdelhay | C8: Ford GER | D8: 2026-07 | E8: 717.1025 | F8: 4.6018526 | G8: 4.7 | H8: 0.12389381 | K8: 0 | M8: MAD | P8: 2000 | Q8: 31 | R8: 31 | S8: ICMP | T8: Grouh Jaouad | U8: Anas OUAKKAD
A9: 204345 | B9: MOUSSA Amjad | C9: Ford GER | D9: 2026-07 | E9: 784.95633 | F9: 4.2040555 | G9: 4 | H9: 0.029850746 | K9: 0 | M9: MAD | P9: 2000 | Q9: 31 | R9: 31 | S9: ICMP | T9: Grouh Jaouad | U9: Anas OUAKKAD
A10: 204602 | B10: DRISSI Sidi Youssef | C10: Ford GER | D10: 2026-07 | E10: 707.70197 | F10: 4.6629798 | G10: 3.8461538 | H10: 0.082987552 | K10: 0 | M10: MAD | P10: 2000 | Q10: 31 | R10: 31 | S10: ICMP | T10: Grouh Jaouad | U10: Anas OUAKKAD
A11: 204349 | B11: NABACH Lara | C11: Ford GER | D11: 2026-07 | E11: 459.94248 | F11: 7.1748102 | G11: 4.2222222 | H11: 0.10655738 | K11: 0 | M11: MAD | P11: 2000 | Q11: 31 | R11: 31 | S11: ICMP | T11: Grouh Jaouad | U11: Anas OUAKKAD
A12: 228205 | B12: Mohamed Amine MERSAK | C12: OEM FR | D12: 2026-07 | E12: 437.32258 | F12: 7.5459172 | G12: 4.9310345 | H12: 0.39303483 | I12: 0.636 | K12: 0 | M12: MAD | P12: 2000 | Q12: 31 | R12: 31 | S12: ICMP | T12: Farouk BOUAZZAOUI | U12: Anas OUAKKAD
A13: 204018 | B13: Mejhed Asmaa | C13: Ford Dutch | D13: 2026-07 | G13: 4.1111111 | H13: 0.056672761 | I13: 0 | K13: 0 | M13: MAD | P13: 2000 | Q13: 31 | R13: 31 | S13: ICMP | T13: DERRAZI Ilyasse | U13: Anas OUAKKAD
A14: 250749 | B14: Achraf ENNAJAH | C14: OEM FR | D14: 2026-07 | K14: 0 | M14: MAD | P14: 2000 | Q14: 31 | R14: 31 | S14: ICMP | T14: Zineb MOUFID | U14: Anas OUAKKAD
A15: 250750 | B15: Ayoub EL ADRAOUI | C15: OEM FR | D15: 2026-07 | K15: 0 | M15: MAD | P15: 2000 | Q15: 31 | R15: 31 | S15: ICMP | T15: Kenza EL MOUMNI | U15: Anas OUAKKAD
A16: 266361 | B16: Mohamed Zuljami | C16: RSA VL | D16: 2026-07 | K16: 0 | M16: MAD | P16: 2000 | Q16: 31 | R16: 31 | S16: ICMP | T16: KAIKAI Faissal | U16: Anas OUAKKAD
A17: 204037 | B17: Ouadie REGRAGUI | C17: RSA NL | D17: 2026-07 | E17: 497.66292 | F17: 6.6309943 | G17: 3 | H17: 0.036184211 | I17: 0.88 | J17: 0.14 | K17: 0 | M17: MAD | P17: 2000 | Q17: 31 | R17: 31 | S17: ICMP | T17: EL GHAZI Youssef | U17: Anas OUAKKAD
A18: 232195 | B18: Khalid BOJADA | C18: RSA NL | D18: 2026-07 | E18: 431.0938 | F18: 7.6549466 | G18: 4.1707317 | H18: 0.10742188 | I18: 0.45 | J18: 0.12 | K18: 0 | M18: MAD | P18: 2000 | Q18: 31 | R18: 31 | S18: ICMP | T18: EL GHAZI Youssef | U18: Anas OUAKKAD
A19: 228217 | B19: Zineb ZAAROURI | C19: OEM FR | D19: 2026-07 | E19: 457.88506 | F19: 7.2070489 | G19: 5 | H19: 0.19166667 | I19: 0.849 | J19: 0 | K19: 0 | M19: MAD | P19: 2000 | Q19: 31 | R19: 31 | S19: ICMP | T19: Malak AZERKI | U19: Anas OUAKKAD
A20: 204033 | B20: Oulad Abdelaziz Youssef | C20: Ford Dutch | D20: 2026-07 | E20: 331.95904 | F20: 9.9409854 | G20: 3.5294118 | H20: 0.059925094 | I20: 0.2 | J20: 0.2 | K20: 0 | M20: MAD | P20: 2000 | Q20: 31 | R20: 31 | S20: ICMP | T20: EL GHAZI Youssef | U20: Anas OUAKKAD
A21: 228202 | B21: Youssef AZIZ | C21: OEM FR | D21: 2026-07 | E21: 619.22154 | F21: 5.329272 | G21: 4.627451 | H21: 0.37016575 | I21: 0.56416667 | J21: 0 | K21: 0 | M21: MAD | P21: 2000 | Q21: 31 | R21: 31 | S21: ICMP | T21: Kenza EL MOUMNI | U21: Anas OUAKKAD
A22: 228201 | B22: Youssef AMNAD | C22: OEM FR | D22: 2026-07 | E22: 459.58571 | F22: 7.1803798 | G22: 4.9705882 | H22: 0.28965517 | I22: 0.65666667 | J22: 0 | K22: 0 | M22: MAD | P22: 2000 | Q22: 31 | R22: 31 | S22: ICMP | T22: Malak AZERKI | U22: Anas OUAKKAD
A23: 250753 | B23: Youness ZBATI | C23: OEM FR | D23: 2026-07 | J23: 0 | K23: 0 | M23: MAD | P23: 2000 | Q23: 31 | R23: 31 | S23: ICMP | T23: Kenza EL MOUMNI | U23: Anas OUAKKAD
A24: 249778 | B24: Youness OUAHBI | C24: RSA FR | D24: 2026-07 | J24: 0 | K24: 0 | M24: MAD | P24: 2000 | Q24: 31 | R24: 31 | S24: ICMP | T24: Farouk BOUAZZAOUI | U24: Anas OUAKKAD
A25: 96496 | B25: HADRI Younes | C25: RSA VL | D25: 2026-07 | E25: 323.5027 | F25: 10.200842 | G25: 3.3333333 | H25: 0.075812274 | I25: 0.96333333 | J25: 0 | K25: 0 | M25: MAD | P25: 2000 | Q25: 31 | R25: 31 | S25: ICMP | T25: Glenn Antoon | U25: Anas OUAKKAD
A26: 228215 | B26: Younes EL FELLAH EL OUAZZANI | C26: OEM FR | D26: 2026-07 | E26: 450.93291 | F26: 7.3181619 | G26: 4.5882353 | H26: 0.20098039 | I26: 0.66461538 | J26: 0 | K26: 0 | M26: MAD | P26: 2000 | Q26: 31 | R26: 31 | S26: ICMP | T26: Zineb MOUFID | U26: Anas OUAKKAD
A27: 228211 | B27: Yazid LAGDEM | C27: OEM FR | D27: 2026-07 | E27: 630.17832 | F27: 5.236613 | G27: 4.8918919 | H27: 0.29310345 | I27: 0.76 | J27: 0 | K27: 0 | M27: MAD | P27: 2000 | Q27: 31 | R27: 31 | S27: ICMP | T27: Kenza EL MOUMNI | U27: Anas OUAKKAD
A28: 232196 | B28: Yassir Issarti | C28: RSA NL | D28: 2026-07 | E28: 645.55617 | F28: 5.1118712 | G28: 4.2142857 | H28: 0.089775561 | I28: 0.176 | J28: 0 | K28: 0 | M28: MAD | P28: 2000 | Q28: 31 | R28: 31 | S28: ICMP | T28: AL TAMIMI Zeynab | U28: Anas OUAKKAD
A29: 203614 | B29: El Mekkaoui Yassir | C29: OEM FR | D29: 2026-07 | E29: 477.53503 | F29: 6.9104878 | G29: 4.5925926 | H29: 0.20574163 | I29: 0.62714286 | J29: 0 | K29: 0 | M29: MAD | P29: 2000 | Q29: 31 | R29: 31 | S29: ICMP | T29: Zineb MOUFID | U29: Anas OUAKKAD
A30: 244554 | B30: Yassine Athmane | C30: RSA NL | D30: 2026-07 | K30: 0 | M30: MAD | P30: 2000 | Q30: 31 | R30: 31 | S30: ICMP | T30: KAIKAI Faissal | U30: Anas OUAKKAD
A31: 203646 | B31: Jemkar Yasmine | C31: OEM FR | D31: 2026-07 | E31: 365.87097 | F31: 9.0195733 | G31: 4.5405405 | H31: 0.20425532 | I31: 0.67923077 | J31: 0 | K31: 0 | M31: MAD | P31: 2000 | Q31: 31 | R31: 31 | S31: ICMP | T31: Kenza EL MOUMNI | U31: Anas OUAKKAD
A32: 96486 | B32: EL BAROUDI El Yassmine | C32: RSA NL | D32: 2026-07 | E32: 246.35317 | F32: 13.395403 | G32: 3.375 | H32: 0.067039106 | I32: 0.2075 | J32: 0 | K32: 0 | M32: MAD | P32: 2000 | Q32: 31 | R32: 31 | S32: ICMP | T32: AL TAMIMI Zeynab | U32: Anas OUAKKAD
A33: 204024 | B33: Van der Laan Tim | C33: Ford Dutch | D33: 2026-07 | E33: 374.85809 | F33: 8.8033314 | G33: 4.1568627 | H33: 0.11347518 | I33: 0 | J33: 0.15 | K33: 0 | M33: MAD | P33: 2000 | Q33: 31 | R33: 31 | S33: ICMP | T33: EL GHAZI Youssef | U33: Anas OUAKKAD
A34: 224102 | B34: Tasnim NAJI | C34: RSA NL | D34: 2026-07 | E34: 574 | F34: 5.7491289 | G34: 4 | H34: 0.062135922 | I34: 0.58666667 | J34: 0.09 | K34: 0 | M34: MAD | P34: 2000 | Q34: 31 | R34: 31 | S34: ICMP | T34: JEANNE NKIKIO RWIBUTSO | U34: Anas OUAKKAD
A35: 228213 | B35: Taoufik MANOUNI | C35: OEM FR | D35: 2026-07 | E35: 415.82136 | F35: 7.9361003 | G35: 4.7083333 | H35: 0.40863787 | I35: 0.73083333 | J35: 0 | K35: 0 | M35: MAD | P35: 2000 | Q35: 31 | R35: 31 | S35: ICMP | T35: Zineb MOUFID | U35: Anas OUAKKAD
A36: 244550 | B36: taissir Bakour | C36: RSA NL | D36: 2026-07 | K36: 0 | M36: MAD | P36: 2000 | Q36: 31 | R36: 31 | S36: ICMP | T36: KAIKAI Faissal | U36: Anas OUAKKAD
A37: 207437 | B37: Taha Aboulhaoul | C37: RSA FR | D37: 2026-07 | E37: 303.85647 | F37: 10.860391 | G37: 2.9090909 | H37: 0.061630219 | I37: 0.79571429 | J37: 0 | K37: 0 | M37: MAD | P37: 2000 | Q37: 31 | R37: 31 | S37: ICMP | T37: Mohamed-Amine SADKI | U37: Anas OUAKKAD
A38: 240747 | B38: Soufiane ROUH | C38: RSA NL | D38: 2026-07 | G38: 1 | H38: 0.05 | K38: 0 | M38: MAD | P38: 2000 | Q38: 31 | R38: 31 | S38: ICMP | T38: EL GHAZI Youssef | U38: Anas OUAKKAD
A39: 221751 | B39: Shaib Hashemi | C39: RSA NL | D39: 2026-07 | E39: 375.34 | F39: 8.7920286 | G39: 3.4 | H39: 0.053299492 | I39: 0 | J39: 0.3 | K39: 0 | M39: MAD | P39: 2000 | Q39: 31 | R39: 31 | S39: ICMP | T39: JEANNE NKIKIO RWIBUTSO | U39: Anas OUAKKAD
A40: 232190 | B40: SCOTT BAHRU DE COENE | C40: RSA VL | D40: 2026-07 | E40: 523.15679 | F40: 6.3078603 | G40: 2.7142857 | H40: 0.057522124 | I40: 0.625 | J40: 0 | K40: 0 | M40: MAD | P40: 2000 | Q40: 31 | R40: 31 | S40: ICMP | T40: Glenn Antoon | U40: Anas OUAKKAD
A41: 204045 | B41: Ait El Bashir Salah Eddine | C41: Ford Dutch | D41: 2026-07 | E41: 358.18152 | F41: 9.2132057 | G41: 4.2278481 | H41: 0.18081181 | I41: 0.66666667 | J41: 0.01 | K41: 0 | M41: MAD | P41: 2000 | Q41: 31 | R41: 31 | S41: ICMP | T41: DERRAZI Ilyasse | U41: Anas OUAKKAD
A42: 96457 | B42: SAMAR Said | C42: RSA NL | D42: 2026-07 | E42: 446.86827 | F42: 7.3847266 | G42: 3.6078431 | H42: 0.12006861 | I42: 0.29333333 | J42: 0.13 | K42: 0 | M42: MAD | P42: 2000 | Q42: 31 | R42: 31 | S42: ICMP | T42: JEANNE NKIKIO RWIBUTSO | U42: Anas OUAKKAD
...

Sheet Results
A1: BONUS RESULTS
A4: Agent ID | B4: Agent Name | C4: LOB | D4: Period | E4: AHT Earned | F4: Productivity Earned | G4: PCS Earned | H4: Participation Earned | I4: QM Earned | J4: Abs Earned | K4: Extra PCS Earned | L4: Gross Achievement | M4: VOC Detractor Count | N4: Malus Impact | O4: Final Achievement | P4: Status | Q4: Currency | R4: Monthly Fixed Salary | S4: Target Bonus Rate | T4: Reference Bonus Amount | U4: Proration Factor | V4: Prorated Bonus Base | W4: Gross Payout | X4: Malus Deduction | Y4: Final Payout | Z4: Team Lead | AA4: Ops Manager
A5: =IF(Raw_Data!A5="","",Raw_Data!A5) -> 204341 | B5: =IF(Raw_Data!B5="","",Raw_Data!B5) -> Felhane Mohamed Amine | C5: =IF(Raw_Data!C5="","",Raw_Data!C5) -> Ford GER | D5: =IF(Raw_Data!D5="","",Raw_Data!D5) -> 2026-07 | E5: =IF($A5="","",IF(Raw_Data!E5="",0,IF(KPI_Config!$C$5="L",IF(Raw_Data!E5<=KPI_Config!$E$5,KPI_Config!$D$5,IF(AND(KPI_Config!$F$5>0,Raw_Data!E5<=KPI_Config!$G$5),KPI_Config!$F$5,0)),IF(Raw_Data!E5>=KPI_Config!$E$5,KPI_Config!$D$5,IF(AND(KPI_Config!$F$5>0,Raw_Data!E5>=KPI_Config!$G$5),KPI_Config!$F$5,0))))) -> 0 | F5: =IF($A5="","",IF(Raw_Data!F5="",0,IF(KPI_Config!$C$6="L",IF(Raw_Data!F5<=KPI_Config!$E$6,KPI_Config!$D$6,IF(AND(KPI_Config!$F$6>0,Raw_Data!F5<=KPI_Config!$G$6),KPI_Config!$F$6,0)),IF(Raw_Data!F5>=KPI_Config!$E$6,KPI_Config!$D$6,IF(AND(KPI_Config!$F$6>0,Raw_Data!F5>=KPI_Config!$G$6),KPI_Config!$F$6,0))))) -> 0.15 | G5: =IF($A5="","",IF(Raw_Data!G5="",0,IF(KPI_Config!$C$7="L",IF(Raw_Data!G5<=KPI_Config!$E$7,KPI_Config!$D$7,IF(AND(KPI_Config!$F$7>0,Raw_Data!G5<=KPI_Config!$G$7),KPI_Config!$F$7,0)),IF(Raw_Data!G5>=KPI_Config!$E$7,KPI_Config!$D$7,IF(AND(KPI_Config!$F$7>0,Raw_Data!G5>=KPI_Config!$G$7),KPI_Config!$F$7,0))))) -> 0 | H5: =IF($A5="","",IF(Raw_Data!H5="",0,IF(KPI_Config!$C$8="L",IF(Raw_Data!H5<=KPI_Config!$E$8,KPI_Config!$D$8,IF(AND(KPI_Config!$F$8>0,Raw_Data!H5<=KPI_Config!$G$8),KPI_Config!$F$8,0)),IF(Raw_Data!H5>=KPI_Config!$E$8,KPI_Config!$D$8,IF(AND(KPI_Config!$F$8>0,Raw_Data!H5>=KPI_Config!$G$8),KPI_Config!$F$8,0))))) -> 0 | I5: =IF($A5="","",IF(Raw_Data!I5="",0,IF(KPI_Config!$C$9="L",IF(Raw_Data!I5<=KPI_Config!$E$9,KPI_Config!$D$9,IF(AND(KPI_Config!$F$9>0,Raw_Data!I5<=KPI_Config!$G$9),KPI_Config!$F$9,0)),IF(Raw_Data!I5>=KPI_Config!$E$9,KPI_Config!$D$9,IF(AND(KPI_Config!$F$9>0,Raw_Data!I5>=KPI_Config!$G$9),KPI_Config!$F$9,0))))) -> 0 | J5: =IF($A5="","",IF(Raw_Data!J5="",0,IF(KPI_Config!$C$10="L",IF(Raw_Data!J5<=KPI_Config!$E$10,KPI_Config!$D$10,IF(AND(KPI_Config!$F$10>0,Raw_Data!J5<=KPI_Config!$G$10),KPI_Config!$F$10,0)),IF(Raw_Data!J5>=KPI_Config!$E$10,KPI_Config!$D$10,IF(AND(KPI_Config!$F$10>0,Raw_Data!J5>=KPI_Config!$G$10),KPI_Config!$F$10,0))))) -> 0 | K5: =IF($A5="","",IF(Raw_Data!G5="",0,IF(KPI_Config!$C$11="L",IF(Raw_Data!G5<=KPI_Config!$E$11,KPI_Config!$D$11,IF(AND(KPI_Config!$F$11>0,Raw_Data!G5<=KPI_Config!$G$11),KPI_Config!$F$11,0)),IF(Raw_Data!G5>=KPI_Config!$E$11,KPI_Config!$D$11,IF(AND(KPI_Config!$F$11>0,Raw_Data!G5>=KPI_Config!$G$11),KPI_Config!$F$11,0))))) -> 0 | L5: =IF($A5="","",MIN(Policy_Decisions!$B$10,IF(Policy_Decisions!$B$6="Additive",SUM(E5:K5),SUM(E5:J5)-G5+MAX(G5,K5)))) -> 0.15 | M5: =IF($A5="","",Raw_Data!K5) -> 0 | N5: =IF($A5="","",IFERROR(VLOOKUP(M5,KPI_Config!$I$5:$J$10,2,FALSE()),0)) -> 0 | O5: =IF($A5="","",IF(Policy_Decisions!$B$5="Percentage points",MAX(0,L5-N5),L5*(1-N5))) -> 0.15 | P5: =IF($A5="","",IF(U5="","Review proration",IF(O5=0,"No payout",IF(N5>0,"Malus applied","Eligible")))) -> Eligible | Q5: =IF($A5="","",Raw_Data!M5) -> MAD | R5: =IF($A5="","",Raw_Data!N5) -> 0 | S5: =IF($A5="","",Raw_Data!O5) -> 0 | T5: =IF($A5="","",IF(Raw_Data!P5>0,Raw_Data!P5,Raw_Data!N5*Raw_Data!O5/IF(Policy_Decisions!$B$7="Annual",12,1))) -> 2000 | U5: =IF($A5="","",IF(OR(Raw_Data!R5="",Raw_Data!R5<=0),"",MIN(1,MAX(0,Raw_Data!Q5/Raw_Data!R5)))) -> 1 | V5: =IF(OR($A5="",U5=""),"",T5*U5) -> 2000 | W5: =IF(OR($A5="",V5=""),"",V5*L5) -> 300 | X5: =IF(OR($A5="",V5=""),"",V5*L5-V5*O5) -> 0 | Y5: =IF(OR($A5="",V5=""),"",ROUND(V5*O5,IF(Policy_Decisions!$B$11="Whole MAD",0,2))) -> 300 | Z5: =Raw_Data!T5 -> Grouh Jaouad | AA5: =Raw_Data!U5 -> Anas OUAKKAD
A6: =IF(Raw_Data!A6="","",Raw_Data!A6) -> 204342 | B6: =IF(Raw_Data!B6="","",Raw_Data!B6) -> Zekhnini Mustapha | C6: =IF(Raw_Data!C6="","",Raw_Data!C6) -> Ford GER | D6: =IF(Raw_Data!D6="","",Raw_Data!D6) -> 2026-07 | E6: =IF($A6="","",IF(Raw_Data!E6="",0,IF(KPI_Config!$C$5="L",IF(Raw_Data!E6<=KPI_Config!$E$5,KPI_Config!$D$5,IF(AND(KPI_Config!$F$5>0,Raw_Data!E6<=KPI_Config!$G$5),KPI_Config!$F$5,0)),IF(Raw_Data!E6>=KPI_Config!$E$5,KPI_Config!$D$5,IF(AND(KPI_Config!$F$5>0,Raw_Data!E6>=KPI_Config!$G$5),KPI_Config!$F$5,0))))) -> 0 | F6: =IF($A6="","",IF(Raw_Data!F6="",0,IF(KPI_Config!$C$6="L",IF(Raw_Data!F6<=KPI_Config!$E$6,KPI_Config!$D$6,IF(AND(KPI_Config!$F$6>0,Raw_Data!F6<=KPI_Config!$G$6),KPI_Config!$F$6,0)),IF(Raw_Data!F6>=KPI_Config!$E$6,KPI_Config!$D$6,IF(AND(KPI_Config!$F$6>0,Raw_Data!F6>=KPI_Config!$G$6),KPI_Config!$F$6,0))))) -> 0 | G6: =IF($A6="","",IF(Raw_Data!G6="",0,IF(KPI_Config!$C$7="L",IF(Raw_Data!G6<=KPI_Config!$E$7,KPI_Config!$D$7,IF(AND(KPI_Config!$F$7>0,Raw_Data!G6<=KPI_Config!$G$7),KPI_Config!$F$7,0)),IF(Raw_Data!G6>=KPI_Config!$E$7,KPI_Config!$D$7,IF(AND(KPI_Config!$F$7>0,Raw_Data!G6>=KPI_Config!$G$7),KPI_Config!$F$7,0))))) -> 0.2 | H6: =IF($A6="","",IF(Raw_Data!H6="",0,IF(KPI_Config!$C$8="L",IF(Raw_Data!H6<=KPI_Config!$E$8,KPI_Config!$D$8,IF(AND(KPI_Config!$F$8>0,Raw_Data!H6<=KPI_Config!$G$8),KPI_Config!$F$8,0)),IF(Raw_Data!H6>=KPI_Config!$E$8,KPI_Config!$D$8,IF(AND(KPI_Config!$F$8>0,Raw_Data!H6>=KPI_Config!$G$8),KPI_Config!$F$8,0))))) -> 0 | I6: =IF($A6="","",IF(Raw_Data!I6="",0,IF(KPI_Config!$C$9="L",IF(Raw_Data!I6<=KPI_Config!$E$9,KPI_Config!$D$9,IF(AND(KPI_Config!$F$9>0,Raw_Data!I6<=KPI_Config!$G$9),KPI_Config!$F$9,0)),IF(Raw_Data!I6>=KPI_Config!$E$9,KPI_Config!$D$9,IF(AND(KPI_Config!$F$9>0,Raw_Data!I6>=KPI_Config!$G$9),KPI_Config!$F$9,0))))) -> 0 | J6: =IF($A6="","",IF(Raw_Data!J6="",0,IF(KPI_Config!$C$10="L",IF(Raw_Data!J6<=KPI_Config!$E$10,KPI_Config!$D$10,IF(AND(KPI_Config!$F$10>0,Raw_Data!J6<=KPI_Config!$G$10),KPI_Config!$F$10,0)),IF(Raw_Data!J6>=KPI_Config!$E$10,KPI_Config!$D$10,IF(AND(KPI_Config!$F$10>0,Raw_Data!J6>=KPI_Config!$G$10),KPI_Config!$F$10,0))))) -> 0 | K6: =IF($A6="","",IF(Raw_Data!G6="",0,IF(KPI_Config!$C$11="L",IF(Raw_Data!G6<=KPI_Config!$E$11,KPI_Config!$D$11,IF(AND(KPI_Config!$F$11>0,Raw_Data!G6<=KPI_Config!$G$11),KPI_Config!$F$11,0)),IF(Raw_Data!G6>=KPI_Config!$E$11,KPI_Config!$D$11,IF(AND(KPI_Config!$F$11>0,Raw_Data!G6>=KPI_Config!$G$11),KPI_Config!$F$11,0))))) -> 0.3 | L6: =IF($A6="","",MIN(Policy_Decisions!$B$10,IF(Policy_Decisions!$B$6="Additive",SUM(E6:K6),SUM(E6:J6)-G6+MAX(G6,K6)))) -> 0.5 | M6: =IF($A6="","",Raw_Data!K6) -> 0 | N6: =IF($A6="","",IFERROR(VLOOKUP(M6,KPI_Config!$I$5:$J$10,2,FALSE()),0)) -> 0 | O6: =IF($A6="","",IF(Policy_Decisions!$B$5="Percentage points",MAX(0,L6-N6),L6*(1-N6))) -> 0.5 | P6: =IF($A6="","",IF(U6="","Review proration",IF(O6=0,"No payout",IF(N6>0,"Malus applied","Eligible")))) -> Eligible | Q6: =IF($A6="","",Raw_Data!M6) -> MAD | R6: =IF($A6="","",Raw_Data!N6) -> 0 | S6: =IF($A6="","",Raw_Data!O6) -> 0 | T6: =IF($A6="","",IF(Raw_Data!P6>0,Raw_Data!P6,Raw_Data!N6*Raw_Data!O6/IF(Policy_Decisions!$B$7="Annual",12,1))) -> 2000 | U6: =IF($A6="","",IF(OR(Raw_Data!R6="",Raw_Data!R6<=0),"",MIN(1,MAX(0,Raw_Data!Q6/Raw_Data!R6)))) -> 1 | V6: =IF(OR($A6="",U6=""),"",T6*U6) -> 2000 | W6: =IF(OR($A6="",V6=""),"",V6*L6) -> 1000 | X6: =IF(OR($A6="",V6=""),"",V6*L6-V6*O6) -> 0 | Y6: =IF(OR($A6="",V6=""),"",ROUND(V6*O6,IF(Policy_Decisions!$B$11="Whole MAD",0,2))) -> 1000 | Z6: =Raw_Data!T6 -> Grouh Jaouad | AA6: =Raw_Data!U6 -> Anas OUAKKAD
A7: =IF(Raw_Data!A7="","",Raw_Data!A7) -> 204343 | B7: =IF(Raw_Data!B7="","",Raw_Data!B7) -> Talhajit Abdellah | C7: =IF(Raw_Data!C7="","",Raw_Data!C7) -> Ford GER | D7: =IF(Raw_Data!D7="","",Raw_Data!D7) -> 2026-07 | E7: =IF($A7="","",IF(Raw_Data!E7="",0,IF(KPI_Config!$C$5="L",IF(Raw_Data!E7<=KPI_Config!$E$5,KPI_Config!$D$5,IF(AND(KPI_Config!$F$5>0,Raw_Data!E7<=KPI_Config!$G$5),KPI_Config!$F$5,0)),IF(Raw_Data!E7>=KPI_Config!$E$5,KPI_Config!$D$5,IF(AND(KPI_Config!$F$5>0,Raw_Data!E7>=KPI_Config!$G$5),KPI_Config!$F$5,0))))) -> 0 | F7: =IF($A7="","",IF(Raw_Data!F7="",0,IF(KPI_Config!$C$6="L",IF(Raw_Data!F7<=KPI_Config!$E$6,KPI_Config!$D$6,IF(AND(KPI_Config!$F$6>0,Raw_Data!F7<=KPI_Config!$G$6),KPI_Config!$F$6,0)),IF(Raw_Data!F7>=KPI_Config!$E$6,KPI_Config!$D$6,IF(AND(KPI_Config!$F$6>0,Raw_Data!F7>=KPI_Config!$G$6),KPI_Config!$F$6,0))))) -> 0 | G7: =IF($A7="","",IF(Raw_Data!G7="",0,IF(KPI_Config!$C$7="L",IF(Raw_Data!G7<=KPI_Config!$E$7,KPI_Config!$D$7,IF(AND(KPI_Config!$F$7>0,Raw_Data!G7<=KPI_Config!$G$7),KPI_Config!$F$7,0)),IF(Raw_Data!G7>=KPI_Config!$E$7,KPI_Config!$D$7,IF(AND(KPI_Config!$F$7>0,Raw_Data!G7>=KPI_Config!$G$7),KPI_Config!$F$7,0))))) -> 0 | H7: =IF($A7="","",IF(Raw_Data!H7="",0,IF(KPI_Config!$C$8="L",IF(Raw_Data!H7<=KPI_Config!$E$8,KPI_Config!$D$8,IF(AND(KPI_Config!$F$8>0,Raw_Data!H7<=KPI_Config!$G$8),KPI_Config!$F$8,0)),IF(Raw_Data!H7>=KPI_Config!$E$8,KPI_Config!$D$8,IF(AND(KPI_Config!$F$8>0,Raw_Data!H7>=KPI_Config!$G$8),KPI_Config!$F$8,0))))) -> 0 | I7: =IF($A7="","",IF(Raw_Data!I7="",0,IF(KPI_Config!$C$9="L",IF(Raw_Data!I7<=KPI_Config!$E$9,KPI_Config!$D$9,IF(AND(KPI_Config!$F$9>0,Raw_Data!I7<=KPI_Config!$G$9),KPI_Config!$F$9,0)),IF(Raw_Data!I7>=KPI_Config!$E$9,KPI_Config!$D$9,IF(AND(KPI_Config!$F$9>0,Raw_Data!I7>=KPI_Config!$G$9),KPI_Config!$F$9,0))))) -> 0 | J7: =IF($A7="","",IF(Raw_Data!J7="",0,IF(KPI_Config!$C$10="L",IF(Raw_Data!J7<=KPI_Config!$E$10,KPI_Config!$D$10,IF(AND(KPI_Config!$F$10>0,Raw_Data!J7<=KPI_Config!$G$10),KPI_Config!$F$10,0)),IF(Raw_Data!J7>=KPI_Config!$E$10,KPI_Config!$D$10,IF(AND(KPI_Config!$F$10>0,Raw_Data!J7>=KPI_Config!$G$10),KPI_Config!$F$10,0))))) -> 0 | K7: =IF($A7="","",IF(Raw_Data!G7="",0,IF(KPI_Config!$C$11="L",IF(Raw_Data!G7<=KPI_Config!$E$11,KPI_Config!$D$11,IF(AND(KPI_Config!$F$11>0,Raw_Data!G7<=KPI_Config!$G$11),KPI_Config!$F$11,0)),IF(Raw_Data!G7>=KPI_Config!$E$11,KPI_Config!$D$11,IF(AND(KPI_Config!$F$11>0,Raw_Data!G7>=KPI_Config!$G$11),KPI_Config!$F$11,0))))) -> 0 | L7: =IF($A7="","",MIN(Policy_Decisions!$B$10,IF(Policy_Decisions!$B$6="Additive",SUM(E7:K7),SUM(E7:J7)-G7+MAX(G7,K7)))) -> 0 | M7: =IF($A7="","",Raw_Data!K7) -> 0 | N7: =IF($A7="","",IFERROR(VLOOKUP(M7,KPI_Config!$I$5:$J$10,2,FALSE()),0)) -> 0 | O7: =IF($A7="","",IF(Policy_Decisions!$B$5="Percentage points",MAX(0,L7-N7),L7*(1-N7))) -> 0 | P7: =IF($A7="","",IF(U7="","Review proration",IF(O7=0,"No payout",IF(N7>0,"Malus applied","Eligible")))) -> No payout | Q7: =IF($A7="","",Raw_Data!M7) -> MAD | R7: =IF($A7="","",Raw_Data!N7) -> 0 | S7: =IF($A7="","",Raw_Data!O7) -> 0 | T7: =IF($A7="","",IF(Raw_Data!P7>0,Raw_Data!P7,Raw_Data!N7*Raw_Data!O7/IF(Policy_Decisions!$B$7="Annual",12,1))) -> 2000 | U7: =IF($A7="","",IF(OR(Raw_Data!R7="",Raw_Data!R7<=0),"",MIN(1,MAX(0,Raw_Data!Q7/Raw_Data!R7)))) -> 1 | V7: =IF(OR($A7="",U7=""),"",T7*U7) -> 2000 | W7: =IF(OR($A7="",V7=""),"",V7*L7) -> 0 | X7: =IF(OR($A7="",V7=""),"",V7*L7-V7*O7) -> 0 | Y7: =IF(OR($A7="",V7=""),"",ROUND(V7*O7,IF(Policy_Decisions!$B$11="Whole MAD",0,2))) -> 0 | Z7: =Raw_Data!T7 -> Grouh Jaouad | AA7: =Raw_Data!U7 -> Anas OUAKKAD
A8: =IF(Raw_Data!A8="","",Raw_Data!A8) -> 204344 | B8: =IF(Raw_Data!B8="","",Raw_Data!B8) -> AYMAZ Abdelhay | C8: =IF(Raw_Data!C8="","",Raw_Data!C8) -> Ford GER | D8: =IF(Raw_Data!D8="","",Raw_Data!D8) -> 2026-07 | E8: =IF($A8="","",IF(Raw_Data!E8="",0,IF(KPI_Config!$C$5="L",IF(Raw_Data!E8<=KPI_Config!$E$5,KPI_Config!$D$5,IF(AND(KPI_Config!$F$5>0,Raw_Data!E8<=KPI_Config!$G$5),KPI_Config!$F$5,0)),IF(Raw_Data!E8>=KPI_Config!$E$5,KPI_Config!$D$5,IF(AND(KPI_Config!$F$5>0,Raw_Data!E8>=KPI_Config!$G$5),KPI_Config!$F$5,0))))) -> 0 | F8: =IF($A8="","",IF(Raw_Data!F8="",0,IF(KPI_Config!$C$6="L",IF(Raw_Data!F8<=KPI_Config!$E$6,KPI_Config!$D$6,IF(AND(KPI_Config!$F$6>0,Raw_Data!F8<=KPI_Config!$G$6),KPI_Config!$F$6,0)),IF(Raw_Data!F8>=KPI_Config!$E$6,KPI_Config!$D$6,IF(AND(KPI_Config!$F$6>0,Raw_Data!F8>=KPI_Config!$G$6),KPI_Config!$F$6,0))))) -> 0 | G8: =IF($A8="","",IF(Raw_Data!G8="",0,IF(KPI_Config!$C$7="L",IF(Raw_Data!G8<=KPI_Config!$E$7,KPI_Config!$D$7,IF(AND(KPI_Config!$F$7>0,Raw_Data!G8<=KPI_Config!$G$7),KPI_Config!$F$7,0)),IF(Raw_Data!G8>=KPI_Config!$E$7,KPI_Config!$D$7,IF(AND(KPI_Config!$F$7>0,Raw_Data!G8>=KPI_Config!$G$7),KPI_Config!$F$7,0))))) -> 0.2 | H8: =IF($A8="","",IF(Raw_Data!H8="",0,IF(KPI_Config!$C$8="L",IF(Raw_Data!H8<=KPI_Config!$E$8,KPI_Config!$D$8,IF(AND(KPI_Config!$F$8>0,Raw_Data!H8<=KPI_Config!$G$8),KPI_Config!$F$8,0)),IF(Raw_Data!H8>=KPI_Config!$E$8,KPI_Config!$D$8,IF(AND(KPI_Config!$F$8>0,Raw_Data!H8>=KPI_Config!$G$8),KPI_Config!$F$8,0))))) -> 0 | I8: =IF($A8="","",IF(Raw_Data!I8="",0,IF(KPI_Config!$C$9="L",IF(Raw_Data!I8<=KPI_Config!$E$9,KPI_Config!$D$9,IF(AND(KPI_Config!$F$9>0,Raw_Data!I8<=KPI_Config!$G$9),KPI_Config!$F$9,0)),IF(Raw_Data!I8>=KPI_Config!$E$9,KPI_Config!$D$9,IF(AND(KPI_Config!$F$9>0,Raw_Data!I8>=KPI_Config!$G$9),KPI_Config!$F$9,0))))) -> 0 | J8: =IF($A8="","",IF(Raw_Data!J8="",0,IF(KPI_Config!$C$10="L",IF(Raw_Data!J8<=KPI_Config!$E$10,KPI_Config!$D$10,IF(AND(KPI_Config!$F$10>0,Raw_Data!J8<=KPI_Config!$G$10),KPI_Config!$F$10,0)),IF(Raw_Data!J8>=KPI_Config!$E$10,KPI_Config!$D$10,IF(AND(KPI_Config!$F$10>0,Raw_Data!J8>=KPI_Config!$G$10),KPI_Config!$F$10,0))))) -> 0 | K8: =IF($A8="","",IF(Raw_Data!G8="",0,IF(KPI_Config!$C$11="L",IF(Raw_Data!G8<=KPI_Config!$E$11,KPI_Config!$D$11,IF(AND(KPI_Config!$F$11>0,Raw_Data!G8<=KPI_Config!$G$11),KPI_Config!$F$11,0)),IF(Raw_Data!G8>=KPI_Config!$E$11,KPI_Config!$D$11,IF(AND(KPI_Config!$F$11>0,Raw_Data!G8>=KPI_Config!$G$11),KPI_Config!$F$11,0))))) -> 0.3 | L8: =IF($A8="","",MIN(Policy_Decisions!$B$10,IF(Policy_Decisions!$B$6="Additive",SUM(E8:K8),SUM(E8:J8)-G8+MAX(G8,K8)))) -> 0.5 | M8: =IF($A8="","",Raw_Data!K8) -> 0 | N8: =IF($A8="","",IFERROR(VLOOKUP(M8,KPI_Config!$I$5:$J$10,2,FALSE()),0)) -> 0 | O8: =IF($A8="","",IF(Policy_Decisions!$B$5="Percentage points",MAX(0,L8-N8),L8*(1-N8))) -> 0.5 | P8: =IF($A8="","",IF(U8="","Review proration",IF(O8=0,"No payout",IF(N8>0,"Malus applied","Eligible")))) -> Eligible | Q8: =IF($A8="","",Raw_Data!M8) -> MAD | R8: =IF($A8="","",Raw_Data!N8) -> 0 | S8: =IF($A8="","",Raw_Data!O8) -> 0 | T8: =IF($A8="","",IF(Raw_Data!P8>0,Raw_Data!P8,Raw_Data!N8*Raw_Data!O8/IF(Policy_Decisions!$B$7="Annual",12,1))) -> 2000 | U8: =IF($A8="","",IF(OR(Raw_Data!R8="",Raw_Data!R8<=0),"",MIN(1,MAX(0,Raw_Data!Q8/Raw_Data!R8)))) -> 1 | V8: =IF(OR($A8="",U8=""),"",T8*U8) -> 2000 | W8: =IF(OR($A8="",V8=""),"",V8*L8) -> 1000 | X8: =IF(OR($A8="",V8=""),"",V8*L8-V8*O8) -> 0 | Y8: =IF(OR($A8="",V8=""),"",ROUND(V8*O8,IF(Policy_Decisions!$B$11="Whole MAD",0,2))) -> 1000 | Z8: =Raw_Data!T8 -> Grouh Jaouad | AA8: =Raw_Data!U8 -> Anas OUAKKAD
A9: =IF(Raw_Data!A9="","",Raw_Data!A9) -> 204345 | B9: =IF(Raw_Data!B9="","",Raw_Data!B9) -> MOUSSA Amjad | C9: =IF(Raw_Data!C9="","",Raw_Data!C9) -> Ford GER | D9: =IF(Raw_Data!D9="","",Raw_Data!D9) -> 2026-07 | E9: =IF($A9="","",IF(Raw_Data!E9="",0,IF(KPI_Config!$C$5="L",IF(Raw_Data!E9<=KPI_Config!$E$5,KPI_Config!$D$5,IF(AND(KPI_Config!$F$5>0,Raw_Data!E9<=KPI_Config!$G$5),KPI_Config!$F$5,0)),IF(Raw_Data!E9>=KPI_Config!$E$5,KPI_Config!$D$5,IF(AND(KPI_Config!$F$5>0,Raw_Data!E9>=KPI_Config!$G$5),KPI_Config!$F$5,0))))) -> 0 | F9: =IF($A9="","",IF(Raw_Data!F9="",0,IF(KPI_Config!$C$6="L",IF(Raw_Data!F9<=KPI_Config!$E$6,KPI_Config!$D$6,IF(AND(KPI_Config!$F$6>0,Raw_Data!F9<=KPI_Config!$G$6),KPI_Config!$F$6,0)),IF(Raw_Data!F9>=KPI_Config!$E$6,KPI_Config!$D$6,IF(AND(KPI_Config!$F$6>0,Raw_Data!F9>=KPI_Config!$G$6),KPI_Config!$F$6,0))))) -> 0 | G9: =IF($A9="","",IF(Raw_Data!G9="",0,IF(KPI_Config!$C$7="L",IF(Raw_Data!G9<=KPI_Config!$E$7,KPI_Config!$D$7,IF(AND(KPI_Config!$F$7>0,Raw_Data!G9<=KPI_Config!$G$7),KPI_Config!$F$7,0)),IF(Raw_Data!G9>=KPI_Config!$E$7,KPI_Config!$D$7,IF(AND(KPI_Config!$F$7>0,Raw_Data!G9>=KPI_Config!$G$7),KPI_Config!$F$7,0))))) -> 0 | H9: =IF($A9="","",IF(Raw_Data!H9="",0,IF(KPI_Config!$C$8="L",IF(Raw_Data!H9<=KPI_Config!$E$8,KPI_Config!$D$8,IF(AND(KPI_Config!$F$8>0,Raw_Data!H9<=KPI_Config!$G$8),KPI_Config!$F$8,0)),IF(Raw_Data!H9>=KPI_Config!$E$8,KPI_Config!$D$8,IF(AND(KPI_Config!$F$8>0,Raw_Data!H9>=KPI_Config!$G$8),KPI_Config!$F$8,0))))) -> 0 | I9: =IF($A9="","",IF(Raw_Data!I9="",0,IF(KPI_Config!$C$9="L",IF(Raw_Data!I9<=KPI_Config!$E$9,KPI_Config!$D$9,IF(AND(KPI_Config!$F$9>0,Raw_Data!I9<=KPI_Config!$G$9),KPI_Config!$F$9,0)),IF(Raw_Data!I9>=KPI_Config!$E$9,KPI_Config!$D$9,IF(AND(KPI_Config!$F$9>0,Raw_Data!I9>=KPI_Config!$G$9),KPI_Config!$F$9,0))))) -> 0 | J9: =IF($A9="","",IF(Raw_Data!J9="",0,IF(KPI_Config!$C$10="L",IF(Raw_Data!J9<=KPI_Config!$E$10,KPI_Config!$D$10,IF(AND(KPI_Config!$F$10>0,Raw_Data!J9<=KPI_Config!$G$10),KPI_Config!$F$10,0)),IF(Raw_Data!J9>=KPI_Config!$E$10,KPI_Config!$D$10,IF(AND(KPI_Config!$F$10>0,Raw_Data!J9>=KPI_Config!$G$10),KPI_Config!$F$10,0))))) -> 0 | K9: =IF($A9="","",IF(Raw_Data!G9="",0,IF(KPI_Config!$C$11="L",IF(Raw_Data!G9<=KPI_Config!$E$11,KPI_Config!$D$11,IF(AND(KPI_Config!$F$11>0,Raw_Data!G9<=KPI_Config!$G$11),KPI_Config!$F$11,0)),IF(Raw_Data!G9>=KPI_Config!$E$11,KPI_Config!$D$11,IF(AND(KPI_Config!$F$11>0,Raw_Data!G9>=KPI_Config!$G$11),KPI_Config!$F$11,0))))) -> 0 | L9: =IF($A9="","",MIN(Policy_Decisions!$B$10,IF(Policy_Decisions!$B$6="Additive",SUM(E9:K9),SUM(E9:J9)-G9+MAX(G9,K9)))) -> 0 | M9: =IF($A9="","",Raw_Data!K9) -> 0 | N9: =IF($A9="","",IFERROR(VLOOKUP(M9,KPI_Config!$I$5:$J$10,2,FALSE()),0)) -> 0 | O9: =IF($A9="","",IF(Policy_Decisions!$B$5="Percentage points",MAX(0,L9-N9),L9*(1-N9))) -> 0 | P9: =IF($A9="","",IF(U9="","Review proration",IF(O9=0,"No payout",IF(N9>0,"Malus applied","Eligible")))) -> No payout | Q9: =IF($A9="","",Raw_Data!M9) -> MAD | R9: =IF($A9="","",Raw_Data!N9) -> 0 | S9: =IF($A9="","",Raw_Data!O9) -> 0 | T9: =IF($A9="","",IF(Raw_Data!P9>0,Raw_Data!P9,Raw_Data!N9*Raw_Data!O9/IF(Policy_Decisions!$B$7="Annual",12,1))) -> 2000 | U9: =IF($A9="","",IF(OR(Raw_Data!R9="",Raw_Data!R9<=0),"",MIN(1,MAX(0,Raw_Data!Q9/Raw_Data!R9)))) -> 1 | V9: =IF(OR($A9="",U9=""),"",T9*U9) -> 2000 | W9: =IF(OR($A9="",V9=""),"",V9*L9) -> 0 | X9: =IF(OR($A9="",V9=""),"",V9*L9-V9*O9) -> 0 | Y9: =IF(OR($A9="",V9=""),"",ROUND(V9*O9,IF(Policy_Decisions!$B$11="Whole MAD",0,2))) -> 0 | Z9: =Raw_Data!T9 -> Grouh Jaouad | AA9: =Raw_Data!U9 -> Anas OUAKKAD
A10: =IF(Raw_Data!A10="","",Raw_Data!A10) -> 204602 | B10: =IF(Raw_Data!B10="","",Raw_Data!B10) -> DRISSI Sidi Youssef | C10: =IF(Raw_Data!C10="","",Raw_Data!C10) -> Ford GER | D10: =IF(Raw_Data!D10="","",Raw_Data!D10) -> 2026-07 | E10: =IF($A10="","",IF(Raw_Data!E10="",0,IF(KPI_Config!$C$5="L",IF(Raw_Data!E10<=KPI_Config!$E$5,KPI_Config!$D$5,IF(AND(KPI_Config!$F$5>0,Raw_Data!E10<=KPI_Config!$G$5),KPI_Config!$F$5,0)),IF(Raw_Data!E10>=KPI_Config!$E$5,KPI_Config!$D$5,IF(AND(KPI_Config!$F$5>0,Raw_Data!E10>=KPI_Config!$G$5),KPI_Config!$F$5,0))))) -> 0 | F10: =IF($A10="","",IF(Raw_Data!F10="",0,IF(KPI_Config!$C$6="L",IF(Raw_Data!F10<=KPI_Config!$E$6,KPI_Config!$D$6,IF(AND(KPI_Config!$F$6>0,Raw_Data!F10<=KPI_Config!$G$6),KPI_Config!$F$6,0)),IF(Raw_Data!F10>=KPI_Config!$E$6,KPI_Config!$D$6,IF(AND(KPI_Config!$F$6>0,Raw_Data!F10>=KPI_Config!$G$6),KPI_Config!$F$6,0))))) -> 0 | G10: =IF($A10="","",IF(Raw_Data!G10="",0,IF(KPI_Config!$C$7="L",IF(Raw_Data!G10<=KPI_Config!$E$7,KPI_Config!$D$7,IF(AND(KPI_Config!$F$7>0,Raw_Data!G10<=KPI_Config!$G$7),KPI_Config!$F$7,0)),IF(Raw_Data!G10>=KPI_Config!$E$7,KPI_Config!$D$7,IF(AND(KPI_Config!$F$7>0,Raw_Data!G10>=KPI_Config!$G$7),KPI_Config!$F$7,0))))) -> 0 | H10: =IF($A10="","",IF(Raw_Data!H10="",0,IF(KPI_Config!$C$8="L",IF(Raw_Data!H10<=KPI_Config!$E$8,KPI_Config!$D$8,IF(AND(KPI_Config!$F$8>0,Raw_Data!H10<=KPI_Config!$G$8),KPI_Config!$F$8,0)),IF(Raw_Data!H10>=KPI_Config!$E$8,KPI_Config!$D$8,IF(AND(KPI_Config!$F$8>0,Raw_Data!H10>=KPI_Config!$G$8),KPI_Config!$F$8,0))))) -> 0 | I10: =IF($A10="","",IF(Raw_Data!I10="",0,IF(KPI_Config!$C$9="L",IF(Raw_Data!I10<=KPI_Config!$E$9,KPI_Config!$D$9,IF(AND(KPI_Config!$F$9>0,Raw_Data!I10<=KPI_Config!$G$9),KPI_Config!$F$9,0)),IF(Raw_Data!I10>=KPI_Config!$E$9,KPI_Config!$D$9,IF(AND(KPI_Config!$F$9>0,Raw_Data!I10>=KPI_Config!$G$9),KPI_Config!$F$9,0))))) -> 0 | J10: =IF($A10="","",IF(Raw_Data!J10="",0,IF(KPI_Config!$C$10="L",IF(Raw_Data!J10<=KPI_Config!$E$10,KPI_Config!$D$10,IF(AND(KPI_Config!$F$10>0,Raw_Data!J10<=KPI_Config!$G$10),KPI_Config!$F$10,0)),IF(Raw_Data!J10>=KPI_Config!$E$10,KPI_Config!$D$10,IF(AND(KPI_Config!$F$10>0,Raw_Data!J10>=KPI_Config!$G$10),KPI_Config!$F$10,0))))) -> 0 | K10: =IF($A10="","",IF(Raw_Data!G10="",0,IF(KPI_Config!$C$11="L",IF(Raw_Data!G10<=KPI_Config!$E$11,KPI_Config!$D$11,IF(AND(KPI_Config!$F$11>0,Raw_Data!G10<=KPI_Config!$G$11),KPI_Config!$F$11,0)),IF(Raw_Data!G10>=KPI_Config!$E$11,KPI_Config!$D$11,IF(AND(KPI_Config!$F$11>0,Raw_Data!G10>=KPI_Config!$G$11),KPI_Config!$F$11,0))))) -> 0 | L10: =IF($A10="","",MIN(Policy_Decisions!$B$10,IF(Policy_Decisions!$B$6="Additive",SUM(E10:K10),SUM(E10:J10)-G10+MAX(G10,K10)))) -> 0 | M10: =IF($A10="","",Raw_Data!K10) -> 0 | N10: =IF($A10="","",IFERROR(VLOOKUP(M10,KPI_Config!$I$5:$J$10,2,FALSE()),0)) -> 0 | O10: =IF($A10="","",IF(Policy_Decisions!$B$5="Percentage points",MAX(0,L10-N10),L10*(1-N10))) -> 0 | P10: =IF($A10="","",IF(U10="","Review proration",IF(O10=0,"No payout",IF(N10>0,"Malus applied","Eligible")))) -> No payout | Q10: =IF($A10="","",Raw_Data!M10) -> MAD | R10: =IF($A10="","",Raw_Data!N10) -> 0 | S10: =IF($A10="","",Raw_Data!O10) -> 0 | T10: =IF($A10="","",IF(Raw_Data!P10>0,Raw_Data!P10,Raw_Data!N10*Raw_Data!O10/IF(Policy_Decisions!$B$7="Annual",12,1))) -> 2000 | U10: =IF($A10="","",IF(OR(Raw_Data!R10="",Raw_Data!R10<=0),"",MIN(1,MAX(0,Raw_Data!Q10/Raw_Data!R10)))) -> 1 | V10: =IF(OR($A10="",U10=""),"",T10*U10) -> 2000 | W10: =IF(OR($A10="",V10=""),"",V10*L10) -> 0 | X10: =IF(OR($A10="",V10=""),"",V10*L10-V10*O10) -> 0 | Y10: =IF(OR($A10="",V10=""),"",ROUND(V10*O10,IF(Policy_Decisions!$B$11="Whole MAD",0,2))) -> 0 | Z10: =Raw_Data!T10 -> Grouh Jaouad | AA10: =Raw_Data!U10 -> Anas OUAKKAD
A11: =IF(Raw_Data!A11="","",Raw_Data!A11) -> 204349 | B11: =IF(Raw_Data!B11="","",Raw_Data!B11) -> NABACH Lara | C11: =IF(Raw_Data!C11="","",Raw_Data!C11) -> Ford GER | D11: =IF(Raw_Data!D11="","",Raw_Data!D11) -> 2026-07 | E11: =IF($A11="","",IF(Raw_Data!E11="",0,IF(KPI_Config!$C$5="L",IF(Raw_Data!E11<=KPI_Config!$E$5,KPI_Config!$D$5,IF(AND(KPI_Config!$F$5>0,Raw_Data!E11<=KPI_Config!$G$5),KPI_Config!$F$5,0)),IF(Raw_Data!E11>=KPI_Config!$E$5,KPI_Config!$D$5,IF(AND(KPI_Config!$F$5>0,Raw_Data!E11>=KPI_Config!$G$5),KPI_Config!$F$5,0))))) -> 0 | F11: =IF($A11="","",IF(Raw_Data!F11="",0,IF(KPI_Config!$C$6="L",IF(Raw_Data!F11<=KPI_Config!$E$6,KPI_Config!$D$6,IF(AND(KPI_Config!$F$6>0,Raw_Data!F11<=KPI_Config!$G$6),KPI_Config!$F$6,0)),IF(Raw_Data!F11>=KPI_Config!$E$6,KPI_Config!$D$6,IF(AND(KPI_Config!$F$6>0,Raw_Data!F11>=KPI_Config!$G$6),KPI_Config!$F$6,0))))) -> 0.15 | G11: =IF($A11="","",IF(Raw_Data!G11="",0,IF(KPI_Config!$C$7="L",IF(Raw_Data!G11<=KPI_Config!$E$7,KPI_Config!$D$7,IF(AND(KPI_Config!$F$7>0,Raw_Data!G11<=KPI_Config!$G$7),KPI_Config!$F$7,0)),IF(Raw_Data!G11>=KPI_Config!$E$7,KPI_Config!$D$7,IF(AND(KPI_Config!$F$7>0,Raw_Data!G11>=KPI_Config!$G$7),KPI_Config!$F$7,0))))) -> 0.15 | H11: =IF($A11="","",IF(Raw_Data!H11="",0,IF(KPI_Config!$C$8="L",IF(Raw_Data!H11<=KPI_Config!$E$8,KPI_Config!$D$8,IF(AND(KPI_Config!$F$8>0,Raw_Data!H11<=KPI_Config!$G$8),KPI_Config!$F$8,0)),IF(Raw_Data!H11>=KPI_Config!$E$8,KPI_Config!$D$8,IF(AND(KPI_Config!$F$8>0,Raw_Data!H11>=KPI_Config!$G$8),KPI_Config!$F$8,0))))) -> 0 | I11: =IF($A11="","",IF(Raw_Data!I11="",0,IF(KPI_Config!$C$9="L",IF(Raw_Data!I11<=KPI_Config!$E$9,KPI_Config!$D$9,IF(AND(KPI_Config!$F$9>0,Raw_Data!I11<=KPI_Config!$G$9),KPI_Config!$F$9,0)),IF(Raw_Data!I11>=KPI_Config!$E$9,KPI_Config!$D$9,IF(AND(KPI_Config!$F$9>0,Raw_Data!I11>=KPI_Config!$G$9),KPI_Config!$F$9,0))))) -> 0 | J11: =IF($A11="","",IF(Raw_Data!J11="",0,IF(KPI_Config!$C$10="L",IF(Raw_Data!J11<=KPI_Config!$E$10,KPI_Config!$D$10,IF(AND(KPI_Config!$F$10>0,Raw_Data!J11<=KPI_Config!$G$10),KPI_Config!$F$10,0)),IF(Raw_Data!J11>=KPI_Config!$E$10,KPI_Config!$D$10,IF(AND(KPI_Config!$F$10>0,Raw_Data!J11>=KPI_Config!$G$10),KPI_Config!$F$10,0))))) -> 0 | K11: =IF($A11="","",IF(Raw_Data!G11="",0,IF(KPI_Config!$C$11="L",IF(Raw_Data!G11<=KPI_Config!$E$11,KPI_Config!$D$11,IF(AND(KPI_Config!$F$11>0,Raw_Data!G11<=KPI_Config!$G$11),KPI_Config!$F$11,0)),IF(Raw_Data!G11>=KPI_Config!$E$11,KPI_Config!$D$11,IF(AND(KPI_Config!$F$11>0,Raw_Data!G11>=KPI_Config!$G$11),KPI_Config!$F$11,0))))) -> 0 | L11: =IF($A11="","",MIN(Policy_Decisions!$B$10,IF(Policy_Decisions!$B$6="Additive",SUM(E11:K11),SUM(E11:J11)-G11+MAX(G11,K11)))) -> 0.3 | M11: =IF($A11="","",Raw_Data!K11) -> 0 | N11: =IF($A11="","",IFERROR(VLOOKUP(M11,KPI_Config!$I$5:$J$10,2,FALSE()),0)) -> 0 | O11: =IF($A11="","",IF(Policy_Decisions!$B$5="Percentage points",MAX(0,L11-N11),L11*(1-N11))) -> 0.3 | P11: =IF($A11="","",IF(U11="","Review proration",IF(O11=0,"No payout",IF(N11>0,"Malus applied","Eligible")))) -> Eligible | Q11: =IF($A11="","",Raw_Data!M11) -> MAD | R11: =IF($A11="","",Raw_Data!N11) -> 0 | S11: =IF($A11="","",Raw_Data!O11) -> 0 | T11: =IF($A11="","",IF(Raw_Data!P11>0,Raw_Data!P11,Raw_Data!N11*Raw_Data!O11/IF(Policy_Decisions!$B$7="Annual",12,1))) -> 2000 | U11: =IF($A11="","",IF(OR(Raw_Data!R11="",Raw_Data!R11<=0),"",MIN(1,MAX(0,Raw_Data!Q11/Raw_Data!R11)))) -> 1 | V11: =IF(OR($A11="",U11=""),"",T11*U11) -> 2000 | W11: =IF(OR($A11="",V11=""),"",V11*L11) -> 600 | X11: =IF(OR($A11="",V11=""),"",V11*L11-V11*O11) -> 0 | Y11: =IF(OR($A11="",V11=""),"",ROUND(V11*O11,IF(Policy_Decisions!$B$11="Whole MAD",0,2))) -> 600 | Z11: =Raw_Data!T11 -> Grouh Jaouad | AA11: =Raw_Data!U11 -> Anas OUAKKAD
A12: =IF(Raw_Data!A12="","",Raw_Data!A12) -> 228205 | B12: =IF(Raw_Data!B12="","",Raw_Data!B12) -> Mohamed Amine MERSAK | C12: =IF(Raw_Data!C12="","",Raw_Data!C12) -> OEM FR | D12: =IF(Raw_Data!D12="","",Raw_Data!D12) -> 2026-07 | E12: =IF($A12="","",IF(Raw_Data!E12="",0,IF(KPI_Config!$C$5="L",IF(Raw_Data!E12<=KPI_Config!$E$5,KPI_Config!$D$5,IF(AND(KPI_Config!$F$5>0,Raw_Data!E12<=KPI_Config!$G$5),KPI_Config!$F$5,0)),IF(Raw_Data!E12>=KPI_Config!$E$5,KPI_Config!$D$5,IF(AND(KPI_Config!$F$5>0,Raw_Data!E12>=KPI_Config!$G$5),KPI_Config!$F$5,0))))) -> 0.15 | F12: =IF($A12="","",IF(Raw_Data!F12="",0,IF(KPI_Config!$C$6="L",IF(Raw_Data!F12<=KPI_Config!$E$6,KPI_Config!$D$6,IF(AND(KPI_Config!$F$6>0,Raw_Data!F12<=KPI_Config!$G$6),KPI_Config!$F$6,0)),IF(Raw_Data!F12>=KPI_Config!$E$6,KPI_Config!$D$6,IF(AND(KPI_Config!$F$6>0,Raw_Data!F12>=KPI_Config!$G$6),KPI_Config!$F$6,0))))) -> 0.15 | G12: =IF($A12="","",IF(Raw_Data!G12="",0,IF(KPI_Config!$C$7="L",IF(Raw_Data!G12<=KPI_Config!$E$7,KPI_Config!$D$7,IF(AND(KPI_Config!$F$7>0,Raw_Data!G12<=KPI_Config!$G$7),KPI_Config!$F$7,0)),IF(Raw_Data!G12>=KPI_Config!$E$7,KPI_Config!$D$7,IF(AND(KPI_Config!$F$7>0,Raw_Data!G12>=KPI_Config!$G$7),KPI_Config!$F$7,0))))) -> 0.2 | H12: =IF($A12="","",IF(Raw_Data!H12="",0,IF(KPI_Config!$C$8="L",IF(Raw_Data!H12<=KPI_Config!$E$8,KPI_Config!$D$8,IF(AND(KPI_Config!$F$8>0,Raw_Data!H12<=KPI_Config!$G$8),KPI_Config!$F$8,0)),IF(Raw_Data!H12>=KPI_Config!$E$8,KPI_Config!$D$8,IF(AND(KPI_Config!$F$8>0,Raw_Data!H12>=KPI_Config!$G$8),KPI_Config!$F$8,0))))) -> 0 | I12: =IF($A12="","",IF(Raw_Data!I12="",0,IF(KPI_Config!$C$9="L",IF(Raw_Data!I12<=KPI_Config!$E$9,KPI_Config!$D$9,IF(AND(KPI_Config!$F$9>0,Raw_Data!I12<=KPI_Config!$G$9),KPI_Config!$F$9,0)),IF(Raw_Data!I12>=KPI_Config!$E$9,KPI_Config!$D$9,IF(AND(KPI_Config!$F$9>0,Raw_Data!I12>=KPI_Config!$G$9),KPI_Config!$F$9,0))))) -> 0 | J12: =IF($A12="","",IF(Raw_Data!J12="",0,IF(KPI_Config!$C$10="L",IF(Raw_Data!J12<=KPI_Config!$E$10,KPI_Config!$D$10,IF(AND(KPI_Config!$F$10>0,Raw_Data!J12<=KPI_Config!$G$10),KPI_Config!$F$10,0)),IF(Raw_Data!J12>=KPI_Config!$E$10,KPI_Config!$D$10,IF(AND(KPI_Config!$F$10>0,Raw_Data!J12>=KPI_Config!$G$10),KPI_Config!$F$10,0))))) -> 0 | K12: =IF($A12="","",IF(Raw_Data!G12="",0,IF(KPI_Config!$C$11="L",IF(Raw_Data!G12<=KPI_Config!$E$11,KPI_Config!$D$11,IF(AND(KPI_Config!$F$11>0,Raw_Data!G12<=KPI_Config!$G$11),KPI_Config!$F$11,0)),IF(Raw_Data!G12>=KPI_Config!$E$11,KPI_Config!$D$11,IF(AND(KPI_Config!$F$11>0,Raw_Data!G12>=KPI_Config!$G$11),KPI_Config!$F$11,0))))) -> 0.3 | L12: =IF($A12="","",MIN(Policy_Decisions!$B$10,IF(Policy_Decisions!$B$6="Additive",SUM(E12:K12),SUM(E12:J12)-G12+MAX(G12,K12)))) -> 0.8 | M12: =IF($A12="","",Raw_Data!K12) -> 0 | N12: =IF($A12="","",IFERROR(VLOOKUP(M12,KPI_Config!$I$5:$J$10,2,FALSE()),0)) -> 0 | O12: =IF($A12="","",IF(Policy_Decisions!$B$5="Percentage points",MAX(0,L12-N12),L12*(1-N12))) -> 0.8 | P12: =IF($A12="","",IF(U12="","Review proration",IF(O12=0,"No payout",IF(N12>0,"Malus applied","Eligible")))) -> Eligible | Q12: =IF($A12="","",Raw_Data!M12) -> MAD | R12: =IF($A12="","",Raw_Data!N12) -> 0 | S12: =IF($A12="","",Raw_Data!O12) -> 0 | T12: =IF($A12="","",IF(Raw_Data!P12>0,Raw_Data!P12,Raw_Data!N12*Raw_Data!O12/IF(Policy_Decisions!$B$7="Annual",12,1))) -> 2000 | U12: =IF($A12="","",IF(OR(Raw_Data!R12="",Raw_Data!R12<=0),"",MIN(1,MAX(0,Raw_Data!Q12/Raw_Data!R12)))) -> 1 | V12: =IF(OR($A12="",U12=""),"",T12*U12) -> 2000 | W12: =IF(OR($A12="",V12=""),"",V12*L12) -> 1600 | X12: =IF(OR($A12="",V12=""),"",V12*L12-V12*O12) -> 0 | Y12: =IF(OR($A12="",V12=""),"",ROUND(V12*O12,IF(Policy_Decisions!$B$11="Whole MAD",0,2))) -> 1600 | Z12: =Raw_Data!T12 -> Farouk BOUAZZAOUI | AA12: =Raw_Data!U12 -> Anas OUAKKAD
A13: =IF(Raw_Data!A13="","",Raw_Data!A13) -> 204018 | B13: =IF(Raw_Data!B13="","",Raw_Data!B13) -> Mejhed Asmaa | C13: =IF(Raw_Data!C13="","",Raw_Data!C13) -> Ford Dutch | D13: =IF(Raw_Data!D13="","",Raw_Data!D13) -> 2026-07 | E13: =IF($A13="","",IF(Raw_Data!E13="",0,IF(KPI_Config!$C$5="L",IF(Raw_Data!E13<=KPI_Config!$E$5,KPI_Config!$D$5,IF(AND(KPI_Config!$F$5>0,Raw_Data!E13<=KPI_Config!$G$5),KPI_Config!$F$5,0)),IF(Raw_Data!E13>=KPI_Config!$E$5,KPI_Config!$D$5,IF(AND(KPI_Config!$F$5>0,Raw_Data!E13>=KPI_Config!$G$5),KPI_Config!$F$5,0))))) -> 0 | F13: =IF($A13="","",IF(Raw_Data!F13="",0,IF(KPI_Config!$C$6="L",IF(Raw_Data!F13<=KPI_Config!$E$6,KPI_Config!$D$6,IF(AND(KPI_Config!$F$6>0,Raw_Data!F13<=KPI_Config!$G$6),KPI_Config!$F$6,0)),IF(Raw_Data!F13>=KPI_Config!$E$6,KPI_Config!$D$6,IF(AND(KPI_Config!$F$6>0,Raw_Data!F13>=KPI_Config!$G$6),KPI_Config!$F$6,0))))) -> 0 | G13: =IF($A13="","",IF(Raw_Data!G13="",0,IF(KPI_Config!$C$7="L",IF(Raw_Data!G13<=KPI_Config!$E$7,KPI_Config!$D$7,IF(AND(KPI_Config!$F$7>0,Raw_Data!G13<=KPI_Config!$G$7),KPI_Config!$F$7,0)),IF(Raw_Data!G13>=KPI_Config!$E$7,KPI_Config!$D$7,IF(AND(KPI_Config!$F$7>0,Raw_Data!G13>=KPI_Config!$G$7),KPI_Config!$F$7,0))))) -> 0.15 | H13: =IF($A13="","",IF(Raw_Data!H13="",0,IF(KPI_Config!$C$8="L",IF(Raw_Data!H13<=KPI_Config!$E$8,KPI_Config!$D$8,IF(AND(KPI_Config!$F$8>0,Raw_Data!H13<=KPI_Config!$G$8),KPI_Config!$F$8,0)),IF(Raw_Data!H13>=KPI_Config!$E$8,KPI_Config!$D$8,IF(AND(KPI_Config!$F$8>0,Raw_Data!H13>=KPI_Config!$G$8),KPI_Config!$F$8,0))))) -> 0 | I13: =IF($A13="","",IF(Raw_Data!I13="",0,IF(KPI_Config!$C$9="L",IF(Raw_Data!I13<=KPI_Config!$E$9,KPI_Config!$D$9,IF(AND(KPI_Config!$F$9>0,Raw_Data!I13<=KPI_Config!$G$9),KPI_Config!$F$9,0)),IF(Raw_Data!I13>=KPI_Config!$E$9,KPI_Config!$D$9,IF(AND(KPI_Config!$F$9>0,Raw_Data!I13>=KPI_Config!$G$9),KPI_Config!$F$9,0))))) -> 0 | J13: =IF($A13="","",IF(Raw_Data!J13="",0,IF(KPI_Config!$C$10="L",IF(Raw_Data!J13<=KPI_Config!$E$10,KPI_Config!$D$10,IF(AND(KPI_Config!$F$10>0,Raw_Data!J13<=KPI_Config!$G$10),KPI_Config!$F$10,0)),IF(Raw_Data!J13>=KPI_Config!$E$10,KPI_Config!$D$10,IF(AND(KPI_Config!$F$10>0,Raw_Data!J13>=KPI_Config!$G$10),KPI_Config!$F$10,0))))) -> 0 | K13: =IF($A13="","",IF(Raw_Data!G13="",0,IF(KPI_Config!$C$11="L",IF(Raw_Data!G13<=KPI_Config!$E$11,KPI_Config!$D$11,IF(AND(KPI_Config!$F$11>0,Raw_Data!G13<=KPI_Config!$G$11),KPI_Config!$F$11,0)),IF(Raw_Data!G13>=KPI_Config!$E$11,KPI_Config!$D$11,IF(AND(KPI_Config!$F$11>0,Raw_Data!G13>=KPI_Config!$G$11),KPI_Config!$F$11,0))))) -> 0 | L13: =IF($A13="","",MIN(Policy_Decisions!$B$10,IF(Policy_Decisions!$B$6="Additive",SUM(E13:K13),SUM(E13:J13)-G13+MAX(G13,K13)))) -> 0.15 | M13: =IF($A13="","",Raw_Data!K13) -> 0 | N13: =IF($A13="","",IFERROR(VLOOKUP(M13,KPI_Config!$I$5:$J$10,2,FALSE()),0)) -> 0 | O13: =IF($A13="","",IF(Policy_Decisions!$B$5="Percentage points",MAX(0,L13-N13),L13*(1-N13))) -> 0.15 | P13: =IF($A13="","",IF(U13="","Review proration",IF(O13=0,"No payout",IF(N13>0,"Malus applied","Eligible")))) -> Eligible | Q13: =IF($A13="","",Raw_Data!M13) -> MAD | R13: =IF($A13="","",Raw_Data!N13) -> 0 | S13: =IF($A13="","",Raw_Data!O13) -> 0 | T13: =IF($A13="","",IF(Raw_Data!P13>0,Raw_Data!P13,Raw_Data!N13*Raw_Data!O13/IF(Policy_Decisions!$B$7="Annual",12,1))) -> 2000 | U13: =IF($A13="","",IF(OR(Raw_Data!R13="",Raw_Data!R13<=0),"",MIN(1,MAX(0,Raw_Data!Q13/Raw_Data!R13)))) -> 1 | V13: =IF(OR($A13="",U13=""),"",T13*U13) -> 2000 | W13: =IF(OR($A13="",V13=""),"",V13*L13) -> 300 | X13: =IF(OR($A13="",V13=""),"",V13*L13-V13*O13) -> 0 | Y13: =IF(OR($A13="",V13=""),"",ROUND(V13*O13,IF(Policy_Decisions!$B$11="Whole MAD",0,2))) -> 300 | Z13: =Raw_Data!T13 -> DERRAZI Ilyasse | AA13: =Raw_Data!U13 -> Anas OUAKKAD
A14: =IF(Raw_Data!A14="","",Raw_Data!A14) -> 250749 | B14: =IF(Raw_Data!B14="","",Raw_Data!B14) -> Achraf ENNAJAH | C14: =IF(Raw_Data!C14="","",Raw_Data!C14) -> OEM FR | D14: =IF(Raw_Data!D14="","",Raw_Data!D14) -> 2026-07 | E14: =IF($A14="","",IF(Raw_Data!E14="",0,IF(KPI_Config!$C$5="L",IF(Raw_Data!E14<=KPI_Config!$E$5,KPI_Config!$D$5,IF(AND(KPI_Config!$F$5>0,Raw_Data!E14<=KPI_Config!$G$5),KPI_Config!$F$5,0)),IF(Raw_Data!E14>=KPI_Config!$E$5,KPI_Config!$D$5,IF(AND(KPI_Config!$F$5>0,Raw_Data!E14>=KPI_Config!$G$5),KPI_Config!$F$5,0))))) -> 0 | F14: =IF($A14="","",IF(Raw_Data!F14="",0,IF(KPI_Config!$C$6="L",IF(Raw_Data!F14<=KPI_Config!$E$6,KPI_Config!$D$6,IF(AND(KPI_Config!$F$6>0,Raw_Data!F14<=KPI_Config!$G$6),KPI_Config!$F$6,0)),IF(Raw_Data!F14>=KPI_Config!$E$6,KPI_Config!$D$6,IF(AND(KPI_Config!$F$6>0,Raw_Data!F14>=KPI_Config!$G$6),KPI_Config!$F$6,0))))) -> 0 | G14: =IF($A14="","",IF(Raw_Data!G14="",0,IF(KPI_Config!$C$7="L",IF(Raw_Data!G14<=KPI_Config!$E$7,KPI_Config!$D$7,IF(AND(KPI_Config!$F$7>0,Raw_Data!G14<=KPI_Config!$G$7),KPI_Config!$F$7,0)),IF(Raw_Data!G14>=KPI_Config!$E$7,KPI_Config!$D$7,IF(AND(KPI_Config!$F$7>0,Raw_Data!G14>=KPI_Config!$G$7),KPI_Config!$F$7,0))))) -> 0 | H14: =IF($A14="","",IF(Raw_Data!H14="",0,IF(KPI_Config!$C$8="L",IF(Raw_Data!H14<=KPI_Config!$E$8,KPI_Config!$D$8,IF(AND(KPI_Config!$F$8>0,Raw_Data!H14<=KPI_Config!$G$8),KPI_Config!$F$8,0)),IF(Raw_Data!H14>=KPI_Config!$E$8,KPI_Config!$D$8,IF(AND(KPI_Config!$F$8>0,Raw_Data!H14>=KPI_Config!$G$8),KPI_Config!$F$8,0))))) -> 0 | I14: =IF($A14="","",IF(Raw_Data!I14="",0,IF(KPI_Config!$C$9="L",IF(Raw_Data!I14<=KPI_Config!$E$9,KPI_Config!$D$9,IF(AND(KPI_Config!$F$9>0,Raw_Data!I14<=KPI_Config!$G$9),KPI_Config!$F$9,0)),IF(Raw_Data!I14>=KPI_Config!$E$9,KPI_Config!$D$9,IF(AND(KPI_Config!$F$9>0,Raw_Data!I14>=KPI_Config!$G$9),KPI_Config!$F$9,0))))) -> 0 | J14: =IF($A14="","",IF(Raw_Data!J14="",0,IF(KPI_Config!$C$10="L",IF(Raw_Data!J14<=KPI_Config!$E$10,KPI_Config!$D$10,IF(AND(KPI_Config!$F$10>0,Raw_Data!J14<=KPI_Config!$G$10),KPI_Config!$F$10,0)),IF(Raw_Data!J14>=KPI_Config!$E$10,KPI_Config!$D$10,IF(AND(KPI_Config!$F$10>0,Raw_Data!J14>=KPI_Config!$G$10),KPI_Config!$F$10,0))))) -> 0 | K14: =IF($A14="","",IF(Raw_Data!G14="",0,IF(KPI_Config!$C$11="L",IF(Raw_Data!G14<=KPI_Config!$E$11,KPI_Config!$D$11,IF(AND(KPI_Config!$F$11>0,Raw_Data!G14<=KPI_Config!$G$11),KPI_Config!$F$11,0)),IF(Raw_Data!G14>=KPI_Config!$E$11,KPI_Config!$D$11,IF(AND(KPI_Config!$F$11>0,Raw_Data!G14>=KPI_Config!$G$11),KPI_Config!$F$11,0))))) -> 0 | L14: =IF($A14="","",MIN(Policy_Decisions!$B$10,IF(Policy_Decisions!$B$6="Additive",SUM(E14:K14),SUM(E14:J14)-G14+MAX(G14,K14)))) -> 0 | M14: =IF($A14="","",Raw_Data!K14) -> 0 | N14: =IF($A14="","",IFERROR(VLOOKUP(M14,KPI_Config!$I$5:$J$10,2,FALSE()),0)) -> 0 | O14: =IF($A14="","",IF(Policy_Decisions!$B$5="Percentage points",MAX(0,L14-N14),L14*(1-N14))) -> 0 | P14: =IF($A14="","",IF(U14="","Review proration",IF(O14=0,"No payout",IF(N14>0,"Malus applied","Eligible")))) -> No payout | Q14: =IF($A14="","",Raw_Data!M14) -> MAD | R14: =IF($A14="","",Raw_Data!N14) -> 0 | S14: =IF($A14="","",Raw_Data!O14) -> 0 | T14: =IF($A14="","",IF(Raw_Data!P14>0,Raw_Data!P14,Raw_Data!N14*Raw_Data!O14/IF(Policy_Decisions!$B$7="Annual",12,1))) -> 2000 | U14: =IF($A14="","",IF(OR(Raw_Data!R14="",Raw_Data!R14<=0),"",MIN(1,MAX(0,Raw_Data!Q14/Raw_Data!R14)))) -> 1 | V14: =IF(OR($A14="",U14=""),"",T14*U14) -> 2000 | W14: =IF(OR($A14="",V14=""),"",V14*L14) -> 0 | X14: =IF(OR($A14="",V14=""),"",V14*L14-V14*O14) -> 0 | Y14: =IF(OR($A14="",V14=""),"",ROUND(V14*O14,IF(Policy_Decisions!$B$11="Whole MAD",0,2))) -> 0 | Z14: =Raw_Data!T14 -> Zineb MOUFID | AA14: =Raw_Data!U14 -> Anas OUAKKAD
A15: =IF(Raw_Data!A15="","",Raw_Data!A15) -> 250750 | B15: =IF(Raw_Data!B15="","",Raw_Data!B15) -> Ayoub EL ADRAOUI | C15: =IF(Raw_Data!C15="","",Raw_Data!C15) -> OEM FR | D15: =IF(Raw_Data!D15="","",Raw_Data!D15) -> 2026-07 | E15: =IF($A15="","",IF(Raw_Data!E15="",0,IF(KPI_Config!$C$5="L",IF(Raw_Data!E15<=KPI_Config!$E$5,KPI_Config!$D$5,IF(AND(KPI_Config!$F$5>0,Raw_Data!E15<=KPI_Config!$G$5),KPI_Config!$F$5,0)),IF(Raw_Data!E15>=KPI_Config!$E$5,KPI_Config!$D$5,IF(AND(KPI_Config!$F$5>0,Raw_Data!E15>=KPI_Config!$G$5),KPI_Config!$F$5,0))))) -> 0 | F15: =IF($A15="","",IF(Raw_Data!F15="",0,IF(KPI_Config!$C$6="L",IF(Raw_Data!F15<=KPI_Config!$E$6,KPI_Config!$D$6,IF(AND(KPI_Config!$F$6>0,Raw_Data!F15<=KPI_Config!$G$6),KPI_Config!$F$6,0)),IF(Raw_Data!F15>=KPI_Config!$E$6,KPI_Config!$D$6,IF(AND(KPI_Config!$F$6>0,Raw_Data!F15>=KPI_Config!$G$6),KPI_Config!$F$6,0))))) -> 0 | G15: =IF($A15="","",IF(Raw_Data!G15="",0,IF(KPI_Config!$C$7="L",IF(Raw_Data!G15<=KPI_Config!$E$7,KPI_Config!$D$7,IF(AND(KPI_Config!$F$7>0,Raw_Data!G15<=KPI_Config!$G$7),KPI_Config!$F$7,0)),IF(Raw_Data!G15>=KPI_Config!$E$7,KPI_Config!$D$7,IF(AND(KPI_Config!$F$7>0,Raw_Data!G15>=KPI_Config!$G$7),KPI_Config!$F$7,0))))) -> 0 | H15: =IF($A15="","",IF(Raw_Data!H15="",0,IF(KPI_Config!$C$8="L",IF(Raw_Data!H15<=KPI_Config!$E$8,KPI_Config!$D$8,IF(AND(KPI_Config!$F$8>0,Raw_Data!H15<=KPI_Config!$G$8),KPI_Config!$F$8,0)),IF(Raw_Data!H15>=KPI_Config!$E$8,KPI_Config!$D$8,IF(AND(KPI_Config!$F$8>0,Raw_Data!H15>=KPI_Config!$G$8),KPI_Config!$F$8,0))))) -> 0 | I15: =IF($A15="","",IF(Raw_Data!I15="",0,IF(KPI_Config!$C$9="L",IF(Raw_Data!I15<=KPI_Config!$E$9,KPI_Config!$D$9,IF(AND(KPI_Config!$F$9>0,Raw_Data!I15<=KPI_Config!$G$9),KPI_Config!$F$9,0)),IF(Raw_Data!I15>=KPI_Config!$E$9,KPI_Config!$D$9,IF(AND(KPI_Config!$F$9>0,Raw_Data!I15>=KPI_Config!$G$9),KPI_Config!$F$9,0))))) -> 0 | J15: =IF($A15="","",IF(Raw_Data!J15="",0,IF(KPI_Config!$C$10="L",IF(Raw_Data!J15<=KPI_Config!$E$10,KPI_Config!$D$10,IF(AND(KPI_Config!$F$10>0,Raw_Data!J15<=KPI_Config!$G$10),KPI_Config!$F$10,0)),IF(Raw_Data!J15>=KPI_Config!$E$10,KPI_Config!$D$10,IF(AND(KPI_Config!$F$10>0,Raw_Data!J15>=KPI_Config!$G$10),KPI_Config!$F$10,0))))) -> 0 | K15: =IF($A15="","",IF(Raw_Data!G15="",0,IF(KPI_Config!$C$11="L",IF(Raw_Data!G15<=KPI_Config!$E$11,KPI_Config!$D$11,IF(AND(KPI_Config!$F$11>0,Raw_Data!G15<=KPI_Config!$G$11),KPI_Config!$F$11,0)),IF(Raw_Data!G15>=KPI_Config!$E$11,KPI_Config!$D$11,IF(AND(KPI_Config!$F$11>0,Raw_Data!G15>=KPI_Config!$G$11),KPI_Config!$F$11,0))))) -> 0 | L15: =IF($A15="","",MIN(Policy_Decisions!$B$10,IF(Policy_Decisions!$B$6="Additive",SUM(E15:K15),SUM(E15:J15)-G15+MAX(G15,K15)))) -> 0 | M15: =IF($A15="","",Raw_Data!K15) -> 0 | N15: =IF($A15="","",IFERROR(VLOOKUP(M15,KPI_Config!$I$5:$J$10,2,FALSE()),0)) -> 0 | O15: =IF($A15="","",IF(Policy_Decisions!$B$5="Percentage points",MAX(0,L15-N15),L15*(1-N15))) -> 0 | P15: =IF($A15="","",IF(U15="","Review proration",IF(O15=0,"No payout",IF(N15>0,"Malus applied","Eligible")))) -> No payout | Q15: =IF($A15="","",Raw_Data!M15) -> MAD | R15: =IF($A15="","",Raw_Data!N15) -> 0 | S15: =IF($A15="","",Raw_Data!O15) -> 0 | T15: =IF($A15="","",IF(Raw_Data!P15>0,Raw_Data!P15,Raw_Data!N15*Raw_Data!O15/IF(Policy_Decisions!$B$7="Annual",12,1))) -> 2000 | U15: =IF($A15="","",IF(OR(Raw_Data!R15="",Raw_Data!R15<=0),"",MIN(1,MAX(0,Raw_Data!Q15/Raw_Data!R15)))) -> 1 | V15: =IF(OR($A15="",U15=""),"",T15*U15) -> 2000 | W15: =IF(OR($A15="",V15=""),"",V15*L15) -> 0 | X15: =IF(OR($A15="",V15=""),"",V15*L15-V15*O15) -> 0 | Y15: =IF(OR($A15="",V15=""),"",ROUND(V15*O15,IF(Policy_Decisions!$B$11="Whole MAD",0,2))) -> 0 | Z15: =Raw_Data!T15 -> Kenza EL MOUMNI | AA15: =Raw_Data!U15 -> Anas OUAKKAD
