Workbook
Name Segment_Date: #N/A
Name Segment_Date1: #N/A
Name Segment_Date3: #N/A
Name Segment_Date31: #N/A
Name Segment_Date311: #N/A

Sheet Croisé NL
N4: Étiquettes de colonnes
N5: (vide) | O5: général
M6: SLA% | N6: #DIV/0! | O6: #DIV/0!
M10: [Agent] | N10: (Tous)
M12: Call Received | N12: Étiquettes de colonnes
M13: Étiquettes de lignes | N13: (vide) | O13: général
M14: (vide)
M15: général
A24: Handled + Abandonned
A25: [Call Direction] | B25: I
A26: [Agent] | B26: (Tous)
A27: [Queue] | B27: (Tous)
C29: Valeurs | D29: Queue
C30: Calls Answered | E30: Call in SL | G30: AHT | I30: SLA% | K30: Total Calls Answered | L30: Total Call in SL | M30: Total AHT | N30: Total SLA%
A31: Date | B31: Heures ([Call Date/Time]) | C31: Alliannz Contract | D31: RSA | E31: Alliannz Contract | F31: RSA | G31: Alliannz Contract | H31: RSA | I31: Alliannz Contract | J31: RSA
A32: 46268 | B32: 07 | C32: 8 | D32: 2 | E32: 8 | F32: 2 | G32: 183 | H32: 449 | I32: 1 | J32: 1 | K32: 10 | L32: 10 | M32: 236.2 | N32: 1
A33: 46268 | B33: 08 | C33: 22 | D33: 31 | E33: 16 | F33: 18 | G33: 260.63636 | H33: 297.45161 | I33: 0.72727273 | J33: 0.58064516 | K33: 53 | L33: 34 | M33: 282.16981 | N33: 0.64150943
A34: 46268 | B34: 09 | C34: 37 | D34: 23 | E34: 34 | F34: 19 | G34: 379.54054 | H34: 317.52174 | I34: 0.91891892 | J34: 0.82608696 | K34: 60 | L34: 53 | M34: 355.76667 | N34: 0.88333333
A35: 46268 | B35: 10 | C35: 33 | D35: 22 | E35: 33 | F35: 18 | G35: 472.57576 | H35: 381.95455 | I35: 1 | J35: 0.81818182 | K35: 55 | L35: 51 | M35: 436.32727 | N35: 0.92727273
A36: 46268 | B36: 11 | C36: 32 | D36: 21 | E36: 30 | F36: 20 | G36: 403.5625 | H36: 370.57143 | I36: 0.9375 | J36: 0.95238095 | K36: 53 | L36: 50 | M36: 390.49057 | N36: 0.94339623
A37: 46268 | B37: 12 | C37: 35 | D37: 24 | E37: 35 | F37: 23 | G37: 344.17143 | H37: 350.54167 | I37: 1 | J37: 0.95833333 | K37: 59 | L37: 58 | M37: 346.76271 | N37: 0.98305085
A38: 46268 | B38: 13 | C38: 43 | D38: 19 | E38: 43 | F38: 19 | G38: 385.74419 | H38: 365.84211 | I38: 1 | J38: 1 | K38: 62 | L38: 62 | M38: 379.64516 | N38: 1
A39: 46268 | B39: 14 | C39: 35 | D39: 20 | E39: 35 | F39: 19 | G39: 344.05714 | H39: 287.65 | I39: 1 | J39: 0.95 | K39: 55 | L39: 54 | M39: 323.54545 | N39: 0.98181818
A40: Total 03/09/2026 | C40: 245 | D40: 162 | E40: 234 | F40: 138 | G40: 369.08163 | H40: 337.80247 | I40: 0.95510204 | J40: 0.85185185 | K40: 407 | L40: 372 | M40: 356.63145 | N40: 0.91400491
A41: Total général | C41: 245 | D41: 162 | E41: 234 | F41: 138 | G41: 369.08163 | H41: 337.80247 | I41: 0.95510204 | J41: 0.85185185 | K41: 407 | L41: 372 | M41: 356.63145 | N41: 0.91400491
A63: Handled only
A64: [Call Direction] | B64: I
A65: [Agent] | B65: (Plusieurs éléments)
A66: [Queue] | B66: (Tous)
C68: Valeurs | D68: Queue
C69: Calls Answered | E69: AHT | G69: SLA% | I69: Total Calls Answered | J69: Total AHT | K69: Total SLA%
A70: Date | B70: Heures ([Call Date/Time]) | C70: Alliannz Contract | D70: RSA | E70: Alliannz Contract | F70: RSA | G70: Alliannz Contract | H70: RSA
A71: 46268 | B71: 07 | C71: 8 | D71: 2 | E71: 183 | F71: 449 | G71: 1 | H71: 1 | I71: 10 | J71: 236.2 | K71: 1
A72: 46268 | B72: 08 | C72: 22 | D72: 30 | E72: 260.63636 | F72: 307.36667 | G72: 0.72727273 | H72: 0.6 | I72: 52 | J72: 287.59615 | K72: 0.65384615
A73: 46268 | B73: 09 | C73: 37 | D73: 23 | E73: 379.54054 | F73: 317.52174 | G73: 0.91891892 | H73: 0.82608696 | I73: 60 | J73: 355.76667 | K73: 0.88333333
A74: 46268 | B74: 10 | C74: 33 | D74: 22 | E74: 472.57576 | F74: 381.95455 | G74: 1 | H74: 0.81818182 | I74: 55 | J74: 436.32727 | K74: 0.92727273
A75: 46268 | B75: 11 | C75: 32 | D75: 21 | E75: 403.5625 | F75: 370.57143 | G75: 0.9375 | H75: 0.95238095 | I75: 53 | J75: 390.49057 | K75: 0.94339623
A76: 46268 | B76: 12 | C76: 35 | D76: 24 | E76: 344.17143 | F76: 350.54167 | G76: 1 | H76: 0.95833333 | I76: 59 | J76: 346.76271 | K76: 0.98305085
A77: 46268 | B77: 13 | C77: 43 | D77: 19 | E77: 385.74419 | F77: 365.84211 | G77: 1 | H77: 1 | I77: 62 | J77: 379.64516 | K77: 1
A78: 46268 | B78: 14 | C78: 35 | D78: 20 | E78: 344.05714 | F78: 287.65 | G78: 1 | H78: 0.95 | I78: 55 | J78: 323.54545 | K78: 0.98181818
...

Sheet Croisé VL
N4: Étiquettes de colonnes
N5: (vide) | O5: général
M6: SLA% | N6: #DIV/0! | O6: #DIV/0!
M10: [Agent] | N10: (Tous)
M12: Call Received | N12: Étiquettes de colonnes
M13: Étiquettes de lignes | N13: (vide) | O13: général
M14: (vide)
M15: général
A24: Handled + Abandonned
A25: [Call Direction] | B25: I
A26: [Agent] | B26: (Tous)
A27: [Queue] | B27: (Tous)
C29: Valeurs | D29: Queue
C30: Calls Answered | E30: Call in SL | G30: AHT | I30: SLA% | K30: Total Calls Answered | L30: Total Call in SL | M30: Total AHT | N30: Total SLA%
A31: Date | B31: Heures ([Call Date/Time]) | C31: RSA BE | D31: Alliannz Contract BE | E31: RSA BE | F31: Alliannz Contract BE | G31: RSA BE | H31: Alliannz Contract BE | I31: RSA BE | J31: Alliannz Contract BE
A32: 46268 | B32: 07 | C32: 2 | E32: 2 | G32: 452.5 | I32: 1 | K32: 2 | L32: 2 | M32: 452.5 | N32: 1
A33: 46268 | B33: 08 | C33: 12 | D33: 2 | E33: 10 | F33: 2 | G33: 486.75 | H33: 295.5 | I33: 0.83333333 | J33: 1 | K33: 14 | L33: 12 | M33: 459.42857 | N33: 0.85714286
A34: 46268 | B34: 09 | C34: 11 | D34: 3 | E34: 11 | F34: 3 | G34: 410.27273 | H34: 452.66667 | I34: 1 | J34: 1 | K34: 14 | L34: 14 | M34: 419.35714 | N34: 1
A35: 46268 | B35: 10 | C35: 23 | D35: 1 | E35: 22 | F35: 1 | G35: 465.86957 | H35: 101 | I35: 0.95652174 | J35: 1 | K35: 24 | L35: 23 | M35: 450.66667 | N35: 0.95833333
A36: 46268 | B36: 11 | C36: 17 | D36: 1 | E36: 16 | F36: 1 | G36: 359.05882 | H36: 1191 | I36: 0.94117647 | J36: 1 | K36: 18 | L36: 17 | M36: 405.27778 | N36: 0.94444444
A37: 46268 | B37: 12 | C37: 12 | D37: 1 | E37: 12 | F37: 1 | G37: 453.5 | H37: 5 | I37: 1 | J37: 1 | K37: 13 | L37: 13 | M37: 419 | N37: 1
A38: 46268 | B38: 13 | C38: 19 | D38: 1 | E38: 19 | F38: 1 | G38: 461.73684 | H38: 729 | I38: 1 | J38: 1 | K38: 20 | L38: 20 | M38: 475.1 | N38: 1
A39: 46268 | B39: 14 | C39: 14 | D39: 1 | E39: 14 | F39: 1 | G39: 651.71429 | H39: 288 | I39: 1 | J39: 1 | K39: 15 | L39: 15 | M39: 627.46667 | N39: 1
A40: Total 03/09/2026 | C40: 110 | D40: 10 | E40: 106 | F40: 10 | G40: 467.42727 | H40: 426.3 | I40: 0.96363636 | J40: 1 | K40: 120 | L40: 116 | M40: 464 | N40: 0.96666667
A41: Total général | C41: 110 | D41: 10 | E41: 106 | F41: 10 | G41: 467.42727 | H41: 426.3 | I41: 0.96363636 | J41: 1 | K41: 120 | L41: 116 | M41: 464 | N41: 0.96666667
A63: Handled only
A64: [Call Direction] | B64: I
A65: [Agent] | B65: (Plusieurs éléments)
A66: [Queue] | B66: (Tous)
C68: Valeurs | D68: Queue
C69: Calls Answered | E69: AHT | G69: SLA% | I69: Total Calls Answered | J69: Total AHT | K69: Total SLA%
A70: Date | B70: Heures ([Call Date/Time]) | C70: RSA BE | D70: Alliannz Contract BE | E70: RSA BE | F70: Alliannz Contract BE | G70: RSA BE | H70: Alliannz Contract BE
A71: 46268 | B71: 07 | C71: 2 | E71: 452.5 | G71: 1 | I71: 2 | J71: 452.5 | K71: 1
A72: 46268 | B72: 08 | C72: 11 | D72: 2 | E72: 531 | F72: 295.5 | G72: 0.90909091 | H72: 1 | I72: 13 | J72: 494.76923 | K72: 0.92307692
A73: 46268 | B73: 09 | C73: 11 | D73: 3 | E73: 410.27273 | F73: 452.66667 | G73: 1 | H73: 1 | I73: 14 | J73: 419.35714 | K73: 1
A74: 46268 | B74: 10 | C74: 23 | D74: 1 | E74: 465.86957 | F74: 101 | G74: 0.95652174 | H74: 1 | I74: 24 | J74: 450.66667 | K74: 0.95833333
A75: 46268 | B75: 11 | C75: 17 | D75: 1 | E75: 359.05882 | F75: 1191 | G75: 0.94117647 | H75: 1 | I75: 18 | J75: 405.27778 | K75: 0.94444444
A76: 46268 | B76: 12 | C76: 12 | D76: 1 | E76: 453.5 | F76: 5 | G76: 1 | H76: 1 | I76: 13 | J76: 419 | K76: 1
A77: 46268 | B77: 13 | C77: 19 | D77: 1 | E77: 461.73684 | F77: 729 | G77: 1 | H77: 1 | I77: 20 | J77: 475.1 | K77: 1
A78: 46268 | B78: 14 | C78: 14 | D78: 1 | E78: 651.71429 | F78: 288 | G78: 1 | H78: 1 | I78: 15 | J78: 627.46667 | K78: 1
...

Sheet Ford NL
N4: Étiquettes de colonnes
N5: (vide) | O5: général
M6: SLA% | N6: #DIV/0! | O6: #DIV/0!
M10: [Agent] | N10: (Tous)
M12: Call Received | N12: Étiquettes de colonnes
M13: Étiquettes de lignes | N13: (vide) | O13: général
M14: (vide)
M15: général
A24: Handled + Abandonned
A25: [Call Direction] | B25: I
A26: [Agent] | B26: (Plusieurs éléments)
A27: [Queue] | B27: (Tous)
B29: Valeurs | C29: Queue
B30: Calls Answered | C30: Call in SL | D30: AHT | E30: SLA% | F30: Total Calls Answered | G30: Total Call in SL | H30: Total AHT | I30: Total SLA%
A31: Date | B31: RSA BE | C31: RSA BE | D31: RSA BE | E31: RSA BE
A32: 46268 | B32: 13 | C32: 11 | D32: 467.07692 | E32: 0.84615385 | F32: 13 | G32: 11 | H32: 467.07692 | I32: 0.84615385
A33: Total général | B33: 13 | C33: 11 | D33: 467.07692 | E33: 0.84615385 | F33: 13 | G33: 11 | H33: 467.07692 | I33: 0.84615385
A63: Handled only
A64: [Call Direction] | B64: I
A65: [Agent] | B65: (Plusieurs éléments)
A66: [Queue] | B66: (Tous)
B68: Valeurs | C68: Queue
B69: Calls Answered | C69: AHT | D69: SLA% | E69: Total Calls Answered | F69: Total AHT | G69: Total SLA%
A70: Date | B70: RSA BE | C70: RSA BE | D70: RSA BE
A71: 46268 | B71: 3 | C71: 424 | D71: 1 | E71: 3 | F71: 424 | G71: 1
A72: Total général | B72: 3 | C72: 424 | D72: 1 | E72: 3 | F72: 424 | G72: 1

Sheet Ford FR & Toyota
N4: Étiquettes de colonnes
N5: (vide) | O5: général
M6: SLA% | N6: #DIV/0! | O6: #DIV/0!
M10: [Agent] | N10: (Tous)
M12: Call Received | N12: Étiquettes de colonnes
M13: Étiquettes de lignes | N13: (vide) | O13: général
M14: (vide)
M15: général
A24: Handled + Abandonned
A25: [Call Direction] | B25: I
A26: [Agent] | B26: (Plusieurs éléments)
A27: [Queue] | B27: (Tous)
B29: Valeurs | C29: Queue
B30: Calls Answered | C30: Call in SL | D30: AHT | E30: SLA% | F30: Total Calls Answered | G30: Total Call in SL | H30: Total AHT | I30: Total SLA%
A31: Date | B31: RSA BE | C31: RSA BE | D31: RSA BE | E31: RSA BE
A32: 46268 | B32: 13 | C32: 11 | D32: 467.07692 | E32: 0.84615385 | F32: 13 | G32: 11 | H32: 467.07692 | I32: 0.84615385
A33: Total général | B33: 13 | C33: 11 | D33: 467.07692 | E33: 0.84615385 | F33: 13 | G33: 11 | H33: 467.07692 | I33: 0.84615385
A63: Handled only
A64: [Call Direction] | B64: I
A65: [Agent] | B65: (Plusieurs éléments)
A66: [Queue] | B66: (Tous)
B68: Valeurs | C68: Queue
B69: Calls Answered | C69: AHT | D69: SLA% | E69: Total Calls Answered | F69: Total AHT | G69: Total SLA%
A70: Date | B70: RSA BE | C70: RSA BE | D70: RSA BE
A71: 46268 | B71: 3 | C71: 424 | D71: 1 | E71: 3 | F71: 424 | G71: 1
A72: Total général | B72: 3 | C72: 424 | D72: 1 | E72: 3 | F72: 424 | G72: 1

Sheet Raw data
A1: Source.Name | B1: [Communication Type] | C1: [Call Direction] | D1: [Call Date/Time] | E1: [Originating Address] | F1: [BusinessPartnerID] | G1: [LineOfBusiness] | H1: [Destination Address] | I1: [Service] | J1: [Call Reference Number] | K1: [Call ID] | L1: [CallProgress] | M1: [Total Queue Wait Time] | N1: [Queue ID] | O1: [Queue] | P1: [Call Treatment ID] | Q1: [Call Treatment] | R1: [Agent Group ID] | S1: [Agent Group] | T1: [Called User Group] | U1: [Agent ID] | V1: [Agent] | W1: [Clearing Party] | X1: [Talk Time] | Y1: [Hold Time] | Z1: [Total Wrap Time] | AA1: [Call Completion Code] | AB1: [Transferred?] | AC1: [Call End Date/Time] | AD1: [Date/Time Conferenced] | AE1: [Call Duration Until Conferenced] | AF1: [Shared Call Reference] | AG1: [Ringing Duration] | AH1: [Internal] | AI1: [Direct] | AJ1: [MenuProgress] | AK1: [CallRecordingMode] | AL1: [CallRecordingConsent] | AM1: [LanguageIVR] | AN1: [Language] | AO1: [VoicebotID] | AP1: [VoicebotDestination] | AQ1: [VoicebotPercentageSplit] | AR1: [VoicebotName] | AS1: [RoutingIntent] | AT1: [AgentIntent] | AU1: [LicencePlate] | AV1: [ANI] | AW1: [PostCallSurveyMode] | AX1: [PCSStatus] | AY1: [Question 1] | AZ1: [Question 2] | BA1: [Question 3] | BB1: [Question 4] | BC1: [Question 5] | BD1: [Question 6] | BE1: [Question 7] | BF1: [Question 8] | BG1: [Question 9] | BH1: [Question 10] | BI1: [SessionIdentifier] | BJ1: [CallbackID] | BK1: [CallbackDateTime] | BL1: [CallbackStatus] | BM1: [CallbackOffered] | BN1: Designation | BO1: Date | BP1: Call Received | BQ1: Call in SL | BR1: Queue
A2: AP-Historical-Report---Call-by-Call 2026-09-03 0000 - 2026-09-03 1500.csv | B2: F | C2: I | D2: 46268.001 | E2: +31681613683 | F2: Ominimo | G2: RSA_SubLOB | H2: +31205929015 | I2: APBN_AMS_MOBILITY_INSURAN_Front | J2: 2.7421294e+18 | K2: 37.4332910 | L2: Route_Success | M2: 0.00019675926 | N2: 19760 | O2: APBN_AMS_MOBILITY_INSURAN_Front_NL | P2: 21199 | Q2: APBN_AMS_MOBILITY_INSURAN_Front_NL | R2: 99819 | S2: APBN_AMS_MOBILITY_INSURAN_Front_NL_10 | T2: APBN_AMS_MOBILITY_AGENT-BO_1 | U2: 96166 | V2: Amber Jiawan | W2: L | X2: 0.0024537037 | Y2: 0 | Z2: 0.0003587963 | AB2: 0 | AC2: 46268.004 | AE2: 0 | AF2: 20260903000225620758272 | AG2: 3.4722222e-05 | AH2: 0 | AI2: 0 | AK2: 2 | AL2: 0 | AM2: 0 | AN2: NL | AW2: 0 | AX2: 0 | BN2: Alliannz Contract | BO2: 46268 | BP2: =1 -> 1 | BQ2: =IF(M2+AG2>=parametres!$B$2,0,1) -> 0 | BR2: =VLOOKUP(O2,parametres!G:H,2,0) -> Alliannz Contract
A3: AP-Historical-Report---Call-by-Call 2026-09-03 0000 - 2026-09-03 1500.csv | B3: F | C3: O | D3: 46268.002 | E3: +31681613683 | H3: WebiPath_180_102301 | J3: 2.7421294e+18 | K3: 37.4332911 | M3: 0 | N3: 19760 | O3: APBN_AMS_MOBILITY_INSURAN_Front_NL | P3: 21199 | Q3: APBN_AMS_MOBILITY_INSURAN_Front_NL | R3: 99819 | S3: APBN_AMS_MOBILITY_INSURAN_Front_NL_10 | T3: APBN_AMS_MOBILITY_AGENT-BO_1 | U3: 96166 | V3: Amber Jiawan | W3: R | X3: 0.0024537037 | Y3: 0 | Z3: 0 | AB3: 0 | AC3: 46268.004 | AE3: 0 | AF3: 20260903000225620758272 | AG3: 0.00013888889 | BN3: Alliannz Contract | BO3: 46268 | BP3: =1 -> 1 | BQ3: =IF(M3+AG3>=parametres!$B$2,0,1) -> 1 | BR3: =VLOOKUP(O3,parametres!G:H,2,0) -> Alliannz Contract
A4: AP-Historical-Report---Call-by-Call 2026-09-03 0000 - 2026-09-03 1500.csv | B4: F | C4: I | D4: 46268.023 | E4: +31623803628 | F4: AGA | G4: RSA_SubLOB | H4: +31205929292 | I4: APBN_AMS_MOBILITY_INSURAN_FollowUp | J4: 2.7421294e+18 | K4: 41.4238308 | L4: Route_Success | M4: 0.00020833333 | N4: 19761 | O4: APBN_AMS_MOBILITY_INSURAN_FollowUp_NL | P4: 21200 | Q4: APBN_AMS_MOBILITY_INSURAN_FollowUp_NL | R4: 99830 | S4: APBN_AMS_MOBILITY_INSURAN_FollowUp_NL_10 | T4: APBN_AMS_MOBILITY_AGENT-BO_1 | U4: 96166 | V4: Amber Jiawan | W4: L | X4: 0.002349537 | Y4: 0 | Z4: 2.3148148e-05 | AB4: 0 | AC4: 46268.027 | AE4: 0 | AF4: 20260903003504687867648 | AG4: 3.4722222e-05 | AH4: 0 | AI4: 0 | AK4: 2 | AL4: 0 | AM4: 0 | AN4: NL | AO4: vb3151 | AP4: 77020001 | AQ4: 10 | AR4: Maud | AS4: 3190084 | AT4: Pech (niet gespecificeerd) in Nederland | AU4: N052DK | AV4: +31623803628 | AW4: 0 | AX4: 0 | BN4: Alliannz Contract | BO4: 46268 | BP4: =1 -> 1 | BQ4: =IF(M4+AG4>=parametres!$B$2,0,1) -> 0 | BR4: =VLOOKUP(O4,parametres!G:H,2,0) -> Alliannz Contract
A5: AP-Historical-Report---Call-by-Call 2026-09-03 0000 - 2026-09-03 1500.csv | B5: F | C5: O | D5: 46268.024 | E5: +31623803628 | H5: WebiPath_180_102301 | J5: 2.7421294e+18 | K5: 41.4238317 | M5: 0 | N5: 19761 | O5: APBN_AMS_MOBILITY_INSURAN_FollowUp_NL | P5: 21200 | Q5: APBN_AMS_MOBILITY_INSURAN_FollowUp_NL | R5: 99830 | S5: APBN_AMS_MOBILITY_INSURAN_FollowUp_NL_10 | T5: APBN_AMS_MOBILITY_AGENT-BO_1 | U5: 96166 | V5: Amber Jiawan | W5: R | X5: 0.002349537 | Y5: 0 | Z5: 0 | AB5: 0 | AC5: 46268.027 | AE5: 0 | AF5: 20260903003504687867648 | AG5: 0.00015046296 | BN5: Alliannz Contract | BO5: 46268 | BP5: =1 -> 1 | BQ5: =IF(M5+AG5>=parametres!$B$2,0,1) -> 1 | BR5: =VLOOKUP(O5,parametres!G:H,2,0) -> Alliannz Contract
A6: AP-Historical-Report---Call-by-Call 2026-09-03 0000 - 2026-09-03 1500.csv | B6: F | C6: I | D6: 46268.033 | E6: +31653185361 | F6: AVECO | G6: RSA_SubLOB | H6: +31205929197 | I6: APBN_AMS_MOBILITY_VIP_Front | J6: 2.7421293e+18 | K6: 9.62177022 | L6: Route_Success | M6: 0.00020833333 | N6: 19765 | O6: APBN_AMS_MOBILITY_VIP_Front_NL | P6: 21204 | Q6: APBN_AMS_MOBILITY_VIP_Front_NL | R6: 99874 | S6: APBN_AMS_MOBILITY_VIP_Front_NL_10 | T6: APBN_AMS_MOBILITY_AGENT-BO_1 | U6: 96166 | V6: Amber Jiawan | W6: R | X6: 0.0103125 | Y6: 0 | Z6: 1.1574074e-05 | AB6: 0 | AC6: 46268.045 | AE6: 0 | AF6: 20260903004910150996861 | AG6: 4.6296296e-05 | AH6: 0 | AI6: 0 | AK6: 2 | AL6: 0 | AM6: 0 | AN6: NL | AO6: vb3151 | AP6: 77020001 | AQ6: 10 | AR6: Maud | AS6: 3190148 | AT6: Transport voertuig in Portugal | AV6: +31653185361 | AW6: 2 | AX6: 1 | BN6: RSA | BO6: 46268 | BP6: =1 -> 1 | BQ6: =IF(M6+AG6>=parametres!$B$2,0,1) -> 0 | BR6: =VLOOKUP(O6,parametres!G:H,2,0) -> RSA
A7: AP-Historical-Report---Call-by-Call 2026-09-03 0000 - 2026-09-03 1500.csv | B7: F | C7: O | D7: 46268.034 | E7: +31653185361 | H7: WebiPath_180_102301 | J7: 2.7421293e+18 | K7: 9.62177026 | M7: 0 | N7: 19765 | O7: APBN_AMS_MOBILITY_VIP_Front_NL | P7: 21204 | Q7: APBN_AMS_MOBILITY_VIP_Front_NL | R7: 99874 | S7: APBN_AMS_MOBILITY_VIP_Front_NL_10 | T7: APBN_AMS_MOBILITY_AGENT-BO_1 | U7: 96166 | V7: Amber Jiawan | W7: R | X7: 0.0103125 | Y7: 0 | Z7: 0 | AB7: 0 | AC7: 46268.045 | AE7: 0 | AF7: 20260903004910150996861 | AG7: 0.00012731481 | BN7: RSA | BO7: 46268 | BP7: =1 -> 1 | BQ7: =IF(M7+AG7>=parametres!$B$2,0,1) -> 1 | BR7: =VLOOKUP(O7,parametres!G:H,2,0) -> RSA
A8: AP-Historical-Report---Call-by-Call 2026-09-03 0000 - 2026-09-03 1500.csv | B8: F | C8: I | D8: 46268.108 | E8: +31615004720 | F8: Ominimo | G8: RSA_SubLOB | H8: +31205929015 | I8: APBN_AMS_MOBILITY_INSURAN_Front | J8: 2.7421293e+18 | K8: 17.83325438 | L8: Route_Success | M8: 0.0024652778 | N8: 19760 | O8: APBN_AMS_MOBILITY_INSURAN_Front_NL | P8: 21199 | Q8: APBN_AMS_MOBILITY_INSURAN_Front_NL | R8: 99819 | S8: APBN_AMS_MOBILITY_INSURAN_Front_NL_10 | T8: APBN_AMS_MOBILITY_AGENT-BO_1 | U8: 96166 | V8: Amber Jiawan | W8: L | X8: 0.011886574 | Y8: 0 | Z8: 1.1574074e-05 | AB8: 0 | AC8: 46268.123 | AE8: 0 | AF8: 20260903023622285213989 | AG8: 1.1574074e-05 | AH8: 0 | AI8: 0 | AK8: 2 | AL8: 0 | AM8: 0 | AN8: NL | AW8: 0 | AX8: 0 | BN8: Alliannz Contract | BO8: 46268 | BP8: =1 -> 1 | BQ8: =IF(M8+AG8>=parametres!$B$2,0,1) -> 0 | BR8: =VLOOKUP(O8,parametres!G:H,2,0) -> Alliannz Contract
A9: AP-Historical-Report---Call-by-Call 2026-09-03 0000 - 2026-09-03 1500.csv | B9: F | C9: O | D9: 46268.109 | E9: +31615004720 | H9: WebiPath_180_102301 | J9: 2.7421293e+18 | K9: 17.83325439 | M9: 0 | N9: 19760 | O9: APBN_AMS_MOBILITY_INSURAN_Front_NL | P9: 21199 | Q9: APBN_AMS_MOBILITY_INSURAN_Front_NL | R9: 99819 | S9: APBN_AMS_MOBILITY_INSURAN_Front_NL_10 | T9: APBN_AMS_MOBILITY_AGENT-BO_1 | U9: 96166 | V9: Amber Jiawan | W9: L | X9: 0 | Y9: 0 | Z9: 0 | AB9: 0 | AC9: 46268.109 | AE9: 0 | AF9: 20260903023622285213989 | AG9: 0.00023148148 | BN9: Alliannz Contract | BO9: 46268 | BP9: =1 -> 1 | BQ9: =IF(M9+AG9>=parametres!$B$2,0,1) -> 0 | BR9: =VLOOKUP(O9,parametres!G:H,2,0) -> Alliannz Contract
A10: AP-Historical-Report---Call-by-Call 2026-09-03 0000 - 2026-09-03 1500.csv | B10: F | C10: O | D10: 46268.111 | E10: +31615004720 | H10: WebiPath_180_102301 | J10: 2.7421293e+18 | K10: 17.83325444 | M10: 0 | N10: 19760 | O10: APBN_AMS_MOBILITY_INSURAN_Front_NL | P10: 21199 | Q10: APBN_AMS_MOBILITY_INSURAN_Front_NL | R10: 99819 | S10: APBN_AMS_MOBILITY_INSURAN_Front_NL_10 | T10: APBN_AMS_MOBILITY_AGENT-BO_1 | U10: 96166 | V10: Amber Jiawan | W10: R | X10: 0.011886574 | Y10: 0 | Z10: 0 | AB10: 0 | AC10: 46268.123 | AE10: 0 | AF10: 20260903023622285213989 | AG10: 5.787037e-05 | BI10: 06df0c16-b8bc-4887-9f95-ae6440da5c16.01 | BN10: Alliannz Contract | BO10: 46268 | BP10: =1 -> 1 | BQ10: =IF(M10+AG10>=parametres!$B$2,0,1) -> 1 | BR10: =VLOOKUP(O10,parametres!G:H,2,0) -> Alliannz Contract
A11: AP-Historical-Report---Call-by-Call 2026-09-03 0000 - 2026-09-03 1500.csv | B11: F | C11: I | D11: 46268.126 | E11: +31615004720 | F11: Ominimo | G11: RSA_SubLOB | H11: +31205929015 | I11: APBN_AMS_MOBILITY_INSURAN_Front | J11: 2.7421293e+18 | K11: 21.20414624 | L11: Route_Queue | M11: 0.01224537 | N11: 19760 | O11: APBN_AMS_MOBILITY_INSURAN_Front_NL | P11: 21199 | Q11: APBN_AMS_MOBILITY_INSURAN_Front_NL | W11: R | X11: 0 | Y11: 0 | Z11: 0 | AB11: 0 | AC11: 46268.138 | AE11: 0 | AF11: 20260903030130352322945 | AG11: 2.3148148e-05 | AH11: 0 | AI11: 0 | AK11: 2 | AL11: 0 | AM11: 0 | AN11: NL | AW11: 0 | AX11: 0 | BN11: Alliannz Contract | BO11: 46268 | BP11: =1 -> 1 | BQ11: =IF(M11+AG11>=parametres!$B$2,0,1) -> 0 | BR11: =VLOOKUP(O11,parametres!G:H,2,0) -> Alliannz Contract
A12: AP-Historical-Report---Call-by-Call 2026-09-03 0000 - 2026-09-03 1500.csv | B12: F | C12: I | D12: 46268.208 | E12: +31653503207 | F12: KIA | G12: RSA_SubLOB | H12: +31208512235 | I12: APBN_AMS_MOBILITY_INSURAN_FollowUp | J12: 2.7421294e+18 | K12: 42.4232779 | L12: Route_Queue | M12: 0.00034722222 | N12: 19761 | O12: APBN_AMS_MOBILITY_INSURAN_FollowUp_NL | P12: 21200 | Q12: APBN_AMS_MOBILITY_INSURAN_FollowUp_NL | R12: 99830 | S12: APBN_AMS_MOBILITY_INSURAN_FollowUp_NL_10 | T12: APBN_AMS_MOBILITY_AGENT-BO_1 | U12: 96166 | V12: Amber Jiawan | W12: R | X12: 0.002349537 | Y12: 0 | Z12: 2.3148148e-05 | AB12: 0 | AC12: 46268.212 | AE12: 0 | AF12: 20260903050043704644304 | AG12: 4.6296296e-05 | AH12: 0 | AI12: 0 | AK12: 2 | AL12: 0 | AM12: 0 | AN12: NL | AO12: vb3151 | AP12: 77020001 | AQ12: 10 | AR12: Maud | AS12: 3190032 | AT12: Geen Intent | AV12: +31653503207 | AW12: 2 | AX12: 1 | BN12: Alliannz Contract | BO12: 46268 | BP12: =1 -> 1 | BQ12: =IF(M12+AG12>=parametres!$B$2,0,1) -> 0 | BR12: =VLOOKUP(O12,parametres!G:H,2,0) -> Alliannz Contract
A13: AP-Historical-Report---Call-by-Call 2026-09-03 0000 - 2026-09-03 1500.csv | B13: F | C13: O | D13: 46268.209 | E13: +31653503207 | H13: WebiPath_180_102301 | J13: 2.7421294e+18 | K13: 42.4232782 | M13: 0 | N13: 19761 | O13: APBN_AMS_MOBILITY_INSURAN_FollowUp_NL | P13: 21200 | Q13: APBN_AMS_MOBILITY_INSURAN_FollowUp_NL | R13: 99830 | S13: APBN_AMS_MOBILITY_INSURAN_FollowUp_NL_10 | T13: APBN_AMS_MOBILITY_AGENT-BO_1 | U13: 96166 | V13: Amber Jiawan | W13: L | X13: 0.002349537 | Y13: 0 | Z13: 0 | AB13: 0 | AC13: 46268.212 | AE13: 0 | AF13: 20260903050043704644304 | AG13: 0.00027777778 | BI13: c8e8f603-96f2-4240-b736-6d84ab48597a.01 | BN13: Alliannz Contract | BO13: 46268 | BP13: =1 -> 1 | BQ13: =IF(M13+AG13>=parametres!$B$2,0,1) -> 0 | BR13: =VLOOKUP(O13,parametres!G:H,2,0) -> Alliannz Contract
A14: AP-Historical-Report---Call-by-Call 2026-09-03 0000 - 2026-09-03 1500.csv | B14: F | C14: I | D14: 46268.243 | E14: +31630070418 | F14: AP_NL_RSA_PROVIDERS | G14: RSA_SubLOB | H14: +31205929107 | I14: APBN_AMS_MOBILITY_PROVIDER_Local | J14: 2.7421294e+18 | K14: 32.8511136 | L14: Route_Queue | M14: 0.00018518519 | N14: 19770 | O14: APBN_AMS_MOBILITY_PROVIDER_Local_NL | P14: 21209 | Q14: APBN_AMS_MOBILITY_PROVIDER_Local_NL | R14: 99924 | S14: APBN_AMS_MOBILITY_PROVIDER_Local_NL_5 | T14: APBN_AMS_MOBILITY_AGENT-BO_1 | U14: 96166 | V14: Amber Jiawan | W14: R | X14: 0.0026851852 | Y14: 0 | Z14: 2.3148148e-05 | AB14: 0 | AC14: 46268.246 | AE14: 0 | AF14: 20260903055013536872738 | AG14: 9.2592593e-05 | AH14: 0 | AI14: 0 | AJ14: m319107:2:1| | AK14: 2 | AL14: 0 | AM14: 0 | AN14: NL | AW14: 0 | AX14: 0 | BN14: RSA Provider | BO14: 46268 | BP14: =1 -> 1 | BQ14: =IF(M14+AG14>=parametres!$B$2,0,1) -> 0 | BR14: =VLOOKUP(O14,parametres!G:H,2,0) -> RSA Provider
A15: AP-Historical-Report---Call-by-Call 2026-09-03 0000 - 2026-09-03 1500.csv | B15: F | C15: O | D15: 46268.243 | E15: +31630070418 | H15: WebiPath_180_102301 | J15: 2.7421294e+18 | K15: 32.8511138 | M15: 0 | N15: 19770 | O15: APBN_AMS_MOBILITY_PROVIDER_Local_NL | P15: 21209 | Q15: APBN_AMS_MOBILITY_PROVIDER_Local_NL | R15: 99924 | S15: APBN_AMS_MOBILITY_PROVIDER_Local_NL_5 | T15: APBN_AMS_MOBILITY_AGENT-BO_1 | U15: 96166 | V15: Amber Jiawan | W15: R | X15: 0.0026736111 | Y15: 0 | Z15: 0 | AB15: 0 | AC15: 46268.246 | AE15: 0 | AF15: 20260903055013536872738 | AG15: 0.00015046296 | BI15: a1b57b49-4919-4279-8515-447aa0d2b70b.01 | BN15: RSA Provider | BO15: 46268 | BP15: =1 -> 1 | BQ15: =IF(M15+AG15>=parametres!$B$2,0,1) -> 1 | BR15: =VLOOKUP(O15,parametres!G:H,2,0) -> RSA Provider
A16: AP-Historical-Report---Call-by-Call 2026-09-03 0000 - 2026-09-03 1500.csv | B16: F | C16: I | D16: 46268.266 | E16: +31641374048 | F16: PSA | G16: RSA_SubLOB | H16: +31208512219 | I16: APBN_AMS_MOBILITY_LEASE-RE_Front | J16: 2.7421293e+18 | K16: 26.7572339 | L16: Route_Queue | M16: 0.00013888889 | N16: 19767 | O16: APBN_AMS_MOBILITY_LEASE-RE_Front_NL | P16: 21206 | Q16: APBN_AMS_MOBILITY_LEASE-RE_Front_NL | R16: 99896 | S16: APBN_AMS_MOBILITY_LEASE-RE_Front_NL_10 | T16: APBN_AMS_MOBILITY_AGENT-BO_1 | U16: 96168 | V16: Esther Ambergen | W16: R | X16: 0.00069444444 | Y16: 0 | Z16: 8.1018519e-05 | AB16: 0 | AC16: 46268.268 | AE16: 0 | AF16: 20260903062457436209107 | AG16: 5.787037e-05 | AH16: 0 | AI16: 0 | AK16: 0 | AL16: 0 | AM16: 0 | AN16: NL | AO16: vb3151 | AP16: 77020001 | AQ16: 10 | AR16: Maud | AT16: Lekke band / bandenprobleem in Nederland | AU16: N514PH | AV16: +31641374048 | AW16: 0 | AX16: 0 | BN16: RSA | BO16: 46268 | BP16: =1 -> 1 | BQ16: =IF(M16+AG16>=parametres!$B$2,0,1) -> 1 | BR16: =VLOOKUP(O16,parametres!G:H,2,0) -> RSA
A17: AP-Historical-Report---Call-by-Call 2026-09-03 0000 - 2026-09-03 1500.csv | B17: F | C17: O | D17: 46268.267 | E17: +31641374048 | H17: WebiPath_180_102303 | J17: 2.7421293e+18 | K17: 26.7572345 | M17: 0 | N17: 19767 | O17: APBN_AMS_MOBILITY_LEASE-RE_Front_NL | P17: 21206 | Q17: APBN_AMS_MOBILITY_LEASE-RE_Front_NL | R17: 99896 | S17: APBN_AMS_MOBILITY_LEASE-RE_Front_NL_10 | T17: APBN_AMS_MOBILITY_AGENT-BO_1 | U17: 96168 | V17: Esther Ambergen | W17: L | X17: 0.00069444444 | Y17: 0 | Z17: 0 | AB17: 0 | AC17: 46268.268 | AE17: 0 | AF17: 20260903062457436209107 | AG17: 9.2592593e-05 | BI17: 9c499f77-e0b0-47c8-81b6-85b7ff396874.01 | BN17: RSA | BO17: 46268 | BP17: =1 -> 1 | BQ17: =IF(M17+AG17>=parametres!$B$2,0,1) -> 1 | BR17: =VLOOKUP(O17,parametres!G:H,2,0) -> RSA
A18: AP-Historical-Report---Call-by-Call 2026-09-03 0000 - 2026-09-03 1500.csv | B18: F | C18: I | D18: 46268.28 | E18: +31610766137 | F18: AP_NL_RSA | G18: RSA_SubLOB | H18: +31208512294 | I18: APBN_AMS_MOBILITY_INSURAN_Front | J18: 2.7421292e+18 | K18: 6.61830690 | L18: Route_Queue | M18: 0.00043981481 | N18: 19760 | O18: APBN_AMS_MOBILITY_INSURAN_Front_NL | P18: 21199 | Q18: APBN_AMS_MOBILITY_INSURAN_Front_NL | R18: 99819 | S18: APBN_AMS_MOBILITY_INSURAN_Front_NL_10 | T18: APBN_AMS_MOBILITY_AGENT-BO_1 | U18: 96168 | V18: Esther Ambergen | W18: R | X18: 0.0014236111 | Y18: 0 | Z18: 3.4722222e-05 | AB18: 0 | AC18: 46268.283 | AE18: 0 | AF18: 20260903064449100663850 | AG18: 4.6296296e-05 | AH18: 0 | AI18: 0 | AK18: 2 | AL18: 0 | AM18: 0 | AN18: NL | AO18: vb3151 | AP18: 77020001 | AQ18: 10 | AR18: Maud | AS18: 3190096 | AT18: Ongeval op snelweg | AV18: +31610766137 | AW18: 2 | AX18: 1 | BN18: Alliannz Contract | BO18: 46268 | BP18: =1 -> 1 | BQ18: =IF(M18+AG18>=parametres!$B$2,0,1) -> 0 | BR18: =VLOOKUP(O18,parametres!G:H,2,0) -> Alliannz Contract
A19: AP-Historical-Report---Call-by-Call 2026-09-03 0000 - 2026-09-03 1500.csv | B19: F | C19: O | D19: 46268.281 | E19: +31610766137 | H19: WebiPath_180_102301 | J19: 2.7421292e+18 | K19: 6.61830700 | M19: 0 | N19: 19760 | O19: APBN_AMS_MOBILITY_INSURAN_Front_NL | P19: 21199 | Q19: APBN_AMS_MOBILITY_INSURAN_Front_NL | R19: 99819 | S19: APBN_AMS_MOBILITY_INSURAN_Front_NL_10 | T19: APBN_AMS_MOBILITY_AGENT-BO_1 | U19: 96166 | V19: Amber Jiawan | W19: L | X19: 0 | Y19: 0 | Z19: 0 | AB19: 0 | AC19: 46268.281 | AE19: 0 | AF19: 20260903064449100663850 | AG19: 0.00023148148 | BN19: Alliannz Contract | BO19: 46268 | BP19: =1 -> 1 | BQ19: =IF(M19+AG19>=parametres!$B$2,0,1) -> 0 | BR19: =VLOOKUP(O19,parametres!G:H,2,0) -> Alliannz Contract
A20: AP-Historical-Report---Call-by-Call 2026-09-03 0000 - 2026-09-03 1500.csv | B20: F | C20: O | D20: 46268.281 | E20: +31610766137 | H20: WebiPath_180_102303 | J20: 2.7421292e+18 | K20: 6.61830704 | M20: 0 | N20: 19760 | O20: APBN_AMS_MOBILITY_INSURAN_Front_NL | P20: 21199 | Q20: APBN_AMS_MOBILITY_INSURAN_Front_NL | R20: 99819 | S20: APBN_AMS_MOBILITY_INSURAN_Front_NL_10 | T20: APBN_AMS_MOBILITY_AGENT-BO_1 | U20: 96168 | V20: Esther Ambergen | W20: R | X20: 0.0014236111 | Y20: 0 | Z20: 0 | AB20: 0 | AC20: 46268.283 | AE20: 0 | AF20: 20260903064449100663850 | AG20: 0.00013888889 | BI20: a52f2c02-eeaa-45b0-b356-82216cb4d5bb.01 | BN20: Alliannz Contract | BO20: 46268 | BP20: =1 -> 1 | BQ20: =IF(M20+AG20>=parametres!$B$2,0,1) -> 1 | BR20: =VLOOKUP(O20,parametres!G:H,2,0) -> Alliannz Contract
A21: AP-Historical-Report---Call-by-Call 2026-09-03 0000 - 2026-09-03 1500.csv | B21: F | C21: I | D21: 46268.284 | E21: +32472484146 | F21: AGA | G21: RSA_Front | H21: +3222906100 | I21: APBN_BRU_MOBILITY_INSURAN_Front | J21: 2.7421294e+18 | K21: 45.4946642 | L21: Route_Queue | M21: 0.00018518519 | N21: 19781 | O21: APBN_BRU_MOBILITY_INSURAN_Front_VL | P21: 21221 | Q21: APBN_BRU_MOBILITY_INSURAN_Front_VL | R21: 100041 | S21: APBN_BRU_MOBILITY_INSURAN_Front_VL_1 | T21: APBN_BRU_MOBILITY_NIGHTSHF_1 | U21: 96364 | V21: Nawfal Laghmich | W21: R | X21: 0.0015509259 | Y21: 0 | Z21: 0.0003587963 | AB21: 0 | AC21: 46268.286 | AE21: 0 | AF21: 20260903064932754975317 | AG21: 1.1574074e-05 | AH21: 0 | AI21: 0 | AJ21: m3229916100:1:1| | AK21: 2 | AL21: 0 | AM21: 1 | AN21: VL | AW21: 2 | AX21: 1 | BN21: RSA BE | BO21: 46268 | BP21: =1 -> 1 | BQ21: =IF(M21+AG21>=parametres!$B$2,0,1) -> 1 | BR21: =VLOOKUP(O21,parametres!G:H,2,0) -> RSA BE
A22: AP-Historical-Report---Call-by-Call 2026-09-03 0000 - 2026-09-03 1500.csv | B22: F | C22: O | D22: 46268.284 | E22: +32472484146 | H22: WebiPath_180_102499 | J22: 2.7421294e+18 | K22: 45.4946644 | M22: 0 | N22: 19781 | O22: APBN_BRU_MOBILITY_INSURAN_Front_VL | P22: 21221 | Q22: APBN_BRU_MOBILITY_INSURAN_Front_VL | R22: 100041 | S22: APBN_BRU_MOBILITY_INSURAN_Front_VL_1 | T22: APBN_BRU_MOBILITY_NIGHTSHF_1 | U22: 96364 | V22: Nawfal Laghmich | W22: R | X22: 0.0015509259 | Y22: 0 | Z22: 0 | AB22: 0 | AC22: 46268.286 | AE22: 0 | AF22: 20260903064932754975317 | AG22: 0.00016203704 | BI22: fe9a7398-ed34-4946-aa7f-5d18f9af1844.01 | BN22: RSA BE | BO22: 46268 | BP22: =1 -> 1 | BQ22: =IF(M22+AG22>=parametres!$B$2,0,1) -> 1 | BR22: =VLOOKUP(O22,parametres!G:H,2,0) -> RSA BE
A23: AP-Historical-Report---Call-by-Call 2026-09-03 0000 - 2026-09-03 1500.csv | B23: F | C23: I | D23: 46268.285 | E23: +31641412292 | F23: AP_NL_MULTI_LOB | G23: RSA_SubLOB | H23: +31205929890 | I23: APBN_AMS_MOBILITY_INSURAN_Front | J23: 2.7421293e+18 | K23: 19.52618279 | L23: Route_Success | M23: 0.00020833333 | N23: 19760 | O23: APBN_AMS_MOBILITY_INSURAN_Front_NL | P23: 21199 | Q23: APBN_AMS_MOBILITY_INSURAN_Front_NL | R23: 99819 | S23: APBN_AMS_MOBILITY_INSURAN_Front_NL_10 | T23: APBN_AMS_MOBILITY_AGENT-BO_1 | U23: 96166 | V23: Amber Jiawan | W23: L | X23: 0.002349537 | Y23: 0.0015277778 | Z23: 0.011979167 | AB23: 0 | AC23: 46268.291 | AE23: 0 | AF23: 20260903065241318769039 | AG23: 8.1018519e-05 | AH23: 0 | AI23: 0 | AK23: 2 | AL23: 0 | AM23: 0 | AN23: NL | AO23: vb3151 | AP23: 77020001 | AQ23: 10 | AR23: Maud | AS23: 3190086 | AV23: +31641412292 | AW23: 0 | AX23: 0 | BN23: Alliannz Contract | BO23: 46268 | BP23: =1 -> 1 | BQ23: =IF(M23+AG23>=parametres!$B$2,0,1) -> 0 | BR23: =VLOOKUP(O23,parametres!G:H,2,0) -> Alliannz Contract
A24: AP-Historical-Report---Call-by-Call 2026-09-03 0000 - 2026-09-03 1500.csv | B24: F | C24: I | D24: 46268.286 | E24: +31617279971 | F24: KIA | G24: RSA_SubLOB | H24: +31208512235 | I24: APBN_AMS_MOBILITY_OEM-CONS_Front | J24: 2.7421293e+18 | K24: 23.11599131 | L24: Route_Queue | M24: 0.00016203704 | N24: 19755 | O24: APBN_AMS_MOBILITY_OEM-CONS_Front_NL | P24: 21194 | Q24: APBN_AMS_MOBILITY_OEM-CONS_Front_NL | R24: 99764 | S24: APBN_AMS_MOBILITY_OEM-CONS_Front_NL_10 | T24: APBN_AMS_MOBILITY_AGENT-BO_1 | U24: 96168 | V24: Esther Ambergen | W24: R | X24: 0.0017013889 | Y24: 0 | Z24: 1.1574074e-05 | AB24: 0 | AC24: 46268.289 | AE24: 0 | AF24: 20260903065355385876002 | AG24: 5.787037e-05 | AH24: 0 | AI24: 0 | AK24: 2 | AL24: 0 | AM24: 0 | AN24: NL | AO24: vb3151 | AP24: 77020001 | AQ24: 10 | AR24: Maud | AS24: 3190031 | AT24: Lekke band / bandenprobleem in Nederland | AV24: +31617279971 | AW24: 2 | AX24: 1 | BN24: RSA | BO24: 46268 | BP24: =1 -> 1 | BQ24: =IF(M24+AG24>=parametres!$B$2,0,1) -> 1 | BR24: =VLOOKUP(O24,parametres!G:H,2,0) -> RSA
A25: AP-Historical-Report---Call-by-Call 2026-09-03 0000 - 2026-09-03 1500.csv | B25: F | C25: O | D25: 46268.287 | E25: +31641412292 | H25: WebiPath_180_102301 | J25: 2.7421293e+18 | K25: 19.52618284 | M25: 0 | N25: 19760 | O25: APBN_AMS_MOBILITY_INSURAN_Front_NL | P25: 21199 | Q25: APBN_AMS_MOBILITY_INSURAN_Front_NL | R25: 99819 | S25: APBN_AMS_MOBILITY_INSURAN_Front_NL_10 | T25: APBN_AMS_MOBILITY_AGENT-BO_1 | U25: 96166 | V25: Amber Jiawan | W25: R | X25: 0.002349537 | Y25: 0.0015277778 | Z25: 0 | AB25: 0 | AC25: 46268.291 | AE25: 0 | AF25: 20260903065241318769039 | AG25: 0.00013888889 | BI25: 512baa38-e47d-4b42-a3cb-09577d96a6b7.01 | BN25: Alliannz Contract | BO25: 46268 | BP25: =1 -> 1 | BQ25: =IF(M25+AG25>=parametres!$B$2,0,1) -> 1 | BR25: =VLOOKUP(O25,parametres!G:H,2,0) -> Alliannz Contract
A26: AP-Historical-Report---Call-by-Call 2026-09-03 0000 - 2026-09-03 1500.csv | B26: F | C26: O | D26: 46268.287 | E26: +31617279971 | H26: WebiPath_180_102303 | J26: 2.7421293e+18 | K26: 23.11599146 | M26: 0 | N26: 19755 | O26: APBN_AMS_MOBILITY_OEM-CONS_Front_NL | P26: 21194 | Q26: APBN_AMS_MOBILITY_OEM-CONS_Front_NL | R26: 99764 | S26: APBN_AMS_MOBILITY_OEM-CONS_Front_NL_10 | T26: APBN_AMS_MOBILITY_AGENT-BO_1 | U26: 96168 | V26: Esther Ambergen | W26: L | X26: 0.0017013889 | Y26: 0 | Z26: 0 | AB26: 0 | AC26: 46268.289 | AE26: 0 | AF26: 20260903065355385876002 | AG26: 0.00010416667 | BI26: be41085c-a3bb-431b-92a8-d225a87f8b5a.01 | BN26: RSA | BO26: 46268 | BP26: =1 -> 1 | BQ26: =IF(M26+AG26>=parametres!$B$2,0,1) -> 1 | BR26: =VLOOKUP(O26,parametres!G:H,2,0) -> RSA
A27: AP-Historical-Report---Call-by-Call 2026-09-03 0000 - 2026-09-03 1500.csv | B27: F | C27: I | D27: 46268.298 | E27: +31651155184 | F27: AP_NL_MULTI_LOB | G27: RSA_SubLOB | H27: +31205929890 | I27: APBN_AMS_MOBILITY_INSURAN_Front | J27: 2.7421294e+18 | K27: 36.8597628 | L27: Route_Queue | M27: 8.1018519e-05 | N27: 19760 | O27: APBN_AMS_MOBILITY_INSURAN_Front_NL | P27: 21199 | Q27: APBN_AMS_MOBILITY_INSURAN_Front_NL | R27: 99810 | S27: APBN_AMS_MOBILITY_INSURAN_Front_NL_1 | T27: APBN_CMN_RSA_FRONT-NL_1 | U27: 96526 | V27: Said Hajhouj | W27: R | X27: 0.0026967593 | Y27: 0 | Z27: 0.0016203704 | AB27: 0 | AC27: 46268.302 | AE27: 0 | AF27: 20260903071058603981466 | AG27: 2.3148148e-05 | AH27: 0 | AI27: 0 | AK27: 2 | AL27: 0 | AM27: 0 | AN27: NL | AO27: vb3151 | AP27: 77020001 | AQ27: 10 | AR27: Maud | AS27: 3190086 | AT27: Accu / Startprobleem in Nederland | AU27: NF024J | AV27: +31651155184 | AW27: 0 | AX27: 0 | BN27: Alliannz Contract | BO27: 46268 | BP27: =1 -> 1 | BQ27: =IF(M27+AG27>=parametres!$B$2,0,1) -> 1 | BR27: =VLOOKUP(O27,parametres!G:H,2,0) -> Alliannz Contract
A28: AP-Historical-Report---Call-by-Call 2026-09-03 0000 - 2026-09-03 1500.csv | B28: F | C28: O | D28: 46268.299 | E28: +31651155184 | H28: WebiPath_180_102661 | J28: 2.7421294e+18 | K28: 36.8597635 | M28: 0 | N28: 19760 | O28: APBN_AMS_MOBILITY_INSURAN_Front_NL | P28: 21199 | Q28: APBN_AMS_MOBILITY_INSURAN_Front_NL | R28: 99810 | S28: APBN_AMS_MOBILITY_INSURAN_Front_NL_1 | T28: APBN_CMN_RSA_FRONT-NL_1 | U28: 96526 | V28: Said Hajhouj | W28: L | X28: 0.0026967593 | Y28: 0 | Z28: 0 | AB28: 0 | AC28: 46268.302 | AE28: 0 | AF28: 20260903071058603981466 | AG28: 1.1574074e-05 | BN28: Alliannz Contract | BO28: 46268 | BP28: =1 -> 1 | BQ28: =IF(M28+AG28>=parametres!$B$2,0,1) -> 1 | BR28: =VLOOKUP(O28,parametres!G:H,2,0) -> Alliannz Contract
A29: AP-Historical-Report---Call-by-Call 2026-09-03 0000 - 2026-09-03 1500.csv | B29: F | C29: I | D29: 46268.303 | E29: +31641412292 | F29: AGA | G29: RSA_SubLOB | H29: +31205929890 | I29: APBN_AMS_MOBILITY_INSURAN_FollowUp | J29: 2.7421294e+18 | K29: 34.8413149 | L29: Route_Queue | M29: 9.2592593e-05 | N29: 19761 | O29: APBN_AMS_MOBILITY_INSURAN_FollowUp_NL | P29: 21200 | Q29: APBN_AMS_MOBILITY_INSURAN_FollowUp_NL | R29: 99821 | S29: APBN_AMS_MOBILITY_INSURAN_FollowUp_NL_1 | T29: APBN_CMN_RSA_FRONT-NL_1 | U29: 224299 | V29: Jacqueline Sint | W29: R | X29: 0.0021759259 | Y29: 0 | Z29: 0.0003587963 | AB29: 0 | AC29: 46268.307 | AE29: 0 | AF29: 20260903071832570427247 | AG29: 2.3148148e-05 | AH29: 0 | AI29: 0 | AK29: 2 | AL29: 0 | AM29: 0 | AN29: NL | AO29: vb3151 | AP29: 77020001 | AQ29: 10 | AR29: Maud | AS29: 3190084 | AU29: 38PTDT | AV29: +31641412292 | AW29: 0 | AX29: 0 | BN29: Alliannz Contract | BO29: 46268 | BP29: =1 -> 1 | BQ29: =IF(M29+AG29>=parametres!$B$2,0,1) -> 1 | BR29: =VLOOKUP(O29,parametres!G:H,2,0) -> Alliannz Contract
A30: AP-Historical-Report---Call-by-Call 2026-09-03 0000 - 2026-09-03 1500.csv | B30: F | C30: O | D30: 46268.305 | E30: +31641412292 | H30: WebiPath_180_177942 | J30: 2.7421294e+18 | K30: 34.8413155 | M30: 0 | N30: 19761 | O30: APBN_AMS_MOBILITY_INSURAN_FollowUp_NL | P30: 21200 | Q30: APBN_AMS_MOBILITY_INSURAN_FollowUp_NL | R30: 99821 | S30: APBN_AMS_MOBILITY_INSURAN_FollowUp_NL_1 | T30: APBN_CMN_RSA_FRONT-NL_1 | U30: 224299 | V30: Jacqueline Sint | W30: R | X30: 0.0021643519 | Y30: 0 | Z30: 0 | AB30: 0 | AC30: 46268.307 | AE30: 0 | AF30: 20260903071832570427247 | AG30: 1.1574074e-05 | BN30: Alliannz Contract | BO30: 46268 | BP30: =1 -> 1 | BQ30: =IF(M30+AG30>=parametres!$B$2,0,1) -> 1 | BR30: =VLOOKUP(O30,parametres!G:H,2,0) -> Alliannz Contract
A31: AP-Historical-Report---Call-by-Call 2026-09-03 0000 - 2026-09-03 1500.csv | B31: F | C31: I | D31: 46268.307 | E31: +31611247401 | F31: Toyota | G31: RSA_SubLOB | H31: +31205929836 | I31: APBN_AMS_MOBILITY_INSURAN_FollowUp | J31: 2.7421294e+18 | K31: 39.4309849 | L31: Route_Success | M31: 6.9444444e-05 | N31: 19761 | O31: APBN_AMS_MOBILITY_INSURAN_FollowUp_NL | P31: 21200 | Q31: APBN_AMS_MOBILITY_INSURAN_FollowUp_NL | R31: 99821 | S31: APBN_AMS_MOBILITY_INSURAN_FollowUp_NL_1 | T31: APBN_CMN_RSA_FRONT-NL_1 | U31: 224096 | V31: Tallih Nahid | W31: R | X31: 0.00094907407 | Y31: 0 | Z31: 0.00038194444 | AB31: 0 | AC31: 46268.308 | AE31: 0 | AF31: 20260903072240654311887 | AG31: 2.3148148e-05 | AH31: 0 | AI31: 0 | AK31: 2 | AL31: 0 | AM31: 0 | AN31: NL | AO31: vb3151 | AP31: 77020001 | AQ31: 10 | AR31: Maud | AS31: 3190051 | AT31: Geen Intent | AV31: +31611247401 | AW31: 2 | AX31: 1 | BN31: Alliannz Contract | BO31: 46268 | BP31: =1 -> 1 | BQ31: =IF(M31+AG31>=parametres!$B$2,0,1) -> 1 | BR31: =VLOOKUP(O31,parametres!G:H,2,0) -> Alliannz Contract
A32: AP-Historical-Report---Call-by-Call 2026-09-03 0000 - 2026-09-03 1500.csv | B32: F | C32: O | D32: 46268.307 | E32: +31611247401 | H32: WebiPath_180_177847 | J32: 2.7421294e+18 | K32: 39.4309854 | M32: 0 | N32: 19761 | O32: APBN_AMS_MOBILITY_INSURAN_FollowUp_NL | P32: 21200 | Q32: APBN_AMS_MOBILITY_INSURAN_FollowUp_NL | R32: 99821 | S32: APBN_AMS_MOBILITY_INSURAN_FollowUp_NL_1 | T32: APBN_CMN_RSA_FRONT-NL_1 | U32: 224096 | V32: Tallih Nahid | W32: R | X32: 0.00094907407 | Y32: 0 | Z32: 0 | AB32: 0 | AC32: 46268.308 | AE32: 0 | AF32: 20260903072240654311887 | AG32: 1.1574074e-05 | BN32: Alliannz Contract | BO32: 46268 | BP32: =1 -> 1 | BQ32: =IF(M32+AG32>=parametres!$B$2,0,1) -> 1 | BR32: =VLOOKUP(O32,parametres!G:H,2,0) -> Alliannz Contract
A33: AP-Historical-Report---Call-by-Call 2026-09-03 0000 - 2026-09-03 1500.csv | B33: F | C33: I | D33: 46268.309 | E33: +31882692888 | F33: Chery | G33: RSA_SubLOB | H33: +31208512232 | I33: APBN_AMS_MOBILITY_OEM-CONS_Front | J33: 2.7421293e+18 | K33: 23.11599289 | L33: Route_Queue | M33: 5.787037e-05 | N33: 19755 | O33: APBN_AMS_MOBILITY_OEM-CONS_Front_NL | P33: 21194 | Q33: APBN_AMS_MOBILITY_OEM-CONS_Front_NL | R33: 99757 | S33: APBN_AMS_MOBILITY_OEM-CONS_Front_NL_3 | T33: APBN_CMN_RSA_FRONT-NL_1 | U33: 96526 | V33: Said Hajhouj | W33: R | X33: 0.0055092593 | Y33: 0 | Z33: 0.00038194444 | AB33: 0 | AC33: 46268.315 | AE33: 0 | AF33: 20260903072542385876135 | AG33: 2.3148148e-05 | AH33: 0 | AI33: 0 | AK33: 2 | AL33: 0 | AM33: 0 | AN33: NL | AW33: 0 | AX33: 0 | BN33: RSA | BO33: 46268 | BP33: =1 -> 1 | BQ33: =IF(M33+AG33>=parametres!$B$2,0,1) -> 1 | BR33: =VLOOKUP(O33,parametres!G:H,2,0) -> RSA
A34: AP-Historical-Report---Call-by-Call 2026-09-03 0000 - 2026-09-03 1500.csv | B34: F | C34: O | D34: 46268.31 | E34: +31882692888 | H34: WebiPath_180_102661 | J34: 2.7421293e+18 | K34: 23.11599290 | M34: 0 | N34: 19755 | O34: APBN_AMS_MOBILITY_OEM-CONS_Front_NL | P34: 21194 | Q34: APBN_AMS_MOBILITY_OEM-CONS_Front_NL | R34: 99757 | S34: APBN_AMS_MOBILITY_OEM-CONS_Front_NL_3 | T34: APBN_CMN_RSA_FRONT-NL_1 | U34: 96526 | V34: Said Hajhouj | W34: L | X34: 0.0055092593 | Y34: 0 | Z34: 0 | AB34: 0 | AC34: 46268.315 | AE34: 0 | AF34: 20260903072542385876135 | AG34: 1.1574074e-05 | BN34: RSA | BO34: 46268 | BP34: =1 -> 1 | BQ34: =IF(M34+AG34>=parametres!$B$2,0,1) -> 1 | BR34: =VLOOKUP(O34,parametres!G:H,2,0) -> RSA
A35: AP-Historical-Report---Call-by-Call 2026-09-03 0000 - 2026-09-03 1500.csv | B35: F | C35: I | D35: 46268.316 | E35: +31610122791 | F35: AzNetherlands | G35: RSA_INSUR | H35: +31205929118 | I35: APBN_AMS_RSA_INSURAN_AzN | J35: 2.7421294e+18 | K35: 43.4240261 | L35: Route_Queue | M35: 6.9444444e-05 | N35: 27173 | O35: APBN_AMS_RSA_INSURAN_AzN_NL | P35: 28184 | Q35: APBN_AMS_RSA_INSURAN_AzN_NL | R35: 208567 | S35: APBN_AMS_RSA_INSURAN_AzN_NL_1 | T35: APBN_CMN_RSA_FRONT-NL_1 | U35: 221519 | V35: Dylan Micha Joren | W35: R | X35: 0.0015972222 | Y35: 0 | Z35: 0.0014236111 | AB35: 0 | AC35: 46268.319 | AE35: 0 | AF35: 20260903073730721422115 | AG35: 3.4722222e-05 | AH35: 0 | AI35: 0 | AK35: 2 | AL35: 0 | AM35: 0 | AN35: NL | AO35: vb3177108 | AP35: 77020108 | AQ35: 10 | AR35: vb3177108 | AS35: 3190911811 | AT35: default_agentIntent | AU35: Unknown | AV35: +31610122791 | AW35: 2 | AX35: 1 | BN35: Alliannz Contract | BO35: 46268 | BP35: =1 -> 1 | BQ35: =IF(M35+AG35>=parametres!$B$2,0,1) -> 1 | BR35: =VLOOKUP(O35,parametres!G:H,2,0) -> Alliannz Contract
A36: AP-Historical-Report---Call-by-Call 2026-09-03 0000 - 2026-09-03 1500.csv | B36: F | C36: O | D36: 46268.318 | E36: +31610122791 | H36: WebiPath_180_176330 | J36: 2.7421294e+18 | K36: 43.4240274 | M36: 0 | N36: 27173 | O36: APBN_AMS_RSA_INSURAN_AzN_NL | P36: 28184 | Q36: APBN_AMS_RSA_INSURAN_AzN_NL | R36: 208567 | S36: APBN_AMS_RSA_INSURAN_AzN_NL_1 | T36: APBN_CMN_RSA_FRONT-NL_1 | U36: 221519 | V36: Dylan Micha Joren | W36: R | X36: 0.0015972222 | Y36: 0 | Z36: 0 | AB36: 0 | AC36: 46268.319 | AE36: 0 | AF36: 20260903073730721422115 | AG36: 1.1574074e-05 | BN36: Alliannz Contract | BO36: 46268 | BP36: =1 -> 1 | BQ36: =IF(M36+AG36>=parametres!$B$2,0,1) -> 1 | BR36: =VLOOKUP(O36,parametres!G:H,2,0) -> Alliannz Contract
A37: AP-Historical-Report---Call-by-Call 2026-09-03 0000 - 2026-09-03 1500.csv | B37: F | C37: I | D37: 46268.32 | E37: +33658339527 | F37: AP_NL_RSA | G37: RSA_SubLOB | H37: +31208512294 | I37: APBN_AMS_MOBILITY_INSURAN_Front | J37: 2.7421294e+18 | K37: 37.4333641 | L37: Route_Queue | M37: 9.2592593e-05 | N37: 19760 | O37: APBN_AMS_MOBILITY_INSURAN_Front_NL | P37: 21199 | Q37: APBN_AMS_MOBILITY_INSURAN_Front_NL | R37: 99810 | S37: APBN_AMS_MOBILITY_INSURAN_Front_NL_1 | T37: APBN_CMN_RSA_FRONT-NL_1 | U37: 224299 | V37: Jacqueline Sint | W37: R | X37: 0.00090277778 | Y37: 0 | Z37: 9.2592593e-05 | AB37: 0 | AC37: 46268.321 | AE37: 0 | AF37: 20260903074109620758255 | AG37: 3.4722222e-05 | AH37: 0 | AI37: 0 | AK37: 2 | AL37: 0 | AM37: 0 | AN37: NL | AO37: vb3151 | AP37: 77020001 | AQ37: 10 | AR37: Maud | AS37: 3190096 | AT37: Geen Intent | AV37: +33658339527 | AW37: 2 | AX37: 1 | BN37: Alliannz Contract | BO37: 46268 | BP37: =1 -> 1 | BQ37: =IF(M37+AG37>=parametres!$B$2,0,1) -> 1 | BR37: =VLOOKUP(O37,parametres!G:H,2,0) -> Alliannz Contract
A38: AP-Historical-Report---Call-by-Call 2026-09-03 0000 - 2026-09-03 1500.csv | B38: F | C38: I | D38: 46268.32 | E38: +31707592640 | F38: KIA | G38: RSA_SubLOB | H38: +31208512235 | I38: APBN_AMS_MOBILITY_INSURAN_FollowUp | J38: 2.7421294e+18 | K38: 33.8488832 | L38: Route_Queue | M38: 9.2592593e-05 | N38: 19761 | O38: APBN_AMS_MOBILITY_INSURAN_FollowUp_NL | P38: 21200 | Q38: APBN_AMS_MOBILITY_INSURAN_FollowUp_NL | R38: 99821 | S38: APBN_AMS_MOBILITY_INSURAN_FollowUp_NL_1 | T38: APBN_CMN_RSA_FRONT-NL_1 | U38: 224096 | V38: Tallih Nahid | W38: R | X38: 0.000625 | Y38: 0 | Z38: 0.0014583333 | AB38: 0 | AC38: 46268.322 | AE38: 0 | AF38: 20260903074208553649316 | AG38: 3.4722222e-05 | AH38: 0 | AI38: 0 | AK38: 2 | AL38: 0 | AM38: 0 | AN38: NL | AO38: vb3151 | AP38: 77020001 | AQ38: 10 | AR38: Maud | AS38: 3190032 | AT38: Lekke band / bandenprobleem in Nederland | AV38: +31707592640 | AW38: 2 | AX38: 1 | BN38: Alliannz Contract | BO38: 46268 | BP38: =1 -> 1 | BQ38: =IF(M38+AG38>=parametres!$B$2,0,1) -> 1 | BR38: =VLOOKUP(O38,parametres!G:H,2,0) -> Alliannz Contract
A39: AP-Historical-Report---Call-by-Call 2026-09-03 0000 - 2026-09-03 1500.csv | B39: F | C39: O | D39: 46268.32 | E39: +33658339527 | H39: WebiPath_180_177942 | J39: 2.7421294e+18 | K39: 37.4333645 | M39: 0 | N39: 19760 | O39: APBN_AMS_MOBILITY_INSURAN_Front_NL | P39: 21199 | Q39: APBN_AMS_MOBILITY_INSURAN_Front_NL | R39: 99810 | S39: APBN_AMS_MOBILITY_INSURAN_Front_NL_1 | T39: APBN_CMN_RSA_FRONT-NL_1 | U39: 224299 | V39: Jacqueline Sint | W39: R | X39: 0.00090277778 | Y39: 0 | Z39: 0 | AB39: 0 | AC39: 46268.321 | AE39: 0 | AF39: 20260903074109620758255 | AG39: 1.1574074e-05 | BN39: Alliannz Contract | BO39: 46268 | BP39: =1 -> 1 | BQ39: =IF(M39+AG39>=parametres!$B$2,0,1) -> 1 | BR39: =VLOOKUP(O39,parametres!G:H,2,0) -> Alliannz Contract
A40: AP-Historical-Report---Call-by-Call 2026-09-03 0000 - 2026-09-03 1500.csv | B40: F | C40: O | D40: 46268.321 | E40: +31707592640 | H40: WebiPath_180_177847 | J40: 2.7421294e+18 | K40: 33.8488837 | M40: 0 | N40: 19761 | O40: APBN_AMS_MOBILITY_INSURAN_FollowUp_NL | P40: 21200 | Q40: APBN_AMS_MOBILITY_INSURAN_FollowUp_NL | R40: 99821 | S40: APBN_AMS_MOBILITY_INSURAN_FollowUp_NL_1 | T40: APBN_CMN_RSA_FRONT-NL_1 | U40: 224096 | V40: Tallih Nahid | W40: L | X40: 0.000625 | Y40: 0 | Z40: 0 | AB40: 0 | AC40: 46268.322 | AE40: 0 | AF40: 20260903074208553649316 | AG40: 1.1574074e-05 | BN40: Alliannz Contract | BO40: 46268 | BP40: =1 -> 1 | BQ40: =IF(M40+AG40>=parametres!$B$2,0,1) -> 1 | BR40: =VLOOKUP(O40,parametres!G:H,2,0) -> Alliannz Contract
...

Sheet SL 20 sec

Sheet parametres
B1: SLA | G1: Queue | H1: Designation
B2: 0.00023148148 | D2: RSA | G2: APBN_AMS_MOBILITY_INSURAN_FollowUp_NL | H2: Alliannz Contract
D3: RSA | G3: APBN_AMS_MOBILITY_INTERNAT_FollowUp_NL | H3: Alliannz Contract | L3: OBILITY_INTERNAT_Front_NL | M3: APBN_AMS_MOBILITY_OEM-CONS_FollowUp_NL | N3: APBN_AMS_MOBILITY_OEM-CONS_Front_NL | O3: APBN_AMS_MOBILITY_VIP_Front_NL
D4: RSA | G4: APBN_AMS_MOBILITY_INTERNAT_Front_NL | H4: Alliannz Contract | L4: Mettre à jour
D5: Alliannz Contract | G5: APBN_AMS_RSA_INSURAN_All_NL | H5: Alliannz Contract
D6: Alliannz Contract | G6: APBN_AMS_RSA_INSURAN_AzN_NL | H6: Alliannz Contract
D7: Alliannz Contract | G7: APBN_AMS_RSA_INTERNAT_All_NL | H7: Alliannz Contract
D8: RSA | G8: APBN_AMS_MOBILITY_INSURAN_Front_NL | H8: Alliannz Contract
D9: RSA | G9: APBN_BRU_RSA_INTERNAT_All_VL | H9: Alliannz Contract BE
D10: RSA | G10: APBN_BRU_RSA_INTERNAT_All_FR | H10: Alliannz Contract BE | K10: APBN_AMS_MOBILITY_INSURAN_Front_NL
D11: RSA | G11: APBN_BRU_RSA_INSURAN_AB_VL | H11: Alliannz Contract BE | K11: APBN_AMS_MOBILITY_OEM-CONS_FollowUp_NL
D12: RSA | G12: APBN_BRU_RSA_INSURAN_AB_FR | H12: Alliannz Contract BE | K12: APBN_AMS_MOBILITY_OEM-CONS_Front_NL
D13: RSA | G13: APBN_AMS_MOBILITY_BIKE_Bike_NL | H13: RSA | K13: APBN_AMS_MOBILITY_VIP_Front_NL
D14: Alliannz Contract | G14: APBN_AMS_MOBILITY_CRM_ConciergeBBH_NL | H14: RSA
D15: Alliannz Contract | G15: APBN_AMS_MOBILITY_INSURAN_AllianzNetherlandsOEM_NL | H15: RSA
D16: Alliannz Contract | G16: APBN_AMS_MOBILITY_LEASE-RE_FollowUp_NL | H16: RSA
D17: Alliannz Contract | G17: APBN_AMS_MOBILITY_LEASE-RE_Front_NL | H17: RSA
D18: RSA | G18: APBN_AMS_MOBILITY_VIP_FollowUp_NL | H18: RSA
D19: RSA | G19: APBN_AMS_MOBILITY_OEM-CONS_FollowUp_NL | H19: RSA
D20: RSA | G20: APBN_AMS_MOBILITY_OEM-CONS_Front_NL | H20: RSA
G21: APBN_AMS_MOBILITY_VIP_Front_NL | H21: RSA
G22: BRU_MOBILITY_BIKE_Bike_FR | H22: RSA BE
G23: APBN_BRU_MOBILITY_INSURAN_Front_FR | H23: RSA BE
G24: APBN_BRU_MOBILITY_INTERNAT_Front_FR | H24: RSA BE
G25: APBN_BRU_MOBILITY_OEM-CONS_Front_FR | H25: RSA BE
G26: APBN_BRU_MOBILITY_VIP_Front_FR | H26: RSA BE
G27: APBN_BRU_RSA_INSURAN_All_FR | H27: RSA BE
G28: BRU_MOBILITY_BIKE_Bike_VL | H28: RSA BE
G29: APBN_BRU_MOBILITY_INSURAN_Front_VL | H29: RSA BE
G30: APBN_BRU_MOBILITY_INTERNAT_Front_VL | H30: RSA BE
G31: APBN_BRU_MOBILITY_OEM-CONS_Front_VL | H31: RSA BE
G32: APBN_BRU_MOBILITY_VIP_Front_VL | H32: RSA BE
... G37: APBN_AMS_MOBILITY_PROVIDER_Morocco_NL | H37: RSA Provider

Sheet Croisé (2)
N4: Étiquettes de colonnes
N5: (vide) | O5: Total général
M6: Somme de SLA% | N6: #DIV/0! | O6: #DIV/0!
M10: [Agent] | N10: (Tous)
M12: Somme de Call Received | N12: Étiquettes de colonnes
M13: Étiquettes de lignes | N13: (vide) | O13: Total général
M14: (vide)
M15: Total général
A24: [Call Direction] | B24: I
A25: [Agent] | B25: (Tous)
A26: [Queue] | B26: (Tous)
A27: Call in SL | B27: (Plusieurs éléments)
A29: Calls Answered | B29: Queue
A30: Date | B30: Total général
A31: Total général

Sheet Feuil4
B1: Date | C1: Heures ([Call Date/Time]) | D1: RSA NL
B2: 46235 | C2: 00 | D2: 10 | F2: 00 | G2: 70 | I2: 00 | J2: =SUMIFS(D:D,C:C,I2) -> 108 | K2: =J2-G2 -> 38
B3: 46235 | C3: 01 | D3: 4 | F3: 01 | G3: 49 | I3: 01 | J3: =SUMIFS(D:D,C:C,I3) -> 65 | K3: =J3-G3 -> 16
B4: 46235 | C4: 02 | D4: 2 | F4: 02 | G4: 35 | I4: 02 | J4: =SUMIFS(D:D,C:C,I4) -> 47 | K4: =J4-G4 -> 12
B5: 46235 | C5: 03 | D5: 1 | F5: 03 | G5: 36 | I5: 03 | J5: =SUMIFS(D:D,C:C,I5) -> 45 | K5: =J5-G5 -> 9
B6: 46235 | C6: 04 | D6: 1 | F6: 04 | G6: 22 | I6: 04 | J6: =SUMIFS(D:D,C:C,I6) -> 28 | K6: =J6-G6 -> 6
B7: 46235 | C7: 05 | D7: 5 | F7: 05 | G7: 52 | I7: 05 | J7: =SUMIFS(D:D,C:C,I7) -> 64 | K7: =J7-G7 -> 12
B8: 46235 | C8: 06 | D8: 9 | F8: 06 | G8: 136 | I8: 06 | J8: =SUMIFS(D:D,C:C,I8) -> 147 | K8: =J8-G8 -> 11
B9: 46235 | C9: 23 | D9: 24 | F9: 23 | G9: 125 | I9: 23 | J9: =SUMIFS(D:D,C:C,I9) -> 187 | K9: =J9-G9 -> 62
B10: Total 01/08/2026 | D10: 56
B11: 46236 | C11: 00 | D11: 13
B12: 46236 | C12: 01 | D12: 13
B13: 46236 | C13: 02 | D13: 2
B14: 46236 | C14: 03 | D14: 6
B15: 46236 | C15: 04 | D15: 4
B16: 46236 | C16: 05 | D16: 10
B17: 46236 | C17: 06 | D17: 6
B18: 46236 | C18: 23 | D18: 8
B19: Total 02/08/2026 | D19: 62
B20: 46237 | C20: 00 | D20: 1
B21: 46237 | C21: 01 | D21: 3
B22: 46237 | C22: 02 | D22: 2
B23: 46237 | C23: 03 | D23: 2
B24: 46237 | C24: 04 | D24: 2
B25: 46237 | C25: 05 | D25: 7
B26: 46237 | C26: 06 | D26: 11
B27: 46237 | C27: 23 | D27: 9
B28: Total 03/08/2026 | D28: 37
B29: 46238 | C29: 00 | D29: 8
B30: 46238 | C30: 01 | D30: 2
B31: 46238 | C31: 02 | D31: 2
B32: 46238 | C32: 03 | D32: 3
B33: 46238 | C33: 05 | D33: 1
B34: 46238 | C34: 06 | D34: 10
B35: 46238 | C35: 23 | D35: 8
B36: Total 04/08/2026 | D36: 34
B37: 46239 | C37: 00 | D37: 2
B38: 46239 | C38: 01 | D38: 1
B39: 46239 | C39: 03 | D39: 3
B40: 46239 | C40: 04 | D40: 1
...

Sheet Feuil2
A1: Date | B1: Heures ([Call Date/Time]) | C1: Calls
A2: 46235 | B2: 1 | C2: =SUMIFS('Croisé (2)'!C:C,'Croisé (2)'!B:B,Feuil2!B2,'Croisé (2)'!A:A,Feuil2!A2) -> 0
A3: 46235 | B3: 2 | C3: =SUMIFS('Croisé (2)'!C:C,'Croisé (2)'!B:B,Feuil2!B3,'Croisé (2)'!A:A,Feuil2!A3) -> 0
A4: 46235 | B4: 3 | C4: =SUMIFS('Croisé (2)'!C:C,'Croisé (2)'!B:B,Feuil2!B4,'Croisé (2)'!A:A,Feuil2!A4) -> 0 | F4: =IF(G4="","",A4) | G4: =IF(B4=7,SUM(C4:C18),"") | I4: =IF(J4="","",D4) | J4: =IF(E4=7,SUM(F4:F18),"")
A5: 46235 | B5: 7 | C5: =SUMIFS('Croisé (2)'!C:C,'Croisé (2)'!B:B,Feuil2!B5,'Croisé (2)'!A:A,Feuil2!A5) -> 0 | F5: =IF(G5="","",A5) -> 46235 | G5: =IF(B5=7,SUM(C5:C20),"") -> 0 | I5: =IF(J5="","",D5) | J5: =IF(E5=7,SUM(F5:F19),"")
A6: 46235 | B6: 8 | C6: =SUMIFS('Croisé (2)'!C:C,'Croisé (2)'!B:B,Feuil2!B6,'Croisé (2)'!A:A,Feuil2!A6) -> 0 | F6: =IF(G6="","",A6) | G6: =IF(B6=7,SUM(C6:C21),"") | I6: =IF(J6="","",D6) | J6: =IF(E6=7,SUM(F6:F20),"")
A7: 46235 | B7: 9 | C7: =SUMIFS('Croisé (2)'!C:C,'Croisé (2)'!B:B,Feuil2!B7,'Croisé (2)'!A:A,Feuil2!A7) -> 0 | F7: =IF(G7="","",A7) | G7: =IF(B7=7,SUM(C7:C22),"") | I7: =IF(J7="","",D7) | J7: =IF(E7=7,SUM(F7:F21),"")
A8: 46235 | B8: 10 | C8: =SUMIFS('Croisé (2)'!C:C,'Croisé (2)'!B:B,Feuil2!B8,'Croisé (2)'!A:A,Feuil2!A8) -> 0 | F8: =IF(G8="","",A8) | G8: =IF(B8=7,SUM(C8:C23),"") | I8: =IF(J8="","",D8) | J8: =IF(E8=7,SUM(F8:F22),"")
A9: 46235 | B9: 11 | C9: =SUMIFS('Croisé (2)'!C:C,'Croisé (2)'!B:B,Feuil2!B9,'Croisé (2)'!A:A,Feuil2!A9) -> 0 | F9: =IF(G9="","",A9) | G9: =IF(B9=7,SUM(C9:C24),"") | I9: =IF(J9="","",D9) | J9: =IF(E9=7,SUM(F9:F23),"")
A10: 46235 | B10: 12 | C10: =SUMIFS('Croisé (2)'!C:C,'Croisé (2)'!B:B,Feuil2!B10,'Croisé (2)'!A:A,Feuil2!A10) -> 0 | F10: =IF(G10="","",A10) | G10: =IF(B10=7,SUM(C10:C25),"") | I10: =IF(J10="","",D10) | J10: =IF(E10=7,SUM(F10:F24),"")
A11: 46235 | B11: 13 | C11: =SUMIFS('Croisé (2)'!C:C,'Croisé (2)'!B:B,Feuil2!B11,'Croisé (2)'!A:A,Feuil2!A11) -> 0 | F11: =IF(G11="","",A11) | G11: =IF(B11=7,SUM(C11:C26),"") | I11: =IF(J11="","",D11) | J11: =IF(E11=7,SUM(F11:F25),"")
A12: 46235 | B12: 14 | C12: =SUMIFS('Croisé (2)'!C:C,'Croisé (2)'!B:B,Feuil2!B12,'Croisé (2)'!A:A,Feuil2!A12) -> 0 | F12: =IF(G12="","",A12) | G12: =IF(B12=7,SUM(C12:C27),"") | I12: =IF(J12="","",D12) | J12: =IF(E12=7,SUM(F12:F26),"")
A13: 46235 | B13: 15 | C13: =SUMIFS('Croisé (2)'!C:C,'Croisé (2)'!B:B,Feuil2!B13,'Croisé (2)'!A:A,Feuil2!A13) -> 0 | F13: =IF(G13="","",A13) | G13: =IF(B13=7,SUM(C13:C28),"") | I13: =IF(J13="","",D13) | J13: =IF(E13=7,SUM(F13:F27),"")
A14: 46235 | B14: 16 | C14: =SUMIFS('Croisé (2)'!C:C,'Croisé (2)'!B:B,Feuil2!B14,'Croisé (2)'!A:A,Feuil2!A14) -> 0 | F14: =IF(G14="","",A14) | G14: =IF(B14=7,SUM(C14:C29),"") | I14: =IF(J14="","",D14) | J14: =IF(E14=7,SUM(F14:F28),"")
A15: 46235 | B15: 17 | C15: =SUMIFS('Croisé (2)'!C:C,'Croisé (2)'!B:B,Feuil2!B15,'Croisé (2)'!A:A,Feuil2!A15) -> 0 | F15: =IF(G15="","",A15) | G15: =IF(B15=7,SUM(C15:C30),"") | I15: =IF(J15="","",D15) | J15: =IF(E15=7,SUM(F15:F29),"")
A16: 46235 | B16: 18 | C16: =SUMIFS('Croisé (2)'!C:C,'Croisé (2)'!B:B,Feuil2!B16,'Croisé (2)'!A:A,Feuil2!A16) -> 0 | F16: =IF(G16="","",A16) | G16: =IF(B16=7,SUM(C16:C31),"") | I16: =IF(J16="","",D16) | J16: =IF(E16=7,SUM(F16:F30),"")
... A457: 46256 | B457: 23 | C457: =SUMIFS('Croisé (2)'!C:C,'Croisé (2)'!B:B,Feuil2!B457,'Croisé (2)'!A:A,Feuil2!A457) -> 0 | F457: =IF(G457="","",A457) | G457: =IF(B457=7,SUM(C457:C472),"") | I457: =IF(J457="","",D457) | J457: =IF(E457=7,SUM(F457:F471),"")

Sheet Feuil3
A1: Total 01/08/2026 | C1: 32 | D1: 32 | G1: Total 01/08/2026 | I1: 24 | J1: 24 | K1: =D1-J1 -> 8 | N1: Date | O1: Heures ([Call Date/Time]) | P1: RSA NL
A2: Total 02/08/2026 | C2: 54 | D2: 54 | G2: Total 02/08/2026 | I2: 30 | J2: 30 | K2: =D2-J2 -> 24 | N2: 46235 | O2: 00 | P2: 5
A3: Total 03/08/2026 | C3: 28 | D3: 28 | G3: Total 03/08/2026 | I3: 22 | J3: 22 | K3: =D3-J3 -> 6 | N3: 46235 | O3: 01 | P3: 4
A4: Total 04/08/2026 | C4: 26 | D4: 26 | G4: Total 04/08/2026 | I4: 24 | J4: 24 | K4: =D4-J4 -> 2 | N4: 46235 | O4: 02 | P4: 2
A5: Total 05/08/2026 | C5: 17 | D5: 17 | G5: Total 05/08/2026 | I5: 16 | J5: 16 | K5: =D5-J5 -> 1 | N5: 46235 | O5: 03 | P5: 1
A6: Total 06/08/2026 | C6: 28 | D6: 28 | G6: Total 06/08/2026 | I6: 22 | J6: 22 | K6: =D6-J6 -> 6 | N6: 46235 | O6: 04 | P6: 1
A7: Total 07/08/2026 | C7: 15 | D7: 15 | G7: Total 07/08/2026 | I7: 15 | J7: 15 | K7: =D7-J7 -> 0 | N7: 46235 | O7: 05 | P7: 4
A8: Total 08/08/2026 | C8: 18 | D8: 18 | G8: Total 08/08/2026 | I8: 18 | J8: 18 | K8: =D8-J8 -> 0 | N8: 46235 | O8: 06 | P8: 7
A9: Total 09/08/2026 | C9: 38 | D9: 38 | G9: Total 09/08/2026 | I9: 27 | J9: 27 | K9: =D9-J9 -> 11 | N9: 46235 | O9: 23 | P9: 9
A10: Total 10/08/2026 | C10: 26 | D10: 26 | G10: Total 10/08/2026 | I10: 22 | J10: 22 | K10: =D10-J10 -> 4 | N10: 46236 | O10: 00 | P10: 6
A11: Total 11/08/2026 | C11: 24 | D11: 24 | G11: 46246 | H11: 00 | I11: 1 | J11: 1 | K11: =D11-J11 -> 23 | N11: 46236 | O11: 01 | P11: 6
A12: Total 12/08/2026 | C12: 21 | D12: 21 | G12: 46247 | H12: 00 | I12: 2 | J12: 2 | K12: =D12-J12 -> 19 | N12: 46236 | O12: 02 | P12: 1
A13: Total 13/08/2026 | C13: 18 | D13: 18 | G13: 46248 | H13: 00 | I13: 4 | J13: 4 | K13: =D13-J13 -> 14 | N13: 46236 | O13: 03 | P13: 4
A14: Total 14/08/2026 | C14: 26 | D14: 26 | G14: 46249 | H14: 00 | I14: 5 | J14: 5 | K14: =D14-J14 -> 21 | N14: 46236 | O14: 04 | P14: 2
A15: Total 15/08/2026 | C15: 22 | D15: 22 | G15: 46250 | H15: 00 | I15: 4 | J15: 4 | K15: =D15-J15 -> 18 | N15: 46236 | O15: 05 | P15: 7
A16: Total 16/08/2026 | C16: 27 | D16: 27 | G16: 46251 | H16: 00 | I16: 1 | J16: 1 | K16: =D16-J16 -> 26 | N16: 46236 | O16: 06 | P16: 4
A17: Total 17/08/2026 | C17: 14 | D17: 14 | G17: 46252 | H17: 01 | I17: 2 | J17: 2 | K17: =D17-J17 -> 12 | N17: 46236 | O17: 23 | P17: 4
A18: Total 18/08/2026 | C18: 14 | D18: 14 | G18: 46253 | H18: 01 | I18: 1 | J18: 1 | K18: =D18-J18 -> 13 | N18: 46237 | O18: 00 | P18: 1
A19: Total 19/08/2026 | C19: 11 | D19: 11 | G19: 46254 | H19: 01 | I19: 1 | J19: 1 | K19: =D19-J19 -> 10 | N19: 46237 | O19: 01 | P19: 2
A20: Total 20/08/2026 | C20: 13 | D20: 13 | G20: 46255 | H20: 01 | I20: 1 | J20: 1 | K20: =D20-J20 -> 12 | N20: 46237 | O20: 02 | P20: 1
A21: Total 21/08/2026 | C21: 12 | D21: 12 | G21: 46256 | H21: 01 | I21: 3 | J21: 3 | K21: =D21-J21 -> 9 | N21: 46237 | O21: 03 | P21: 2
A22: Total 22/08/2026 | C22: 20 | D22: 20 | N22: 46237 | O22: 04 | P22: 1
N23: 46237 | O23: 05 | P23: 5
N24: 46237 | O24: 06 | P24: 10
N25: 46237 | O25: 23 | P25: 9
N26: 46238 | O26: 00 | P26: 6
N27: 46238 | O27: 01 | P27: 2
N28: 46238 | O28: 02 | P28: 2
N29: 46238 | O29: 03 | P29: 3
N30: 46238 | O30: 05 | P30: 1
N31: 46238 | O31: 06 | P31: 10
N32: 46238 | O32: 23 | P32: 7
N33: 46239 | O33: 00 | P33: 1
N34: 46239 | O34: 01 | P34: 1
... N158: 46256 | O158: 23 | P158: 11
