Workbook

Sheet Daily Flash NL
C1: 7 | D1: 7 | E1: 11 | F1: 12 | G1: 13 | H1: 6 | I1: 13 | J1: 13 | K1: 16 | L1: 16 | M1: 11 | N1: 10 | O1: 3 | P1: 7 | Q1: 5 | R1: 5 | S1: 5 | U1: 8 | W1: 8
U2: 10 | W2: 10
U3: 11 | W3: 10
J4: Partimers planned NL | K4: Partimers planned BE | U4: 11 | W4: 10
J5: 2 | K5: 0 | U5: 12 | W5: 10
S6: 1 | U6: 10 | W6: 7
U7: 9 | W7: 6
U8: 5 | W8: 6
U9: 5 | W9: 4
U10: 5 | W10: 4
U11: 5 | W11: 4
I12: OUT OFFICE SHRINKAGE
J13: RSA NL | K13: RSA BE | W13: RSA NL | X13: RSA BE | AF13: RSA NL | AG13: RSA BE
I14: Planned in HC | J14: =J15/8.75 -> 0 | K14: =K15/8.75 -> 0 | V14: Planned in HC | W14: 20 | X14: 16 | AE14: Planned in HC | AF14: 19 | AG14: 15
I15: Planned in Hours | J15: =SUM(M34:M49) -> 0 | K15: =SUM(M87:M103) -> 0 | V15: Planned in Hours | W15: =(W14-(J5*0.75))*8.75 -> 161.875 | X15: =(X14-(X5*0.75))*8.75 -> 140 | AE15: Planned in Hours | AF15: =(AF14-(J5*0.75))*8.75 -> 153.125 | AG15: =(AG14-(AG5*0.75))*8.75 -> 131.25
I16: Absents in HC | J16: 0 | K16: 0 | V16: Absents in HC | W16: 3 | X16: =2/8.75 -> 0.22857143 | AE16: Absents in HC | AF16: 4.75 | AG16: 4
I17: Absents in Hours | J17: =SUM(N34:P49) -> 0 | K17: =SUM(N89:O103) -> 0 | V17: Absents in Hours | W17: =(W16*8.75) -> 26.25 | X17: =(X16*8.75) -> 2 | AE17: Absents in Hours | AF17: =AF16*8.75 -> 41.5625 | AG17: =AG16*8.75 -> 35
I18: Late Hours | J18: =SUM(P34:P63) -> 0 | K18: =SUM(P89:P118) -> 0 | V18: Late Hours | AE18: Late Hours
I19: Absence rate | J19: =(J18+J17)/J15 -> #DIV/0! | K19: =(K18+K17)/K15 -> #DIV/0! | V19: Absence rate | W19: =(W18+W17)/W15 -> 0.16216216 | X19: =(X18+X17)/X15 -> 0.014285714 | AE19: Absence rate | AF19: =(AF18+AF17)/AF15 -> 0.27142857 | AG19: =(AG16-AG18)/AG14 -> 0.26666667
D25: 46270
D27: TSL | F27: Availability | J27: Deviation | N27: Dispatch | P27: Absence Rate in HC
D28: =H64/G64 -> 0.91296625 | F28: =+SUM(G34:G63)/SUM(F33:F62) -> 0.99469965 | J28: =+SUM(F64)/SUM(E64) -> 0.99298246 | N28: 0 | P28: =J19 -> #DIV/0! | AD28: Average Threshold Deviation | AE28: Average Threshold Deviation | AF28: Average Threshold Deviation
AD29: =J28 -> 0.99298246 | AE29: 1 | AF29: 0.6
AD31: Scenario 1 | AE31: Scenario 2 | AF31: Scenario 2
D32: Hour | E32: Volume Forcasted | F32: Volume Actual | G32: Volume Handled | H32: Volume Handle in SL | I32: Deviation | J32: SL | K32: Availability | L32: AHT | M32: Planned | N32: Abs | O32: LT Sickness | P32: Late/early leave | Q32: % Abs | R32: Extras | S32: Volume Actual SL | Y32: Hour | Z32: Forecast | AA32: Actual Fc scenario 1 | AB32: Actual Fc scenario 2 | AC32: Actual Fc scenario 3 | AD32: Actual deviation until EOD | AE32: 100% deviation until EOD | AF32: 90% deviation until EOD
Y33: 6 | Z33: =IF(SUMIFS('Daily Forecast'!D:D,'Daily Forecast'!B:B,$D$25,'Daily Forecast'!F:F,Y33,'Daily Forecast'!A:A,"Netherlands")=0,"",SUMIFS('Daily Forecast'!D:D,'Daily Forecast'!B:B,$D$25,'Daily Forecast'!F:F,Y33,'Daily Forecast'!A:A,"Netherlands")) -> 4 | AA33: =IFERROR(AD33/$J33,AD33) -> 3.9719298 | AB33: =IFERROR(AE33/$J33,AE33) -> 4 | AC33: =IFERROR(AF33/$J33,AF33) -> 2.4 | AD33: =IFERROR(IF(S33="",Z33*$AD$29,S33*J33),0) -> 3.9719298 | AE33: =IFERROR(IF(S33="",Z33*$AE$29,S33*J33),0) -> 4 | AF33: =IFERROR(IF(S33="",Z33*$AF$29,S33*J33),0) -> 2.4
A34: 7 | D34: 0.29166667 | E34: 12 | F34: 11 | G34: 9 | H34: 8 | I34: =IFERROR(Table1[[#This Row],[Volume Actual]]/Table1[[#This Row],[Volume Forcasted]],"") -> 0.91666667 | J34: =IFERROR(H34/G34,"") -> 0.88888889 | K34: =+IFERROR(Table1[[#This Row],[Volume Handled]]/Table1[[#This Row],[Volume Actual]],"") -> 0.81818182 | L34: 395.66667 | Q34: =(O34+N34)/M34 -> #DIV/0! | S34: =IF(SUMIFS('Daily Storm Data 2'!I:I,'Daily Storm Data 2'!$A:$A,$D$25,'Daily Storm Data 2'!$G:$G,$A34,'Daily Storm Data 2'!$E:$E,"Netherlands")=0,"",SUMIFS('Daily Storm Data 2'!I:I,'Daily Storm Data 2'!$A:$A,$D$25,'Daily Storm Data 2'!$G:$G,$A34,'Daily Storm Data 2'!$E:$E,"Netherlands")) | Y34: =+Y33+1 -> 7 | Z34: =IF(SUMIFS('Daily Forecast'!D:D,'Daily Forecast'!B:B,$D$25,'Daily Forecast'!F:F,Y34,'Daily Forecast'!A:A,"Netherlands")=0,"",SUMIFS('Daily Forecast'!D:D,'Daily Forecast'!B:B,$D$25,'Daily Forecast'!F:F,Y34,'Daily Forecast'!A:A,"Netherlands")) -> 12 | AA34: =IFERROR(AD34/$J34,AD34) -> 13.405263 | AB34: =IFERROR(AE34/$J34,AE34) -> 13.5 | AC34: =IFERROR(AF34/$J34,AF34) -> 8.1 | AD34: =IFERROR(IF(S34="",Z34*$AD$29,S34*J34),0) -> 11.915789 | AE34: =IFERROR(IF(S34="",Z34*$AE$29,S34*J34),0) -> 12 | AF34: =IFERROR(IF(S34="",Z34*$AF$29,S34*J34),0) -> 7.2
A35: =+A34+1 -> 8 | D35: 0.33333333 | E35: 19 | F35: 35 | G35: 35 | H35: 34 | I35: =IFERROR(Table1[[#This Row],[Volume Actual]]/Table1[[#This Row],[Volume Forcasted]],"") -> 1.8421053 | J35: =IFERROR(H35/G35,"") -> 0.97142857 | K35: =+IFERROR(Table1[[#This Row],[Volume Handled]]/Table1[[#This Row],[Volume Actual]],"") -> 1 | L35: 354.08571 | Q35: =(O35+N35)/M35 -> #DIV/0! | S35: =IF(SUMIFS('Daily Storm Data 2'!I:I,'Daily Storm Data 2'!$A:$A,$D$25,'Daily Storm Data 2'!$G:$G,$A35,'Daily Storm Data 2'!$E:$E,"Netherlands")=0,"",SUMIFS('Daily Storm Data 2'!I:I,'Daily Storm Data 2'!$A:$A,$D$25,'Daily Storm Data 2'!$G:$G,$A35,'Daily Storm Data 2'!$E:$E,"Netherlands")) | Y35: =+Y34+1 -> 8 | Z35: =IF(SUMIFS('Daily Forecast'!D:D,'Daily Forecast'!B:B,$D$25,'Daily Forecast'!F:F,Y35,'Daily Forecast'!A:A,"Netherlands")=0,"",SUMIFS('Daily Forecast'!D:D,'Daily Forecast'!B:B,$D$25,'Daily Forecast'!F:F,Y35,'Daily Forecast'!A:A,"Netherlands")) -> 19 | AA35: =IFERROR(AD35/$J35,AD35) -> 19.421569 | AB35: =IFERROR(AE35/$J35,AE35) -> 19.558824 | AC35: =IFERROR(AF35/$J35,AF35) -> 11.735294 | AD35: =IFERROR(IF(S35="",Z35*$AD$29,S35*J35),0) -> 18.866667 | AE35: =IFERROR(IF(S35="",Z35*$AE$29,S35*J35),0) -> 19 | AF35: =IFERROR(IF(S35="",Z35*$AF$29,S35*J35),0) -> 11.4 | AI35: Étiquettes de lignes | AJ35: I | AK35: (vide) | AL35: Total général
A36: =+A35+1 -> 9 | D36: 0.375 | E36: 46 | F36: 50 | G36: 50 | H36: 42 | I36: =IFERROR(Table1[[#This Row],[Volume Actual]]/Table1[[#This Row],[Volume Forcasted]],"") -> 1.0869565 | J36: =IFERROR(H36/G36,"") -> 0.84 | K36: =+IFERROR(Table1[[#This Row],[Volume Handled]]/Table1[[#This Row],[Volume Actual]],"") -> 1 | L36: 343.3 | Q36: =(O36+N36)/M36 -> #DIV/0! | S36: =IF(SUMIFS('Daily Storm Data 2'!I:I,'Daily Storm Data 2'!$A:$A,$D$25,'Daily Storm Data 2'!$G:$G,$A36,'Daily Storm Data 2'!$E:$E,"Netherlands")=0,"",SUMIFS('Daily Storm Data 2'!I:I,'Daily Storm Data 2'!$A:$A,$D$25,'Daily Storm Data 2'!$G:$G,$A36,'Daily Storm Data 2'!$E:$E,"Netherlands")) | Y36: =+Y35+1 -> 9 | Z36: =IF(SUMIFS('Daily Forecast'!D:D,'Daily Forecast'!B:B,$D$25,'Daily Forecast'!F:F,Y36,'Daily Forecast'!A:A,"Netherlands")=0,"",SUMIFS('Daily Forecast'!D:D,'Daily Forecast'!B:B,$D$25,'Daily Forecast'!F:F,Y36,'Daily Forecast'!A:A,"Netherlands")) -> 46 | AA36: =IFERROR(AD36/$J36,AD36) -> 54.377611 | AB36: =IFERROR(AE36/$J36,AE36) -> 54.761905 | AC36: =IFERROR(AF36/$J36,AF36) -> 32.857143 | AD36: =IFERROR(IF(S36="",Z36*$AD$29,S36*J36),0) -> 45.677193 | AE36: =IFERROR(IF(S36="",Z36*$AE$29,S36*J36),0) -> 46 | AF36: =IFERROR(IF(S36="",Z36*$AF$29,S36*J36),0) -> 27.6 | AI36: 3 | AJ36: 1 | AL36: 1
A37: =+A36+1 -> 10 | D37: 0.41666667 | E37: 56 | F37: 63 | G37: 63 | H37: 58 | I37: =IFERROR(Table1[[#This Row],[Volume Actual]]/Table1[[#This Row],[Volume Forcasted]],"") -> 1.125 | J37: =IFERROR(H37/G37,"") -> 0.92063492 | K37: =+IFERROR(Table1[[#This Row],[Volume Handled]]/Table1[[#This Row],[Volume Actual]],"") -> 1 | L37: 317.88889 | Q37: =(O37+N37)/M37 -> #DIV/0! | S37: =IF(SUMIFS('Daily Storm Data 2'!I:I,'Daily Storm Data 2'!$A:$A,$D$25,'Daily Storm Data 2'!$G:$G,$A37,'Daily Storm Data 2'!$E:$E,"Netherlands")=0,"",SUMIFS('Daily Storm Data 2'!I:I,'Daily Storm Data 2'!$A:$A,$D$25,'Daily Storm Data 2'!$G:$G,$A37,'Daily Storm Data 2'!$E:$E,"Netherlands")) | Y37: =+Y36+1 -> 10 | Z37: =IF(SUMIFS('Daily Forecast'!D:D,'Daily Forecast'!B:B,$D$25,'Daily Forecast'!F:F,Y37,'Daily Forecast'!A:A,"Netherlands")=0,"",SUMIFS('Daily Forecast'!D:D,'Daily Forecast'!B:B,$D$25,'Daily Forecast'!F:F,Y37,'Daily Forecast'!A:A,"Netherlands")) -> 56 | AA37: =IFERROR(AD37/$J37,AD37) -> 60.400726 | AB37: =IFERROR(AE37/$J37,AE37) -> 60.827586 | AC37: =IFERROR(AF37/$J37,AF37) -> 36.496552 | AD37: =IFERROR(IF(S37="",Z37*$AD$29,S37*J37),0) -> 55.607018 | AE37: =IFERROR(IF(S37="",Z37*$AE$29,S37*J37),0) -> 56 | AF37: =IFERROR(IF(S37="",Z37*$AF$29,S37*J37),0) -> 33.6 | AI37: 4 | AJ37: 1 | AL37: 1
A38: =+A37+1 -> 11 | D38: 0.45833333 | E38: 56 | F38: 69 | G38: 68 | H38: 58 | I38: =IFERROR(Table1[[#This Row],[Volume Actual]]/Table1[[#This Row],[Volume Forcasted]],"") -> 1.2321429 | J38: =IFERROR(H38/G38,"") -> 0.85294118 | K38: =+IFERROR(Table1[[#This Row],[Volume Handled]]/Table1[[#This Row],[Volume Actual]],"") -> 0.98550725 | L38: 312.77941 | Q38: =(O38+N38)/M38 -> #DIV/0! | S38: =IF(SUMIFS('Daily Storm Data 2'!I:I,'Daily Storm Data 2'!$A:$A,$D$25,'Daily Storm Data 2'!$G:$G,$A38,'Daily Storm Data 2'!$E:$E,"Netherlands")=0,"",SUMIFS('Daily Storm Data 2'!I:I,'Daily Storm Data 2'!$A:$A,$D$25,'Daily Storm Data 2'!$G:$G,$A38,'Daily Storm Data 2'!$E:$E,"Netherlands")) | Y38: =+Y37+1 -> 11 | Z38: =IF(SUMIFS('Daily Forecast'!D:D,'Daily Forecast'!B:B,$D$25,'Daily Forecast'!F:F,Y38,'Daily Forecast'!A:A,"Netherlands")=0,"",SUMIFS('Daily Forecast'!D:D,'Daily Forecast'!B:B,$D$25,'Daily Forecast'!F:F,Y38,'Daily Forecast'!A:A,"Netherlands")) -> 56 | AA38: =IFERROR(AD38/$J38,AD38) -> 65.194434 | AB38: =IFERROR(AE38/$J38,AE38) -> 65.655172 | AC38: =IFERROR(AF38/$J38,AF38) -> 39.393103 | AD38: =IFERROR(IF(S38="",Z38*$AD$29,S38*J38),0) -> 55.607018 | AE38: =IFERROR(IF(S38="",Z38*$AE$29,S38*J38),0) -> 56 | AF38: =IFERROR(IF(S38="",Z38*$AF$29,S38*J38),0) -> 33.6 | AI38: 6 | AJ38: 8 | AL38: 8
A39: =+A38+1 -> 12 | D39: 0.5 | E39: 60 | F39: 61 | G39: 61 | H39: 58 | I39: =IFERROR(Table1[[#This Row],[Volume Actual]]/Table1[[#This Row],[Volume Forcasted]],"") -> 1.0166667 | J39: =IFERROR(H39/G39,"") -> 0.95081967 | K39: =+IFERROR(Table1[[#This Row],[Volume Handled]]/Table1[[#This Row],[Volume Actual]],"") -> 1 | L39: 263.80328 | Q39: =(O39+N39)/M39 -> #DIV/0! | S39: =IF(SUMIFS('Daily Storm Data 2'!I:I,'Daily Storm Data 2'!$A:$A,$D$25,'Daily Storm Data 2'!$G:$G,$A39,'Daily Storm Data 2'!$E:$E,"Netherlands")=0,"",SUMIFS('Daily Storm Data 2'!I:I,'Daily Storm Data 2'!$A:$A,$D$25,'Daily Storm Data 2'!$G:$G,$A39,'Daily Storm Data 2'!$E:$E,"Netherlands")) | Y39: =+Y38+1 -> 12 | Z39: =IF(SUMIFS('Daily Forecast'!D:D,'Daily Forecast'!B:B,$D$25,'Daily Forecast'!F:F,Y39,'Daily Forecast'!A:A,"Netherlands")=0,"",SUMIFS('Daily Forecast'!D:D,'Daily Forecast'!B:B,$D$25,'Daily Forecast'!F:F,Y39,'Daily Forecast'!A:A,"Netherlands")) -> 60 | AA39: =IFERROR(AD39/$J39,AD39) -> 62.660617 | AB39: =IFERROR(AE39/$J39,AE39) -> 63.103448 | AC39: =IFERROR(AF39/$J39,AF39) -> 37.862069 | AD39: =IFERROR(IF(S39="",Z39*$AD$29,S39*J39),0) -> 59.578947 | AE39: =IFERROR(IF(S39="",Z39*$AE$29,S39*J39),0) -> 60 | AF39: =IFERROR(IF(S39="",Z39*$AF$29,S39*J39),0) -> 36 | AI39: 7 | AJ39: 42 | AL39: 42
A40: =+A39+1 -> 13 | D40: 0.54166667 | E40: 62 | F40: 58 | G40: 58 | H40: 54 | I40: =IFERROR(Table1[[#This Row],[Volume Actual]]/Table1[[#This Row],[Volume Forcasted]],"") -> 0.93548387 | J40: =IFERROR(H40/G40,"") -> 0.93103448 | K40: =+IFERROR(Table1[[#This Row],[Volume Handled]]/Table1[[#This Row],[Volume Actual]],"") -> 1 | L40: 275.51724 | Q40: =(O40+N40)/M40 -> #DIV/0! | S40: =IF(SUMIFS('Daily Storm Data 2'!I:I,'Daily Storm Data 2'!$A:$A,$D$25,'Daily Storm Data 2'!$G:$G,$A40,'Daily Storm Data 2'!$E:$E,"Netherlands")=0,"",SUMIFS('Daily Storm Data 2'!I:I,'Daily Storm Data 2'!$A:$A,$D$25,'Daily Storm Data 2'!$G:$G,$A40,'Daily Storm Data 2'!$E:$E,"Netherlands")) | Z40: =IF(SUMIFS('Daily Forecast'!D:D,'Daily Forecast'!B:B,$D$25,'Daily Forecast'!F:F,Y40,'Daily Forecast'!A:A,"Netherlands")=0,"",SUMIFS('Daily Forecast'!D:D,'Daily Forecast'!B:B,$D$25,'Daily Forecast'!F:F,Y40,'Daily Forecast'!A:A,"Netherlands")) | AA40: =IFERROR(AD40/$J40,AD40) -> 0 | AB40: =IFERROR(AE40/$J40,AE40) -> 0 | AC40: =IFERROR(AF40/$J40,AF40) -> 0 | AD40: =IFERROR(IF(S40="",Z40*$AD$29,S40*J40),0) -> 0 | AE40: =IFERROR(IF(S40="",Z40*$AE$29,S40*J40),0) -> 0 | AF40: =IFERROR(IF(S40="",Z40*$AF$29,S40*J40),0) -> 0 | AI40: 8 | AJ40: 82 | AL40: 82
A41: =+A40+1 -> 14 | D41: 0.58333333 | E41: 54 | F41: 53 | G41: 53 | H41: 52 | I41: =IFERROR(Table1[[#This Row],[Volume Actual]]/Table1[[#This Row],[Volume Forcasted]],"") -> 0.98148148 | J41: =IFERROR(H41/G41,"") -> 0.98113208 | K41: =+IFERROR(Table1[[#This Row],[Volume Handled]]/Table1[[#This Row],[Volume Actual]],"") -> 1 | L41: 367.07547 | Q41: =(O41+N41)/M41 -> #DIV/0! | S41: =IF(SUMIFS('Daily Storm Data 2'!I:I,'Daily Storm Data 2'!$A:$A,$D$25,'Daily Storm Data 2'!$G:$G,$A41,'Daily Storm Data 2'!$E:$E,"Netherlands")=0,"",SUMIFS('Daily Storm Data 2'!I:I,'Daily Storm Data 2'!$A:$A,$D$25,'Daily Storm Data 2'!$G:$G,$A41,'Daily Storm Data 2'!$E:$E,"Netherlands")) | Z41: =IF(SUMIFS('Daily Forecast'!D:D,'Daily Forecast'!B:B,$D$25,'Daily Forecast'!F:F,Y41,'Daily Forecast'!A:A,"Netherlands")=0,"",SUMIFS('Daily Forecast'!D:D,'Daily Forecast'!B:B,$D$25,'Daily Forecast'!F:F,Y41,'Daily Forecast'!A:A,"Netherlands")) | AA41: =IFERROR(AD41/$J41,AD41) -> 0 | AB41: =IFERROR(AE41/$J41,AE41) -> 0 | AC41: =IFERROR(AF41/$J41,AF41) -> 0 | AD41: =IFERROR(IF(S41="",Z41*$AD$29,S41*J41),0) -> 0 | AE41: =IFERROR(IF(S41="",Z41*$AE$29,S41*J41),0) -> 0 | AF41: =IFERROR(IF(S41="",Z41*$AF$29,S41*J41),0) -> 0 | AI41: 9 | AJ41: 92 | AL41: 92
A42: =+A41+1 -> 15 | D42: 0.625 | E42: 46 | F42: 66 | G42: 66 | H42: 60 | I42: =IFERROR(Table1[[#This Row],[Volume Actual]]/Table1[[#This Row],[Volume Forcasted]],"") -> 1.4347826 | J42: =IFERROR(H42/G42,"") -> 0.90909091 | K42: =+IFERROR(Table1[[#This Row],[Volume Handled]]/Table1[[#This Row],[Volume Actual]],"") -> 1 | L42: 305.92424 | Q42: =(O42+N42)/M42 -> #DIV/0! | S42: =IF(SUMIFS('Daily Storm Data 2'!I:I,'Daily Storm Data 2'!$A:$A,$D$25,'Daily Storm Data 2'!$G:$G,$A42,'Daily Storm Data 2'!$E:$E,"Netherlands")=0,"",SUMIFS('Daily Storm Data 2'!I:I,'Daily Storm Data 2'!$A:$A,$D$25,'Daily Storm Data 2'!$G:$G,$A42,'Daily Storm Data 2'!$E:$E,"Netherlands")) | Z42: =IF(SUMIFS('Daily Forecast'!D:D,'Daily Forecast'!B:B,$D$25,'Daily Forecast'!F:F,Y42,'Daily Forecast'!A:A,"Netherlands")=0,"",SUMIFS('Daily Forecast'!D:D,'Daily Forecast'!B:B,$D$25,'Daily Forecast'!F:F,Y42,'Daily Forecast'!A:A,"Netherlands")) | AA42: =IFERROR(AD42/$J42,AD42) -> 0 | AB42: =IFERROR(AE42/$J42,AE42) -> 0 | AC42: =IFERROR(AF42/$J42,AF42) -> 0 | AD42: =IFERROR(IF(S42="",Z42*$AD$29,S42*J42),0) -> 0 | AE42: =IFERROR(IF(S42="",Z42*$AE$29,S42*J42),0) -> 0 | AF42: =IFERROR(IF(S42="",Z42*$AF$29,S42*J42),0) -> 0 | AI42: 10 | AJ42: 98 | AL42: 98
A43: =+A42+1 -> 16 | D43: 0.66666667 | E43: 37 | F43: 54 | G43: 54 | H43: 52 | I43: =IFERROR(Table1[[#This Row],[Volume Actual]]/Table1[[#This Row],[Volume Forcasted]],"") -> 1.4594595 | J43: =IFERROR(H43/G43,"") -> 0.96296296 | K43: =+IFERROR(Table1[[#This Row],[Volume Handled]]/Table1[[#This Row],[Volume Actual]],"") -> 1 | L43: 283.40741 | Q43: =(O43+N43)/M43 -> #DIV/0! | S43: =IF(SUMIFS('Daily Storm Data 2'!I:I,'Daily Storm Data 2'!$A:$A,$D$25,'Daily Storm Data 2'!$G:$G,$A43,'Daily Storm Data 2'!$E:$E,"Netherlands")=0,"",SUMIFS('Daily Storm Data 2'!I:I,'Daily Storm Data 2'!$A:$A,$D$25,'Daily Storm Data 2'!$G:$G,$A43,'Daily Storm Data 2'!$E:$E,"Netherlands")) | Z43: =IF(SUMIFS('Daily Forecast'!D:D,'Daily Forecast'!B:B,$D$25,'Daily Forecast'!F:F,Y43,'Daily Forecast'!A:A,"Netherlands")=0,"",SUMIFS('Daily Forecast'!D:D,'Daily Forecast'!B:B,$D$25,'Daily Forecast'!F:F,Y43,'Daily Forecast'!A:A,"Netherlands")) | AA43: =IFERROR(AD43/$J43,AD43) -> 0 | AB43: =IFERROR(AE43/$J43,AE43) -> 0 | AC43: =IFERROR(AF43/$J43,AF43) -> 0 | AD43: =IFERROR(IF(S43="",Z43*$AD$29,S43*J43),0) -> 0 | AE43: =IFERROR(IF(S43="",Z43*$AE$29,S43*J43),0) -> 0 | AF43: =IFERROR(IF(S43="",Z43*$AF$29,S43*J43),0) -> 0
D44: 0.70833333 | E44: 29 | F44: 46 | G44: 46 | H44: 38 | I44: =IFERROR(Table1[[#This Row],[Volume Actual]]/Table1[[#This Row],[Volume Forcasted]],"") -> 1.5862069 | J44: =IFERROR(H44/G44,"") -> 0.82608696 | K44: =+IFERROR(Table1[[#This Row],[Volume Handled]]/Table1[[#This Row],[Volume Actual]],"") -> 1 | L44: 269.67391 | Q44: =(O44+N44)/M44 -> #DIV/0! | S44: =IF(SUMIFS('Daily Storm Data 2'!I:I,'Daily Storm Data 2'!$A:$A,$D$25,'Daily Storm Data 2'!$G:$G,$A44,'Daily Storm Data 2'!$E:$E,"Netherlands")=0,"",SUMIFS('Daily Storm Data 2'!I:I,'Daily Storm Data 2'!$A:$A,$D$25,'Daily Storm Data 2'!$G:$G,$A44,'Daily Storm Data 2'!$E:$E,"Netherlands")) | Z44: =IF(SUMIFS('Daily Forecast'!D:D,'Daily Forecast'!B:B,$D$25,'Daily Forecast'!F:F,Y44,'Daily Forecast'!A:A,"Netherlands")=0,"",SUMIFS('Daily Forecast'!D:D,'Daily Forecast'!B:B,$D$25,'Daily Forecast'!F:F,Y44,'Daily Forecast'!A:A,"Netherlands")) | AA44: =IFERROR(AD44/$J44,AD44) -> 0 | AB44: =IFERROR(AE44/$J44,AE44) -> 0 | AC44: =IFERROR(AF44/$J44,AF44) -> 0 | AD44: =IFERROR(IF(S44="",Z44*$AD$29,S44*J44),0) -> 0 | AE44: =IFERROR(IF(S44="",Z44*$AE$29,S44*J44),0) -> 0 | AF44: =IFERROR(IF(S44="",Z44*$AF$29,S44*J44),0) -> 0
D45: 0.75 | E45: 26 | F45: =IFERROR(GETPIVOTDATA("Calls Answered",'[1]Croisé NL'!$A$29,"Date",$D$25,"Heures ([Call Date/Time])",$A45),"") | G45: =IFERROR(GETPIVOTDATA("Calls Answered",'[1]Croisé NL'!$A$68,"Date",$D$25,"Heures ([Call Date/Time])",$A45),"") | H45: =IFERROR(GETPIVOTDATA(" Call in SL",'[1]Croisé NL'!$A$29,"Date",$D$25,"Heures ([Call Date/Time])",$A45),"") | I45: =IFERROR(Table1[[#This Row],[Volume Actual]]/Table1[[#This Row],[Volume Forcasted]],"") | J45: =IFERROR(H45/G45,"") | K45: =+IFERROR(Table1[[#This Row],[Volume Handled]]/Table1[[#This Row],[Volume Actual]],"") | L45: =IFERROR(GETPIVOTDATA(" AHT",'[1]Croisé NL'!$A$29,"Date",$D$25,"Heures ([Call Date/Time])",$A45),"") | Q45: =(O45+N45)/M45 -> #DIV/0! | S45: =IF(SUMIFS('Daily Storm Data 2'!I:I,'Daily Storm Data 2'!$A:$A,$D$25,'Daily Storm Data 2'!$G:$G,$A45,'Daily Storm Data 2'!$E:$E,"Netherlands")=0,"",SUMIFS('Daily Storm Data 2'!I:I,'Daily Storm Data 2'!$A:$A,$D$25,'Daily Storm Data 2'!$G:$G,$A45,'Daily Storm Data 2'!$E:$E,"Netherlands")) | Z45: =IF(SUMIFS('Daily Forecast'!D:D,'Daily Forecast'!B:B,$D$25,'Daily Forecast'!F:F,Y45,'Daily Forecast'!A:A,"Netherlands")=0,"",SUMIFS('Daily Forecast'!D:D,'Daily Forecast'!B:B,$D$25,'Daily Forecast'!F:F,Y45,'Daily Forecast'!A:A,"Netherlands")) | AA45: =IFERROR(AD45/$J45,AD45) -> 0 | AB45: =IFERROR(AE45/$J45,AE45) -> 0 | AC45: =IFERROR(AF45/$J45,AF45) -> 0 | AD45: =IFERROR(IF(S45="",Z45*$AD$29,S45*J45),0) -> 0 | AE45: =IFERROR(IF(S45="",Z45*$AE$29,S45*J45),0) -> 0 | AF45: =IFERROR(IF(S45="",Z45*$AF$29,S45*J45),0) -> 0
D46: 0.79166667 | E46: 23 | F46: =IFERROR(GETPIVOTDATA("Calls Answered",'[1]Croisé NL'!$A$29,"Date",$D$25,"Heures ([Call Date/Time])",$A46),"") | G46: =IFERROR(GETPIVOTDATA("Calls Answered",'[1]Croisé NL'!$A$68,"Date",$D$25,"Heures ([Call Date/Time])",$A46),"") | H46: =IFERROR(GETPIVOTDATA(" Call in SL",'[1]Croisé NL'!$A$29,"Date",$D$25,"Heures ([Call Date/Time])",$A46),"") | I46: =IFERROR(Table1[[#This Row],[Volume Actual]]/Table1[[#This Row],[Volume Forcasted]],"") | J46: =IFERROR(H46/G46,"") | K46: =+IFERROR(Table1[[#This Row],[Volume Handled]]/Table1[[#This Row],[Volume Actual]],"") | L46: =IFERROR(GETPIVOTDATA(" AHT",'[1]Croisé NL'!$A$29,"Date",$D$25,"Heures ([Call Date/Time])",$A46),"") | Q46: =(O46+N46)/M46 -> #DIV/0! | S46: =IF(SUMIFS('Daily Storm Data 2'!I:I,'Daily Storm Data 2'!$A:$A,$D$25,'Daily Storm Data 2'!$G:$G,$A46,'Daily Storm Data 2'!$E:$E,"Netherlands")=0,"",SUMIFS('Daily Storm Data 2'!I:I,'Daily Storm Data 2'!$A:$A,$D$25,'Daily Storm Data 2'!$G:$G,$A46,'Daily Storm Data 2'!$E:$E,"Netherlands")) | Z46: =IF(SUMIFS('Daily Forecast'!D:D,'Daily Forecast'!B:B,$D$25,'Daily Forecast'!F:F,Y46,'Daily Forecast'!A:A,"Netherlands")=0,"",SUMIFS('Daily Forecast'!D:D,'Daily Forecast'!B:B,$D$25,'Daily Forecast'!F:F,Y46,'Daily Forecast'!A:A,"Netherlands")) | AA46: =IFERROR(AD46/$J46,AD46) -> 0 | AB46: =IFERROR(AE46/$J46,AE46) -> 0 | AC46: =IFERROR(AF46/$J46,AF46) -> 0 | AD46: =IFERROR(IF(S46="",Z46*$AD$29,S46*J46),0) -> 0 | AE46: =IFERROR(IF(S46="",Z46*$AE$29,S46*J46),0) -> 0 | AF46: =IFERROR(IF(S46="",Z46*$AF$29,S46*J46),0) -> 0
D47: 0.83333333 | E47: 24 | F47: =IFERROR(GETPIVOTDATA("Calls Answered",'[1]Croisé NL'!$A$29,"Date",$D$25,"Heures ([Call Date/Time])",$A47),"") | G47: =IFERROR(GETPIVOTDATA("Calls Answered",'[1]Croisé NL'!$A$68,"Date",$D$25,"Heures ([Call Date/Time])",$A47),"") | H47: =IFERROR(GETPIVOTDATA(" Call in SL",'[1]Croisé NL'!$A$29,"Date",$D$25,"Heures ([Call Date/Time])",$A47),"") | I47: =IFERROR(Table1[[#This Row],[Volume Actual]]/Table1[[#This Row],[Volume Forcasted]],"") | J47: =IFERROR(H47/G47,"") | K47: =+IFERROR(Table1[[#This Row],[Volume Handled]]/Table1[[#This Row],[Volume Actual]],"") | L47: =IFERROR(GETPIVOTDATA(" AHT",'[1]Croisé NL'!$A$29,"Date",$D$25,"Heures ([Call Date/Time])",$A47),"") | Q47: =(O47+N47)/M47 -> #DIV/0! | S47: =IF(SUMIFS('Daily Storm Data 2'!I:I,'Daily Storm Data 2'!$A:$A,$D$25,'Daily Storm Data 2'!$G:$G,$A47,'Daily Storm Data 2'!$E:$E,"Netherlands")=0,"",SUMIFS('Daily Storm Data 2'!I:I,'Daily Storm Data 2'!$A:$A,$D$25,'Daily Storm Data 2'!$G:$G,$A47,'Daily Storm Data 2'!$E:$E,"Netherlands")) | Z47: =IF(SUMIFS('Daily Forecast'!D:D,'Daily Forecast'!B:B,$D$25,'Daily Forecast'!F:F,Y47,'Daily Forecast'!A:A,"Netherlands")=0,"",SUMIFS('Daily Forecast'!D:D,'Daily Forecast'!B:B,$D$25,'Daily Forecast'!F:F,Y47,'Daily Forecast'!A:A,"Netherlands")) | AA47: =IFERROR(AD47/$J47,AD47) -> 0 | AB47: =IFERROR(AE47/$J47,AE47) -> 0 | AC47: =IFERROR(AF47/$J47,AF47) -> 0 | AD47: =IFERROR(IF(S47="",Z47*$AD$29,S47*J47),0) -> 0 | AE47: =IFERROR(IF(S47="",Z47*$AE$29,S47*J47),0) -> 0 | AF47: =IFERROR(IF(S47="",Z47*$AF$29,S47*J47),0) -> 0
...

Sheet Feuil6
B5: 1. Delivery Performance
B7: Overall performance in Week 17 remained stable, with Service Level on target, as well as controlled HR KPIs (Attrition & ABS%).
B9: • Service Level
B10: • Actual:
B11: NL 67% vs. Target of 70%
B12: BE 82% vs. Target of 70%
B14: • Forecast vs. received deviation:
B15: On NL, 98% over the week, with a couple of days reaching 114%, and several rush morning intervals exceeding 400% deviation.
B17: • Key drivers:
B19: o Sunday 26th had a significant impact on weekly results due to high deviation linked to the school vacation period
B20: o ABS: NL 2% | BE 2%
B21: o Close monitoring of daily delivery by the Local RTAs, combined with daily scheduling coverage checks
B22: o Ongoing exploration of the new reporting “AGENT SCORE CARD / Agent overview” to track gaps and drive remediation at a granular agent level

Sheet Daily Flash NL (2)
AB3: Traité | AC3: Voice Mail
D4: Global TSL RSA | AA4: Ford NL | AB4: 208 | AC4: 69
D5: =(H51+H106)/(G51+G106) -> 0.43638851 | AA5: Fpord FR | AB5: 199 | AC5: 17
D12: 46169
D14: TSL | F14: Availability | J14: Deviation | P14: Absence Rate in HC
D15: =H51/F51 -> 0.2778626 | F15: =+SUM(G20:G50)/SUM(F20:F50) -> 0.79847328 | J15: =+SUM(F20:F50)/SUM(E20:E50) -> 1.1930783 | P15: =SUM(N20:N50)/SUM(M20:M50) -> 0.62962963 | Z15: Average Threshold Deviation | AA15: Average Threshold Deviation | AB15: Average Threshold Deviation
Z16: =J15 -> 1.1930783 | AA16: 1 | AB16: 0.6
Z18: Scenario 1 | AA18: Scenario 2 | AB18: Scenario 2
D19: Hour | E19: Volume Forcasted | F19: Volume Actual | G19: Volume Handled | H19: Volume Handle in SL | I19: Deviation | J19: SL | K19: Availability | L19: AHT | M19: Planned | N19: Abs | O19: Late | P19: % Abs | S19: Calls over Forecast | U19: Hour | V19: Forecast | W19: Actual Fc scenario 1 | X19: Actual Fc scenario 2 | Y19: Actual Fc scenario 3 | Z19: Actual deviation until EOD | AA19: 100% deviation until EOD | AB19: 90% deviation until EOD
D20: 0.25 | E20: =IF(SUMIFS('Daily Forecast'!D:D,'Daily Forecast'!B:B,'Daily Flash NL (2)'!$D$12,'Daily Forecast'!F:F,A20,'Daily Forecast'!A:A,"Netherlands")=0,"",SUMIFS('Daily Forecast'!D:D,'Daily Forecast'!B:B,'Daily Flash NL (2)'!$D$12,'Daily Forecast'!F:F,A20,'Daily Forecast'!A:A,"Netherlands")) | F20: 8 | G20: =SUMIFS('Daily Storm Data 2'!J:J,'Daily Storm Data 2'!$A:$A,'Daily Flash NL (2)'!$D$12,'Daily Storm Data 2'!$G:$G,'Daily Flash NL (2)'!$A20,'Daily Storm Data 2'!$E:$E,"Netherlands") -> 0 | H20: =SUMIFS('Daily Storm Data 2'!K:K,'Daily Storm Data 2'!$A:$A,'Daily Flash NL (2)'!$D$12,'Daily Storm Data 2'!$G:$G,'Daily Flash NL (2)'!$A20,'Daily Storm Data 2'!$E:$E,"Netherlands") -> 0 | I20: =IFERROR(Table17[[#This Row],[Volume Actual]]/Table17[[#This Row],[Volume Forcasted]],"") | J20: =IFERROR(H20/F20,"") -> 0 | K20: =+IFERROR(Table17[[#This Row],[Volume Handled]]/Table17[[#This Row],[Volume Actual]],"") -> 0 | L20: =SUMIFS('Daily Storm Data 2'!O:O,'Daily Storm Data 2'!$A:$A,'Daily Flash NL (2)'!$D$12,'Daily Storm Data 2'!$G:$G,'Daily Flash NL (2)'!$A20,'Daily Storm Data 2'!$E:$E,"Netherlands") -> 0 | M20: 5 | N20: 1 | P20: =IFERROR(Table17[[#This Row],[Abs]]/Table17[[#This Row],[Planned]],"") -> 0.2 | S20: =Table17[[#This Row],[Volume Actual]]-Table17[[#This Row],[Volume Forcasted]] -> #VALUE! | U20: 6 | V20: =IF(SUMIFS('Daily Forecast'!D:D,'Daily Forecast'!B:B,'Daily Flash NL (2)'!$D$12,'Daily Forecast'!F:F,U20,'Daily Forecast'!A:A,"Netherlands")=0,"",SUMIFS('Daily Forecast'!D:D,'Daily Forecast'!B:B,'Daily Flash NL (2)'!$D$12,'Daily Forecast'!F:F,U20,'Daily Forecast'!A:A,"Netherlands")) -> 6 | W20: =IFERROR(Z20/$J20,Z20) -> 0 | X20: =IFERROR(AA20/$J20,AA20) -> 0 | Y20: =IFERROR(AB20/$J20,AB20) -> 0 | Z20: =IFERROR(IF(F20="",V20*$Z$16,F20*J20),0) -> 0 | AA20: =IFERROR(IF(F20="",V20*$AA$16,F20*J20),0) -> 0 | AB20: =IFERROR(IF(F20="",V20*$AB$16,F20*J20),0) -> 0
A21: 7 | D21: 0.29166667 | E21: =IF(SUMIFS('Daily Forecast'!D:D,'Daily Forecast'!B:B,'Daily Flash NL (2)'!$D$12,'Daily Forecast'!F:F,A21,'Daily Forecast'!A:A,"Netherlands")=0,"",SUMIFS('Daily Forecast'!D:D,'Daily Forecast'!B:B,'Daily Flash NL (2)'!$D$12,'Daily Forecast'!F:F,A21,'Daily Forecast'!A:A,"Netherlands")) -> 15 | F21: =IF(SUMIFS('Daily Storm Data 2'!I:I,'Daily Storm Data 2'!$A:$A,'Daily Flash NL (2)'!$D$12,'Daily Storm Data 2'!$G:$G,'Daily Flash NL (2)'!$A21,'Daily Storm Data 2'!$E:$E,"Netherlands")=0,"",SUMIFS('Daily Storm Data 2'!I:I,'Daily Storm Data 2'!$A:$A,'Daily Flash NL (2)'!$D$12,'Daily Storm Data 2'!$G:$G,'Daily Flash NL (2)'!$A21,'Daily Storm Data 2'!$E:$E,"Netherlands")) -> 20 | G21: =SUMIFS('Daily Storm Data 2'!J:J,'Daily Storm Data 2'!$A:$A,'Daily Flash NL (2)'!$D$12,'Daily Storm Data 2'!$G:$G,'Daily Flash NL (2)'!$A21,'Daily Storm Data 2'!$E:$E,"Netherlands") -> 20 | H21: =SUMIFS('Daily Storm Data 2'!K:K,'Daily Storm Data 2'!$A:$A,'Daily Flash NL (2)'!$D$12,'Daily Storm Data 2'!$G:$G,'Daily Flash NL (2)'!$A21,'Daily Storm Data 2'!$E:$E,"Netherlands") -> 14 | I21: =IFERROR(Table17[[#This Row],[Volume Actual]]/Table17[[#This Row],[Volume Forcasted]],"") -> 1.3333333 | J21: =IFERROR(H21/F21,"") -> 0.7 | K21: =+IFERROR(Table17[[#This Row],[Volume Handled]]/Table17[[#This Row],[Volume Actual]],"") -> 1 | L21: =SUMIFS('Daily Storm Data 2'!O:O,'Daily Storm Data 2'!$A:$A,'Daily Flash NL (2)'!$D$12,'Daily Storm Data 2'!$G:$G,'Daily Flash NL (2)'!$A21,'Daily Storm Data 2'!$E:$E,"Netherlands") -> 288.3908 | M21: 6 | N21: 3 | P21: =IFERROR(Table17[[#This Row],[Abs]]/Table17[[#This Row],[Planned]],"") -> 0.5 | S21: 3 | U21: =+U20+1 -> 7 | V21: =IF(SUMIFS('Daily Forecast'!D:D,'Daily Forecast'!B:B,'Daily Flash NL (2)'!$D$12,'Daily Forecast'!F:F,U21,'Daily Forecast'!A:A,"Netherlands")=0,"",SUMIFS('Daily Forecast'!D:D,'Daily Forecast'!B:B,'Daily Flash NL (2)'!$D$12,'Daily Forecast'!F:F,U21,'Daily Forecast'!A:A,"Netherlands")) -> 15 | W21: =IFERROR(Z21/$J21,Z21) -> 20 | X21: =IFERROR(AA21/$J21,AA21) -> 20 | Y21: =IFERROR(AB21/$J21,AB21) -> 20 | Z21: =IFERROR(IF(F21="",V21*$Z$16,F21*J21),0) -> 14 | AA21: =IFERROR(IF(F21="",V21*$AA$16,F21*J21),0) -> 14 | AB21: =IFERROR(IF(F21="",V21*$AB$16,F21*J21),0) -> 14
A22: =+A21+1 -> 8 | D22: 0.33333333 | E22: =IF(SUMIFS('Daily Forecast'!D:D,'Daily Forecast'!B:B,'Daily Flash NL (2)'!$D$12,'Daily Forecast'!F:F,A22,'Daily Forecast'!A:A,"Netherlands")=0,"",SUMIFS('Daily Forecast'!D:D,'Daily Forecast'!B:B,'Daily Flash NL (2)'!$D$12,'Daily Forecast'!F:F,A22,'Daily Forecast'!A:A,"Netherlands")) -> 42 | F22: =IF(SUMIFS('Daily Storm Data 2'!I:I,'Daily Storm Data 2'!$A:$A,'Daily Flash NL (2)'!$D$12,'Daily Storm Data 2'!$G:$G,'Daily Flash NL (2)'!$A22,'Daily Storm Data 2'!$E:$E,"Netherlands")=0,"",SUMIFS('Daily Storm Data 2'!I:I,'Daily Storm Data 2'!$A:$A,'Daily Flash NL (2)'!$D$12,'Daily Storm Data 2'!$G:$G,'Daily Flash NL (2)'!$A22,'Daily Storm Data 2'!$E:$E,"Netherlands")) -> 67 | G22: =SUMIFS('Daily Storm Data 2'!J:J,'Daily Storm Data 2'!$A:$A,'Daily Flash NL (2)'!$D$12,'Daily Storm Data 2'!$G:$G,'Daily Flash NL (2)'!$A22,'Daily Storm Data 2'!$E:$E,"Netherlands") -> 50 | H22: =SUMIFS('Daily Storm Data 2'!K:K,'Daily Storm Data 2'!$A:$A,'Daily Flash NL (2)'!$D$12,'Daily Storm Data 2'!$G:$G,'Daily Flash NL (2)'!$A22,'Daily Storm Data 2'!$E:$E,"Netherlands") -> 9 | I22: =IFERROR(Table17[[#This Row],[Volume Actual]]/Table17[[#This Row],[Volume Forcasted]],"") -> 1.5952381 | J22: =IFERROR(H22/F22,"") -> 0.13432836 | K22: =+IFERROR(Table17[[#This Row],[Volume Handled]]/Table17[[#This Row],[Volume Actual]],"") -> 0.74626866 | L22: =SUMIFS('Daily Storm Data 2'!O:O,'Daily Storm Data 2'!$A:$A,'Daily Flash NL (2)'!$D$12,'Daily Storm Data 2'!$G:$G,'Daily Flash NL (2)'!$A22,'Daily Storm Data 2'!$E:$E,"Netherlands") -> 151.0559 | M22: 11 | N22: 7 | P22: =IFERROR(Table17[[#This Row],[Abs]]/Table17[[#This Row],[Planned]],"") -> 0.63636364 | S22: 5 | U22: =+U21+1 -> 8 | V22: =IF(SUMIFS('Daily Forecast'!D:D,'Daily Forecast'!B:B,'Daily Flash NL (2)'!$D$12,'Daily Forecast'!F:F,U22,'Daily Forecast'!A:A,"Netherlands")=0,"",SUMIFS('Daily Forecast'!D:D,'Daily Forecast'!B:B,'Daily Flash NL (2)'!$D$12,'Daily Forecast'!F:F,U22,'Daily Forecast'!A:A,"Netherlands")) -> 42 | W22: =IFERROR(Z22/$J22,Z22) -> 67 | X22: =IFERROR(AA22/$J22,AA22) -> 67 | Y22: =IFERROR(AB22/$J22,AB22) -> 67 | Z22: =IFERROR(IF(F22="",V22*$Z$16,F22*J22),0) -> 9 | AA22: =IFERROR(IF(F22="",V22*$AA$16,F22*J22),0) -> 9 | AB22: =IFERROR(IF(F22="",V22*$AB$16,F22*J22),0) -> 9 | AE22: Étiquettes de lignes | AF22: I | AG22: (vide) | AH22: Total général
A23: =+A22+1 -> 9 | D23: 0.375 | E23: =IF(SUMIFS('Daily Forecast'!D:D,'Daily Forecast'!B:B,'Daily Flash NL (2)'!$D$12,'Daily Forecast'!F:F,A23,'Daily Forecast'!A:A,"Netherlands")=0,"",SUMIFS('Daily Forecast'!D:D,'Daily Forecast'!B:B,'Daily Flash NL (2)'!$D$12,'Daily Forecast'!F:F,A23,'Daily Forecast'!A:A,"Netherlands")) -> 62 | F23: =IF(SUMIFS('Daily Storm Data 2'!I:I,'Daily Storm Data 2'!$A:$A,'Daily Flash NL (2)'!$D$12,'Daily Storm Data 2'!$G:$G,'Daily Flash NL (2)'!$A23,'Daily Storm Data 2'!$E:$E,"Netherlands")=0,"",SUMIFS('Daily Storm Data 2'!I:I,'Daily Storm Data 2'!$A:$A,'Daily Flash NL (2)'!$D$12,'Daily Storm Data 2'!$G:$G,'Daily Flash NL (2)'!$A23,'Daily Storm Data 2'!$E:$E,"Netherlands")) -> 88 | G23: =SUMIFS('Daily Storm Data 2'!J:J,'Daily Storm Data 2'!$A:$A,'Daily Flash NL (2)'!$D$12,'Daily Storm Data 2'!$G:$G,'Daily Flash NL (2)'!$A23,'Daily Storm Data 2'!$E:$E,"Netherlands") -> 49 | H23: =SUMIFS('Daily Storm Data 2'!K:K,'Daily Storm Data 2'!$A:$A,'Daily Flash NL (2)'!$D$12,'Daily Storm Data 2'!$G:$G,'Daily Flash NL (2)'!$A23,'Daily Storm Data 2'!$E:$E,"Netherlands") -> 0 | I23: =IFERROR(Table17[[#This Row],[Volume Actual]]/Table17[[#This Row],[Volume Forcasted]],"") -> 1.4193548 | J23: =IFERROR(H23/F23,"") -> 0 | K23: =+IFERROR(Table17[[#This Row],[Volume Handled]]/Table17[[#This Row],[Volume Actual]],"") -> 0.55681818 | L23: =SUMIFS('Daily Storm Data 2'!O:O,'Daily Storm Data 2'!$A:$A,'Daily Flash NL (2)'!$D$12,'Daily Storm Data 2'!$G:$G,'Daily Flash NL (2)'!$A23,'Daily Storm Data 2'!$E:$E,"Netherlands") -> 240.45225 | M23: 14 | N23: 10 | P23: =IFERROR(Table17[[#This Row],[Abs]]/Table17[[#This Row],[Planned]],"") -> 0.71428571 | S23: 5 | U23: =+U22+1 -> 9 | V23: =IF(SUMIFS('Daily Forecast'!D:D,'Daily Forecast'!B:B,'Daily Flash NL (2)'!$D$12,'Daily Forecast'!F:F,U23,'Daily Forecast'!A:A,"Netherlands")=0,"",SUMIFS('Daily Forecast'!D:D,'Daily Forecast'!B:B,'Daily Flash NL (2)'!$D$12,'Daily Forecast'!F:F,U23,'Daily Forecast'!A:A,"Netherlands")) -> 62 | W23: =IFERROR(Z23/$J23,Z23) -> 0 | X23: =IFERROR(AA23/$J23,AA23) -> 0 | Y23: =IFERROR(AB23/$J23,AB23) -> 0 | Z23: =IFERROR(IF(F23="",V23*$Z$16,F23*J23),0) -> 0 | AA23: =IFERROR(IF(F23="",V23*$AA$16,F23*J23),0) -> 0 | AB23: =IFERROR(IF(F23="",V23*$AB$16,F23*J23),0) -> 0 | AE23: 3 | AF23: 1 | AH23: 1
A24: =+A23+1 -> 10 | D24: 0.41666667 | E24: =IF(SUMIFS('Daily Forecast'!D:D,'Daily Forecast'!B:B,'Daily Flash NL (2)'!$D$12,'Daily Forecast'!F:F,A24,'Daily Forecast'!A:A,"Netherlands")=0,"",SUMIFS('Daily Forecast'!D:D,'Daily Forecast'!B:B,'Daily Flash NL (2)'!$D$12,'Daily Forecast'!F:F,A24,'Daily Forecast'!A:A,"Netherlands")) -> 55 | F24: =IF(SUMIFS('Daily Storm Data 2'!I:I,'Daily Storm Data 2'!$A:$A,'Daily Flash NL (2)'!$D$12,'Daily Storm Data 2'!$G:$G,'Daily Flash NL (2)'!$A24,'Daily Storm Data 2'!$E:$E,"Netherlands")=0,"",SUMIFS('Daily Storm Data 2'!I:I,'Daily Storm Data 2'!$A:$A,'Daily Flash NL (2)'!$D$12,'Daily Storm Data 2'!$G:$G,'Daily Flash NL (2)'!$A24,'Daily Storm Data 2'!$E:$E,"Netherlands")) -> 79 | G24: =SUMIFS('Daily Storm Data 2'!J:J,'Daily Storm Data 2'!$A:$A,'Daily Flash NL (2)'!$D$12,'Daily Storm Data 2'!$G:$G,'Daily Flash NL (2)'!$A24,'Daily Storm Data 2'!$E:$E,"Netherlands") -> 46 | H24: =SUMIFS('Daily Storm Data 2'!K:K,'Daily Storm Data 2'!$A:$A,'Daily Flash NL (2)'!$D$12,'Daily Storm Data 2'!$G:$G,'Daily Flash NL (2)'!$A24,'Daily Storm Data 2'!$E:$E,"Netherlands") -> 0 | I24: =IFERROR(Table17[[#This Row],[Volume Actual]]/Table17[[#This Row],[Volume Forcasted]],"") -> 1.4363636 | J24: =IFERROR(H24/F24,"") -> 0 | K24: =+IFERROR(Table17[[#This Row],[Volume Handled]]/Table17[[#This Row],[Volume Actual]],"") -> 0.58227848 | L24: =SUMIFS('Daily Storm Data 2'!O:O,'Daily Storm Data 2'!$A:$A,'Daily Flash NL (2)'!$D$12,'Daily Storm Data 2'!$G:$G,'Daily Flash NL (2)'!$A24,'Daily Storm Data 2'!$E:$E,"Netherlands") -> 201.54635 | M24: 14 | N24: 10 | P24: =IFERROR(Table17[[#This Row],[Abs]]/Table17[[#This Row],[Planned]],"") -> 0.71428571 | S24: 5 | U24: =+U23+1 -> 10 | V24: =IF(SUMIFS('Daily Forecast'!D:D,'Daily Forecast'!B:B,'Daily Flash NL (2)'!$D$12,'Daily Forecast'!F:F,U24,'Daily Forecast'!A:A,"Netherlands")=0,"",SUMIFS('Daily Forecast'!D:D,'Daily Forecast'!B:B,'Daily Flash NL (2)'!$D$12,'Daily Forecast'!F:F,U24,'Daily Forecast'!A:A,"Netherlands")) -> 55 | W24: =IFERROR(Z24/$J24,Z24) -> 0 | X24: =IFERROR(AA24/$J24,AA24) -> 0 | Y24: =IFERROR(AB24/$J24,AB24) -> 0 | Z24: =IFERROR(IF(F24="",V24*$Z$16,F24*J24),0) -> 0 | AA24: =IFERROR(IF(F24="",V24*$AA$16,F24*J24),0) -> 0 | AB24: =IFERROR(IF(F24="",V24*$AB$16,F24*J24),0) -> 0 | AE24: 4 | AF24: 1 | AH24: 1
A25: =+A24+1 -> 11 | D25: 0.45833333 | E25: =IF(SUMIFS('Daily Forecast'!D:D,'Daily Forecast'!B:B,'Daily Flash NL (2)'!$D$12,'Daily Forecast'!F:F,A25,'Daily Forecast'!A:A,"Netherlands")=0,"",SUMIFS('Daily Forecast'!D:D,'Daily Forecast'!B:B,'Daily Flash NL (2)'!$D$12,'Daily Forecast'!F:F,A25,'Daily Forecast'!A:A,"Netherlands")) -> 53 | F25: =IF(SUMIFS('Daily Storm Data 2'!I:I,'Daily Storm Data 2'!$A:$A,'Daily Flash NL (2)'!$D$12,'Daily Storm Data 2'!$G:$G,'Daily Flash NL (2)'!$A25,'Daily Storm Data 2'!$E:$E,"Netherlands")=0,"",SUMIFS('Daily Storm Data 2'!I:I,'Daily Storm Data 2'!$A:$A,'Daily Flash NL (2)'!$D$12,'Daily Storm Data 2'!$G:$G,'Daily Flash NL (2)'!$A25,'Daily Storm Data 2'!$E:$E,"Netherlands")) -> 55 | G25: =SUMIFS('Daily Storm Data 2'!J:J,'Daily Storm Data 2'!$A:$A,'Daily Flash NL (2)'!$D$12,'Daily Storm Data 2'!$G:$G,'Daily Flash NL (2)'!$A25,'Daily Storm Data 2'!$E:$E,"Netherlands") -> 50 | H25: =SUMIFS('Daily Storm Data 2'!K:K,'Daily Storm Data 2'!$A:$A,'Daily Flash NL (2)'!$D$12,'Daily Storm Data 2'!$G:$G,'Daily Flash NL (2)'!$A25,'Daily Storm Data 2'!$E:$E,"Netherlands") -> 2 | I25: =IFERROR(Table17[[#This Row],[Volume Actual]]/Table17[[#This Row],[Volume Forcasted]],"") -> 1.0377358 | J25: =IFERROR(H25/F25,"") -> 0.036363636 | K25: =+IFERROR(Table17[[#This Row],[Volume Handled]]/Table17[[#This Row],[Volume Actual]],"") -> 0.90909091 | L25: =SUMIFS('Daily Storm Data 2'!O:O,'Daily Storm Data 2'!$A:$A,'Daily Flash NL (2)'!$D$12,'Daily Storm Data 2'!$G:$G,'Daily Flash NL (2)'!$A25,'Daily Storm Data 2'!$E:$E,"Netherlands") -> 260.48874 | M25: 15 | N25: 11 | P25: =IFERROR(Table17[[#This Row],[Abs]]/Table17[[#This Row],[Planned]],"") -> 0.73333333 | S25: 5 | U25: =+U24+1 -> 11 | V25: =IF(SUMIFS('Daily Forecast'!D:D,'Daily Forecast'!B:B,'Daily Flash NL (2)'!$D$12,'Daily Forecast'!F:F,U25,'Daily Forecast'!A:A,"Netherlands")=0,"",SUMIFS('Daily Forecast'!D:D,'Daily Forecast'!B:B,'Daily Flash NL (2)'!$D$12,'Daily Forecast'!F:F,U25,'Daily Forecast'!A:A,"Netherlands")) -> 53 | W25: =IFERROR(Z25/$J25,Z25) -> 55 | X25: =IFERROR(AA25/$J25,AA25) -> 55 | Y25: =IFERROR(AB25/$J25,AB25) -> 55 | Z25: =IFERROR(IF(F25="",V25*$Z$16,F25*J25),0) -> 2 | AA25: =IFERROR(IF(F25="",V25*$AA$16,F25*J25),0) -> 2 | AB25: =IFERROR(IF(F25="",V25*$AB$16,F25*J25),0) -> 2 | AE25: 6 | AF25: 8 | AH25: 8
A26: =+A25+1 -> 12 | D26: 0.5 | E26: =IF(SUMIFS('Daily Forecast'!D:D,'Daily Forecast'!B:B,'Daily Flash NL (2)'!$D$12,'Daily Forecast'!F:F,A26,'Daily Forecast'!A:A,"Netherlands")=0,"",SUMIFS('Daily Forecast'!D:D,'Daily Forecast'!B:B,'Daily Flash NL (2)'!$D$12,'Daily Forecast'!F:F,A26,'Daily Forecast'!A:A,"Netherlands")) -> 57 | F26: =IF(SUMIFS('Daily Storm Data 2'!I:I,'Daily Storm Data 2'!$A:$A,'Daily Flash NL (2)'!$D$12,'Daily Storm Data 2'!$G:$G,'Daily Flash NL (2)'!$A26,'Daily Storm Data 2'!$E:$E,"Netherlands")=0,"",SUMIFS('Daily Storm Data 2'!I:I,'Daily Storm Data 2'!$A:$A,'Daily Flash NL (2)'!$D$12,'Daily Storm Data 2'!$G:$G,'Daily Flash NL (2)'!$A26,'Daily Storm Data 2'!$E:$E,"Netherlands")) -> 46 | G26: =SUMIFS('Daily Storm Data 2'!J:J,'Daily Storm Data 2'!$A:$A,'Daily Flash NL (2)'!$D$12,'Daily Storm Data 2'!$G:$G,'Daily Flash NL (2)'!$A26,'Daily Storm Data 2'!$E:$E,"Netherlands") -> 45 | H26: =SUMIFS('Daily Storm Data 2'!K:K,'Daily Storm Data 2'!$A:$A,'Daily Flash NL (2)'!$D$12,'Daily Storm Data 2'!$G:$G,'Daily Flash NL (2)'!$A26,'Daily Storm Data 2'!$E:$E,"Netherlands") -> 37 | I26: =IFERROR(Table17[[#This Row],[Volume Actual]]/Table17[[#This Row],[Volume Forcasted]],"") -> 0.80701754 | J26: =IFERROR(H26/F26,"") -> 0.80434783 | K26: =+IFERROR(Table17[[#This Row],[Volume Handled]]/Table17[[#This Row],[Volume Actual]],"") -> 0.97826087 | L26: =SUMIFS('Daily Storm Data 2'!O:O,'Daily Storm Data 2'!$A:$A,'Daily Flash NL (2)'!$D$12,'Daily Storm Data 2'!$G:$G,'Daily Flash NL (2)'!$A26,'Daily Storm Data 2'!$E:$E,"Netherlands") -> 247.03957 | M26: 16 | N26: 11 | P26: =IFERROR(Table17[[#This Row],[Abs]]/Table17[[#This Row],[Planned]],"") -> 0.6875 | S26: 5 | U26: =+U25+1 -> 12 | V26: =IF(SUMIFS('Daily Forecast'!D:D,'Daily Forecast'!B:B,'Daily Flash NL (2)'!$D$12,'Daily Forecast'!F:F,U26,'Daily Forecast'!A:A,"Netherlands")=0,"",SUMIFS('Daily Forecast'!D:D,'Daily Forecast'!B:B,'Daily Flash NL (2)'!$D$12,'Daily Forecast'!F:F,U26,'Daily Forecast'!A:A,"Netherlands")) -> 57 | W26: =IFERROR(Z26/$J26,Z26) -> 46 | X26: =IFERROR(AA26/$J26,AA26) -> 46 | Y26: =IFERROR(AB26/$J26,AB26) -> 46 | Z26: =IFERROR(IF(F26="",V26*$Z$16,F26*J26),0) -> 37 | AA26: =IFERROR(IF(F26="",V26*$AA$16,F26*J26),0) -> 37 | AB26: =IFERROR(IF(F26="",V26*$AB$16,F26*J26),0) -> 37 | AE26: 7 | AF26: 42 | AH26: 42
A27: =+A26+1 -> 13 | D27: 0.54166667 | E27: =IF(SUMIFS('Daily Forecast'!D:D,'Daily Forecast'!B:B,'Daily Flash NL (2)'!$D$12,'Daily Forecast'!F:F,A27,'Daily Forecast'!A:A,"Netherlands")=0,"",SUMIFS('Daily Forecast'!D:D,'Daily Forecast'!B:B,'Daily Flash NL (2)'!$D$12,'Daily Forecast'!F:F,A27,'Daily Forecast'!A:A,"Netherlands")) -> 55 | F27: =IF(SUMIFS('Daily Storm Data 2'!I:I,'Daily Storm Data 2'!$A:$A,'Daily Flash NL (2)'!$D$12,'Daily Storm Data 2'!$G:$G,'Daily Flash NL (2)'!$A27,'Daily Storm Data 2'!$E:$E,"Netherlands")=0,"",SUMIFS('Daily Storm Data 2'!I:I,'Daily Storm Data 2'!$A:$A,'Daily Flash NL (2)'!$D$12,'Daily Storm Data 2'!$G:$G,'Daily Flash NL (2)'!$A27,'Daily Storm Data 2'!$E:$E,"Netherlands")) -> 57 | G27: =SUMIFS('Daily Storm Data 2'!J:J,'Daily Storm Data 2'!$A:$A,'Daily Flash NL (2)'!$D$12,'Daily Storm Data 2'!$G:$G,'Daily Flash NL (2)'!$A27,'Daily Storm Data 2'!$E:$E,"Netherlands") -> 57 | H27: =SUMIFS('Daily Storm Data 2'!K:K,'Daily Storm Data 2'!$A:$A,'Daily Flash NL (2)'!$D$12,'Daily Storm Data 2'!$G:$G,'Daily Flash NL (2)'!$A27,'Daily Storm Data 2'!$E:$E,"Netherlands") -> 44 | I27: =IFERROR(Table17[[#This Row],[Volume Actual]]/Table17[[#This Row],[Volume Forcasted]],"") -> 1.0363636 | J27: =IFERROR(H27/F27,"") -> 0.77192982 | K27: =+IFERROR(Table17[[#This Row],[Volume Handled]]/Table17[[#This Row],[Volume Actual]],"") -> 1 | L27: =SUMIFS('Daily Storm Data 2'!O:O,'Daily Storm Data 2'!$A:$A,'Daily Flash NL (2)'!$D$12,'Daily Storm Data 2'!$G:$G,'Daily Flash NL (2)'!$A27,'Daily Storm Data 2'!$E:$E,"Netherlands") -> 322.06828 | M27: 16 | N27: 11 | P27: =IFERROR(Table17[[#This Row],[Abs]]/Table17[[#This Row],[Planned]],"") -> 0.6875 | S27: 5 | U27: =+U26+1 -> 13 | V27: =IF(SUMIFS('Daily Forecast'!D:D,'Daily Forecast'!B:B,'Daily Flash NL (2)'!$D$12,'Daily Forecast'!F:F,U27,'Daily Forecast'!A:A,"Netherlands")=0,"",SUMIFS('Daily Forecast'!D:D,'Daily Forecast'!B:B,'Daily Flash NL (2)'!$D$12,'Daily Forecast'!F:F,U27,'Daily Forecast'!A:A,"Netherlands")) -> 55 | W27: =IFERROR(Z27/$J27,Z27) -> 57 | X27: =IFERROR(AA27/$J27,AA27) -> 57 | Y27: =IFERROR(AB27/$J27,AB27) -> 57 | Z27: =IFERROR(IF(F27="",V27*$Z$16,F27*J27),0) -> 44 | AA27: =IFERROR(IF(F27="",V27*$AA$16,F27*J27),0) -> 44 | AB27: =IFERROR(IF(F27="",V27*$AB$16,F27*J27),0) -> 44 | AE27: 8 | AF27: 82 | AH27: 82
A28: =+A27+1 -> 14 | D28: 0.58333333 | E28: =IF(SUMIFS('Daily Forecast'!D:D,'Daily Forecast'!B:B,'Daily Flash NL (2)'!$D$12,'Daily Forecast'!F:F,A28,'Daily Forecast'!A:A,"Netherlands")=0,"",SUMIFS('Daily Forecast'!D:D,'Daily Forecast'!B:B,'Daily Flash NL (2)'!$D$12,'Daily Forecast'!F:F,A28,'Daily Forecast'!A:A,"Netherlands")) -> 52 | F28: =IF(SUMIFS('Daily Storm Data 2'!I:I,'Daily Storm Data 2'!$A:$A,'Daily Flash NL (2)'!$D$12,'Daily Storm Data 2'!$G:$G,'Daily Flash NL (2)'!$A28,'Daily Storm Data 2'!$E:$E,"Netherlands")=0,"",SUMIFS('Daily Storm Data 2'!I:I,'Daily Storm Data 2'!$A:$A,'Daily Flash NL (2)'!$D$12,'Daily Storm Data 2'!$G:$G,'Daily Flash NL (2)'!$A28,'Daily Storm Data 2'!$E:$E,"Netherlands")) -> 65 | G28: =SUMIFS('Daily Storm Data 2'!J:J,'Daily Storm Data 2'!$A:$A,'Daily Flash NL (2)'!$D$12,'Daily Storm Data 2'!$G:$G,'Daily Flash NL (2)'!$A28,'Daily Storm Data 2'!$E:$E,"Netherlands") -> 55 | H28: =SUMIFS('Daily Storm Data 2'!K:K,'Daily Storm Data 2'!$A:$A,'Daily Flash NL (2)'!$D$12,'Daily Storm Data 2'!$G:$G,'Daily Flash NL (2)'!$A28,'Daily Storm Data 2'!$E:$E,"Netherlands") -> 11 | I28: =IFERROR(Table17[[#This Row],[Volume Actual]]/Table17[[#This Row],[Volume Forcasted]],"") -> 1.25 | J28: =IFERROR(H28/F28,"") -> 0.16923077 | K28: =+IFERROR(Table17[[#This Row],[Volume Handled]]/Table17[[#This Row],[Volume Actual]],"") -> 0.84615385 | L28: =SUMIFS('Daily Storm Data 2'!O:O,'Daily Storm Data 2'!$A:$A,'Daily Flash NL (2)'!$D$12,'Daily Storm Data 2'!$G:$G,'Daily Flash NL (2)'!$A28,'Daily Storm Data 2'!$E:$E,"Netherlands") -> 196.73504 | M28: 19 | N28: 12 | P28: =IFERROR(Table17[[#This Row],[Abs]]/Table17[[#This Row],[Planned]],"") -> 0.63157895 | S28: 6 | U28: =+U27+1 -> 14 | V28: =IF(SUMIFS('Daily Forecast'!D:D,'Daily Forecast'!B:B,'Daily Flash NL (2)'!$D$12,'Daily Forecast'!F:F,U28,'Daily Forecast'!A:A,"Netherlands")=0,"",SUMIFS('Daily Forecast'!D:D,'Daily Forecast'!B:B,'Daily Flash NL (2)'!$D$12,'Daily Forecast'!F:F,U28,'Daily Forecast'!A:A,"Netherlands")) -> 52 | W28: =IFERROR(Z28/$J28,Z28) -> 65 | X28: =IFERROR(AA28/$J28,AA28) -> 65 | Y28: =IFERROR(AB28/$J28,AB28) -> 65 | Z28: =IFERROR(IF(F28="",V28*$Z$16,F28*J28),0) -> 11 | AA28: =IFERROR(IF(F28="",V28*$AA$16,F28*J28),0) -> 11 | AB28: =IFERROR(IF(F28="",V28*$AB$16,F28*J28),0) -> 11 | AE28: 9 | AF28: 92 | AH28: 92
A29: =+A28+1 -> 15 | D29: 0.625 | E29: =IF(SUMIFS('Daily Forecast'!D:D,'Daily Forecast'!B:B,'Daily Flash NL (2)'!$D$12,'Daily Forecast'!F:F,A29,'Daily Forecast'!A:A,"Netherlands")=0,"",SUMIFS('Daily Forecast'!D:D,'Daily Forecast'!B:B,'Daily Flash NL (2)'!$D$12,'Daily Forecast'!F:F,A29,'Daily Forecast'!A:A,"Netherlands")) -> 45 | F29: =IF(SUMIFS('Daily Storm Data 2'!I:I,'Daily Storm Data 2'!$A:$A,'Daily Flash NL (2)'!$D$12,'Daily Storm Data 2'!$G:$G,'Daily Flash NL (2)'!$A29,'Daily Storm Data 2'!$E:$E,"Netherlands")=0,"",SUMIFS('Daily Storm Data 2'!I:I,'Daily Storm Data 2'!$A:$A,'Daily Flash NL (2)'!$D$12,'Daily Storm Data 2'!$G:$G,'Daily Flash NL (2)'!$A29,'Daily Storm Data 2'!$E:$E,"Netherlands")) -> 51 | G29: =SUMIFS('Daily Storm Data 2'!J:J,'Daily Storm Data 2'!$A:$A,'Daily Flash NL (2)'!$D$12,'Daily Storm Data 2'!$G:$G,'Daily Flash NL (2)'!$A29,'Daily Storm Data 2'!$E:$E,"Netherlands") -> 51 | H29: =SUMIFS('Daily Storm Data 2'!K:K,'Daily Storm Data 2'!$A:$A,'Daily Flash NL (2)'!$D$12,'Daily Storm Data 2'!$G:$G,'Daily Flash NL (2)'!$A29,'Daily Storm Data 2'!$E:$E,"Netherlands") -> 35 | I29: =IFERROR(Table17[[#This Row],[Volume Actual]]/Table17[[#This Row],[Volume Forcasted]],"") -> 1.1333333 | J29: =IFERROR(H29/F29,"") -> 0.68627451 | K29: =+IFERROR(Table17[[#This Row],[Volume Handled]]/Table17[[#This Row],[Volume Actual]],"") -> 1 | L29: =SUMIFS('Daily Storm Data 2'!O:O,'Daily Storm Data 2'!$A:$A,'Daily Flash NL (2)'!$D$12,'Daily Storm Data 2'!$G:$G,'Daily Flash NL (2)'!$A29,'Daily Storm Data 2'!$E:$E,"Netherlands") -> 253.2306 | M29: 18 | N29: 12 | P29: =IFERROR(Table17[[#This Row],[Abs]]/Table17[[#This Row],[Planned]],"") -> 0.66666667 | S29: 6 | U29: =+U28+1 -> 15 | V29: =IF(SUMIFS('Daily Forecast'!D:D,'Daily Forecast'!B:B,'Daily Flash NL (2)'!$D$12,'Daily Forecast'!F:F,U29,'Daily Forecast'!A:A,"Netherlands")=0,"",SUMIFS('Daily Forecast'!D:D,'Daily Forecast'!B:B,'Daily Flash NL (2)'!$D$12,'Daily Forecast'!F:F,U29,'Daily Forecast'!A:A,"Netherlands")) -> 45 | W29: =IFERROR(Z29/$J29,Z29) -> 51 | X29: =IFERROR(AA29/$J29,AA29) -> 51 | Y29: =IFERROR(AB29/$J29,AB29) -> 51 | Z29: =IFERROR(IF(F29="",V29*$Z$16,F29*J29),0) -> 35 | AA29: =IFERROR(IF(F29="",V29*$AA$16,F29*J29),0) -> 35 | AB29: =IFERROR(IF(F29="",V29*$AB$16,F29*J29),0) -> 35 | AE29: 10 | AF29: 98 | AH29: 98
A30: =+A29+1 -> 16 | D30: 0.66666667 | E30: =IF(SUMIFS('Daily Forecast'!D:D,'Daily Forecast'!B:B,'Daily Flash NL (2)'!$D$12,'Daily Forecast'!F:F,A30,'Daily Forecast'!A:A,"Netherlands")=0,"",SUMIFS('Daily Forecast'!D:D,'Daily Forecast'!B:B,'Daily Flash NL (2)'!$D$12,'Daily Forecast'!F:F,A30,'Daily Forecast'!A:A,"Netherlands")) -> 48 | F30: =IF(SUMIFS('Daily Storm Data 2'!I:I,'Daily Storm Data 2'!$A:$A,'Daily Flash NL (2)'!$D$12,'Daily Storm Data 2'!$G:$G,'Daily Flash NL (2)'!$A30,'Daily Storm Data 2'!$E:$E,"Netherlands")=0,"",SUMIFS('Daily Storm Data 2'!I:I,'Daily Storm Data 2'!$A:$A,'Daily Flash NL (2)'!$D$12,'Daily Storm Data 2'!$G:$G,'Daily Flash NL (2)'!$A30,'Daily Storm Data 2'!$E:$E,"Netherlands")) -> 53 | G30: =SUMIFS('Daily Storm Data 2'!J:J,'Daily Storm Data 2'!$A:$A,'Daily Flash NL (2)'!$D$12,'Daily Storm Data 2'!$G:$G,'Daily Flash NL (2)'!$A30,'Daily Storm Data 2'!$E:$E,"Netherlands") -> 48 | H30: =SUMIFS('Daily Storm Data 2'!K:K,'Daily Storm Data 2'!$A:$A,'Daily Flash NL (2)'!$D$12,'Daily Storm Data 2'!$G:$G,'Daily Flash NL (2)'!$A30,'Daily Storm Data 2'!$E:$E,"Netherlands") -> 24 | I30: =IFERROR(Table17[[#This Row],[Volume Actual]]/Table17[[#This Row],[Volume Forcasted]],"") -> 1.1041667 | J30: =IFERROR(H30/F30,"") -> 0.45283019 | K30: =+IFERROR(Table17[[#This Row],[Volume Handled]]/Table17[[#This Row],[Volume Actual]],"") -> 0.90566038 | L30: =SUMIFS('Daily Storm Data 2'!O:O,'Daily Storm Data 2'!$A:$A,'Daily Flash NL (2)'!$D$12,'Daily Storm Data 2'!$G:$G,'Daily Flash NL (2)'!$A30,'Daily Storm Data 2'!$E:$E,"Netherlands") -> 289.96221 | M30: 18 | N30: 12 | P30: =IFERROR(Table17[[#This Row],[Abs]]/Table17[[#This Row],[Planned]],"") -> 0.66666667 | S30: 7 | U30: =+U29+1 -> 16 | V30: =IF(SUMIFS('Daily Forecast'!D:D,'Daily Forecast'!B:B,'Daily Flash NL (2)'!$D$12,'Daily Forecast'!F:F,U30,'Daily Forecast'!A:A,"Netherlands")=0,"",SUMIFS('Daily Forecast'!D:D,'Daily Forecast'!B:B,'Daily Flash NL (2)'!$D$12,'Daily Forecast'!F:F,U30,'Daily Forecast'!A:A,"Netherlands")) -> 48 | W30: =IFERROR(Z30/$J30,Z30) -> 53 | X30: =IFERROR(AA30/$J30,AA30) -> 53 | Y30: =IFERROR(AB30/$J30,AB30) -> 53 | Z30: =IFERROR(IF(F30="",V30*$Z$16,F30*J30),0) -> 24 | AA30: =IFERROR(IF(F30="",V30*$AA$16,F30*J30),0) -> 24 | AB30: =IFERROR(IF(F30="",V30*$AB$16,F30*J30),0) -> 24
A31: =+A30+1 -> 17 | D31: 0.70833333 | E31: =IF(SUMIFS('Daily Forecast'!D:D,'Daily Forecast'!B:B,'Daily Flash NL (2)'!$D$12,'Daily Forecast'!F:F,A31,'Daily Forecast'!A:A,"Netherlands")=0,"",SUMIFS('Daily Forecast'!D:D,'Daily Forecast'!B:B,'Daily Flash NL (2)'!$D$12,'Daily Forecast'!F:F,A31,'Daily Forecast'!A:A,"Netherlands")) -> 40 | F31: =IF(SUMIFS('Daily Storm Data 2'!I:I,'Daily Storm Data 2'!$A:$A,'Daily Flash NL (2)'!$D$12,'Daily Storm Data 2'!$G:$G,'Daily Flash NL (2)'!$A31,'Daily Storm Data 2'!$E:$E,"Netherlands")=0,"",SUMIFS('Daily Storm Data 2'!I:I,'Daily Storm Data 2'!$A:$A,'Daily Flash NL (2)'!$D$12,'Daily Storm Data 2'!$G:$G,'Daily Flash NL (2)'!$A31,'Daily Storm Data 2'!$E:$E,"Netherlands")) -> 42 | G31: =SUMIFS('Daily Storm Data 2'!J:J,'Daily Storm Data 2'!$A:$A,'Daily Flash NL (2)'!$D$12,'Daily Storm Data 2'!$G:$G,'Daily Flash NL (2)'!$A31,'Daily Storm Data 2'!$E:$E,"Netherlands") -> 34 | H31: =SUMIFS('Daily Storm Data 2'!K:K,'Daily Storm Data 2'!$A:$A,'Daily Flash NL (2)'!$D$12,'Daily Storm Data 2'!$G:$G,'Daily Flash NL (2)'!$A31,'Daily Storm Data 2'!$E:$E,"Netherlands") -> 2 | I31: =IFERROR(Table17[[#This Row],[Volume Actual]]/Table17[[#This Row],[Volume Forcasted]],"") -> 1.05 | J31: =IFERROR(H31/F31,"") -> 0.047619048 | K31: =+IFERROR(Table17[[#This Row],[Volume Handled]]/Table17[[#This Row],[Volume Actual]],"") -> 0.80952381 | L31: =SUMIFS('Daily Storm Data 2'!O:O,'Daily Storm Data 2'!$A:$A,'Daily Flash NL (2)'!$D$12,'Daily Storm Data 2'!$G:$G,'Daily Flash NL (2)'!$A31,'Daily Storm Data 2'!$E:$E,"Netherlands") -> 294.75531 | M31: 12 | N31: 8 | P31: =IFERROR(Table17[[#This Row],[Abs]]/Table17[[#This Row],[Planned]],"") -> 0.66666667 | S31: 5 | U31: =+U30+1 -> 17 | V31: =IF(SUMIFS('Daily Forecast'!D:D,'Daily Forecast'!B:B,'Daily Flash NL (2)'!$D$12,'Daily Forecast'!F:F,U31,'Daily Forecast'!A:A,"Netherlands")=0,"",SUMIFS('Daily Forecast'!D:D,'Daily Forecast'!B:B,'Daily Flash NL (2)'!$D$12,'Daily Forecast'!F:F,U31,'Daily Forecast'!A:A,"Netherlands")) -> 40 | W31: =IFERROR(Z31/$J31,Z31) -> 42 | X31: =IFERROR(AA31/$J31,AA31) -> 42 | Y31: =IFERROR(AB31/$J31,AB31) -> 42 | Z31: =IFERROR(IF(F31="",V31*$Z$16,F31*J31),0) -> 2 | AA31: =IFERROR(IF(F31="",V31*$AA$16,F31*J31),0) -> 2 | AB31: =IFERROR(IF(F31="",V31*$AB$16,F31*J31),0) -> 2
A32: =+A31+1 -> 18 | D32: 0.75 | E32: =IF(SUMIFS('Daily Forecast'!D:D,'Daily Forecast'!B:B,'Daily Flash NL (2)'!$D$12,'Daily Forecast'!F:F,A32,'Daily Forecast'!A:A,"Netherlands")=0,"",SUMIFS('Daily Forecast'!D:D,'Daily Forecast'!B:B,'Daily Flash NL (2)'!$D$12,'Daily Forecast'!F:F,A32,'Daily Forecast'!A:A,"Netherlands")) -> 25 | F32: =IF(SUMIFS('Daily Storm Data 2'!I:I,'Daily Storm Data 2'!$A:$A,'Daily Flash NL (2)'!$D$12,'Daily Storm Data 2'!$G:$G,'Daily Flash NL (2)'!$A32,'Daily Storm Data 2'!$E:$E,"Netherlands")=0,"",SUMIFS('Daily Storm Data 2'!I:I,'Daily Storm Data 2'!$A:$A,'Daily Flash NL (2)'!$D$12,'Daily Storm Data 2'!$G:$G,'Daily Flash NL (2)'!$A32,'Daily Storm Data 2'!$E:$E,"Netherlands")) -> 24 | G32: =SUMIFS('Daily Storm Data 2'!J:J,'Daily Storm Data 2'!$A:$A,'Daily Flash NL (2)'!$D$12,'Daily Storm Data 2'!$G:$G,'Daily Flash NL (2)'!$A32,'Daily Storm Data 2'!$E:$E,"Netherlands") -> 18 | H32: =SUMIFS('Daily Storm Data 2'!K:K,'Daily Storm Data 2'!$A:$A,'Daily Flash NL (2)'!$D$12,'Daily Storm Data 2'!$G:$G,'Daily Flash NL (2)'!$A32,'Daily Storm Data 2'!$E:$E,"Netherlands") -> 4 | I32: =IFERROR(Table17[[#This Row],[Volume Actual]]/Table17[[#This Row],[Volume Forcasted]],"") -> 0.96 | J32: =IFERROR(H32/F32,"") -> 0.16666667 | K32: =+IFERROR(Table17[[#This Row],[Volume Handled]]/Table17[[#This Row],[Volume Actual]],"") -> 0.75 | L32: =SUMIFS('Daily Storm Data 2'!O:O,'Daily Storm Data 2'!$A:$A,'Daily Flash NL (2)'!$D$12,'Daily Storm Data 2'!$G:$G,'Daily Flash NL (2)'!$A32,'Daily Storm Data 2'!$E:$E,"Netherlands") -> 479.36481 | M32: 8 | N32: 5 | P32: =IFERROR(Table17[[#This Row],[Abs]]/Table17[[#This Row],[Planned]],"") -> 0.625 | S32: 3 | U32: =+U31+1 -> 18 | V32: =IF(SUMIFS('Daily Forecast'!D:D,'Daily Forecast'!B:B,'Daily Flash NL (2)'!$D$12,'Daily Forecast'!F:F,U32,'Daily Forecast'!A:A,"Netherlands")=0,"",SUMIFS('Daily Forecast'!D:D,'Daily Forecast'!B:B,'Daily Flash NL (2)'!$D$12,'Daily Forecast'!F:F,U32,'Daily Forecast'!A:A,"Netherlands")) -> 25 | W32: =IFERROR(Z32/$J32,Z32) -> 24 | X32: =IFERROR(AA32/$J32,AA32) -> 24 | Y32: =IFERROR(AB32/$J32,AB32) -> 24 | Z32: =IFERROR(IF(F32="",V32*$Z$16,F32*J32),0) -> 4 | AA32: =IFERROR(IF(F32="",V32*$AA$16,F32*J32),0) -> 4 | AB32: =IFERROR(IF(F32="",V32*$AB$16,F32*J32),0) -> 4
D33: 0.79166667 | E33: =IF(SUMIFS('Daily Forecast'!D:D,'Daily Forecast'!B:B,'Daily Flash NL (2)'!$D$12,'Daily Forecast'!F:F,A33,'Daily Forecast'!A:A,"Netherlands")=0,"",SUMIFS('Daily Forecast'!D:D,'Daily Forecast'!B:B,'Daily Flash NL (2)'!$D$12,'Daily Forecast'!F:F,A33,'Daily Forecast'!A:A,"Netherlands")) | F33: =IF(SUMIFS('Daily Storm Data 2'!I:I,'Daily Storm Data 2'!$A:$A,'Daily Flash NL (2)'!$D$12,'Daily Storm Data 2'!$G:$G,'Daily Flash NL (2)'!$A33,'Daily Storm Data 2'!$E:$E,"Netherlands")=0,"",SUMIFS('Daily Storm Data 2'!I:I,'Daily Storm Data 2'!$A:$A,'Daily Flash NL (2)'!$D$12,'Daily Storm Data 2'!$G:$G,'Daily Flash NL (2)'!$A33,'Daily Storm Data 2'!$E:$E,"Netherlands")) | G33: =SUMIFS('Daily Storm Data 2'!J:J,'Daily Storm Data 2'!$A:$A,'Daily Flash NL (2)'!$D$12,'Daily Storm Data 2'!$G:$G,'Daily Flash NL (2)'!$A33,'Daily Storm Data 2'!$E:$E,"Netherlands") -> 0 | H33: =SUMIFS('Daily Storm Data 2'!K:K,'Daily Storm Data 2'!$A:$A,'Daily Flash NL (2)'!$D$12,'Daily Storm Data 2'!$G:$G,'Daily Flash NL (2)'!$A33,'Daily Storm Data 2'!$E:$E,"Netherlands") -> 0 | I33: =IFERROR(Table17[[#This Row],[Volume Actual]]/Table17[[#This Row],[Volume Forcasted]],"") | J33: =IFERROR(H33/F33,"") | K33: =+IFERROR(Table17[[#This Row],[Volume Handled]]/Table17[[#This Row],[Volume Actual]],"") | L33: =SUMIFS('Daily Storm Data 2'!O:O,'Daily Storm Data 2'!$A:$A,'Daily Flash NL (2)'!$D$12,'Daily Storm Data 2'!$G:$G,'Daily Flash NL (2)'!$A33,'Daily Storm Data 2'!$E:$E,"Netherlands") -> 0 | M33: 5 | N33: 2 | P33: =IFERROR(Table17[[#This Row],[Abs]]/Table17[[#This Row],[Planned]],"") -> 0.4 | S33: 3 | U33: =+U32+1 -> 19 | V33: =IF(SUMIFS('Daily Forecast'!D:D,'Daily Forecast'!B:B,'Daily Flash NL (2)'!$D$12,'Daily Forecast'!F:F,U33,'Daily Forecast'!A:A,"Netherlands")=0,"",SUMIFS('Daily Forecast'!D:D,'Daily Forecast'!B:B,'Daily Flash NL (2)'!$D$12,'Daily Forecast'!F:F,U33,'Daily Forecast'!A:A,"Netherlands")) -> 16 | W33: =IFERROR(Z33/$J33,Z33) -> 19.089253 | X33: =IFERROR(AA33/$J33,AA33) -> 16 | Y33: =IFERROR(AB33/$J33,AB33) -> 9.6 | Z33: =IFERROR(IF(F33="",V33*$Z$16,F33*J33),0) -> 19.089253 | AA33: =IFERROR(IF(F33="",V33*$AA$16,F33*J33),0) -> 16 | AB33: =IFERROR(IF(F33="",V33*$AB$16,F33*J33),0) -> 9.6
D34: 0.83333333 | E34: =IF(SUMIFS('Daily Forecast'!D:D,'Daily Forecast'!B:B,'Daily Flash NL (2)'!$D$12,'Daily Forecast'!F:F,A34,'Daily Forecast'!A:A,"Netherlands")=0,"",SUMIFS('Daily Forecast'!D:D,'Daily Forecast'!B:B,'Daily Flash NL (2)'!$D$12,'Daily Forecast'!F:F,A34,'Daily Forecast'!A:A,"Netherlands")) | F34: =IF(SUMIFS('Daily Storm Data 2'!I:I,'Daily Storm Data 2'!$A:$A,'Daily Flash NL (2)'!$D$12,'Daily Storm Data 2'!$G:$G,'Daily Flash NL (2)'!$A34,'Daily Storm Data 2'!$E:$E,"Netherlands")=0,"",SUMIFS('Daily Storm Data 2'!I:I,'Daily Storm Data 2'!$A:$A,'Daily Flash NL (2)'!$D$12,'Daily Storm Data 2'!$G:$G,'Daily Flash NL (2)'!$A34,'Daily Storm Data 2'!$E:$E,"Netherlands")) | G34: =SUMIFS('Daily Storm Data 2'!J:J,'Daily Storm Data 2'!$A:$A,'Daily Flash NL (2)'!$D$12,'Daily Storm Data 2'!$G:$G,'Daily Flash NL (2)'!$A34,'Daily Storm Data 2'!$E:$E,"Netherlands") -> 0 | H34: =SUMIFS('Daily Storm Data 2'!K:K,'Daily Storm Data 2'!$A:$A,'Daily Flash NL (2)'!$D$12,'Daily Storm Data 2'!$G:$G,'Daily Flash NL (2)'!$A34,'Daily Storm Data 2'!$E:$E,"Netherlands") -> 0 | I34: =IFERROR(Table17[[#This Row],[Volume Actual]]/Table17[[#This Row],[Volume Forcasted]],"") | J34: =IFERROR(H34/F34,"") | K34: =+IFERROR(Table17[[#This Row],[Volume Handled]]/Table17[[#This Row],[Volume Actual]],"") | L34: =SUMIFS('Daily Storm Data 2'!O:O,'Daily Storm Data 2'!$A:$A,'Daily Flash NL (2)'!$D$12,'Daily Storm Data 2'!$G:$G,'Daily Flash NL (2)'!$A34,'Daily Storm Data 2'!$E:$E,"Netherlands") -> 0 | M34: 5 | N34: 2 | P34: =IFERROR(Table17[[#This Row],[Abs]]/Table17[[#This Row],[Planned]],"") -> 0.4 | S34: 3 | U34: =+U33+1 -> 20 | V34: =IF(SUMIFS('Daily Forecast'!D:D,'Daily Forecast'!B:B,'Daily Flash NL (2)'!$D$12,'Daily Forecast'!F:F,U34,'Daily Forecast'!A:A,"Netherlands")=0,"",SUMIFS('Daily Forecast'!D:D,'Daily Forecast'!B:B,'Daily Flash NL (2)'!$D$12,'Daily Forecast'!F:F,U34,'Daily Forecast'!A:A,"Netherlands")) -> 12 | W34: =IFERROR(Z34/$J34,Z34) -> 14.31694 | X34: =IFERROR(AA34/$J34,AA34) -> 12 | Y34: =IFERROR(AB34/$J34,AB34) -> 7.2 | Z34: =IFERROR(IF(F34="",V34*$Z$16,F34*J34),0) -> 14.31694 | AA34: =IFERROR(IF(F34="",V34*$AA$16,F34*J34),0) -> 12 | AB34: =IFERROR(IF(F34="",V34*$AB$16,F34*J34),0) -> 7.2
D35: 0.875 | E35: =IF(SUMIFS('Daily Forecast'!D:D,'Daily Forecast'!B:B,'Daily Flash NL (2)'!$D$12,'Daily Forecast'!F:F,A35,'Daily Forecast'!A:A,"Netherlands")=0,"",SUMIFS('Daily Forecast'!D:D,'Daily Forecast'!B:B,'Daily Flash NL (2)'!$D$12,'Daily Forecast'!F:F,A35,'Daily Forecast'!A:A,"Netherlands")) | F35: =IF(SUMIFS('Daily Storm Data 2'!I:I,'Daily Storm Data 2'!$A:$A,'Daily Flash NL (2)'!$D$12,'Daily Storm Data 2'!$G:$G,'Daily Flash NL (2)'!$A35,'Daily Storm Data 2'!$E:$E,"Netherlands")=0,"",SUMIFS('Daily Storm Data 2'!I:I,'Daily Storm Data 2'!$A:$A,'Daily Flash NL (2)'!$D$12,'Daily Storm Data 2'!$G:$G,'Daily Flash NL (2)'!$A35,'Daily Storm Data 2'!$E:$E,"Netherlands")) | G35: =SUMIFS('Daily Storm Data 2'!J:J,'Daily Storm Data 2'!$A:$A,'Daily Flash NL (2)'!$D$12,'Daily Storm Data 2'!$G:$G,'Daily Flash NL (2)'!$A35,'Daily Storm Data 2'!$E:$E,"Netherlands") -> 0 | H35: =SUMIFS('Daily Storm Data 2'!K:K,'Daily Storm Data 2'!$A:$A,'Daily Flash NL (2)'!$D$12,'Daily Storm Data 2'!$G:$G,'Daily Flash NL (2)'!$A35,'Daily Storm Data 2'!$E:$E,"Netherlands") -> 0 | I35: =IFERROR(Table17[[#This Row],[Volume Actual]]/Table17[[#This Row],[Volume Forcasted]],"") | J35: =IFERROR(H35/F35,"") | K35: =+IFERROR(Table17[[#This Row],[Volume Handled]]/Table17[[#This Row],[Volume Actual]],"") | L35: =SUMIFS('Daily Storm Data 2'!O:O,'Daily Storm Data 2'!$A:$A,'Daily Flash NL (2)'!$D$12,'Daily Storm Data 2'!$G:$G,'Daily Flash NL (2)'!$A35,'Daily Storm Data 2'!$E:$E,"Netherlands") -> 0 | M35: 4 | N35: 1 | P35: =IFERROR(Table17[[#This Row],[Abs]]/Table17[[#This Row],[Planned]],"") -> 0.25 | S35: 3 | U35: =+U34+1 -> 21 | V35: =IF(SUMIFS('Daily Forecast'!D:D,'Daily Forecast'!B:B,'Daily Flash NL (2)'!$D$12,'Daily Forecast'!F:F,U35,'Daily Forecast'!A:A,"Netherlands")=0,"",SUMIFS('Daily Forecast'!D:D,'Daily Forecast'!B:B,'Daily Flash NL (2)'!$D$12,'Daily Forecast'!F:F,U35,'Daily Forecast'!A:A,"Netherlands")) -> 9 | W35: =IFERROR(Z35/$J35,Z35) -> 10.737705 | X35: =IFERROR(AA35/$J35,AA35) -> 9 | Y35: =IFERROR(AB35/$J35,AB35) -> 5.4 | Z35: =IFERROR(IF(F35="",V35*$Z$16,F35*J35),0) -> 10.737705 | AA35: =IFERROR(IF(F35="",V35*$AA$16,F35*J35),0) -> 9 | AB35: =IFERROR(IF(F35="",V35*$AB$16,F35*J35),0) -> 5.4
