Workbook
Name Bonus_Report_Period: SETUP!$B$5

Sheet SETUP
A1: Bonus management setup
A2: Blue cells are the only operating inputs. One period controls the complete workbook.
A4: Control | B4: Value
A5: Report period | B5: 2026-07
A6: Generated at | B6: 46265.014
A7: Prepared by | B7: Anass ASSRI
A8: Workbook version | B8: 1.0
A9: Policy release gate | B9: =IF(COUNTIF(tblPolicies[Status],"Validated")=ROWS(tblPolicies[Status]),"READY","BLOCKED") -> BLOCKED
A11: Operating rule
A12: Scenario payout is visible for management discussion. Released payout remains blank until every policy is Validated, the employee is eligible, and Data Status is VALIDATED. The source workbook is never modified.

Sheet POLICY_APPROVAL
A1: Policy approval
A2: Every row must be Validated before payroll release. Owners must document the approved choice.
A4: Policy | B4: Selected Decision | C4: Allowed Values | D4: Formula Impact | E4: Owner | F4: Status | G4: Comments
A5: Malus method | B5: Proportional | C5: Proportional | Percentage points | D5: Final Achievement = Gross x (1-Malus), or Gross-Malus | E5: HR / Compensation | F5: Validated
A6: Extra PCS treatment | B6: Additive | C6: Additive | Replacement | D6: Additive sums standard and extra PCS; Replacement keeps the higher PCS award | E6: Operations / HR | F6: Validated
A7: Target bonus rate basis | B7: Monthly | C7: Monthly | Annual | D7: Annual rates are divided by 12 before monthly payout calculation | E7: HR / Payroll | F7: Validated
A8: Proration denominator | B8: Calendar days | C8: Calendar days | Working days | Planned days | D8: Determines how Scheduled Days and Eligible Days must be populated | E8: HR / Payroll | F8: Validated
A9: Absence treatment | B9: KPI only | C9: KPI only | Eligibility only | Both | D9: Prevents unintended double reduction unless Both is explicitly approved | E9: HR / Operations | F9: Validated
A10: Achievement cap | B10: 1.3 | C10: 0% to 200% | D10: Caps Gross Achievement after KPI aggregation | E10: HR / Compensation | F10: Validated
A11: Rounding | B11: Centime | C11: Centime | Whole MAD | D11: Final Payout rounded to 2 decimals or 0 decimals | E11: Payroll | F11: To validate
A12: Employee eligibility | B12: Active eligible population | C12: Policy reference required | D12: Controls joiners, leavers, probation and exclusions | E12: HR | F12: To validate

Sheet BONUS_RULES
A1: Central bonus rules
A2: All thresholds and weights are visible here. Duplicate Population + KPI rows are blocked by controls.
A4: Population | B4: KPI | C4: Direction | D4: Tier 1 Bonus % | E4: Tier 1 Target | F4: Tier 2 Bonus % | G4: Tier 2 Target | I4: VOC Detractors | J4: Malus Impact
A5: Ford GER | B5: AHT | C5: L | D5: 0.15 | E5: 450 | F5: 0 | G5: 0 | I5: 0 | J5: 0
A6: Ford GER | B6: Productivity | C6: H | D6: 0.15 | E6: 7 | F6: 0 | G6: 0 | I6: 1 | J6: 0.1
A7: Ford GER | B7: PCS Score | C7: H | D7: 0.2 | E7: 4.3 | F7: 0.15 | G7: 4.1 | I7: 2 | J7: 0.2
A8: Ford GER | B8: PCS % (Participation) | C8: H | D8: 0.15 | E8: 0.5 | F8: 0.1 | G8: 0.4 | I8: 3 | J8: 0.5
A9: Ford GER | B9: QM | C9: H | D9: 0.2 | E9: 0.9 | F9: 0.15 | G9: 0.8 | I9: 4 | J9: 0.75
A10: Ford GER | B10: Abs% | C10: L | D10: 0.15 | E10: 0.05 | F10: 0 | G10: 0 | I10: 5 | J10: 1
A11: Ford GER | B11: Extra Bonus (PCS Score) | C11: H | D11: 0.3 | E11: 4.5 | F11: 0.2 | G11: 4.3
A12: Ford Dutch | B12: AHT | C12: L | D12: 0.15 | E12: 450 | F12: 0 | G12: 0
A13: Ford Dutch | B13: Productivity | C13: H | D13: 0.15 | E13: 7 | F13: 0 | G13: 0
A14: Ford Dutch | B14: PCS Score | C14: H | D14: 0.2 | E14: 4.3 | F14: 0.15 | G14: 4.1
A15: Ford Dutch | B15: PCS % (Participation) | C15: H | D15: 0.15 | E15: 0.5 | F15: 0.1 | G15: 0.4
A16: Ford Dutch | B16: QM | C16: H | D16: 0.2 | E16: 0.9 | F16: 0.15 | G16: 0.8
A17: Ford Dutch | B17: Abs% | C17: L | D17: 0.15 | E17: 0.05 | F17: 0 | G17: 0
A18: Ford Dutch | B18: Extra Bonus (PCS Score) | C18: H | D18: 0.3 | E18: 4.5 | F18: 0.2 | G18: 4.3
A19: OEM FR | B19: AHT | C19: L | D19: 0.15 | E19: 450 | F19: 0 | G19: 0
A20: OEM FR | B20: Productivity | C20: H | D20: 0.15 | E20: 7 | F20: 0 | G20: 0
A21: OEM FR | B21: PCS Score | C21: H | D21: 0.2 | E21: 4.3 | F21: 0.15 | G21: 4.1
A22: OEM FR | B22: PCS % (Participation) | C22: H | D22: 0.15 | E22: 0.5 | F22: 0.1 | G22: 0.4
... A46: RSA VL | B46: Extra Bonus (PCS Score) | C46: H | D46: 0.3 | E46: 4.5 | F46: 0.2 | G46: 4.3

Sheet AGENT_INPUT
A1: Agent bonus input
A2: Paste or type one agent-period per row. Blue cells are inputs; synthetic rows remain clearly labelled.
A4: Agent ID | B4: Agent Name | C4: Population | D4: Period | E4: AHT | F4: Productivity | G4: PCS Score | H4: PCS Participation | I4: QM | J4: Absence % | K4: VOC Detractors | L4: Currency | M4: Monthly Fixed Salary | N4: Target Bonus Rate | O4: Reference Bonus Override | P4: Eligible Days | Q4: Scheduled Days | R4: Employment Status | S4: Data Status | T4: Notes
A5: 204341 | B5: Felhane Mohamed Amine | C5: Ford GER | D5: 2026-07 | E5: 451.41525 | F5: 7.3103422 | G5: 2.1538462 | H5: 0.091872792 | K5: 0 | L5: MAD | O5: 2000 | P5: 31 | Q5: 31 | R5: Not supplied | S5: ICMP
A6: 204342 | B6: Zekhnini Mustapha | C6: Ford GER | D6: 2026-07 | E6: 664.04077 | F6: 4.9695744 | G6: 4.7142857 | H6: 0.090128755 | K6: 0 | L6: MAD | O6: 2000 | P6: 31 | Q6: 31 | R6: Not supplied | S6: ICMP
A7: 204343 | B7: Talhajit Abdellah | C7: Ford GER | D7: 2026-07 | E7: 589.97174 | F7: 5.5934883 | G7: 1 | H7: 0.109375 | K7: 0 | L7: MAD | O7: 2000 | P7: 31 | Q7: 31 | R7: Not supplied | S7: ICMP
A8: 204344 | B8: AYMAZ Abdelhay | C8: Ford GER | D8: 2026-07 | E8: 717.1025 | F8: 4.6018526 | G8: 4.7 | H8: 0.12389381 | K8: 0 | L8: MAD | O8: 2000 | P8: 31 | Q8: 31 | R8: Not supplied | S8: ICMP
A9: 204345 | B9: MOUSSA Amjad | C9: Ford GER | D9: 2026-07 | E9: 784.95633 | F9: 4.2040555 | G9: 4 | H9: 0.029850746 | K9: 0 | L9: MAD | O9: 2000 | P9: 31 | Q9: 31 | R9: Not supplied | S9: ICMP
A10: 204602 | B10: DRISSI Sidi Youssef | C10: Ford GER | D10: 2026-07 | E10: 707.70197 | F10: 4.6629798 | G10: 3.8461538 | H10: 0.082987552 | K10: 0 | L10: MAD | O10: 2000 | P10: 31 | Q10: 31 | R10: Not supplied | S10: ICMP
A11: 204349 | B11: NABACH Lara | C11: Ford GER | D11: 2026-07 | E11: 459.94248 | F11: 7.1748102 | G11: 4.2222222 | H11: 0.10655738 | K11: 0 | L11: MAD | O11: 2000 | P11: 31 | Q11: 31 | R11: Not supplied | S11: ICMP
A12: 228205 | B12: Mohamed Amine MERSAK | C12: OEM FR | D12: 2026-07 | E12: 437.32258 | F12: 7.5459172 | G12: 4.9310345 | H12: 0.39303483 | I12: 0.636 | K12: 0 | L12: MAD | O12: 2000 | P12: 31 | Q12: 31 | R12: Not supplied | S12: ICMP
A13: 204018 | B13: Mejhed Asmaa | C13: Ford Dutch | D13: 2026-07 | G13: 4.1111111 | H13: 0.056672761 | I13: 0 | K13: 0 | L13: MAD | O13: 2000 | P13: 31 | Q13: 31 | R13: Not supplied | S13: ICMP
A14: 250749 | B14: Achraf ENNAJAH | C14: OEM FR | D14: 2026-07 | K14: 0 | L14: MAD | O14: 2000 | P14: 31 | Q14: 31 | R14: Not supplied | S14: ICMP
A15: 250750 | B15: Ayoub EL ADRAOUI | C15: OEM FR | D15: 2026-07 | K15: 0 | L15: MAD | O15: 2000 | P15: 31 | Q15: 31 | R15: Not supplied | S15: ICMP
A16: 266361 | B16: Mohamed Zuljami | C16: RSA VL | D16: 2026-07 | K16: 0 | L16: MAD | O16: 2000 | P16: 31 | Q16: 31 | R16: Not supplied | S16: ICMP
A17: 204037 | B17: Ouadie REGRAGUI | C17: RSA NL | D17: 2026-07 | E17: 497.66292 | F17: 6.6309943 | G17: 3 | H17: 0.036184211 | I17: 0.88 | J17: 0.14 | K17: 0 | L17: MAD | O17: 2000 | P17: 31 | Q17: 31 | R17: Not supplied | S17: ICMP
A18: 232195 | B18: Khalid BOJADA | C18: RSA NL | D18: 2026-07 | E18: 431.0938 | F18: 7.6549466 | G18: 4.1707317 | H18: 0.10742188 | I18: 0.45 | J18: 0.12 | K18: 0 | L18: MAD | O18: 2000 | P18: 31 | Q18: 31 | R18: Not supplied | S18: ICMP
A19: 228217 | B19: Zineb ZAAROURI | C19: OEM FR | D19: 2026-07 | E19: 457.88506 | F19: 7.2070489 | G19: 5 | H19: 0.19166667 | I19: 0.849 | J19: 0 | K19: 0 | L19: MAD | O19: 2000 | P19: 31 | Q19: 31 | R19: Not supplied | S19: ICMP
A20: 204033 | B20: Oulad Abdelaziz Youssef | C20: Ford Dutch | D20: 2026-07 | E20: 331.95904 | F20: 9.9409854 | G20: 3.5294118 | H20: 0.059925094 | I20: 0.2 | J20: 0.2 | K20: 0 | L20: MAD | O20: 2000 | P20: 31 | Q20: 31 | R20: Not supplied | S20: ICMP
A21: 228202 | B21: Youssef AZIZ | C21: OEM FR | D21: 2026-07 | E21: 619.22154 | F21: 5.329272 | G21: 4.627451 | H21: 0.37016575 | I21: 0.56416667 | J21: 0 | K21: 0 | L21: MAD | O21: 2000 | P21: 31 | Q21: 31 | R21: Not supplied | S21: ICMP
A22: 228201 | B22: Youssef AMNAD | C22: OEM FR | D22: 2026-07 | E22: 459.58571 | F22: 7.1803798 | G22: 4.9705882 | H22: 0.28965517 | I22: 0.65666667 | J22: 0 | K22: 0 | L22: MAD | O22: 2000 | P22: 31 | Q22: 31 | R22: Not supplied | S22: ICMP
A23: 250753 | B23: Youness ZBATI | C23: OEM FR | D23: 2026-07 | J23: 0 | K23: 0 | L23: MAD | O23: 2000 | P23: 31 | Q23: 31 | R23: Not supplied | S23: ICMP
A24: 249778 | B24: Youness OUAHBI | C24: RSA FR | D24: 2026-07 | J24: 0 | K24: 0 | L24: MAD | O24: 2000 | P24: 31 | Q24: 31 | R24: Not supplied | S24: ICMP
A25: 96496 | B25: HADRI Younes | C25: RSA VL | D25: 2026-07 | E25: 323.5027 | F25: 10.200842 | G25: 3.3333333 | H25: 0.075812274 | I25: 0.96333333 | J25: 0 | K25: 0 | L25: MAD | O25: 2000 | P25: 31 | Q25: 31 | R25: Not supplied | S25: ICMP
A26: 228215 | B26: Younes EL FELLAH EL OUAZZANI | C26: OEM FR | D26: 2026-07 | E26: 450.93291 | F26: 7.3181619 | G26: 4.5882353 | H26: 0.20098039 | I26: 0.66461538 | J26: 0 | K26: 0 | L26: MAD | O26: 2000 | P26: 31 | Q26: 31 | R26: Not supplied | S26: ICMP
A27: 228211 | B27: Yazid LAGDEM | C27: OEM FR | D27: 2026-07 | E27: 630.17832 | F27: 5.236613 | G27: 4.8918919 | H27: 0.29310345 | I27: 0.76 | J27: 0 | K27: 0 | L27: MAD | O27: 2000 | P27: 31 | Q27: 31 | R27: Not supplied | S27: ICMP
A28: 232196 | B28: Yassir Issarti | C28: RSA NL | D28: 2026-07 | E28: 645.55617 | F28: 5.1118712 | G28: 4.2142857 | H28: 0.089775561 | I28: 0.176 | J28: 0 | K28: 0 | L28: MAD | O28: 2000 | P28: 31 | Q28: 31 | R28: Not supplied | S28: ICMP
A29: 203614 | B29: El Mekkaoui Yassir | C29: OEM FR | D29: 2026-07 | E29: 477.53503 | F29: 6.9104878 | G29: 4.5925926 | H29: 0.20574163 | I29: 0.62714286 | J29: 0 | K29: 0 | L29: MAD | O29: 2000 | P29: 31 | Q29: 31 | R29: Not supplied | S29: ICMP
A30: 244554 | B30: Yassine Athmane | C30: RSA NL | D30: 2026-07 | K30: 0 | L30: MAD | O30: 2000 | P30: 31 | Q30: 31 | R30: Not supplied | S30: ICMP
A31: 203646 | B31: Jemkar Yasmine | C31: OEM FR | D31: 2026-07 | E31: 365.87097 | F31: 9.0195733 | G31: 4.5405405 | H31: 0.20425532 | I31: 0.67923077 | J31: 0 | K31: 0 | L31: MAD | O31: 2000 | P31: 31 | Q31: 31 | R31: Not supplied | S31: ICMP
A32: 96486 | B32: EL BAROUDI El Yassmine | C32: RSA NL | D32: 2026-07 | E32: 246.35317 | F32: 13.395403 | G32: 3.375 | H32: 0.067039106 | I32: 0.2075 | J32: 0 | K32: 0 | L32: MAD | O32: 2000 | P32: 31 | Q32: 31 | R32: Not supplied | S32: ICMP
A33: 204024 | B33: Van der Laan Tim | C33: Ford Dutch | D33: 2026-07 | E33: 374.85809 | F33: 8.8033314 | G33: 4.1568627 | H33: 0.11347518 | I33: 0 | J33: 0.15 | K33: 0 | L33: MAD | O33: 2000 | P33: 31 | Q33: 31 | R33: Not supplied | S33: ICMP
A34: 224102 | B34: Tasnim NAJI | C34: RSA NL | D34: 2026-07 | E34: 574 | F34: 5.7491289 | G34: 4 | H34: 0.062135922 | I34: 0.58666667 | J34: 0.09 | K34: 0 | L34: MAD | O34: 2000 | P34: 31 | Q34: 31 | R34: Not supplied | S34: ICMP
A35: 228213 | B35: Taoufik MANOUNI | C35: OEM FR | D35: 2026-07 | E35: 415.82136 | F35: 7.9361003 | G35: 4.7083333 | H35: 0.40863787 | I35: 0.73083333 | J35: 0 | K35: 0 | L35: MAD | O35: 2000 | P35: 31 | Q35: 31 | R35: Not supplied | S35: ICMP
A36: 244550 | B36: taissir Bakour | C36: RSA NL | D36: 2026-07 | K36: 0 | L36: MAD | O36: 2000 | P36: 31 | Q36: 31 | R36: Not supplied | S36: ICMP
A37: 207437 | B37: Taha Aboulhaoul | C37: RSA FR | D37: 2026-07 | E37: 303.85647 | F37: 10.860391 | G37: 2.9090909 | H37: 0.061630219 | I37: 0.79571429 | J37: 0 | K37: 0 | L37: MAD | O37: 2000 | P37: 31 | Q37: 31 | R37: Not supplied | S37: ICMP
A38: 240747 | B38: Soufiane ROUH | C38: RSA NL | D38: 2026-07 | G38: 1 | H38: 0.05 | K38: 0 | L38: MAD | O38: 2000 | P38: 31 | Q38: 31 | R38: Not supplied | S38: ICMP
A39: 221751 | B39: Shaib Hashemi | C39: RSA NL | D39: 2026-07 | E39: 375.34 | F39: 8.7920286 | G39: 3.4 | H39: 0.053299492 | I39: 0 | J39: 0.3 | K39: 0 | L39: MAD | O39: 2000 | P39: 31 | Q39: 31 | R39: Not supplied | S39: ICMP
A40: 232190 | B40: SCOTT BAHRU DE COENE | C40: RSA VL | D40: 2026-07 | E40: 523.15679 | F40: 6.3078603 | G40: 2.7142857 | H40: 0.057522124 | I40: 0.625 | J40: 0 | K40: 0 | L40: MAD | O40: 2000 | P40: 31 | Q40: 31 | R40: Not supplied | S40: ICMP
A41: 204045 | B41: Ait El Bashir Salah Eddine | C41: Ford Dutch | D41: 2026-07 | E41: 358.18152 | F41: 9.2132057 | G41: 4.2278481 | H41: 0.18081181 | I41: 0.66666667 | J41: 0.01 | K41: 0 | L41: MAD | O41: 2000 | P41: 31 | Q41: 31 | R41: Not supplied | S41: ICMP
...

Sheet AGENT_RESULTS
A1: Agent calculation
A2: Formula-driven scenario and released payout. Released payout cannot appear while a gate is blocked.
A4: Agent ID | B4: Agent | C4: Population | D4: Core Input | E4: Eligibility Review | F4: AHT Earned | G4: Productivity Earned | H4: PCS Earned | I4: Participation Earned | J4: QM Earned | K4: Absence Earned | L4: Extra PCS Earned | M4: Gross Achievement | N4: VOC Malus | O4: Final Achievement | P4: Reference Bonus | Q4: Proration | R4: Scenario Payout | S4: Released Payout | T4: Release Status | U4: Data Issue
A5: =IF(AGENT_INPUT!A5="","",AGENT_INPUT!A5) -> 204341 | B5: =IF($A5="","",AGENT_INPUT!B5) -> Felhane Mohamed Amine | C5: =IF($A5="","",AGENT_INPUT!C5) -> Ford GER | D5: =IF($A5="","",IF(AND(COUNT(AGENT_INPUT!E5:J5)=6,COUNT(AGENT_INPUT!K5)=1,COUNTIF(BONUS_RULES!$A$5:$A$46,AGENT_INPUT!C5)>0,OR(AGENT_INPUT!O5>0,AND(AGENT_INPUT!M5>0,AGENT_INPUT!N5>0)),AGENT_INPUT!P5>=0,AGENT_INPUT!Q5>0,AGENT_INPUT!P5<=AGENT_INPUT!Q5,AGENT_INPUT!H5>=0,AGENT_INPUT!H5<=1,AGENT_INPUT!I5>=0,AGENT_INPUT!I5<=1,AGENT_INPUT!J5>=0,AGENT_INPUT!J5<=1),"READY","BLOCKED")) -> BLOCKED | E5: =IF($A5="","",IF(AGENT_INPUT!R5<>"Active","REVIEW",IF(OR(POLICY_APPROVAL!$B$9="Eligibility only",POLICY_APPROVAL!$B$9="Both"),IF(AGENT_INPUT!J5<=SUMIFS(BONUS_RULES!$E$5:$E$46,BONUS_RULES!$A$5:$A$46,$C5,BONUS_RULES!$B$5:$B$46,"Abs%"),"ELIGIBLE","INELIGIBLE ABS"),"ELIGIBLE"))) | F5: =IF(OR($A5="",$D5<>"READY"),"",IF(AGENT_INPUT!E5<=SUMIFS(BONUS_RULES!$E$5:$E$46,BONUS_RULES!$A$5:$A$46,$C5,BONUS_RULES!$B$5:$B$46,"AHT"),SUMIFS(BONUS_RULES!$D$5:$D$46,BONUS_RULES!$A$5:$A$46,$C5,BONUS_RULES!$B$5:$B$46,"AHT"),IF(AGENT_INPUT!E5<=SUMIFS(BONUS_RULES!$G$5:$G$46,BONUS_RULES!$A$5:$A$46,$C5,BONUS_RULES!$B$5:$B$46,"AHT"),SUMIFS(BONUS_RULES!$F$5:$F$46,BONUS_RULES!$A$5:$A$46,$C5,BONUS_RULES!$B$5:$B$46,"AHT"),0))) | G5: =IF(OR($A5="",$D5<>"READY"),"",IF(AGENT_INPUT!F5>=SUMIFS(BONUS_RULES!$E$5:$E$46,BONUS_RULES!$A$5:$A$46,$C5,BONUS_RULES!$B$5:$B$46,"Productivity"),SUMIFS(BONUS_RULES!$D$5:$D$46,BONUS_RULES!$A$5:$A$46,$C5,BONUS_RULES!$B$5:$B$46,"Productivity"),IF(AGENT_INPUT!F5>=SUMIFS(BONUS_RULES!$G$5:$G$46,BONUS_RULES!$A$5:$A$46,$C5,BONUS_RULES!$B$5:$B$46,"Productivity"),SUMIFS(BONUS_RULES!$F$5:$F$46,BONUS_RULES!$A$5:$A$46,$C5,BONUS_RULES!$B$5:$B$46,"Productivity"),0))) | H5: =IF(OR($A5="",$D5<>"READY"),"",IF(AGENT_INPUT!G5>=SUMIFS(BONUS_RULES!$E$5:$E$46,BONUS_RULES!$A$5:$A$46,$C5,BONUS_RULES!$B$5:$B$46,"PCS Score"),SUMIFS(BONUS_RULES!$D$5:$D$46,BONUS_RULES!$A$5:$A$46,$C5,BONUS_RULES!$B$5:$B$46,"PCS Score"),IF(AGENT_INPUT!G5>=SUMIFS(BONUS_RULES!$G$5:$G$46,BONUS_RULES!$A$5:$A$46,$C5,BONUS_RULES!$B$5:$B$46,"PCS Score"),SUMIFS(BONUS_RULES!$F$5:$F$46,BONUS_RULES!$A$5:$A$46,$C5,BONUS_RULES!$B$5:$B$46,"PCS Score"),0))) | I5: =IF(OR($A5="",$D5<>"READY"),"",IF(AGENT_INPUT!H5>=SUMIFS(BONUS_RULES!$E$5:$E$46,BONUS_RULES!$A$5:$A$46,$C5,BONUS_RULES!$B$5:$B$46,"PCS % (Participation)"),SUMIFS(BONUS_RULES!$D$5:$D$46,BONUS_RULES!$A$5:$A$46,$C5,BONUS_RULES!$B$5:$B$46,"PCS % (Participation)"),IF(AGENT_INPUT!H5>=SUMIFS(BONUS_RULES!$G$5:$G$46,BONUS_RULES!$A$5:$A$46,$C5,BONUS_RULES!$B$5:$B$46,"PCS % (Participation)"),SUMIFS(BONUS_RULES!$F$5:$F$46,BONUS_RULES!$A$5:$A$46,$C5,BONUS_RULES!$B$5:$B$46,"PCS % (Participation)"),0))) | J5: =IF(OR($A5="",$D5<>"READY"),"",IF(AGENT_INPUT!I5>=SUMIFS(BONUS_RULES!$E$5:$E$46,BONUS_RULES!$A$5:$A$46,$C5,BONUS_RULES!$B$5:$B$46,"QM"),SUMIFS(BONUS_RULES!$D$5:$D$46,BONUS_RULES!$A$5:$A$46,$C5,BONUS_RULES!$B$5:$B$46,"QM"),IF(AGENT_INPUT!I5>=SUMIFS(BONUS_RULES!$G$5:$G$46,BONUS_RULES!$A$5:$A$46,$C5,BONUS_RULES!$B$5:$B$46,"QM"),SUMIFS(BONUS_RULES!$F$5:$F$46,BONUS_RULES!$A$5:$A$46,$C5,BONUS_RULES!$B$5:$B$46,"QM"),0))) | K5: =IF(POLICY_APPROVAL!$B$9="Eligibility only",0,IF(OR($A5="",$D5<>"READY"),"",IF(AGENT_INPUT!J5<=SUMIFS(BONUS_RULES!$E$5:$E$46,BONUS_RULES!$A$5:$A$46,$C5,BONUS_RULES!$B$5:$B$46,"Abs%"),SUMIFS(BONUS_RULES!$D$5:$D$46,BONUS_RULES!$A$5:$A$46,$C5,BONUS_RULES!$B$5:$B$46,"Abs%"),IF(AGENT_INPUT!J5<=SUMIFS(BONUS_RULES!$G$5:$G$46,BONUS_RULES!$A$5:$A$46,$C5,BONUS_RULES!$B$5:$B$46,"Abs%"),SUMIFS(BONUS_RULES!$F$5:$F$46,BONUS_RULES!$A$5:$A$46,$C5,BONUS_RULES!$B$5:$B$46,"Abs%"),0)))) | L5: =IF(OR($A5="",$D5<>"READY"),"",IF(AGENT_INPUT!G5>=SUMIFS(BONUS_RULES!$E$5:$E$46,BONUS_RULES!$A$5:$A$46,$C5,BONUS_RULES!$B$5:$B$46,"Extra Bonus (PCS Score)"),SUMIFS(BONUS_RULES!$D$5:$D$46,BONUS_RULES!$A$5:$A$46,$C5,BONUS_RULES!$B$5:$B$46,"Extra Bonus (PCS Score)"),IF(AGENT_INPUT!G5>=SUMIFS(BONUS_RULES!$G$5:$G$46,BONUS_RULES!$A$5:$A$46,$C5,BONUS_RULES!$B$5:$B$46,"Extra Bonus (PCS Score)"),SUMIFS(BONUS_RULES!$F$5:$F$46,BONUS_RULES!$A$5:$A$46,$C5,BONUS_RULES!$B$5:$B$46,"Extra Bonus (PCS Score)"),0))) | M5: =IF($A5="","",MIN(IF(POLICY_APPROVAL!$B$6="Replacement",SUM(F5:K5)-H5+MAX(H5,L5),SUM(F5:L5)),POLICY_APPROVAL!$B$10)) -> 0 | N5: =IF($A5="","",IFERROR(INDEX(BONUS_RULES!$J$5:$J$10,MATCH(MIN(MAX(AGENT_INPUT!K5,0),5),BONUS_RULES!$I$5:$I$10,0)),1)) -> 0 | O5: =IF(M5="","",MAX(0,IF(POLICY_APPROVAL!$B$5="Percentage points",M5-N5,M5*(1-N5)))) -> 0 | P5: =IF(D5<>"READY","",IF(AGENT_INPUT!O5>0,AGENT_INPUT!O5,AGENT_INPUT!M5*AGENT_INPUT!N5/IF(POLICY_APPROVAL!$B$7="Annual",12,1))) | Q5: =IF(D5<>"READY","",MIN(1,AGENT_INPUT!P5/AGENT_INPUT!Q5)) | R5: =IF(D5<>"READY","",ROUND(P5*Q5*O5,IF(POLICY_APPROVAL!$B$11="Whole MAD",0,2))) | S5: =IF(AND(SETUP!$B$9="READY",T5="READY"),R5,"") | T5: =IF($A5="","",IF(D5<>"READY","BLOCKED - INPUT",IF(E5<>"ELIGIBLE","BLOCKED - ELIGIBILITY",IF(AGENT_INPUT!S5<>"VALIDATED","BLOCKED - DATA",IF(SETUP!$B$9<>"READY","BLOCKED - POLICY","READY"))))) -> BLOCKED - INPUT | U5: =IF($A5="","",IF(COUNTIFS(AGENT_INPUT!$A$5:$A$254,$A5,AGENT_INPUT!$D$5:$D$254,AGENT_INPUT!D5)>1,"DUPLICATE AGENT + PERIOD",IF(D5<>"READY","INPUT OR CONFIG REVIEW",IF(T5<>"READY",T5,"")))) -> Missing, invalid, or unconfigured required input
A6: =IF(AGENT_INPUT!A6="","",AGENT_INPUT!A6) -> 204342 | B6: =IF($A6="","",AGENT_INPUT!B6) -> Zekhnini Mustapha | C6: =IF($A6="","",AGENT_INPUT!C6) -> Ford GER | D6: =IF($A6="","",IF(AND(COUNT(AGENT_INPUT!E6:J6)=6,COUNT(AGENT_INPUT!K6)=1,COUNTIF(BONUS_RULES!$A$5:$A$46,AGENT_INPUT!C6)>0,OR(AGENT_INPUT!O6>0,AND(AGENT_INPUT!M6>0,AGENT_INPUT!N6>0)),AGENT_INPUT!P6>=0,AGENT_INPUT!Q6>0,AGENT_INPUT!P6<=AGENT_INPUT!Q6,AGENT_INPUT!H6>=0,AGENT_INPUT!H6<=1,AGENT_INPUT!I6>=0,AGENT_INPUT!I6<=1,AGENT_INPUT!J6>=0,AGENT_INPUT!J6<=1),"READY","BLOCKED")) -> BLOCKED | E6: =IF($A6="","",IF(AGENT_INPUT!R6<>"Active","REVIEW",IF(OR(POLICY_APPROVAL!$B$9="Eligibility only",POLICY_APPROVAL!$B$9="Both"),IF(AGENT_INPUT!J6<=SUMIFS(BONUS_RULES!$E$5:$E$46,BONUS_RULES!$A$5:$A$46,$C6,BONUS_RULES!$B$5:$B$46,"Abs%"),"ELIGIBLE","INELIGIBLE ABS"),"ELIGIBLE"))) | F6: =IF(OR($A6="",$D6<>"READY"),"",IF(AGENT_INPUT!E6<=SUMIFS(BONUS_RULES!$E$5:$E$46,BONUS_RULES!$A$5:$A$46,$C6,BONUS_RULES!$B$5:$B$46,"AHT"),SUMIFS(BONUS_RULES!$D$5:$D$46,BONUS_RULES!$A$5:$A$46,$C6,BONUS_RULES!$B$5:$B$46,"AHT"),IF(AGENT_INPUT!E6<=SUMIFS(BONUS_RULES!$G$5:$G$46,BONUS_RULES!$A$5:$A$46,$C6,BONUS_RULES!$B$5:$B$46,"AHT"),SUMIFS(BONUS_RULES!$F$5:$F$46,BONUS_RULES!$A$5:$A$46,$C6,BONUS_RULES!$B$5:$B$46,"AHT"),0))) | G6: =IF(OR($A6="",$D6<>"READY"),"",IF(AGENT_INPUT!F6>=SUMIFS(BONUS_RULES!$E$5:$E$46,BONUS_RULES!$A$5:$A$46,$C6,BONUS_RULES!$B$5:$B$46,"Productivity"),SUMIFS(BONUS_RULES!$D$5:$D$46,BONUS_RULES!$A$5:$A$46,$C6,BONUS_RULES!$B$5:$B$46,"Productivity"),IF(AGENT_INPUT!F6>=SUMIFS(BONUS_RULES!$G$5:$G$46,BONUS_RULES!$A$5:$A$46,$C6,BONUS_RULES!$B$5:$B$46,"Productivity"),SUMIFS(BONUS_RULES!$F$5:$F$46,BONUS_RULES!$A$5:$A$46,$C6,BONUS_RULES!$B$5:$B$46,"Productivity"),0))) | H6: =IF(OR($A6="",$D6<>"READY"),"",IF(AGENT_INPUT!G6>=SUMIFS(BONUS_RULES!$E$5:$E$46,BONUS_RULES!$A$5:$A$46,$C6,BONUS_RULES!$B$5:$B$46,"PCS Score"),SUMIFS(BONUS_RULES!$D$5:$D$46,BONUS_RULES!$A$5:$A$46,$C6,BONUS_RULES!$B$5:$B$46,"PCS Score"),IF(AGENT_INPUT!G6>=SUMIFS(BONUS_RULES!$G$5:$G$46,BONUS_RULES!$A$5:$A$46,$C6,BONUS_RULES!$B$5:$B$46,"PCS Score"),SUMIFS(BONUS_RULES!$F$5:$F$46,BONUS_RULES!$A$5:$A$46,$C6,BONUS_RULES!$B$5:$B$46,"PCS Score"),0))) | I6: =IF(OR($A6="",$D6<>"READY"),"",IF(AGENT_INPUT!H6>=SUMIFS(BONUS_RULES!$E$5:$E$46,BONUS_RULES!$A$5:$A$46,$C6,BONUS_RULES!$B$5:$B$46,"PCS % (Participation)"),SUMIFS(BONUS_RULES!$D$5:$D$46,BONUS_RULES!$A$5:$A$46,$C6,BONUS_RULES!$B$5:$B$46,"PCS % (Participation)"),IF(AGENT_INPUT!H6>=SUMIFS(BONUS_RULES!$G$5:$G$46,BONUS_RULES!$A$5:$A$46,$C6,BONUS_RULES!$B$5:$B$46,"PCS % (Participation)"),SUMIFS(BONUS_RULES!$F$5:$F$46,BONUS_RULES!$A$5:$A$46,$C6,BONUS_RULES!$B$5:$B$46,"PCS % (Participation)"),0))) | J6: =IF(OR($A6="",$D6<>"READY"),"",IF(AGENT_INPUT!I6>=SUMIFS(BONUS_RULES!$E$5:$E$46,BONUS_RULES!$A$5:$A$46,$C6,BONUS_RULES!$B$5:$B$46,"QM"),SUMIFS(BONUS_RULES!$D$5:$D$46,BONUS_RULES!$A$5:$A$46,$C6,BONUS_RULES!$B$5:$B$46,"QM"),IF(AGENT_INPUT!I6>=SUMIFS(BONUS_RULES!$G$5:$G$46,BONUS_RULES!$A$5:$A$46,$C6,BONUS_RULES!$B$5:$B$46,"QM"),SUMIFS(BONUS_RULES!$F$5:$F$46,BONUS_RULES!$A$5:$A$46,$C6,BONUS_RULES!$B$5:$B$46,"QM"),0))) | K6: =IF(POLICY_APPROVAL!$B$9="Eligibility only",0,IF(OR($A6="",$D6<>"READY"),"",IF(AGENT_INPUT!J6<=SUMIFS(BONUS_RULES!$E$5:$E$46,BONUS_RULES!$A$5:$A$46,$C6,BONUS_RULES!$B$5:$B$46,"Abs%"),SUMIFS(BONUS_RULES!$D$5:$D$46,BONUS_RULES!$A$5:$A$46,$C6,BONUS_RULES!$B$5:$B$46,"Abs%"),IF(AGENT_INPUT!J6<=SUMIFS(BONUS_RULES!$G$5:$G$46,BONUS_RULES!$A$5:$A$46,$C6,BONUS_RULES!$B$5:$B$46,"Abs%"),SUMIFS(BONUS_RULES!$F$5:$F$46,BONUS_RULES!$A$5:$A$46,$C6,BONUS_RULES!$B$5:$B$46,"Abs%"),0)))) | L6: =IF(OR($A6="",$D6<>"READY"),"",IF(AGENT_INPUT!G6>=SUMIFS(BONUS_RULES!$E$5:$E$46,BONUS_RULES!$A$5:$A$46,$C6,BONUS_RULES!$B$5:$B$46,"Extra Bonus (PCS Score)"),SUMIFS(BONUS_RULES!$D$5:$D$46,BONUS_RULES!$A$5:$A$46,$C6,BONUS_RULES!$B$5:$B$46,"Extra Bonus (PCS Score)"),IF(AGENT_INPUT!G6>=SUMIFS(BONUS_RULES!$G$5:$G$46,BONUS_RULES!$A$5:$A$46,$C6,BONUS_RULES!$B$5:$B$46,"Extra Bonus (PCS Score)"),SUMIFS(BONUS_RULES!$F$5:$F$46,BONUS_RULES!$A$5:$A$46,$C6,BONUS_RULES!$B$5:$B$46,"Extra Bonus (PCS Score)"),0))) | M6: =IF($A6="","",MIN(IF(POLICY_APPROVAL!$B$6="Replacement",SUM(F6:K6)-H6+MAX(H6,L6),SUM(F6:L6)),POLICY_APPROVAL!$B$10)) -> 0 | N6: =IF($A6="","",IFERROR(INDEX(BONUS_RULES!$J$5:$J$10,MATCH(MIN(MAX(AGENT_INPUT!K6,0),5),BONUS_RULES!$I$5:$I$10,0)),1)) -> 0 | O6: =IF(M6="","",MAX(0,IF(POLICY_APPROVAL!$B$5="Percentage points",M6-N6,M6*(1-N6)))) -> 0 | P6: =IF(D6<>"READY","",IF(AGENT_INPUT!O6>0,AGENT_INPUT!O6,AGENT_INPUT!M6*AGENT_INPUT!N6/IF(POLICY_APPROVAL!$B$7="Annual",12,1))) | Q6: =IF(D6<>"READY","",MIN(1,AGENT_INPUT!P6/AGENT_INPUT!Q6)) | R6: =IF(D6<>"READY","",ROUND(P6*Q6*O6,IF(POLICY_APPROVAL!$B$11="Whole MAD",0,2))) | S6: =IF(AND(SETUP!$B$9="READY",T6="READY"),R6,"") | T6: =IF($A6="","",IF(D6<>"READY","BLOCKED - INPUT",IF(E6<>"ELIGIBLE","BLOCKED - ELIGIBILITY",IF(AGENT_INPUT!S6<>"VALIDATED","BLOCKED - DATA",IF(SETUP!$B$9<>"READY","BLOCKED - POLICY","READY"))))) -> BLOCKED - INPUT | U6: =IF($A6="","",IF(COUNTIFS(AGENT_INPUT!$A$5:$A$254,$A6,AGENT_INPUT!$D$5:$D$254,AGENT_INPUT!D6)>1,"DUPLICATE AGENT + PERIOD",IF(D6<>"READY","INPUT OR CONFIG REVIEW",IF(T6<>"READY",T6,"")))) -> Missing, invalid, or unconfigured required input
A7: =IF(AGENT_INPUT!A7="","",AGENT_INPUT!A7) -> 204343 | B7: =IF($A7="","",AGENT_INPUT!B7) -> Talhajit Abdellah | C7: =IF($A7="","",AGENT_INPUT!C7) -> Ford GER | D7: =IF($A7="","",IF(AND(COUNT(AGENT_INPUT!E7:J7)=6,COUNT(AGENT_INPUT!K7)=1,COUNTIF(BONUS_RULES!$A$5:$A$46,AGENT_INPUT!C7)>0,OR(AGENT_INPUT!O7>0,AND(AGENT_INPUT!M7>0,AGENT_INPUT!N7>0)),AGENT_INPUT!P7>=0,AGENT_INPUT!Q7>0,AGENT_INPUT!P7<=AGENT_INPUT!Q7,AGENT_INPUT!H7>=0,AGENT_INPUT!H7<=1,AGENT_INPUT!I7>=0,AGENT_INPUT!I7<=1,AGENT_INPUT!J7>=0,AGENT_INPUT!J7<=1),"READY","BLOCKED")) -> BLOCKED | E7: =IF($A7="","",IF(AGENT_INPUT!R7<>"Active","REVIEW",IF(OR(POLICY_APPROVAL!$B$9="Eligibility only",POLICY_APPROVAL!$B$9="Both"),IF(AGENT_INPUT!J7<=SUMIFS(BONUS_RULES!$E$5:$E$46,BONUS_RULES!$A$5:$A$46,$C7,BONUS_RULES!$B$5:$B$46,"Abs%"),"ELIGIBLE","INELIGIBLE ABS"),"ELIGIBLE"))) | F7: =IF(OR($A7="",$D7<>"READY"),"",IF(AGENT_INPUT!E7<=SUMIFS(BONUS_RULES!$E$5:$E$46,BONUS_RULES!$A$5:$A$46,$C7,BONUS_RULES!$B$5:$B$46,"AHT"),SUMIFS(BONUS_RULES!$D$5:$D$46,BONUS_RULES!$A$5:$A$46,$C7,BONUS_RULES!$B$5:$B$46,"AHT"),IF(AGENT_INPUT!E7<=SUMIFS(BONUS_RULES!$G$5:$G$46,BONUS_RULES!$A$5:$A$46,$C7,BONUS_RULES!$B$5:$B$46,"AHT"),SUMIFS(BONUS_RULES!$F$5:$F$46,BONUS_RULES!$A$5:$A$46,$C7,BONUS_RULES!$B$5:$B$46,"AHT"),0))) | G7: =IF(OR($A7="",$D7<>"READY"),"",IF(AGENT_INPUT!F7>=SUMIFS(BONUS_RULES!$E$5:$E$46,BONUS_RULES!$A$5:$A$46,$C7,BONUS_RULES!$B$5:$B$46,"Productivity"),SUMIFS(BONUS_RULES!$D$5:$D$46,BONUS_RULES!$A$5:$A$46,$C7,BONUS_RULES!$B$5:$B$46,"Productivity"),IF(AGENT_INPUT!F7>=SUMIFS(BONUS_RULES!$G$5:$G$46,BONUS_RULES!$A$5:$A$46,$C7,BONUS_RULES!$B$5:$B$46,"Productivity"),SUMIFS(BONUS_RULES!$F$5:$F$46,BONUS_RULES!$A$5:$A$46,$C7,BONUS_RULES!$B$5:$B$46,"Productivity"),0))) | H7: =IF(OR($A7="",$D7<>"READY"),"",IF(AGENT_INPUT!G7>=SUMIFS(BONUS_RULES!$E$5:$E$46,BONUS_RULES!$A$5:$A$46,$C7,BONUS_RULES!$B$5:$B$46,"PCS Score"),SUMIFS(BONUS_RULES!$D$5:$D$46,BONUS_RULES!$A$5:$A$46,$C7,BONUS_RULES!$B$5:$B$46,"PCS Score"),IF(AGENT_INPUT!G7>=SUMIFS(BONUS_RULES!$G$5:$G$46,BONUS_RULES!$A$5:$A$46,$C7,BONUS_RULES!$B$5:$B$46,"PCS Score"),SUMIFS(BONUS_RULES!$F$5:$F$46,BONUS_RULES!$A$5:$A$46,$C7,BONUS_RULES!$B$5:$B$46,"PCS Score"),0))) | I7: =IF(OR($A7="",$D7<>"READY"),"",IF(AGENT_INPUT!H7>=SUMIFS(BONUS_RULES!$E$5:$E$46,BONUS_RULES!$A$5:$A$46,$C7,BONUS_RULES!$B$5:$B$46,"PCS % (Participation)"),SUMIFS(BONUS_RULES!$D$5:$D$46,BONUS_RULES!$A$5:$A$46,$C7,BONUS_RULES!$B$5:$B$46,"PCS % (Participation)"),IF(AGENT_INPUT!H7>=SUMIFS(BONUS_RULES!$G$5:$G$46,BONUS_RULES!$A$5:$A$46,$C7,BONUS_RULES!$B$5:$B$46,"PCS % (Participation)"),SUMIFS(BONUS_RULES!$F$5:$F$46,BONUS_RULES!$A$5:$A$46,$C7,BONUS_RULES!$B$5:$B$46,"PCS % (Participation)"),0))) | J7: =IF(OR($A7="",$D7<>"READY"),"",IF(AGENT_INPUT!I7>=SUMIFS(BONUS_RULES!$E$5:$E$46,BONUS_RULES!$A$5:$A$46,$C7,BONUS_RULES!$B$5:$B$46,"QM"),SUMIFS(BONUS_RULES!$D$5:$D$46,BONUS_RULES!$A$5:$A$46,$C7,BONUS_RULES!$B$5:$B$46,"QM"),IF(AGENT_INPUT!I7>=SUMIFS(BONUS_RULES!$G$5:$G$46,BONUS_RULES!$A$5:$A$46,$C7,BONUS_RULES!$B$5:$B$46,"QM"),SUMIFS(BONUS_RULES!$F$5:$F$46,BONUS_RULES!$A$5:$A$46,$C7,BONUS_RULES!$B$5:$B$46,"QM"),0))) | K7: =IF(POLICY_APPROVAL!$B$9="Eligibility only",0,IF(OR($A7="",$D7<>"READY"),"",IF(AGENT_INPUT!J7<=SUMIFS(BONUS_RULES!$E$5:$E$46,BONUS_RULES!$A$5:$A$46,$C7,BONUS_RULES!$B$5:$B$46,"Abs%"),SUMIFS(BONUS_RULES!$D$5:$D$46,BONUS_RULES!$A$5:$A$46,$C7,BONUS_RULES!$B$5:$B$46,"Abs%"),IF(AGENT_INPUT!J7<=SUMIFS(BONUS_RULES!$G$5:$G$46,BONUS_RULES!$A$5:$A$46,$C7,BONUS_RULES!$B$5:$B$46,"Abs%"),SUMIFS(BONUS_RULES!$F$5:$F$46,BONUS_RULES!$A$5:$A$46,$C7,BONUS_RULES!$B$5:$B$46,"Abs%"),0)))) | L7: =IF(OR($A7="",$D7<>"READY"),"",IF(AGENT_INPUT!G7>=SUMIFS(BONUS_RULES!$E$5:$E$46,BONUS_RULES!$A$5:$A$46,$C7,BONUS_RULES!$B$5:$B$46,"Extra Bonus (PCS Score)"),SUMIFS(BONUS_RULES!$D$5:$D$46,BONUS_RULES!$A$5:$A$46,$C7,BONUS_RULES!$B$5:$B$46,"Extra Bonus (PCS Score)"),IF(AGENT_INPUT!G7>=SUMIFS(BONUS_RULES!$G$5:$G$46,BONUS_RULES!$A$5:$A$46,$C7,BONUS_RULES!$B$5:$B$46,"Extra Bonus (PCS Score)"),SUMIFS(BONUS_RULES!$F$5:$F$46,BONUS_RULES!$A$5:$A$46,$C7,BONUS_RULES!$B$5:$B$46,"Extra Bonus (PCS Score)"),0))) | M7: =IF($A7="","",MIN(IF(POLICY_APPROVAL!$B$6="Replacement",SUM(F7:K7)-H7+MAX(H7,L7),SUM(F7:L7)),POLICY_APPROVAL!$B$10)) -> 0 | N7: =IF($A7="","",IFERROR(INDEX(BONUS_RULES!$J$5:$J$10,MATCH(MIN(MAX(AGENT_INPUT!K7,0),5),BONUS_RULES!$I$5:$I$10,0)),1)) -> 0 | O7: =IF(M7="","",MAX(0,IF(POLICY_APPROVAL!$B$5="Percentage points",M7-N7,M7*(1-N7)))) -> 0 | P7: =IF(D7<>"READY","",IF(AGENT_INPUT!O7>0,AGENT_INPUT!O7,AGENT_INPUT!M7*AGENT_INPUT!N7/IF(POLICY_APPROVAL!$B$7="Annual",12,1))) | Q7: =IF(D7<>"READY","",MIN(1,AGENT_INPUT!P7/AGENT_INPUT!Q7)) | R7: =IF(D7<>"READY","",ROUND(P7*Q7*O7,IF(POLICY_APPROVAL!$B$11="Whole MAD",0,2))) | S7: =IF(AND(SETUP!$B$9="READY",T7="READY"),R7,"") | T7: =IF($A7="","",IF(D7<>"READY","BLOCKED - INPUT",IF(E7<>"ELIGIBLE","BLOCKED - ELIGIBILITY",IF(AGENT_INPUT!S7<>"VALIDATED","BLOCKED - DATA",IF(SETUP!$B$9<>"READY","BLOCKED - POLICY","READY"))))) -> BLOCKED - INPUT | U7: =IF($A7="","",IF(COUNTIFS(AGENT_INPUT!$A$5:$A$254,$A7,AGENT_INPUT!$D$5:$D$254,AGENT_INPUT!D7)>1,"DUPLICATE AGENT + PERIOD",IF(D7<>"READY","INPUT OR CONFIG REVIEW",IF(T7<>"READY",T7,"")))) -> Missing, invalid, or unconfigured required input
A8: =IF(AGENT_INPUT!A8="","",AGENT_INPUT!A8) -> 204344 | B8: =IF($A8="","",AGENT_INPUT!B8) -> AYMAZ Abdelhay | C8: =IF($A8="","",AGENT_INPUT!C8) -> Ford GER | D8: =IF($A8="","",IF(AND(COUNT(AGENT_INPUT!E8:J8)=6,COUNT(AGENT_INPUT!K8)=1,COUNTIF(BONUS_RULES!$A$5:$A$46,AGENT_INPUT!C8)>0,OR(AGENT_INPUT!O8>0,AND(AGENT_INPUT!M8>0,AGENT_INPUT!N8>0)),AGENT_INPUT!P8>=0,AGENT_INPUT!Q8>0,AGENT_INPUT!P8<=AGENT_INPUT!Q8,AGENT_INPUT!H8>=0,AGENT_INPUT!H8<=1,AGENT_INPUT!I8>=0,AGENT_INPUT!I8<=1,AGENT_INPUT!J8>=0,AGENT_INPUT!J8<=1),"READY","BLOCKED")) -> BLOCKED | E8: =IF($A8="","",IF(AGENT_INPUT!R8<>"Active","REVIEW",IF(OR(POLICY_APPROVAL!$B$9="Eligibility only",POLICY_APPROVAL!$B$9="Both"),IF(AGENT_INPUT!J8<=SUMIFS(BONUS_RULES!$E$5:$E$46,BONUS_RULES!$A$5:$A$46,$C8,BONUS_RULES!$B$5:$B$46,"Abs%"),"ELIGIBLE","INELIGIBLE ABS"),"ELIGIBLE"))) | F8: =IF(OR($A8="",$D8<>"READY"),"",IF(AGENT_INPUT!E8<=SUMIFS(BONUS_RULES!$E$5:$E$46,BONUS_RULES!$A$5:$A$46,$C8,BONUS_RULES!$B$5:$B$46,"AHT"),SUMIFS(BONUS_RULES!$D$5:$D$46,BONUS_RULES!$A$5:$A$46,$C8,BONUS_RULES!$B$5:$B$46,"AHT"),IF(AGENT_INPUT!E8<=SUMIFS(BONUS_RULES!$G$5:$G$46,BONUS_RULES!$A$5:$A$46,$C8,BONUS_RULES!$B$5:$B$46,"AHT"),SUMIFS(BONUS_RULES!$F$5:$F$46,BONUS_RULES!$A$5:$A$46,$C8,BONUS_RULES!$B$5:$B$46,"AHT"),0))) | G8: =IF(OR($A8="",$D8<>"READY"),"",IF(AGENT_INPUT!F8>=SUMIFS(BONUS_RULES!$E$5:$E$46,BONUS_RULES!$A$5:$A$46,$C8,BONUS_RULES!$B$5:$B$46,"Productivity"),SUMIFS(BONUS_RULES!$D$5:$D$46,BONUS_RULES!$A$5:$A$46,$C8,BONUS_RULES!$B$5:$B$46,"Productivity"),IF(AGENT_INPUT!F8>=SUMIFS(BONUS_RULES!$G$5:$G$46,BONUS_RULES!$A$5:$A$46,$C8,BONUS_RULES!$B$5:$B$46,"Productivity"),SUMIFS(BONUS_RULES!$F$5:$F$46,BONUS_RULES!$A$5:$A$46,$C8,BONUS_RULES!$B$5:$B$46,"Productivity"),0))) | H8: =IF(OR($A8="",$D8<>"READY"),"",IF(AGENT_INPUT!G8>=SUMIFS(BONUS_RULES!$E$5:$E$46,BONUS_RULES!$A$5:$A$46,$C8,BONUS_RULES!$B$5:$B$46,"PCS Score"),SUMIFS(BONUS_RULES!$D$5:$D$46,BONUS_RULES!$A$5:$A$46,$C8,BONUS_RULES!$B$5:$B$46,"PCS Score"),IF(AGENT_INPUT!G8>=SUMIFS(BONUS_RULES!$G$5:$G$46,BONUS_RULES!$A$5:$A$46,$C8,BONUS_RULES!$B$5:$B$46,"PCS Score"),SUMIFS(BONUS_RULES!$F$5:$F$46,BONUS_RULES!$A$5:$A$46,$C8,BONUS_RULES!$B$5:$B$46,"PCS Score"),0))) | I8: =IF(OR($A8="",$D8<>"READY"),"",IF(AGENT_INPUT!H8>=SUMIFS(BONUS_RULES!$E$5:$E$46,BONUS_RULES!$A$5:$A$46,$C8,BONUS_RULES!$B$5:$B$46,"PCS % (Participation)"),SUMIFS(BONUS_RULES!$D$5:$D$46,BONUS_RULES!$A$5:$A$46,$C8,BONUS_RULES!$B$5:$B$46,"PCS % (Participation)"),IF(AGENT_INPUT!H8>=SUMIFS(BONUS_RULES!$G$5:$G$46,BONUS_RULES!$A$5:$A$46,$C8,BONUS_RULES!$B$5:$B$46,"PCS % (Participation)"),SUMIFS(BONUS_RULES!$F$5:$F$46,BONUS_RULES!$A$5:$A$46,$C8,BONUS_RULES!$B$5:$B$46,"PCS % (Participation)"),0))) | J8: =IF(OR($A8="",$D8<>"READY"),"",IF(AGENT_INPUT!I8>=SUMIFS(BONUS_RULES!$E$5:$E$46,BONUS_RULES!$A$5:$A$46,$C8,BONUS_RULES!$B$5:$B$46,"QM"),SUMIFS(BONUS_RULES!$D$5:$D$46,BONUS_RULES!$A$5:$A$46,$C8,BONUS_RULES!$B$5:$B$46,"QM"),IF(AGENT_INPUT!I8>=SUMIFS(BONUS_RULES!$G$5:$G$46,BONUS_RULES!$A$5:$A$46,$C8,BONUS_RULES!$B$5:$B$46,"QM"),SUMIFS(BONUS_RULES!$F$5:$F$46,BONUS_RULES!$A$5:$A$46,$C8,BONUS_RULES!$B$5:$B$46,"QM"),0))) | K8: =IF(POLICY_APPROVAL!$B$9="Eligibility only",0,IF(OR($A8="",$D8<>"READY"),"",IF(AGENT_INPUT!J8<=SUMIFS(BONUS_RULES!$E$5:$E$46,BONUS_RULES!$A$5:$A$46,$C8,BONUS_RULES!$B$5:$B$46,"Abs%"),SUMIFS(BONUS_RULES!$D$5:$D$46,BONUS_RULES!$A$5:$A$46,$C8,BONUS_RULES!$B$5:$B$46,"Abs%"),IF(AGENT_INPUT!J8<=SUMIFS(BONUS_RULES!$G$5:$G$46,BONUS_RULES!$A$5:$A$46,$C8,BONUS_RULES!$B$5:$B$46,"Abs%"),SUMIFS(BONUS_RULES!$F$5:$F$46,BONUS_RULES!$A$5:$A$46,$C8,BONUS_RULES!$B$5:$B$46,"Abs%"),0)))) | L8: =IF(OR($A8="",$D8<>"READY"),"",IF(AGENT_INPUT!G8>=SUMIFS(BONUS_RULES!$E$5:$E$46,BONUS_RULES!$A$5:$A$46,$C8,BONUS_RULES!$B$5:$B$46,"Extra Bonus (PCS Score)"),SUMIFS(BONUS_RULES!$D$5:$D$46,BONUS_RULES!$A$5:$A$46,$C8,BONUS_RULES!$B$5:$B$46,"Extra Bonus (PCS Score)"),IF(AGENT_INPUT!G8>=SUMIFS(BONUS_RULES!$G$5:$G$46,BONUS_RULES!$A$5:$A$46,$C8,BONUS_RULES!$B$5:$B$46,"Extra Bonus (PCS Score)"),SUMIFS(BONUS_RULES!$F$5:$F$46,BONUS_RULES!$A$5:$A$46,$C8,BONUS_RULES!$B$5:$B$46,"Extra Bonus (PCS Score)"),0))) | M8: =IF($A8="","",MIN(IF(POLICY_APPROVAL!$B$6="Replacement",SUM(F8:K8)-H8+MAX(H8,L8),SUM(F8:L8)),POLICY_APPROVAL!$B$10)) -> 0 | N8: =IF($A8="","",IFERROR(INDEX(BONUS_RULES!$J$5:$J$10,MATCH(MIN(MAX(AGENT_INPUT!K8,0),5),BONUS_RULES!$I$5:$I$10,0)),1)) -> 0 | O8: =IF(M8="","",MAX(0,IF(POLICY_APPROVAL!$B$5="Percentage points",M8-N8,M8*(1-N8)))) -> 0 | P8: =IF(D8<>"READY","",IF(AGENT_INPUT!O8>0,AGENT_INPUT!O8,AGENT_INPUT!M8*AGENT_INPUT!N8/IF(POLICY_APPROVAL!$B$7="Annual",12,1))) | Q8: =IF(D8<>"READY","",MIN(1,AGENT_INPUT!P8/AGENT_INPUT!Q8)) | R8: =IF(D8<>"READY","",ROUND(P8*Q8*O8,IF(POLICY_APPROVAL!$B$11="Whole MAD",0,2))) | S8: =IF(AND(SETUP!$B$9="READY",T8="READY"),R8,"") | T8: =IF($A8="","",IF(D8<>"READY","BLOCKED - INPUT",IF(E8<>"ELIGIBLE","BLOCKED - ELIGIBILITY",IF(AGENT_INPUT!S8<>"VALIDATED","BLOCKED - DATA",IF(SETUP!$B$9<>"READY","BLOCKED - POLICY","READY"))))) -> BLOCKED - INPUT | U8: =IF($A8="","",IF(COUNTIFS(AGENT_INPUT!$A$5:$A$254,$A8,AGENT_INPUT!$D$5:$D$254,AGENT_INPUT!D8)>1,"DUPLICATE AGENT + PERIOD",IF(D8<>"READY","INPUT OR CONFIG REVIEW",IF(T8<>"READY",T8,"")))) -> Missing, invalid, or unconfigured required input
A9: =IF(AGENT_INPUT!A9="","",AGENT_INPUT!A9) -> 204345 | B9: =IF($A9="","",AGENT_INPUT!B9) -> MOUSSA Amjad | C9: =IF($A9="","",AGENT_INPUT!C9) -> Ford GER | D9: =IF($A9="","",IF(AND(COUNT(AGENT_INPUT!E9:J9)=6,COUNT(AGENT_INPUT!K9)=1,COUNTIF(BONUS_RULES!$A$5:$A$46,AGENT_INPUT!C9)>0,OR(AGENT_INPUT!O9>0,AND(AGENT_INPUT!M9>0,AGENT_INPUT!N9>0)),AGENT_INPUT!P9>=0,AGENT_INPUT!Q9>0,AGENT_INPUT!P9<=AGENT_INPUT!Q9,AGENT_INPUT!H9>=0,AGENT_INPUT!H9<=1,AGENT_INPUT!I9>=0,AGENT_INPUT!I9<=1,AGENT_INPUT!J9>=0,AGENT_INPUT!J9<=1),"READY","BLOCKED")) -> BLOCKED | E9: =IF($A9="","",IF(AGENT_INPUT!R9<>"Active","REVIEW",IF(OR(POLICY_APPROVAL!$B$9="Eligibility only",POLICY_APPROVAL!$B$9="Both"),IF(AGENT_INPUT!J9<=SUMIFS(BONUS_RULES!$E$5:$E$46,BONUS_RULES!$A$5:$A$46,$C9,BONUS_RULES!$B$5:$B$46,"Abs%"),"ELIGIBLE","INELIGIBLE ABS"),"ELIGIBLE"))) | F9: =IF(OR($A9="",$D9<>"READY"),"",IF(AGENT_INPUT!E9<=SUMIFS(BONUS_RULES!$E$5:$E$46,BONUS_RULES!$A$5:$A$46,$C9,BONUS_RULES!$B$5:$B$46,"AHT"),SUMIFS(BONUS_RULES!$D$5:$D$46,BONUS_RULES!$A$5:$A$46,$C9,BONUS_RULES!$B$5:$B$46,"AHT"),IF(AGENT_INPUT!E9<=SUMIFS(BONUS_RULES!$G$5:$G$46,BONUS_RULES!$A$5:$A$46,$C9,BONUS_RULES!$B$5:$B$46,"AHT"),SUMIFS(BONUS_RULES!$F$5:$F$46,BONUS_RULES!$A$5:$A$46,$C9,BONUS_RULES!$B$5:$B$46,"AHT"),0))) | G9: =IF(OR($A9="",$D9<>"READY"),"",IF(AGENT_INPUT!F9>=SUMIFS(BONUS_RULES!$E$5:$E$46,BONUS_RULES!$A$5:$A$46,$C9,BONUS_RULES!$B$5:$B$46,"Productivity"),SUMIFS(BONUS_RULES!$D$5:$D$46,BONUS_RULES!$A$5:$A$46,$C9,BONUS_RULES!$B$5:$B$46,"Productivity"),IF(AGENT_INPUT!F9>=SUMIFS(BONUS_RULES!$G$5:$G$46,BONUS_RULES!$A$5:$A$46,$C9,BONUS_RULES!$B$5:$B$46,"Productivity"),SUMIFS(BONUS_RULES!$F$5:$F$46,BONUS_RULES!$A$5:$A$46,$C9,BONUS_RULES!$B$5:$B$46,"Productivity"),0))) | H9: =IF(OR($A9="",$D9<>"READY"),"",IF(AGENT_INPUT!G9>=SUMIFS(BONUS_RULES!$E$5:$E$46,BONUS_RULES!$A$5:$A$46,$C9,BONUS_RULES!$B$5:$B$46,"PCS Score"),SUMIFS(BONUS_RULES!$D$5:$D$46,BONUS_RULES!$A$5:$A$46,$C9,BONUS_RULES!$B$5:$B$46,"PCS Score"),IF(AGENT_INPUT!G9>=SUMIFS(BONUS_RULES!$G$5:$G$46,BONUS_RULES!$A$5:$A$46,$C9,BONUS_RULES!$B$5:$B$46,"PCS Score"),SUMIFS(BONUS_RULES!$F$5:$F$46,BONUS_RULES!$A$5:$A$46,$C9,BONUS_RULES!$B$5:$B$46,"PCS Score"),0))) | I9: =IF(OR($A9="",$D9<>"READY"),"",IF(AGENT_INPUT!H9>=SUMIFS(BONUS_RULES!$E$5:$E$46,BONUS_RULES!$A$5:$A$46,$C9,BONUS_RULES!$B$5:$B$46,"PCS % (Participation)"),SUMIFS(BONUS_RULES!$D$5:$D$46,BONUS_RULES!$A$5:$A$46,$C9,BONUS_RULES!$B$5:$B$46,"PCS % (Participation)"),IF(AGENT_INPUT!H9>=SUMIFS(BONUS_RULES!$G$5:$G$46,BONUS_RULES!$A$5:$A$46,$C9,BONUS_RULES!$B$5:$B$46,"PCS % (Participation)"),SUMIFS(BONUS_RULES!$F$5:$F$46,BONUS_RULES!$A$5:$A$46,$C9,BONUS_RULES!$B$5:$B$46,"PCS % (Participation)"),0))) | J9: =IF(OR($A9="",$D9<>"READY"),"",IF(AGENT_INPUT!I9>=SUMIFS(BONUS_RULES!$E$5:$E$46,BONUS_RULES!$A$5:$A$46,$C9,BONUS_RULES!$B$5:$B$46,"QM"),SUMIFS(BONUS_RULES!$D$5:$D$46,BONUS_RULES!$A$5:$A$46,$C9,BONUS_RULES!$B$5:$B$46,"QM"),IF(AGENT_INPUT!I9>=SUMIFS(BONUS_RULES!$G$5:$G$46,BONUS_RULES!$A$5:$A$46,$C9,BONUS_RULES!$B$5:$B$46,"QM"),SUMIFS(BONUS_RULES!$F$5:$F$46,BONUS_RULES!$A$5:$A$46,$C9,BONUS_RULES!$B$5:$B$46,"QM"),0))) | K9: =IF(POLICY_APPROVAL!$B$9="Eligibility only",0,IF(OR($A9="",$D9<>"READY"),"",IF(AGENT_INPUT!J9<=SUMIFS(BONUS_RULES!$E$5:$E$46,BONUS_RULES!$A$5:$A$46,$C9,BONUS_RULES!$B$5:$B$46,"Abs%"),SUMIFS(BONUS_RULES!$D$5:$D$46,BONUS_RULES!$A$5:$A$46,$C9,BONUS_RULES!$B$5:$B$46,"Abs%"),IF(AGENT_INPUT!J9<=SUMIFS(BONUS_RULES!$G$5:$G$46,BONUS_RULES!$A$5:$A$46,$C9,BONUS_RULES!$B$5:$B$46,"Abs%"),SUMIFS(BONUS_RULES!$F$5:$F$46,BONUS_RULES!$A$5:$A$46,$C9,BONUS_RULES!$B$5:$B$46,"Abs%"),0)))) | L9: =IF(OR($A9="",$D9<>"READY"),"",IF(AGENT_INPUT!G9>=SUMIFS(BONUS_RULES!$E$5:$E$46,BONUS_RULES!$A$5:$A$46,$C9,BONUS_RULES!$B$5:$B$46,"Extra Bonus (PCS Score)"),SUMIFS(BONUS_RULES!$D$5:$D$46,BONUS_RULES!$A$5:$A$46,$C9,BONUS_RULES!$B$5:$B$46,"Extra Bonus (PCS Score)"),IF(AGENT_INPUT!G9>=SUMIFS(BONUS_RULES!$G$5:$G$46,BONUS_RULES!$A$5:$A$46,$C9,BONUS_RULES!$B$5:$B$46,"Extra Bonus (PCS Score)"),SUMIFS(BONUS_RULES!$F$5:$F$46,BONUS_RULES!$A$5:$A$46,$C9,BONUS_RULES!$B$5:$B$46,"Extra Bonus (PCS Score)"),0))) | M9: =IF($A9="","",MIN(IF(POLICY_APPROVAL!$B$6="Replacement",SUM(F9:K9)-H9+MAX(H9,L9),SUM(F9:L9)),POLICY_APPROVAL!$B$10)) -> 0 | N9: =IF($A9="","",IFERROR(INDEX(BONUS_RULES!$J$5:$J$10,MATCH(MIN(MAX(AGENT_INPUT!K9,0),5),BONUS_RULES!$I$5:$I$10,0)),1)) -> 0 | O9: =IF(M9="","",MAX(0,IF(POLICY_APPROVAL!$B$5="Percentage points",M9-N9,M9*(1-N9)))) -> 0 | P9: =IF(D9<>"READY","",IF(AGENT_INPUT!O9>0,AGENT_INPUT!O9,AGENT_INPUT!M9*AGENT_INPUT!N9/IF(POLICY_APPROVAL!$B$7="Annual",12,1))) | Q9: =IF(D9<>"READY","",MIN(1,AGENT_INPUT!P9/AGENT_INPUT!Q9)) | R9: =IF(D9<>"READY","",ROUND(P9*Q9*O9,IF(POLICY_APPROVAL!$B$11="Whole MAD",0,2))) | S9: =IF(AND(SETUP!$B$9="READY",T9="READY"),R9,"") | T9: =IF($A9="","",IF(D9<>"READY","BLOCKED - INPUT",IF(E9<>"ELIGIBLE","BLOCKED - ELIGIBILITY",IF(AGENT_INPUT!S9<>"VALIDATED","BLOCKED - DATA",IF(SETUP!$B$9<>"READY","BLOCKED - POLICY","READY"))))) -> BLOCKED - INPUT | U9: =IF($A9="","",IF(COUNTIFS(AGENT_INPUT!$A$5:$A$254,$A9,AGENT_INPUT!$D$5:$D$254,AGENT_INPUT!D9)>1,"DUPLICATE AGENT + PERIOD",IF(D9<>"READY","INPUT OR CONFIG REVIEW",IF(T9<>"READY",T9,"")))) -> Missing, invalid, or unconfigured required input
A10: =IF(AGENT_INPUT!A10="","",AGENT_INPUT!A10) -> 204602 | B10: =IF($A10="","",AGENT_INPUT!B10) -> DRISSI Sidi Youssef | C10: =IF($A10="","",AGENT_INPUT!C10) -> Ford GER | D10: =IF($A10="","",IF(AND(COUNT(AGENT_INPUT!E10:J10)=6,COUNT(AGENT_INPUT!K10)=1,COUNTIF(BONUS_RULES!$A$5:$A$46,AGENT_INPUT!C10)>0,OR(AGENT_INPUT!O10>0,AND(AGENT_INPUT!M10>0,AGENT_INPUT!N10>0)),AGENT_INPUT!P10>=0,AGENT_INPUT!Q10>0,AGENT_INPUT!P10<=AGENT_INPUT!Q10,AGENT_INPUT!H10>=0,AGENT_INPUT!H10<=1,AGENT_INPUT!I10>=0,AGENT_INPUT!I10<=1,AGENT_INPUT!J10>=0,AGENT_INPUT!J10<=1),"READY","BLOCKED")) -> BLOCKED | E10: =IF($A10="","",IF(AGENT_INPUT!R10<>"Active","REVIEW",IF(OR(POLICY_APPROVAL!$B$9="Eligibility only",POLICY_APPROVAL!$B$9="Both"),IF(AGENT_INPUT!J10<=SUMIFS(BONUS_RULES!$E$5:$E$46,BONUS_RULES!$A$5:$A$46,$C10,BONUS_RULES!$B$5:$B$46,"Abs%"),"ELIGIBLE","INELIGIBLE ABS"),"ELIGIBLE"))) | F10: =IF(OR($A10="",$D10<>"READY"),"",IF(AGENT_INPUT!E10<=SUMIFS(BONUS_RULES!$E$5:$E$46,BONUS_RULES!$A$5:$A$46,$C10,BONUS_RULES!$B$5:$B$46,"AHT"),SUMIFS(BONUS_RULES!$D$5:$D$46,BONUS_RULES!$A$5:$A$46,$C10,BONUS_RULES!$B$5:$B$46,"AHT"),IF(AGENT_INPUT!E10<=SUMIFS(BONUS_RULES!$G$5:$G$46,BONUS_RULES!$A$5:$A$46,$C10,BONUS_RULES!$B$5:$B$46,"AHT"),SUMIFS(BONUS_RULES!$F$5:$F$46,BONUS_RULES!$A$5:$A$46,$C10,BONUS_RULES!$B$5:$B$46,"AHT"),0))) | G10: =IF(OR($A10="",$D10<>"READY"),"",IF(AGENT_INPUT!F10>=SUMIFS(BONUS_RULES!$E$5:$E$46,BONUS_RULES!$A$5:$A$46,$C10,BONUS_RULES!$B$5:$B$46,"Productivity"),SUMIFS(BONUS_RULES!$D$5:$D$46,BONUS_RULES!$A$5:$A$46,$C10,BONUS_RULES!$B$5:$B$46,"Productivity"),IF(AGENT_INPUT!F10>=SUMIFS(BONUS_RULES!$G$5:$G$46,BONUS_RULES!$A$5:$A$46,$C10,BONUS_RULES!$B$5:$B$46,"Productivity"),SUMIFS(BONUS_RULES!$F$5:$F$46,BONUS_RULES!$A$5:$A$46,$C10,BONUS_RULES!$B$5:$B$46,"Productivity"),0))) | H10: =IF(OR($A10="",$D10<>"READY"),"",IF(AGENT_INPUT!G10>=SUMIFS(BONUS_RULES!$E$5:$E$46,BONUS_RULES!$A$5:$A$46,$C10,BONUS_RULES!$B$5:$B$46,"PCS Score"),SUMIFS(BONUS_RULES!$D$5:$D$46,BONUS_RULES!$A$5:$A$46,$C10,BONUS_RULES!$B$5:$B$46,"PCS Score"),IF(AGENT_INPUT!G10>=SUMIFS(BONUS_RULES!$G$5:$G$46,BONUS_RULES!$A$5:$A$46,$C10,BONUS_RULES!$B$5:$B$46,"PCS Score"),SUMIFS(BONUS_RULES!$F$5:$F$46,BONUS_RULES!$A$5:$A$46,$C10,BONUS_RULES!$B$5:$B$46,"PCS Score"),0))) | I10: =IF(OR($A10="",$D10<>"READY"),"",IF(AGENT_INPUT!H10>=SUMIFS(BONUS_RULES!$E$5:$E$46,BONUS_RULES!$A$5:$A$46,$C10,BONUS_RULES!$B$5:$B$46,"PCS % (Participation)"),SUMIFS(BONUS_RULES!$D$5:$D$46,BONUS_RULES!$A$5:$A$46,$C10,BONUS_RULES!$B$5:$B$46,"PCS % (Participation)"),IF(AGENT_INPUT!H10>=SUMIFS(BONUS_RULES!$G$5:$G$46,BONUS_RULES!$A$5:$A$46,$C10,BONUS_RULES!$B$5:$B$46,"PCS % (Participation)"),SUMIFS(BONUS_RULES!$F$5:$F$46,BONUS_RULES!$A$5:$A$46,$C10,BONUS_RULES!$B$5:$B$46,"PCS % (Participation)"),0))) | J10: =IF(OR($A10="",$D10<>"READY"),"",IF(AGENT_INPUT!I10>=SUMIFS(BONUS_RULES!$E$5:$E$46,BONUS_RULES!$A$5:$A$46,$C10,BONUS_RULES!$B$5:$B$46,"QM"),SUMIFS(BONUS_RULES!$D$5:$D$46,BONUS_RULES!$A$5:$A$46,$C10,BONUS_RULES!$B$5:$B$46,"QM"),IF(AGENT_INPUT!I10>=SUMIFS(BONUS_RULES!$G$5:$G$46,BONUS_RULES!$A$5:$A$46,$C10,BONUS_RULES!$B$5:$B$46,"QM"),SUMIFS(BONUS_RULES!$F$5:$F$46,BONUS_RULES!$A$5:$A$46,$C10,BONUS_RULES!$B$5:$B$46,"QM"),0))) | K10: =IF(POLICY_APPROVAL!$B$9="Eligibility only",0,IF(OR($A10="",$D10<>"READY"),"",IF(AGENT_INPUT!J10<=SUMIFS(BONUS_RULES!$E$5:$E$46,BONUS_RULES!$A$5:$A$46,$C10,BONUS_RULES!$B$5:$B$46,"Abs%"),SUMIFS(BONUS_RULES!$D$5:$D$46,BONUS_RULES!$A$5:$A$46,$C10,BONUS_RULES!$B$5:$B$46,"Abs%"),IF(AGENT_INPUT!J10<=SUMIFS(BONUS_RULES!$G$5:$G$46,BONUS_RULES!$A$5:$A$46,$C10,BONUS_RULES!$B$5:$B$46,"Abs%"),SUMIFS(BONUS_RULES!$F$5:$F$46,BONUS_RULES!$A$5:$A$46,$C10,BONUS_RULES!$B$5:$B$46,"Abs%"),0)))) | L10: =IF(OR($A10="",$D10<>"READY"),"",IF(AGENT_INPUT!G10>=SUMIFS(BONUS_RULES!$E$5:$E$46,BONUS_RULES!$A$5:$A$46,$C10,BONUS_RULES!$B$5:$B$46,"Extra Bonus (PCS Score)"),SUMIFS(BONUS_RULES!$D$5:$D$46,BONUS_RULES!$A$5:$A$46,$C10,BONUS_RULES!$B$5:$B$46,"Extra Bonus (PCS Score)"),IF(AGENT_INPUT!G10>=SUMIFS(BONUS_RULES!$G$5:$G$46,BONUS_RULES!$A$5:$A$46,$C10,BONUS_RULES!$B$5:$B$46,"Extra Bonus (PCS Score)"),SUMIFS(BONUS_RULES!$F$5:$F$46,BONUS_RULES!$A$5:$A$46,$C10,BONUS_RULES!$B$5:$B$46,"Extra Bonus (PCS Score)"),0))) | M10: =IF($A10="","",MIN(IF(POLICY_APPROVAL!$B$6="Replacement",SUM(F10:K10)-H10+MAX(H10,L10),SUM(F10:L10)),POLICY_APPROVAL!$B$10)) -> 0 | N10: =IF($A10="","",IFERROR(INDEX(BONUS_RULES!$J$5:$J$10,MATCH(MIN(MAX(AGENT_INPUT!K10,0),5),BONUS_RULES!$I$5:$I$10,0)),1)) -> 0 | O10: =IF(M10="","",MAX(0,IF(POLICY_APPROVAL!$B$5="Percentage points",M10-N10,M10*(1-N10)))) -> 0 | P10: =IF(D10<>"READY","",IF(AGENT_INPUT!O10>0,AGENT_INPUT!O10,AGENT_INPUT!M10*AGENT_INPUT!N10/IF(POLICY_APPROVAL!$B$7="Annual",12,1))) | Q10: =IF(D10<>"READY","",MIN(1,AGENT_INPUT!P10/AGENT_INPUT!Q10)) | R10: =IF(D10<>"READY","",ROUND(P10*Q10*O10,IF(POLICY_APPROVAL!$B$11="Whole MAD",0,2))) | S10: =IF(AND(SETUP!$B$9="READY",T10="READY"),R10,"") | T10: =IF($A10="","",IF(D10<>"READY","BLOCKED - INPUT",IF(E10<>"ELIGIBLE","BLOCKED - ELIGIBILITY",IF(AGENT_INPUT!S10<>"VALIDATED","BLOCKED - DATA",IF(SETUP!$B$9<>"READY","BLOCKED - POLICY","READY"))))) -> BLOCKED - INPUT | U10: =IF($A10="","",IF(COUNTIFS(AGENT_INPUT!$A$5:$A$254,$A10,AGENT_INPUT!$D$5:$D$254,AGENT_INPUT!D10)>1,"DUPLICATE AGENT + PERIOD",IF(D10<>"READY","INPUT OR CONFIG REVIEW",IF(T10<>"READY",T10,"")))) -> Missing, invalid, or unconfigured required input
A11: =IF(AGENT_INPUT!A11="","",AGENT_INPUT!A11) -> 204349 | B11: =IF($A11="","",AGENT_INPUT!B11) -> NABACH Lara | C11: =IF($A11="","",AGENT_INPUT!C11) -> Ford GER | D11: =IF($A11="","",IF(AND(COUNT(AGENT_INPUT!E11:J11)=6,COUNT(AGENT_INPUT!K11)=1,COUNTIF(BONUS_RULES!$A$5:$A$46,AGENT_INPUT!C11)>0,OR(AGENT_INPUT!O11>0,AND(AGENT_INPUT!M11>0,AGENT_INPUT!N11>0)),AGENT_INPUT!P11>=0,AGENT_INPUT!Q11>0,AGENT_INPUT!P11<=AGENT_INPUT!Q11,AGENT_INPUT!H11>=0,AGENT_INPUT!H11<=1,AGENT_INPUT!I11>=0,AGENT_INPUT!I11<=1,AGENT_INPUT!J11>=0,AGENT_INPUT!J11<=1),"READY","BLOCKED")) -> BLOCKED | E11: =IF($A11="","",IF(AGENT_INPUT!R11<>"Active","REVIEW",IF(OR(POLICY_APPROVAL!$B$9="Eligibility only",POLICY_APPROVAL!$B$9="Both"),IF(AGENT_INPUT!J11<=SUMIFS(BONUS_RULES!$E$5:$E$46,BONUS_RULES!$A$5:$A$46,$C11,BONUS_RULES!$B$5:$B$46,"Abs%"),"ELIGIBLE","INELIGIBLE ABS"),"ELIGIBLE"))) | F11: =IF(OR($A11="",$D11<>"READY"),"",IF(AGENT_INPUT!E11<=SUMIFS(BONUS_RULES!$E$5:$E$46,BONUS_RULES!$A$5:$A$46,$C11,BONUS_RULES!$B$5:$B$46,"AHT"),SUMIFS(BONUS_RULES!$D$5:$D$46,BONUS_RULES!$A$5:$A$46,$C11,BONUS_RULES!$B$5:$B$46,"AHT"),IF(AGENT_INPUT!E11<=SUMIFS(BONUS_RULES!$G$5:$G$46,BONUS_RULES!$A$5:$A$46,$C11,BONUS_RULES!$B$5:$B$46,"AHT"),SUMIFS(BONUS_RULES!$F$5:$F$46,BONUS_RULES!$A$5:$A$46,$C11,BONUS_RULES!$B$5:$B$46,"AHT"),0))) | G11: =IF(OR($A11="",$D11<>"READY"),"",IF(AGENT_INPUT!F11>=SUMIFS(BONUS_RULES!$E$5:$E$46,BONUS_RULES!$A$5:$A$46,$C11,BONUS_RULES!$B$5:$B$46,"Productivity"),SUMIFS(BONUS_RULES!$D$5:$D$46,BONUS_RULES!$A$5:$A$46,$C11,BONUS_RULES!$B$5:$B$46,"Productivity"),IF(AGENT_INPUT!F11>=SUMIFS(BONUS_RULES!$G$5:$G$46,BONUS_RULES!$A$5:$A$46,$C11,BONUS_RULES!$B$5:$B$46,"Productivity"),SUMIFS(BONUS_RULES!$F$5:$F$46,BONUS_RULES!$A$5:$A$46,$C11,BONUS_RULES!$B$5:$B$46,"Productivity"),0))) | H11: =IF(OR($A11="",$D11<>"READY"),"",IF(AGENT_INPUT!G11>=SUMIFS(BONUS_RULES!$E$5:$E$46,BONUS_RULES!$A$5:$A$46,$C11,BONUS_RULES!$B$5:$B$46,"PCS Score"),SUMIFS(BONUS_RULES!$D$5:$D$46,BONUS_RULES!$A$5:$A$46,$C11,BONUS_RULES!$B$5:$B$46,"PCS Score"),IF(AGENT_INPUT!G11>=SUMIFS(BONUS_RULES!$G$5:$G$46,BONUS_RULES!$A$5:$A$46,$C11,BONUS_RULES!$B$5:$B$46,"PCS Score"),SUMIFS(BONUS_RULES!$F$5:$F$46,BONUS_RULES!$A$5:$A$46,$C11,BONUS_RULES!$B$5:$B$46,"PCS Score"),0))) | I11: =IF(OR($A11="",$D11<>"READY"),"",IF(AGENT_INPUT!H11>=SUMIFS(BONUS_RULES!$E$5:$E$46,BONUS_RULES!$A$5:$A$46,$C11,BONUS_RULES!$B$5:$B$46,"PCS % (Participation)"),SUMIFS(BONUS_RULES!$D$5:$D$46,BONUS_RULES!$A$5:$A$46,$C11,BONUS_RULES!$B$5:$B$46,"PCS % (Participation)"),IF(AGENT_INPUT!H11>=SUMIFS(BONUS_RULES!$G$5:$G$46,BONUS_RULES!$A$5:$A$46,$C11,BONUS_RULES!$B$5:$B$46,"PCS % (Participation)"),SUMIFS(BONUS_RULES!$F$5:$F$46,BONUS_RULES!$A$5:$A$46,$C11,BONUS_RULES!$B$5:$B$46,"PCS % (Participation)"),0))) | J11: =IF(OR($A11="",$D11<>"READY"),"",IF(AGENT_INPUT!I11>=SUMIFS(BONUS_RULES!$E$5:$E$46,BONUS_RULES!$A$5:$A$46,$C11,BONUS_RULES!$B$5:$B$46,"QM"),SUMIFS(BONUS_RULES!$D$5:$D$46,BONUS_RULES!$A$5:$A$46,$C11,BONUS_RULES!$B$5:$B$46,"QM"),IF(AGENT_INPUT!I11>=SUMIFS(BONUS_RULES!$G$5:$G$46,BONUS_RULES!$A$5:$A$46,$C11,BONUS_RULES!$B$5:$B$46,"QM"),SUMIFS(BONUS_RULES!$F$5:$F$46,BONUS_RULES!$A$5:$A$46,$C11,BONUS_RULES!$B$5:$B$46,"QM"),0))) | K11: =IF(POLICY_APPROVAL!$B$9="Eligibility only",0,IF(OR($A11="",$D11<>"READY"),"",IF(AGENT_INPUT!J11<=SUMIFS(BONUS_RULES!$E$5:$E$46,BONUS_RULES!$A$5:$A$46,$C11,BONUS_RULES!$B$5:$B$46,"Abs%"),SUMIFS(BONUS_RULES!$D$5:$D$46,BONUS_RULES!$A$5:$A$46,$C11,BONUS_RULES!$B$5:$B$46,"Abs%"),IF(AGENT_INPUT!J11<=SUMIFS(BONUS_RULES!$G$5:$G$46,BONUS_RULES!$A$5:$A$46,$C11,BONUS_RULES!$B$5:$B$46,"Abs%"),SUMIFS(BONUS_RULES!$F$5:$F$46,BONUS_RULES!$A$5:$A$46,$C11,BONUS_RULES!$B$5:$B$46,"Abs%"),0)))) | L11: =IF(OR($A11="",$D11<>"READY"),"",IF(AGENT_INPUT!G11>=SUMIFS(BONUS_RULES!$E$5:$E$46,BONUS_RULES!$A$5:$A$46,$C11,BONUS_RULES!$B$5:$B$46,"Extra Bonus (PCS Score)"),SUMIFS(BONUS_RULES!$D$5:$D$46,BONUS_RULES!$A$5:$A$46,$C11,BONUS_RULES!$B$5:$B$46,"Extra Bonus (PCS Score)"),IF(AGENT_INPUT!G11>=SUMIFS(BONUS_RULES!$G$5:$G$46,BONUS_RULES!$A$5:$A$46,$C11,BONUS_RULES!$B$5:$B$46,"Extra Bonus (PCS Score)"),SUMIFS(BONUS_RULES!$F$5:$F$46,BONUS_RULES!$A$5:$A$46,$C11,BONUS_RULES!$B$5:$B$46,"Extra Bonus (PCS Score)"),0))) | M11: =IF($A11="","",MIN(IF(POLICY_APPROVAL!$B$6="Replacement",SUM(F11:K11)-H11+MAX(H11,L11),SUM(F11:L11)),POLICY_APPROVAL!$B$10)) -> 0 | N11: =IF($A11="","",IFERROR(INDEX(BONUS_RULES!$J$5:$J$10,MATCH(MIN(MAX(AGENT_INPUT!K11,0),5),BONUS_RULES!$I$5:$I$10,0)),1)) -> 0 | O11: =IF(M11="","",MAX(0,IF(POLICY_APPROVAL!$B$5="Percentage points",M11-N11,M11*(1-N11)))) -> 0 | P11: =IF(D11<>"READY","",IF(AGENT_INPUT!O11>0,AGENT_INPUT!O11,AGENT_INPUT!M11*AGENT_INPUT!N11/IF(POLICY_APPROVAL!$B$7="Annual",12,1))) | Q11: =IF(D11<>"READY","",MIN(1,AGENT_INPUT!P11/AGENT_INPUT!Q11)) | R11: =IF(D11<>"READY","",ROUND(P11*Q11*O11,IF(POLICY_APPROVAL!$B$11="Whole MAD",0,2))) | S11: =IF(AND(SETUP!$B$9="READY",T11="READY"),R11,"") | T11: =IF($A11="","",IF(D11<>"READY","BLOCKED - INPUT",IF(E11<>"ELIGIBLE","BLOCKED - ELIGIBILITY",IF(AGENT_INPUT!S11<>"VALIDATED","BLOCKED - DATA",IF(SETUP!$B$9<>"READY","BLOCKED - POLICY","READY"))))) -> BLOCKED - INPUT | U11: =IF($A11="","",IF(COUNTIFS(AGENT_INPUT!$A$5:$A$254,$A11,AGENT_INPUT!$D$5:$D$254,AGENT_INPUT!D11)>1,"DUPLICATE AGENT + PERIOD",IF(D11<>"READY","INPUT OR CONFIG REVIEW",IF(T11<>"READY",T11,"")))) -> Missing, invalid, or unconfigured required input
A12: =IF(AGENT_INPUT!A12="","",AGENT_INPUT!A12) -> 228205 | B12: =IF($A12="","",AGENT_INPUT!B12) -> Mohamed Amine MERSAK | C12: =IF($A12="","",AGENT_INPUT!C12) -> OEM FR | D12: =IF($A12="","",IF(AND(COUNT(AGENT_INPUT!E12:J12)=6,COUNT(AGENT_INPUT!K12)=1,COUNTIF(BONUS_RULES!$A$5:$A$46,AGENT_INPUT!C12)>0,OR(AGENT_INPUT!O12>0,AND(AGENT_INPUT!M12>0,AGENT_INPUT!N12>0)),AGENT_INPUT!P12>=0,AGENT_INPUT!Q12>0,AGENT_INPUT!P12<=AGENT_INPUT!Q12,AGENT_INPUT!H12>=0,AGENT_INPUT!H12<=1,AGENT_INPUT!I12>=0,AGENT_INPUT!I12<=1,AGENT_INPUT!J12>=0,AGENT_INPUT!J12<=1),"READY","BLOCKED")) -> BLOCKED | E12: =IF($A12="","",IF(AGENT_INPUT!R12<>"Active","REVIEW",IF(OR(POLICY_APPROVAL!$B$9="Eligibility only",POLICY_APPROVAL!$B$9="Both"),IF(AGENT_INPUT!J12<=SUMIFS(BONUS_RULES!$E$5:$E$46,BONUS_RULES!$A$5:$A$46,$C12,BONUS_RULES!$B$5:$B$46,"Abs%"),"ELIGIBLE","INELIGIBLE ABS"),"ELIGIBLE"))) | F12: =IF(OR($A12="",$D12<>"READY"),"",IF(AGENT_INPUT!E12<=SUMIFS(BONUS_RULES!$E$5:$E$46,BONUS_RULES!$A$5:$A$46,$C12,BONUS_RULES!$B$5:$B$46,"AHT"),SUMIFS(BONUS_RULES!$D$5:$D$46,BONUS_RULES!$A$5:$A$46,$C12,BONUS_RULES!$B$5:$B$46,"AHT"),IF(AGENT_INPUT!E12<=SUMIFS(BONUS_RULES!$G$5:$G$46,BONUS_RULES!$A$5:$A$46,$C12,BONUS_RULES!$B$5:$B$46,"AHT"),SUMIFS(BONUS_RULES!$F$5:$F$46,BONUS_RULES!$A$5:$A$46,$C12,BONUS_RULES!$B$5:$B$46,"AHT"),0))) | G12: =IF(OR($A12="",$D12<>"READY"),"",IF(AGENT_INPUT!F12>=SUMIFS(BONUS_RULES!$E$5:$E$46,BONUS_RULES!$A$5:$A$46,$C12,BONUS_RULES!$B$5:$B$46,"Productivity"),SUMIFS(BONUS_RULES!$D$5:$D$46,BONUS_RULES!$A$5:$A$46,$C12,BONUS_RULES!$B$5:$B$46,"Productivity"),IF(AGENT_INPUT!F12>=SUMIFS(BONUS_RULES!$G$5:$G$46,BONUS_RULES!$A$5:$A$46,$C12,BONUS_RULES!$B$5:$B$46,"Productivity"),SUMIFS(BONUS_RULES!$F$5:$F$46,BONUS_RULES!$A$5:$A$46,$C12,BONUS_RULES!$B$5:$B$46,"Productivity"),0))) | H12: =IF(OR($A12="",$D12<>"READY"),"",IF(AGENT_INPUT!G12>=SUMIFS(BONUS_RULES!$E$5:$E$46,BONUS_RULES!$A$5:$A$46,$C12,BONUS_RULES!$B$5:$B$46,"PCS Score"),SUMIFS(BONUS_RULES!$D$5:$D$46,BONUS_RULES!$A$5:$A$46,$C12,BONUS_RULES!$B$5:$B$46,"PCS Score"),IF(AGENT_INPUT!G12>=SUMIFS(BONUS_RULES!$G$5:$G$46,BONUS_RULES!$A$5:$A$46,$C12,BONUS_RULES!$B$5:$B$46,"PCS Score"),SUMIFS(BONUS_RULES!$F$5:$F$46,BONUS_RULES!$A$5:$A$46,$C12,BONUS_RULES!$B$5:$B$46,"PCS Score"),0))) | I12: =IF(OR($A12="",$D12<>"READY"),"",IF(AGENT_INPUT!H12>=SUMIFS(BONUS_RULES!$E$5:$E$46,BONUS_RULES!$A$5:$A$46,$C12,BONUS_RULES!$B$5:$B$46,"PCS % (Participation)"),SUMIFS(BONUS_RULES!$D$5:$D$46,BONUS_RULES!$A$5:$A$46,$C12,BONUS_RULES!$B$5:$B$46,"PCS % (Participation)"),IF(AGENT_INPUT!H12>=SUMIFS(BONUS_RULES!$G$5:$G$46,BONUS_RULES!$A$5:$A$46,$C12,BONUS_RULES!$B$5:$B$46,"PCS % (Participation)"),SUMIFS(BONUS_RULES!$F$5:$F$46,BONUS_RULES!$A$5:$A$46,$C12,BONUS_RULES!$B$5:$B$46,"PCS % (Participation)"),0))) | J12: =IF(OR($A12="",$D12<>"READY"),"",IF(AGENT_INPUT!I12>=SUMIFS(BONUS_RULES!$E$5:$E$46,BONUS_RULES!$A$5:$A$46,$C12,BONUS_RULES!$B$5:$B$46,"QM"),SUMIFS(BONUS_RULES!$D$5:$D$46,BONUS_RULES!$A$5:$A$46,$C12,BONUS_RULES!$B$5:$B$46,"QM"),IF(AGENT_INPUT!I12>=SUMIFS(BONUS_RULES!$G$5:$G$46,BONUS_RULES!$A$5:$A$46,$C12,BONUS_RULES!$B$5:$B$46,"QM"),SUMIFS(BONUS_RULES!$F$5:$F$46,BONUS_RULES!$A$5:$A$46,$C12,BONUS_RULES!$B$5:$B$46,"QM"),0))) | K12: =IF(POLICY_APPROVAL!$B$9="Eligibility only",0,IF(OR($A12="",$D12<>"READY"),"",IF(AGENT_INPUT!J12<=SUMIFS(BONUS_RULES!$E$5:$E$46,BONUS_RULES!$A$5:$A$46,$C12,BONUS_RULES!$B$5:$B$46,"Abs%"),SUMIFS(BONUS_RULES!$D$5:$D$46,BONUS_RULES!$A$5:$A$46,$C12,BONUS_RULES!$B$5:$B$46,"Abs%"),IF(AGENT_INPUT!J12<=SUMIFS(BONUS_RULES!$G$5:$G$46,BONUS_RULES!$A$5:$A$46,$C12,BONUS_RULES!$B$5:$B$46,"Abs%"),SUMIFS(BONUS_RULES!$F$5:$F$46,BONUS_RULES!$A$5:$A$46,$C12,BONUS_RULES!$B$5:$B$46,"Abs%"),0)))) | L12: =IF(OR($A12="",$D12<>"READY"),"",IF(AGENT_INPUT!G12>=SUMIFS(BONUS_RULES!$E$5:$E$46,BONUS_RULES!$A$5:$A$46,$C12,BONUS_RULES!$B$5:$B$46,"Extra Bonus (PCS Score)"),SUMIFS(BONUS_RULES!$D$5:$D$46,BONUS_RULES!$A$5:$A$46,$C12,BONUS_RULES!$B$5:$B$46,"Extra Bonus (PCS Score)"),IF(AGENT_INPUT!G12>=SUMIFS(BONUS_RULES!$G$5:$G$46,BONUS_RULES!$A$5:$A$46,$C12,BONUS_RULES!$B$5:$B$46,"Extra Bonus (PCS Score)"),SUMIFS(BONUS_RULES!$F$5:$F$46,BONUS_RULES!$A$5:$A$46,$C12,BONUS_RULES!$B$5:$B$46,"Extra Bonus (PCS Score)"),0))) | M12: =IF($A12="","",MIN(IF(POLICY_APPROVAL!$B$6="Replacement",SUM(F12:K12)-H12+MAX(H12,L12),SUM(F12:L12)),POLICY_APPROVAL!$B$10)) -> 0 | N12: =IF($A12="","",IFERROR(INDEX(BONUS_RULES!$J$5:$J$10,MATCH(MIN(MAX(AGENT_INPUT!K12,0),5),BONUS_RULES!$I$5:$I$10,0)),1)) -> 0 | O12: =IF(M12="","",MAX(0,IF(POLICY_APPROVAL!$B$5="Percentage points",M12-N12,M12*(1-N12)))) -> 0 | P12: =IF(D12<>"READY","",IF(AGENT_INPUT!O12>0,AGENT_INPUT!O12,AGENT_INPUT!M12*AGENT_INPUT!N12/IF(POLICY_APPROVAL!$B$7="Annual",12,1))) | Q12: =IF(D12<>"READY","",MIN(1,AGENT_INPUT!P12/AGENT_INPUT!Q12)) | R12: =IF(D12<>"READY","",ROUND(P12*Q12*O12,IF(POLICY_APPROVAL!$B$11="Whole MAD",0,2))) | S12: =IF(AND(SETUP!$B$9="READY",T12="READY"),R12,"") | T12: =IF($A12="","",IF(D12<>"READY","BLOCKED - INPUT",IF(E12<>"ELIGIBLE","BLOCKED - ELIGIBILITY",IF(AGENT_INPUT!S12<>"VALIDATED","BLOCKED - DATA",IF(SETUP!$B$9<>"READY","BLOCKED - POLICY","READY"))))) -> BLOCKED - INPUT | U12: =IF($A12="","",IF(COUNTIFS(AGENT_INPUT!$A$5:$A$254,$A12,AGENT_INPUT!$D$5:$D$254,AGENT_INPUT!D12)>1,"DUPLICATE AGENT + PERIOD",IF(D12<>"READY","INPUT OR CONFIG REVIEW",IF(T12<>"READY",T12,"")))) -> Missing, invalid, or unconfigured required input
