Workbook
Name PCS_Report_Date: SETUP!$B$5
Name PCS_Window_End: SETUP!$B$7
Name PCS_Window_Start: SETUP!$B$6

Sheet SETUP
A1: PCS management setup
A2: Change the blue date/window cells before each management send.
A4: Control | B4: Value
A5: Report date | B5: 46265
A6: 3-hour window start | B6: 46265.375
A7: 3-hour window end | B7: 46265.5
A8: Prepared by | B8: Anass ASSRI
A9: Generated at | B9: 46265.012
A11: Data through | B11: =IFERROR(MAX(tblPCSInput[Call Date/Time]),"")
A13: How to refresh
A14: 1. Clear only the blue source columns in INPUT_CALLS. 2. Paste the required Call-by-Call fields under matching headers. 3. Update Report date and the three-hour window. 4. Review DATA_QUALITY. 5. Copy EMAIL_BRIEF and send the workbook. Every input row is one call leg; transferred calls can create multiple legs.

Sheet ROSTER
A1: PCS roster
A2: Paste the current FTE roster here. Agent ID is the Storm/Verint Client ID.
A4: Agent ID | B4: Status | C4: Agent | D4: Team Leader | E4: Ops Manager | F4: LOB
A5: 96458 | B5: Active | C5: MOKHTAR Kawtar | D5: Farouk BOUAZZAOUI | E5: Anas OUAKKAD | F5: RSA FR
A6: 96527 | B6: Active | C6: NASSER Meryem | D6: Farouk BOUAZZAOUI | E6: Anas OUAKKAD | F6: RSA FR
A7: 96472 | B7: Active | C7: LAOOUINA Meryem | D7: Farouk BOUAZZAOUI | E7: Anas OUAKKAD | F7: RSA FR
A8: 144564 | B8: Active | C8: BENSIF Hamza | D8: Farouk BOUAZZAOUI | E8: Anas OUAKKAD | F8: RSA FR
A9: 144565 | B9: Active | C9: NABAT Nouhaila | D9: Farouk BOUAZZAOUI | E9: Anas OUAKKAD | F9: RSA FR
A10: 199554 | B10: Active | C10: Ez-Zouaghi Amira | D10: Farouk BOUAZZAOUI | E10: Anas OUAKKAD | F10: RSA FR
A11: 203080 | B11: Active | C11: Lamtibbou Nizar | D11: Farouk BOUAZZAOUI | E11: Anas OUAKKAD | F11: RSA FR
A12: 203079 | B12: Active | C12: Ghali Haddad | D12: Farouk BOUAZZAOUI | E12: Anas OUAKKAD | F12: RSA FR
A13: 207437 | B13: Active | C13: Taha Aboulhaoul | D13: Farouk BOUAZZAOUI | E13: Anas OUAKKAD | F13: RSA FR
A14: 96491 | B14: Active | C14: AHLAL Ainane | D14: Adil LAGRAOUI | E14: Anas OUAKKAD | F14: RSA NL
A15: 96500 | B15: Active | C15: Mejhed Asmaa | D15: Ilyasse Derrazi | E15: Anas OUAKKAD | F15: Ford Dutch
A16: 199529 | B16: Active | C16: Ajermite Khalil | D16: Adil LAGRAOUI | E16: Anas OUAKKAD | F16: RSA NL
... A125: 228667 | B125: Active | C125: Hajar El Moustaid | D125: Zineb MOUFID | E125: Anas OUAKKAD | F125: OEM FR
A126: #N/A | B126: Active | C126: Najib Abdelhadi | D126: Kenza EL MOUMNI | E126: Anas OUAKKAD | F126: OEM FR
A127: 228669 | B127: Active | C127: Ayoub Failouss | D127: Malak AZERKI | E127: Anas OUAKKAD | F127: OEM FR
A128: 206139 | B128: Active | C128: El Mehdi El Guiri | D128: Kenza EL MOUMNI | E128: Anas OUAKKAD | F128: OEM FR
A129: 228670 | B129: Active | C129: Chaimaa Benlaghlimi | D129: Malak AZERKI | E129: Anas OUAKKAD | F129: OEM FR
A130: 228672 | B130: Active | C130: Mohamed Ali Dreif | D130: Zineb MOUFID | E130: Anas OUAKKAD | F130: OEM FR
A131: 228673 | B131: Active | C131: Imane Karoui | D131: Zineb MOUFID | E131: Anas OUAKKAD | F131: OEM FR
A132: 230748 | B132: Active | C132: Driss Oujer | D132: Zineb MOUFID | E132: Anas OUAKKAD | F132: OEM FR
A133: 96457 | B133: Active | C133: SAMAR Said | D133: Youssef KHADLY | E133: Jawad BAKRIMI | F133: RSA NL
A134: 96475 | B134: Active | C134: AL TAMIMI Zeynab | D134: Onboarding | E134: Anas OUAKKAD | F134: RSA NL

Sheet INPUT_CALLS
A1: Call-by-Call input
A2: Paste source values only in blue columns. Formula columns match roster and validate Question 1.
A4: Call Date/Time | B4: Call End Date/Time | C4: Call ID | D4: Call Direction | E4: Agent ID | F4: Agent | G4: Talk Time | H4: Hold Time | I4: Total Wrap Time | J4: Language | K4: Queue | L4: PostCallSurveyMode | M4: PCSStatus | N4: Question 1 | O4: Team Leader | P4: Ops Manager | Q4: LOB | R4: Valid Q1 | S4: Q1 Nonblank | T4: Data Issue
O5: =IF([[#This Row],[Call Date/Time]]="","",IFERROR(INDEX(tblPCSRoster[Team Leader],MATCH([[#This Row],[Agent ID]],tblPCSRoster[Agent ID],0)),"")) -> 0 | P5: =IF([[#This Row],[Call Date/Time]]="","",IFERROR(INDEX(tblPCSRoster[Ops Manager],MATCH([[#This Row],[Agent ID]],tblPCSRoster[Agent ID],0)),"")) -> 0 | Q5: =IF([[#This Row],[Call Date/Time]]="","",IFERROR(INDEX(tblPCSRoster[LOB],MATCH([[#This Row],[Agent ID]],tblPCSRoster[Agent ID],0)),"")) -> 0 | R5: =IF([[#This Row],[Call Date/Time]]="","",IF(AND(ISNUMBER([[#This Row],[Question 1]]),[[#This Row],[Question 1]]>=1,[[#This Row],[Question 1]]<=5,MOD([[#This Row],[Question 1]],1)=0),[[#This Row],[Question 1]],"")) -> 0 | S5: =IF([[#This Row],[Call Date/Time]]="","",--([[#This Row],[Question 1]]<>"")) -> 0 | T5: =IF([[#This Row],[Call Date/Time]]="","",IF([[#This Row],[Agent ID]]="","MISSING AGENT ID",IF(COUNTIF(tblPCSRoster[Agent ID],[[#This Row],[Agent ID]])=0,"UNMATCHED AGENT",IF(AND([[#This Row],[Question 1]]<>"",[[#This Row],[Valid Q1]]=""),"INVALID Q1","")))) -> 0

Sheet AGENT_DETAIL
A1: PCS agent detail
A2: Original O/P/Q/R logic, plus valid-response diagnostics and the selected three-hour interval.
A4: Agent ID | B4: Agent | C4: Team Leader | D4: Ops Manager | E4: LOB | F4: Eligible Calls Day | G4: Q1 Nonblank Day | H4: Valid Q1 Day | I4: PCS Average Day | J4: <=3 Day | K4: >3 Day | L4: PCS Participation Day | M4: Valid Response Day | N4: Invalid Q1 Day | O4: Sample Flag | P4: Eligible Calls 3H | Q4: Q1 Nonblank 3H | R4: Valid Q1 3H | S4: PCS Average 3H | T4: <=3 3H | U4: >3 3H | V4: PCS Participation 3H | W4: Valid Response 3H
A5: =IF(ROSTER!A5="","",ROSTER!A5) -> 96458 | B5: =IF($A5="","",ROSTER!C5) -> MOKHTAR Kawtar | C5: =IF($A5="","",ROSTER!D5) -> Farouk BOUAZZAOUI | D5: =IF($A5="","",ROSTER!E5) -> Anas OUAKKAD | E5: =IF($A5="","",ROSTER!F5) -> RSA FR | F5: =IF($A5="","",COUNTIFS(tblPCSInput[Call Date/Time],">="&(SETUP!$B$5),tblPCSInput[Call Date/Time],"<"&(SETUP!$B$5+1),tblPCSInput[Call Direction],"I",tblPCSInput[Agent ID],$A5,tblPCSInput[PCSStatus],1)) | G5: =IF($A5="","",COUNTIFS(tblPCSInput[Call Date/Time],">="&(SETUP!$B$5),tblPCSInput[Call Date/Time],"<"&(SETUP!$B$5+1),tblPCSInput[Call Direction],"I",tblPCSInput[Agent ID],$A5,tblPCSInput[Question 1],"<>")) | H5: =IF($A5="","",COUNTIFS(tblPCSInput[Call Date/Time],">="&(SETUP!$B$5),tblPCSInput[Call Date/Time],"<"&(SETUP!$B$5+1),tblPCSInput[Call Direction],"I",tblPCSInput[Agent ID],$A5,tblPCSInput[Valid Q1],">=1")) | I5: =IFERROR(SUMIFS(tblPCSInput[Valid Q1],tblPCSInput[Call Date/Time],">="&SETUP!$B$5,tblPCSInput[Call Date/Time],"<"&SETUP!$B$5+1,tblPCSInput[Call Direction],"I",tblPCSInput[Agent ID],$A5)/COUNTIFS(tblPCSInput[Call Date/Time],">="&(SETUP!$B$5),tblPCSInput[Call Date/Time],"<"&(SETUP!$B$5+1),tblPCSInput[Call Direction],"I",tblPCSInput[Agent ID],$A5,tblPCSInput[Valid Q1],">=1"),"") | J5: =IF(I5="","",COUNTIFS(tblPCSInput[Call Date/Time],">="&(SETUP!$B$5),tblPCSInput[Call Date/Time],"<"&(SETUP!$B$5+1),tblPCSInput[Call Direction],"I",tblPCSInput[Agent ID],$A5,tblPCSInput[Valid Q1],"<=3",tblPCSInput[Valid Q1],">=1")) | K5: =IF(I5="","",COUNTIFS(tblPCSInput[Call Date/Time],">="&(SETUP!$B$5),tblPCSInput[Call Date/Time],"<"&(SETUP!$B$5+1),tblPCSInput[Call Direction],"I",tblPCSInput[Agent ID],$A5,tblPCSInput[Valid Q1],">3")) | L5: =IFERROR(G5/F5,"") | M5: =IFERROR(H5/F5,"") | N5: =IF($A5="","",MAX(0,G5-H5)) | O5: =IF($A5="","",IF(H5=0,"NO VALID SURVEY",IF(H5<5,"LOW SAMPLE","OK"))) | P5: =IF($A5="","",COUNTIFS(tblPCSInput[Call Date/Time],">="&(SETUP!$B$6),tblPCSInput[Call Date/Time],"<"&(SETUP!$B$7),tblPCSInput[Call Direction],"I",tblPCSInput[Agent ID],$A5,tblPCSInput[PCSStatus],1)) | Q5: =IF($A5="","",COUNTIFS(tblPCSInput[Call Date/Time],">="&(SETUP!$B$6),tblPCSInput[Call Date/Time],"<"&(SETUP!$B$7),tblPCSInput[Call Direction],"I",tblPCSInput[Agent ID],$A5,tblPCSInput[Question 1],"<>")) | R5: =IF($A5="","",COUNTIFS(tblPCSInput[Call Date/Time],">="&(SETUP!$B$6),tblPCSInput[Call Date/Time],"<"&(SETUP!$B$7),tblPCSInput[Call Direction],"I",tblPCSInput[Agent ID],$A5,tblPCSInput[Valid Q1],">=1")) | S5: =IFERROR(SUMIFS(tblPCSInput[Valid Q1],tblPCSInput[Call Date/Time],">="&SETUP!$B$6,tblPCSInput[Call Date/Time],"<"&SETUP!$B$7,tblPCSInput[Call Direction],"I",tblPCSInput[Agent ID],$A5)/COUNTIFS(tblPCSInput[Call Date/Time],">="&(SETUP!$B$6),tblPCSInput[Call Date/Time],"<"&(SETUP!$B$7),tblPCSInput[Call Direction],"I",tblPCSInput[Agent ID],$A5,tblPCSInput[Valid Q1],">=1"),"") | T5: =IF(S5="","",COUNTIFS(tblPCSInput[Call Date/Time],">="&(SETUP!$B$6),tblPCSInput[Call Date/Time],"<"&(SETUP!$B$7),tblPCSInput[Call Direction],"I",tblPCSInput[Agent ID],$A5,tblPCSInput[Valid Q1],"<=3",tblPCSInput[Valid Q1],">=1")) | U5: =IF(S5="","",COUNTIFS(tblPCSInput[Call Date/Time],">="&(SETUP!$B$6),tblPCSInput[Call Date/Time],"<"&(SETUP!$B$7),tblPCSInput[Call Direction],"I",tblPCSInput[Agent ID],$A5,tblPCSInput[Valid Q1],">3")) | V5: =IFERROR(Q5/P5,"") | W5: =IFERROR(R5/P5,"")
A6: =IF(ROSTER!A6="","",ROSTER!A6) -> 96527 | B6: =IF($A6="","",ROSTER!C6) -> NASSER Meryem | C6: =IF($A6="","",ROSTER!D6) -> Farouk BOUAZZAOUI | D6: =IF($A6="","",ROSTER!E6) -> Anas OUAKKAD | E6: =IF($A6="","",ROSTER!F6) -> RSA FR | F6: =IF($A6="","",COUNTIFS(tblPCSInput[Call Date/Time],">="&(SETUP!$B$5),tblPCSInput[Call Date/Time],"<"&(SETUP!$B$5+1),tblPCSInput[Call Direction],"I",tblPCSInput[Agent ID],$A6,tblPCSInput[PCSStatus],1)) | G6: =IF($A6="","",COUNTIFS(tblPCSInput[Call Date/Time],">="&(SETUP!$B$5),tblPCSInput[Call Date/Time],"<"&(SETUP!$B$5+1),tblPCSInput[Call Direction],"I",tblPCSInput[Agent ID],$A6,tblPCSInput[Question 1],"<>")) | H6: =IF($A6="","",COUNTIFS(tblPCSInput[Call Date/Time],">="&(SETUP!$B$5),tblPCSInput[Call Date/Time],"<"&(SETUP!$B$5+1),tblPCSInput[Call Direction],"I",tblPCSInput[Agent ID],$A6,tblPCSInput[Valid Q1],">=1")) | I6: =IFERROR(SUMIFS(tblPCSInput[Valid Q1],tblPCSInput[Call Date/Time],">="&SETUP!$B$5,tblPCSInput[Call Date/Time],"<"&SETUP!$B$5+1,tblPCSInput[Call Direction],"I",tblPCSInput[Agent ID],$A6)/COUNTIFS(tblPCSInput[Call Date/Time],">="&(SETUP!$B$5),tblPCSInput[Call Date/Time],"<"&(SETUP!$B$5+1),tblPCSInput[Call Direction],"I",tblPCSInput[Agent ID],$A6,tblPCSInput[Valid Q1],">=1"),"") | J6: =IF(I6="","",COUNTIFS(tblPCSInput[Call Date/Time],">="&(SETUP!$B$5),tblPCSInput[Call Date/Time],"<"&(SETUP!$B$5+1),tblPCSInput[Call Direction],"I",tblPCSInput[Agent ID],$A6,tblPCSInput[Valid Q1],"<=3",tblPCSInput[Valid Q1],">=1")) | K6: =IF(I6="","",COUNTIFS(tblPCSInput[Call Date/Time],">="&(SETUP!$B$5),tblPCSInput[Call Date/Time],"<"&(SETUP!$B$5+1),tblPCSInput[Call Direction],"I",tblPCSInput[Agent ID],$A6,tblPCSInput[Valid Q1],">3")) | L6: =IFERROR(G6/F6,"") | M6: =IFERROR(H6/F6,"") | N6: =IF($A6="","",MAX(0,G6-H6)) | O6: =IF($A6="","",IF(H6=0,"NO VALID SURVEY",IF(H6<5,"LOW SAMPLE","OK"))) | P6: =IF($A6="","",COUNTIFS(tblPCSInput[Call Date/Time],">="&(SETUP!$B$6),tblPCSInput[Call Date/Time],"<"&(SETUP!$B$7),tblPCSInput[Call Direction],"I",tblPCSInput[Agent ID],$A6,tblPCSInput[PCSStatus],1)) | Q6: =IF($A6="","",COUNTIFS(tblPCSInput[Call Date/Time],">="&(SETUP!$B$6),tblPCSInput[Call Date/Time],"<"&(SETUP!$B$7),tblPCSInput[Call Direction],"I",tblPCSInput[Agent ID],$A6,tblPCSInput[Question 1],"<>")) | R6: =IF($A6="","",COUNTIFS(tblPCSInput[Call Date/Time],">="&(SETUP!$B$6),tblPCSInput[Call Date/Time],"<"&(SETUP!$B$7),tblPCSInput[Call Direction],"I",tblPCSInput[Agent ID],$A6,tblPCSInput[Valid Q1],">=1")) | S6: =IFERROR(SUMIFS(tblPCSInput[Valid Q1],tblPCSInput[Call Date/Time],">="&SETUP!$B$6,tblPCSInput[Call Date/Time],"<"&SETUP!$B$7,tblPCSInput[Call Direction],"I",tblPCSInput[Agent ID],$A6)/COUNTIFS(tblPCSInput[Call Date/Time],">="&(SETUP!$B$6),tblPCSInput[Call Date/Time],"<"&(SETUP!$B$7),tblPCSInput[Call Direction],"I",tblPCSInput[Agent ID],$A6,tblPCSInput[Valid Q1],">=1"),"") | T6: =IF(S6="","",COUNTIFS(tblPCSInput[Call Date/Time],">="&(SETUP!$B$6),tblPCSInput[Call Date/Time],"<"&(SETUP!$B$7),tblPCSInput[Call Direction],"I",tblPCSInput[Agent ID],$A6,tblPCSInput[Valid Q1],"<=3",tblPCSInput[Valid Q1],">=1")) | U6: =IF(S6="","",COUNTIFS(tblPCSInput[Call Date/Time],">="&(SETUP!$B$6),tblPCSInput[Call Date/Time],"<"&(SETUP!$B$7),tblPCSInput[Call Direction],"I",tblPCSInput[Agent ID],$A6,tblPCSInput[Valid Q1],">3")) | V6: =IFERROR(Q6/P6,"") | W6: =IFERROR(R6/P6,"")
A7: =IF(ROSTER!A7="","",ROSTER!A7) -> 96472 | B7: =IF($A7="","",ROSTER!C7) -> LAOOUINA Meryem | C7: =IF($A7="","",ROSTER!D7) -> Farouk BOUAZZAOUI | D7: =IF($A7="","",ROSTER!E7) -> Anas OUAKKAD | E7: =IF($A7="","",ROSTER!F7) -> RSA FR | F7: =IF($A7="","",COUNTIFS(tblPCSInput[Call Date/Time],">="&(SETUP!$B$5),tblPCSInput[Call Date/Time],"<"&(SETUP!$B$5+1),tblPCSInput[Call Direction],"I",tblPCSInput[Agent ID],$A7,tblPCSInput[PCSStatus],1)) | G7: =IF($A7="","",COUNTIFS(tblPCSInput[Call Date/Time],">="&(SETUP!$B$5),tblPCSInput[Call Date/Time],"<"&(SETUP!$B$5+1),tblPCSInput[Call Direction],"I",tblPCSInput[Agent ID],$A7,tblPCSInput[Question 1],"<>")) | H7: =IF($A7="","",COUNTIFS(tblPCSInput[Call Date/Time],">="&(SETUP!$B$5),tblPCSInput[Call Date/Time],"<"&(SETUP!$B$5+1),tblPCSInput[Call Direction],"I",tblPCSInput[Agent ID],$A7,tblPCSInput[Valid Q1],">=1")) | I7: =IFERROR(SUMIFS(tblPCSInput[Valid Q1],tblPCSInput[Call Date/Time],">="&SETUP!$B$5,tblPCSInput[Call Date/Time],"<"&SETUP!$B$5+1,tblPCSInput[Call Direction],"I",tblPCSInput[Agent ID],$A7)/COUNTIFS(tblPCSInput[Call Date/Time],">="&(SETUP!$B$5),tblPCSInput[Call Date/Time],"<"&(SETUP!$B$5+1),tblPCSInput[Call Direction],"I",tblPCSInput[Agent ID],$A7,tblPCSInput[Valid Q1],">=1"),"") | J7: =IF(I7="","",COUNTIFS(tblPCSInput[Call Date/Time],">="&(SETUP!$B$5),tblPCSInput[Call Date/Time],"<"&(SETUP!$B$5+1),tblPCSInput[Call Direction],"I",tblPCSInput[Agent ID],$A7,tblPCSInput[Valid Q1],"<=3",tblPCSInput[Valid Q1],">=1")) | K7: =IF(I7="","",COUNTIFS(tblPCSInput[Call Date/Time],">="&(SETUP!$B$5),tblPCSInput[Call Date/Time],"<"&(SETUP!$B$5+1),tblPCSInput[Call Direction],"I",tblPCSInput[Agent ID],$A7,tblPCSInput[Valid Q1],">3")) | L7: =IFERROR(G7/F7,"") | M7: =IFERROR(H7/F7,"") | N7: =IF($A7="","",MAX(0,G7-H7)) | O7: =IF($A7="","",IF(H7=0,"NO VALID SURVEY",IF(H7<5,"LOW SAMPLE","OK"))) | P7: =IF($A7="","",COUNTIFS(tblPCSInput[Call Date/Time],">="&(SETUP!$B$6),tblPCSInput[Call Date/Time],"<"&(SETUP!$B$7),tblPCSInput[Call Direction],"I",tblPCSInput[Agent ID],$A7,tblPCSInput[PCSStatus],1)) | Q7: =IF($A7="","",COUNTIFS(tblPCSInput[Call Date/Time],">="&(SETUP!$B$6),tblPCSInput[Call Date/Time],"<"&(SETUP!$B$7),tblPCSInput[Call Direction],"I",tblPCSInput[Agent ID],$A7,tblPCSInput[Question 1],"<>")) | R7: =IF($A7="","",COUNTIFS(tblPCSInput[Call Date/Time],">="&(SETUP!$B$6),tblPCSInput[Call Date/Time],"<"&(SETUP!$B$7),tblPCSInput[Call Direction],"I",tblPCSInput[Agent ID],$A7,tblPCSInput[Valid Q1],">=1")) | S7: =IFERROR(SUMIFS(tblPCSInput[Valid Q1],tblPCSInput[Call Date/Time],">="&SETUP!$B$6,tblPCSInput[Call Date/Time],"<"&SETUP!$B$7,tblPCSInput[Call Direction],"I",tblPCSInput[Agent ID],$A7)/COUNTIFS(tblPCSInput[Call Date/Time],">="&(SETUP!$B$6),tblPCSInput[Call Date/Time],"<"&(SETUP!$B$7),tblPCSInput[Call Direction],"I",tblPCSInput[Agent ID],$A7,tblPCSInput[Valid Q1],">=1"),"") | T7: =IF(S7="","",COUNTIFS(tblPCSInput[Call Date/Time],">="&(SETUP!$B$6),tblPCSInput[Call Date/Time],"<"&(SETUP!$B$7),tblPCSInput[Call Direction],"I",tblPCSInput[Agent ID],$A7,tblPCSInput[Valid Q1],"<=3",tblPCSInput[Valid Q1],">=1")) | U7: =IF(S7="","",COUNTIFS(tblPCSInput[Call Date/Time],">="&(SETUP!$B$6),tblPCSInput[Call Date/Time],"<"&(SETUP!$B$7),tblPCSInput[Call Direction],"I",tblPCSInput[Agent ID],$A7,tblPCSInput[Valid Q1],">3")) | V7: =IFERROR(Q7/P7,"") | W7: =IFERROR(R7/P7,"")
A8: =IF(ROSTER!A8="","",ROSTER!A8) -> 144564 | B8: =IF($A8="","",ROSTER!C8) -> BENSIF Hamza | C8: =IF($A8="","",ROSTER!D8) -> Farouk BOUAZZAOUI | D8: =IF($A8="","",ROSTER!E8) -> Anas OUAKKAD | E8: =IF($A8="","",ROSTER!F8) -> RSA FR | F8: =IF($A8="","",COUNTIFS(tblPCSInput[Call Date/Time],">="&(SETUP!$B$5),tblPCSInput[Call Date/Time],"<"&(SETUP!$B$5+1),tblPCSInput[Call Direction],"I",tblPCSInput[Agent ID],$A8,tblPCSInput[PCSStatus],1)) | G8: =IF($A8="","",COUNTIFS(tblPCSInput[Call Date/Time],">="&(SETUP!$B$5),tblPCSInput[Call Date/Time],"<"&(SETUP!$B$5+1),tblPCSInput[Call Direction],"I",tblPCSInput[Agent ID],$A8,tblPCSInput[Question 1],"<>")) | H8: =IF($A8="","",COUNTIFS(tblPCSInput[Call Date/Time],">="&(SETUP!$B$5),tblPCSInput[Call Date/Time],"<"&(SETUP!$B$5+1),tblPCSInput[Call Direction],"I",tblPCSInput[Agent ID],$A8,tblPCSInput[Valid Q1],">=1")) | I8: =IFERROR(SUMIFS(tblPCSInput[Valid Q1],tblPCSInput[Call Date/Time],">="&SETUP!$B$5,tblPCSInput[Call Date/Time],"<"&SETUP!$B$5+1,tblPCSInput[Call Direction],"I",tblPCSInput[Agent ID],$A8)/COUNTIFS(tblPCSInput[Call Date/Time],">="&(SETUP!$B$5),tblPCSInput[Call Date/Time],"<"&(SETUP!$B$5+1),tblPCSInput[Call Direction],"I",tblPCSInput[Agent ID],$A8,tblPCSInput[Valid Q1],">=1"),"") | J8: =IF(I8="","",COUNTIFS(tblPCSInput[Call Date/Time],">="&(SETUP!$B$5),tblPCSInput[Call Date/Time],"<"&(SETUP!$B$5+1),tblPCSInput[Call Direction],"I",tblPCSInput[Agent ID],$A8,tblPCSInput[Valid Q1],"<=3",tblPCSInput[Valid Q1],">=1")) | K8: =IF(I8="","",COUNTIFS(tblPCSInput[Call Date/Time],">="&(SETUP!$B$5),tblPCSInput[Call Date/Time],"<"&(SETUP!$B$5+1),tblPCSInput[Call Direction],"I",tblPCSInput[Agent ID],$A8,tblPCSInput[Valid Q1],">3")) | L8: =IFERROR(G8/F8,"") | M8: =IFERROR(H8/F8,"") | N8: =IF($A8="","",MAX(0,G8-H8)) | O8: =IF($A8="","",IF(H8=0,"NO VALID SURVEY",IF(H8<5,"LOW SAMPLE","OK"))) | P8: =IF($A8="","",COUNTIFS(tblPCSInput[Call Date/Time],">="&(SETUP!$B$6),tblPCSInput[Call Date/Time],"<"&(SETUP!$B$7),tblPCSInput[Call Direction],"I",tblPCSInput[Agent ID],$A8,tblPCSInput[PCSStatus],1)) | Q8: =IF($A8="","",COUNTIFS(tblPCSInput[Call Date/Time],">="&(SETUP!$B$6),tblPCSInput[Call Date/Time],"<"&(SETUP!$B$7),tblPCSInput[Call Direction],"I",tblPCSInput[Agent ID],$A8,tblPCSInput[Question 1],"<>")) | R8: =IF($A8="","",COUNTIFS(tblPCSInput[Call Date/Time],">="&(SETUP!$B$6),tblPCSInput[Call Date/Time],"<"&(SETUP!$B$7),tblPCSInput[Call Direction],"I",tblPCSInput[Agent ID],$A8,tblPCSInput[Valid Q1],">=1")) | S8: =IFERROR(SUMIFS(tblPCSInput[Valid Q1],tblPCSInput[Call Date/Time],">="&SETUP!$B$6,tblPCSInput[Call Date/Time],"<"&SETUP!$B$7,tblPCSInput[Call Direction],"I",tblPCSInput[Agent ID],$A8)/COUNTIFS(tblPCSInput[Call Date/Time],">="&(SETUP!$B$6),tblPCSInput[Call Date/Time],"<"&(SETUP!$B$7),tblPCSInput[Call Direction],"I",tblPCSInput[Agent ID],$A8,tblPCSInput[Valid Q1],">=1"),"") | T8: =IF(S8="","",COUNTIFS(tblPCSInput[Call Date/Time],">="&(SETUP!$B$6),tblPCSInput[Call Date/Time],"<"&(SETUP!$B$7),tblPCSInput[Call Direction],"I",tblPCSInput[Agent ID],$A8,tblPCSInput[Valid Q1],"<=3",tblPCSInput[Valid Q1],">=1")) | U8: =IF(S8="","",COUNTIFS(tblPCSInput[Call Date/Time],">="&(SETUP!$B$6),tblPCSInput[Call Date/Time],"<"&(SETUP!$B$7),tblPCSInput[Call Direction],"I",tblPCSInput[Agent ID],$A8,tblPCSInput[Valid Q1],">3")) | V8: =IFERROR(Q8/P8,"") | W8: =IFERROR(R8/P8,"")
A9: =IF(ROSTER!A9="","",ROSTER!A9) -> 144565 | B9: =IF($A9="","",ROSTER!C9) -> NABAT Nouhaila | C9: =IF($A9="","",ROSTER!D9) -> Farouk BOUAZZAOUI | D9: =IF($A9="","",ROSTER!E9) -> Anas OUAKKAD | E9: =IF($A9="","",ROSTER!F9) -> RSA FR | F9: =IF($A9="","",COUNTIFS(tblPCSInput[Call Date/Time],">="&(SETUP!$B$5),tblPCSInput[Call Date/Time],"<"&(SETUP!$B$5+1),tblPCSInput[Call Direction],"I",tblPCSInput[Agent ID],$A9,tblPCSInput[PCSStatus],1)) | G9: =IF($A9="","",COUNTIFS(tblPCSInput[Call Date/Time],">="&(SETUP!$B$5),tblPCSInput[Call Date/Time],"<"&(SETUP!$B$5+1),tblPCSInput[Call Direction],"I",tblPCSInput[Agent ID],$A9,tblPCSInput[Question 1],"<>")) | H9: =IF($A9="","",COUNTIFS(tblPCSInput[Call Date/Time],">="&(SETUP!$B$5),tblPCSInput[Call Date/Time],"<"&(SETUP!$B$5+1),tblPCSInput[Call Direction],"I",tblPCSInput[Agent ID],$A9,tblPCSInput[Valid Q1],">=1")) | I9: =IFERROR(SUMIFS(tblPCSInput[Valid Q1],tblPCSInput[Call Date/Time],">="&SETUP!$B$5,tblPCSInput[Call Date/Time],"<"&SETUP!$B$5+1,tblPCSInput[Call Direction],"I",tblPCSInput[Agent ID],$A9)/COUNTIFS(tblPCSInput[Call Date/Time],">="&(SETUP!$B$5),tblPCSInput[Call Date/Time],"<"&(SETUP!$B$5+1),tblPCSInput[Call Direction],"I",tblPCSInput[Agent ID],$A9,tblPCSInput[Valid Q1],">=1"),"") | J9: =IF(I9="","",COUNTIFS(tblPCSInput[Call Date/Time],">="&(SETUP!$B$5),tblPCSInput[Call Date/Time],"<"&(SETUP!$B$5+1),tblPCSInput[Call Direction],"I",tblPCSInput[Agent ID],$A9,tblPCSInput[Valid Q1],"<=3",tblPCSInput[Valid Q1],">=1")) | K9: =IF(I9="","",COUNTIFS(tblPCSInput[Call Date/Time],">="&(SETUP!$B$5),tblPCSInput[Call Date/Time],"<"&(SETUP!$B$5+1),tblPCSInput[Call Direction],"I",tblPCSInput[Agent ID],$A9,tblPCSInput[Valid Q1],">3")) | L9: =IFERROR(G9/F9,"") | M9: =IFERROR(H9/F9,"") | N9: =IF($A9="","",MAX(0,G9-H9)) | O9: =IF($A9="","",IF(H9=0,"NO VALID SURVEY",IF(H9<5,"LOW SAMPLE","OK"))) | P9: =IF($A9="","",COUNTIFS(tblPCSInput[Call Date/Time],">="&(SETUP!$B$6),tblPCSInput[Call Date/Time],"<"&(SETUP!$B$7),tblPCSInput[Call Direction],"I",tblPCSInput[Agent ID],$A9,tblPCSInput[PCSStatus],1)) | Q9: =IF($A9="","",COUNTIFS(tblPCSInput[Call Date/Time],">="&(SETUP!$B$6),tblPCSInput[Call Date/Time],"<"&(SETUP!$B$7),tblPCSInput[Call Direction],"I",tblPCSInput[Agent ID],$A9,tblPCSInput[Question 1],"<>")) | R9: =IF($A9="","",COUNTIFS(tblPCSInput[Call Date/Time],">="&(SETUP!$B$6),tblPCSInput[Call Date/Time],"<"&(SETUP!$B$7),tblPCSInput[Call Direction],"I",tblPCSInput[Agent ID],$A9,tblPCSInput[Valid Q1],">=1")) | S9: =IFERROR(SUMIFS(tblPCSInput[Valid Q1],tblPCSInput[Call Date/Time],">="&SETUP!$B$6,tblPCSInput[Call Date/Time],"<"&SETUP!$B$7,tblPCSInput[Call Direction],"I",tblPCSInput[Agent ID],$A9)/COUNTIFS(tblPCSInput[Call Date/Time],">="&(SETUP!$B$6),tblPCSInput[Call Date/Time],"<"&(SETUP!$B$7),tblPCSInput[Call Direction],"I",tblPCSInput[Agent ID],$A9,tblPCSInput[Valid Q1],">=1"),"") | T9: =IF(S9="","",COUNTIFS(tblPCSInput[Call Date/Time],">="&(SETUP!$B$6),tblPCSInput[Call Date/Time],"<"&(SETUP!$B$7),tblPCSInput[Call Direction],"I",tblPCSInput[Agent ID],$A9,tblPCSInput[Valid Q1],"<=3",tblPCSInput[Valid Q1],">=1")) | U9: =IF(S9="","",COUNTIFS(tblPCSInput[Call Date/Time],">="&(SETUP!$B$6),tblPCSInput[Call Date/Time],"<"&(SETUP!$B$7),tblPCSInput[Call Direction],"I",tblPCSInput[Agent ID],$A9,tblPCSInput[Valid Q1],">3")) | V9: =IFERROR(Q9/P9,"") | W9: =IFERROR(R9/P9,"")
A10: =IF(ROSTER!A10="","",ROSTER!A10) -> 199554 | B10: =IF($A10="","",ROSTER!C10) -> Ez-Zouaghi Amira | C10: =IF($A10="","",ROSTER!D10) -> Farouk BOUAZZAOUI | D10: =IF($A10="","",ROSTER!E10) -> Anas OUAKKAD | E10: =IF($A10="","",ROSTER!F10) -> RSA FR | F10: =IF($A10="","",COUNTIFS(tblPCSInput[Call Date/Time],">="&(SETUP!$B$5),tblPCSInput[Call Date/Time],"<"&(SETUP!$B$5+1),tblPCSInput[Call Direction],"I",tblPCSInput[Agent ID],$A10,tblPCSInput[PCSStatus],1)) | G10: =IF($A10="","",COUNTIFS(tblPCSInput[Call Date/Time],">="&(SETUP!$B$5),tblPCSInput[Call Date/Time],"<"&(SETUP!$B$5+1),tblPCSInput[Call Direction],"I",tblPCSInput[Agent ID],$A10,tblPCSInput[Question 1],"<>")) | H10: =IF($A10="","",COUNTIFS(tblPCSInput[Call Date/Time],">="&(SETUP!$B$5),tblPCSInput[Call Date/Time],"<"&(SETUP!$B$5+1),tblPCSInput[Call Direction],"I",tblPCSInput[Agent ID],$A10,tblPCSInput[Valid Q1],">=1")) | I10: =IFERROR(SUMIFS(tblPCSInput[Valid Q1],tblPCSInput[Call Date/Time],">="&SETUP!$B$5,tblPCSInput[Call Date/Time],"<"&SETUP!$B$5+1,tblPCSInput[Call Direction],"I",tblPCSInput[Agent ID],$A10)/COUNTIFS(tblPCSInput[Call Date/Time],">="&(SETUP!$B$5),tblPCSInput[Call Date/Time],"<"&(SETUP!$B$5+1),tblPCSInput[Call Direction],"I",tblPCSInput[Agent ID],$A10,tblPCSInput[Valid Q1],">=1"),"") | J10: =IF(I10="","",COUNTIFS(tblPCSInput[Call Date/Time],">="&(SETUP!$B$5),tblPCSInput[Call Date/Time],"<"&(SETUP!$B$5+1),tblPCSInput[Call Direction],"I",tblPCSInput[Agent ID],$A10,tblPCSInput[Valid Q1],"<=3",tblPCSInput[Valid Q1],">=1")) | K10: =IF(I10="","",COUNTIFS(tblPCSInput[Call Date/Time],">="&(SETUP!$B$5),tblPCSInput[Call Date/Time],"<"&(SETUP!$B$5+1),tblPCSInput[Call Direction],"I",tblPCSInput[Agent ID],$A10,tblPCSInput[Valid Q1],">3")) | L10: =IFERROR(G10/F10,"") | M10: =IFERROR(H10/F10,"") | N10: =IF($A10="","",MAX(0,G10-H10)) | O10: =IF($A10="","",IF(H10=0,"NO VALID SURVEY",IF(H10<5,"LOW SAMPLE","OK"))) | P10: =IF($A10="","",COUNTIFS(tblPCSInput[Call Date/Time],">="&(SETUP!$B$6),tblPCSInput[Call Date/Time],"<"&(SETUP!$B$7),tblPCSInput[Call Direction],"I",tblPCSInput[Agent ID],$A10,tblPCSInput[PCSStatus],1)) | Q10: =IF($A10="","",COUNTIFS(tblPCSInput[Call Date/Time],">="&(SETUP!$B$6),tblPCSInput[Call Date/Time],"<"&(SETUP!$B$7),tblPCSInput[Call Direction],"I",tblPCSInput[Agent ID],$A10,tblPCSInput[Question 1],"<>")) | R10: =IF($A10="","",COUNTIFS(tblPCSInput[Call Date/Time],">="&(SETUP!$B$6),tblPCSInput[Call Date/Time],"<"&(SETUP!$B$7),tblPCSInput[Call Direction],"I",tblPCSInput[Agent ID],$A10,tblPCSInput[Valid Q1],">=1")) | S10: =IFERROR(SUMIFS(tblPCSInput[Valid Q1],tblPCSInput[Call Date/Time],">="&SETUP!$B$6,tblPCSInput[Call Date/Time],"<"&SETUP!$B$7,tblPCSInput[Call Direction],"I",tblPCSInput[Agent ID],$A10)/COUNTIFS(tblPCSInput[Call Date/Time],">="&(SETUP!$B$6),tblPCSInput[Call Date/Time],"<"&(SETUP!$B$7),tblPCSInput[Call Direction],"I",tblPCSInput[Agent ID],$A10,tblPCSInput[Valid Q1],">=1"),"") | T10: =IF(S10="","",COUNTIFS(tblPCSInput[Call Date/Time],">="&(SETUP!$B$6),tblPCSInput[Call Date/Time],"<"&(SETUP!$B$7),tblPCSInput[Call Direction],"I",tblPCSInput[Agent ID],$A10,tblPCSInput[Valid Q1],"<=3",tblPCSInput[Valid Q1],">=1")) | U10: =IF(S10="","",COUNTIFS(tblPCSInput[Call Date/Time],">="&(SETUP!$B$6),tblPCSInput[Call Date/Time],"<"&(SETUP!$B$7),tblPCSInput[Call Direction],"I",tblPCSInput[Agent ID],$A10,tblPCSInput[Valid Q1],">3")) | V10: =IFERROR(Q10/P10,"") | W10: =IFERROR(R10/P10,"")
A11: =IF(ROSTER!A11="","",ROSTER!A11) -> 203080 | B11: =IF($A11="","",ROSTER!C11) -> Lamtibbou Nizar | C11: =IF($A11="","",ROSTER!D11) -> Farouk BOUAZZAOUI | D11: =IF($A11="","",ROSTER!E11) -> Anas OUAKKAD | E11: =IF($A11="","",ROSTER!F11) -> RSA FR | F11: =IF($A11="","",COUNTIFS(tblPCSInput[Call Date/Time],">="&(SETUP!$B$5),tblPCSInput[Call Date/Time],"<"&(SETUP!$B$5+1),tblPCSInput[Call Direction],"I",tblPCSInput[Agent ID],$A11,tblPCSInput[PCSStatus],1)) | G11: =IF($A11="","",COUNTIFS(tblPCSInput[Call Date/Time],">="&(SETUP!$B$5),tblPCSInput[Call Date/Time],"<"&(SETUP!$B$5+1),tblPCSInput[Call Direction],"I",tblPCSInput[Agent ID],$A11,tblPCSInput[Question 1],"<>")) | H11: =IF($A11="","",COUNTIFS(tblPCSInput[Call Date/Time],">="&(SETUP!$B$5),tblPCSInput[Call Date/Time],"<"&(SETUP!$B$5+1),tblPCSInput[Call Direction],"I",tblPCSInput[Agent ID],$A11,tblPCSInput[Valid Q1],">=1")) | I11: =IFERROR(SUMIFS(tblPCSInput[Valid Q1],tblPCSInput[Call Date/Time],">="&SETUP!$B$5,tblPCSInput[Call Date/Time],"<"&SETUP!$B$5+1,tblPCSInput[Call Direction],"I",tblPCSInput[Agent ID],$A11)/COUNTIFS(tblPCSInput[Call Date/Time],">="&(SETUP!$B$5),tblPCSInput[Call Date/Time],"<"&(SETUP!$B$5+1),tblPCSInput[Call Direction],"I",tblPCSInput[Agent ID],$A11,tblPCSInput[Valid Q1],">=1"),"") | J11: =IF(I11="","",COUNTIFS(tblPCSInput[Call Date/Time],">="&(SETUP!$B$5),tblPCSInput[Call Date/Time],"<"&(SETUP!$B$5+1),tblPCSInput[Call Direction],"I",tblPCSInput[Agent ID],$A11,tblPCSInput[Valid Q1],"<=3",tblPCSInput[Valid Q1],">=1")) | K11: =IF(I11="","",COUNTIFS(tblPCSInput[Call Date/Time],">="&(SETUP!$B$5),tblPCSInput[Call Date/Time],"<"&(SETUP!$B$5+1),tblPCSInput[Call Direction],"I",tblPCSInput[Agent ID],$A11,tblPCSInput[Valid Q1],">3")) | L11: =IFERROR(G11/F11,"") | M11: =IFERROR(H11/F11,"") | N11: =IF($A11="","",MAX(0,G11-H11)) | O11: =IF($A11="","",IF(H11=0,"NO VALID SURVEY",IF(H11<5,"LOW SAMPLE","OK"))) | P11: =IF($A11="","",COUNTIFS(tblPCSInput[Call Date/Time],">="&(SETUP!$B$6),tblPCSInput[Call Date/Time],"<"&(SETUP!$B$7),tblPCSInput[Call Direction],"I",tblPCSInput[Agent ID],$A11,tblPCSInput[PCSStatus],1)) | Q11: =IF($A11="","",COUNTIFS(tblPCSInput[Call Date/Time],">="&(SETUP!$B$6),tblPCSInput[Call Date/Time],"<"&(SETUP!$B$7),tblPCSInput[Call Direction],"I",tblPCSInput[Agent ID],$A11,tblPCSInput[Question 1],"<>")) | R11: =IF($A11="","",COUNTIFS(tblPCSInput[Call Date/Time],">="&(SETUP!$B$6),tblPCSInput[Call Date/Time],"<"&(SETUP!$B$7),tblPCSInput[Call Direction],"I",tblPCSInput[Agent ID],$A11,tblPCSInput[Valid Q1],">=1")) | S11: =IFERROR(SUMIFS(tblPCSInput[Valid Q1],tblPCSInput[Call Date/Time],">="&SETUP!$B$6,tblPCSInput[Call Date/Time],"<"&SETUP!$B$7,tblPCSInput[Call Direction],"I",tblPCSInput[Agent ID],$A11)/COUNTIFS(tblPCSInput[Call Date/Time],">="&(SETUP!$B$6),tblPCSInput[Call Date/Time],"<"&(SETUP!$B$7),tblPCSInput[Call Direction],"I",tblPCSInput[Agent ID],$A11,tblPCSInput[Valid Q1],">=1"),"") | T11: =IF(S11="","",COUNTIFS(tblPCSInput[Call Date/Time],">="&(SETUP!$B$6),tblPCSInput[Call Date/Time],"<"&(SETUP!$B$7),tblPCSInput[Call Direction],"I",tblPCSInput[Agent ID],$A11,tblPCSInput[Valid Q1],"<=3",tblPCSInput[Valid Q1],">=1")) | U11: =IF(S11="","",COUNTIFS(tblPCSInput[Call Date/Time],">="&(SETUP!$B$6),tblPCSInput[Call Date/Time],"<"&(SETUP!$B$7),tblPCSInput[Call Direction],"I",tblPCSInput[Agent ID],$A11,tblPCSInput[Valid Q1],">3")) | V11: =IFERROR(Q11/P11,"") | W11: =IFERROR(R11/P11,"")
A12: =IF(ROSTER!A12="","",ROSTER!A12) -> 203079 | B12: =IF($A12="","",ROSTER!C12) -> Ghali Haddad | C12: =IF($A12="","",ROSTER!D12) -> Farouk BOUAZZAOUI | D12: =IF($A12="","",ROSTER!E12) -> Anas OUAKKAD | E12: =IF($A12="","",ROSTER!F12) -> RSA FR | F12: =IF($A12="","",COUNTIFS(tblPCSInput[Call Date/Time],">="&(SETUP!$B$5),tblPCSInput[Call Date/Time],"<"&(SETUP!$B$5+1),tblPCSInput[Call Direction],"I",tblPCSInput[Agent ID],$A12,tblPCSInput[PCSStatus],1)) | G12: =IF($A12="","",COUNTIFS(tblPCSInput[Call Date/Time],">="&(SETUP!$B$5),tblPCSInput[Call Date/Time],"<"&(SETUP!$B$5+1),tblPCSInput[Call Direction],"I",tblPCSInput[Agent ID],$A12,tblPCSInput[Question 1],"<>")) | H12: =IF($A12="","",COUNTIFS(tblPCSInput[Call Date/Time],">="&(SETUP!$B$5),tblPCSInput[Call Date/Time],"<"&(SETUP!$B$5+1),tblPCSInput[Call Direction],"I",tblPCSInput[Agent ID],$A12,tblPCSInput[Valid Q1],">=1")) | I12: =IFERROR(SUMIFS(tblPCSInput[Valid Q1],tblPCSInput[Call Date/Time],">="&SETUP!$B$5,tblPCSInput[Call Date/Time],"<"&SETUP!$B$5+1,tblPCSInput[Call Direction],"I",tblPCSInput[Agent ID],$A12)/COUNTIFS(tblPCSInput[Call Date/Time],">="&(SETUP!$B$5),tblPCSInput[Call Date/Time],"<"&(SETUP!$B$5+1),tblPCSInput[Call Direction],"I",tblPCSInput[Agent ID],$A12,tblPCSInput[Valid Q1],">=1"),"") | J12: =IF(I12="","",COUNTIFS(tblPCSInput[Call Date/Time],">="&(SETUP!$B$5),tblPCSInput[Call Date/Time],"<"&(SETUP!$B$5+1),tblPCSInput[Call Direction],"I",tblPCSInput[Agent ID],$A12,tblPCSInput[Valid Q1],"<=3",tblPCSInput[Valid Q1],">=1")) | K12: =IF(I12="","",COUNTIFS(tblPCSInput[Call Date/Time],">="&(SETUP!$B$5),tblPCSInput[Call Date/Time],"<"&(SETUP!$B$5+1),tblPCSInput[Call Direction],"I",tblPCSInput[Agent ID],$A12,tblPCSInput[Valid Q1],">3")) | L12: =IFERROR(G12/F12,"") | M12: =IFERROR(H12/F12,"") | N12: =IF($A12="","",MAX(0,G12-H12)) | O12: =IF($A12="","",IF(H12=0,"NO VALID SURVEY",IF(H12<5,"LOW SAMPLE","OK"))) | P12: =IF($A12="","",COUNTIFS(tblPCSInput[Call Date/Time],">="&(SETUP!$B$6),tblPCSInput[Call Date/Time],"<"&(SETUP!$B$7),tblPCSInput[Call Direction],"I",tblPCSInput[Agent ID],$A12,tblPCSInput[PCSStatus],1)) | Q12: =IF($A12="","",COUNTIFS(tblPCSInput[Call Date/Time],">="&(SETUP!$B$6),tblPCSInput[Call Date/Time],"<"&(SETUP!$B$7),tblPCSInput[Call Direction],"I",tblPCSInput[Agent ID],$A12,tblPCSInput[Question 1],"<>")) | R12: =IF($A12="","",COUNTIFS(tblPCSInput[Call Date/Time],">="&(SETUP!$B$6),tblPCSInput[Call Date/Time],"<"&(SETUP!$B$7),tblPCSInput[Call Direction],"I",tblPCSInput[Agent ID],$A12,tblPCSInput[Valid Q1],">=1")) | S12: =IFERROR(SUMIFS(tblPCSInput[Valid Q1],tblPCSInput[Call Date/Time],">="&SETUP!$B$6,tblPCSInput[Call Date/Time],"<"&SETUP!$B$7,tblPCSInput[Call Direction],"I",tblPCSInput[Agent ID],$A12)/COUNTIFS(tblPCSInput[Call Date/Time],">="&(SETUP!$B$6),tblPCSInput[Call Date/Time],"<"&(SETUP!$B$7),tblPCSInput[Call Direction],"I",tblPCSInput[Agent ID],$A12,tblPCSInput[Valid Q1],">=1"),"") | T12: =IF(S12="","",COUNTIFS(tblPCSInput[Call Date/Time],">="&(SETUP!$B$6),tblPCSInput[Call Date/Time],"<"&(SETUP!$B$7),tblPCSInput[Call Direction],"I",tblPCSInput[Agent ID],$A12,tblPCSInput[Valid Q1],"<=3",tblPCSInput[Valid Q1],">=1")) | U12: =IF(S12="","",COUNTIFS(tblPCSInput[Call Date/Time],">="&(SETUP!$B$6),tblPCSInput[Call Date/Time],"<"&(SETUP!$B$7),tblPCSInput[Call Direction],"I",tblPCSInput[Agent ID],$A12,tblPCSInput[Valid Q1],">3")) | V12: =IFERROR(Q12/P12,"") | W12: =IFERROR(R12/P12,"")
A13: =IF(ROSTER!A13="","",ROSTER!A13) -> 207437 | B13: =IF($A13="","",ROSTER!C13) -> Taha Aboulhaoul | C13: =IF($A13="","",ROSTER!D13) -> Farouk BOUAZZAOUI | D13: =IF($A13="","",ROSTER!E13) -> Anas OUAKKAD | E13: =IF($A13="","",ROSTER!F13) -> RSA FR | F13: =IF($A13="","",COUNTIFS(tblPCSInput[Call Date/Time],">="&(SETUP!$B$5),tblPCSInput[Call Date/Time],"<"&(SETUP!$B$5+1),tblPCSInput[Call Direction],"I",tblPCSInput[Agent ID],$A13,tblPCSInput[PCSStatus],1)) | G13: =IF($A13="","",COUNTIFS(tblPCSInput[Call Date/Time],">="&(SETUP!$B$5),tblPCSInput[Call Date/Time],"<"&(SETUP!$B$5+1),tblPCSInput[Call Direction],"I",tblPCSInput[Agent ID],$A13,tblPCSInput[Question 1],"<>")) | H13: =IF($A13="","",COUNTIFS(tblPCSInput[Call Date/Time],">="&(SETUP!$B$5),tblPCSInput[Call Date/Time],"<"&(SETUP!$B$5+1),tblPCSInput[Call Direction],"I",tblPCSInput[Agent ID],$A13,tblPCSInput[Valid Q1],">=1")) | I13: =IFERROR(SUMIFS(tblPCSInput[Valid Q1],tblPCSInput[Call Date/Time],">="&SETUP!$B$5,tblPCSInput[Call Date/Time],"<"&SETUP!$B$5+1,tblPCSInput[Call Direction],"I",tblPCSInput[Agent ID],$A13)/COUNTIFS(tblPCSInput[Call Date/Time],">="&(SETUP!$B$5),tblPCSInput[Call Date/Time],"<"&(SETUP!$B$5+1),tblPCSInput[Call Direction],"I",tblPCSInput[Agent ID],$A13,tblPCSInput[Valid Q1],">=1"),"") | J13: =IF(I13="","",COUNTIFS(tblPCSInput[Call Date/Time],">="&(SETUP!$B$5),tblPCSInput[Call Date/Time],"<"&(SETUP!$B$5+1),tblPCSInput[Call Direction],"I",tblPCSInput[Agent ID],$A13,tblPCSInput[Valid Q1],"<=3",tblPCSInput[Valid Q1],">=1")) | K13: =IF(I13="","",COUNTIFS(tblPCSInput[Call Date/Time],">="&(SETUP!$B$5),tblPCSInput[Call Date/Time],"<"&(SETUP!$B$5+1),tblPCSInput[Call Direction],"I",tblPCSInput[Agent ID],$A13,tblPCSInput[Valid Q1],">3")) | L13: =IFERROR(G13/F13,"") | M13: =IFERROR(H13/F13,"") | N13: =IF($A13="","",MAX(0,G13-H13)) | O13: =IF($A13="","",IF(H13=0,"NO VALID SURVEY",IF(H13<5,"LOW SAMPLE","OK"))) | P13: =IF($A13="","",COUNTIFS(tblPCSInput[Call Date/Time],">="&(SETUP!$B$6),tblPCSInput[Call Date/Time],"<"&(SETUP!$B$7),tblPCSInput[Call Direction],"I",tblPCSInput[Agent ID],$A13,tblPCSInput[PCSStatus],1)) | Q13: =IF($A13="","",COUNTIFS(tblPCSInput[Call Date/Time],">="&(SETUP!$B$6),tblPCSInput[Call Date/Time],"<"&(SETUP!$B$7),tblPCSInput[Call Direction],"I",tblPCSInput[Agent ID],$A13,tblPCSInput[Question 1],"<>")) | R13: =IF($A13="","",COUNTIFS(tblPCSInput[Call Date/Time],">="&(SETUP!$B$6),tblPCSInput[Call Date/Time],"<"&(SETUP!$B$7),tblPCSInput[Call Direction],"I",tblPCSInput[Agent ID],$A13,tblPCSInput[Valid Q1],">=1")) | S13: =IFERROR(SUMIFS(tblPCSInput[Valid Q1],tblPCSInput[Call Date/Time],">="&SETUP!$B$6,tblPCSInput[Call Date/Time],"<"&SETUP!$B$7,tblPCSInput[Call Direction],"I",tblPCSInput[Agent ID],$A13)/COUNTIFS(tblPCSInput[Call Date/Time],">="&(SETUP!$B$6),tblPCSInput[Call Date/Time],"<"&(SETUP!$B$7),tblPCSInput[Call Direction],"I",tblPCSInput[Agent ID],$A13,tblPCSInput[Valid Q1],">=1"),"") | T13: =IF(S13="","",COUNTIFS(tblPCSInput[Call Date/Time],">="&(SETUP!$B$6),tblPCSInput[Call Date/Time],"<"&(SETUP!$B$7),tblPCSInput[Call Direction],"I",tblPCSInput[Agent ID],$A13,tblPCSInput[Valid Q1],"<=3",tblPCSInput[Valid Q1],">=1")) | U13: =IF(S13="","",COUNTIFS(tblPCSInput[Call Date/Time],">="&(SETUP!$B$6),tblPCSInput[Call Date/Time],"<"&(SETUP!$B$7),tblPCSInput[Call Direction],"I",tblPCSInput[Agent ID],$A13,tblPCSInput[Valid Q1],">3")) | V13: =IFERROR(Q13/P13,"") | W13: =IFERROR(R13/P13,"")
A14: =IF(ROSTER!A14="","",ROSTER!A14) -> 96491 | B14: =IF($A14="","",ROSTER!C14) -> AHLAL Ainane | C14: =IF($A14="","",ROSTER!D14) -> Adil LAGRAOUI | D14: =IF($A14="","",ROSTER!E14) -> Anas OUAKKAD | E14: =IF($A14="","",ROSTER!F14) -> RSA NL | F14: =IF($A14="","",COUNTIFS(tblPCSInput[Call Date/Time],">="&(SETUP!$B$5),tblPCSInput[Call Date/Time],"<"&(SETUP!$B$5+1),tblPCSInput[Call Direction],"I",tblPCSInput[Agent ID],$A14,tblPCSInput[PCSStatus],1)) | G14: =IF($A14="","",COUNTIFS(tblPCSInput[Call Date/Time],">="&(SETUP!$B$5),tblPCSInput[Call Date/Time],"<"&(SETUP!$B$5+1),tblPCSInput[Call Direction],"I",tblPCSInput[Agent ID],$A14,tblPCSInput[Question 1],"<>")) | H14: =IF($A14="","",COUNTIFS(tblPCSInput[Call Date/Time],">="&(SETUP!$B$5),tblPCSInput[Call Date/Time],"<"&(SETUP!$B$5+1),tblPCSInput[Call Direction],"I",tblPCSInput[Agent ID],$A14,tblPCSInput[Valid Q1],">=1")) | I14: =IFERROR(SUMIFS(tblPCSInput[Valid Q1],tblPCSInput[Call Date/Time],">="&SETUP!$B$5,tblPCSInput[Call Date/Time],"<"&SETUP!$B$5+1,tblPCSInput[Call Direction],"I",tblPCSInput[Agent ID],$A14)/COUNTIFS(tblPCSInput[Call Date/Time],">="&(SETUP!$B$5),tblPCSInput[Call Date/Time],"<"&(SETUP!$B$5+1),tblPCSInput[Call Direction],"I",tblPCSInput[Agent ID],$A14,tblPCSInput[Valid Q1],">=1"),"") | J14: =IF(I14="","",COUNTIFS(tblPCSInput[Call Date/Time],">="&(SETUP!$B$5),tblPCSInput[Call Date/Time],"<"&(SETUP!$B$5+1),tblPCSInput[Call Direction],"I",tblPCSInput[Agent ID],$A14,tblPCSInput[Valid Q1],"<=3",tblPCSInput[Valid Q1],">=1")) | K14: =IF(I14="","",COUNTIFS(tblPCSInput[Call Date/Time],">="&(SETUP!$B$5),tblPCSInput[Call Date/Time],"<"&(SETUP!$B$5+1),tblPCSInput[Call Direction],"I",tblPCSInput[Agent ID],$A14,tblPCSInput[Valid Q1],">3")) | L14: =IFERROR(G14/F14,"") | M14: =IFERROR(H14/F14,"") | N14: =IF($A14="","",MAX(0,G14-H14)) | O14: =IF($A14="","",IF(H14=0,"NO VALID SURVEY",IF(H14<5,"LOW SAMPLE","OK"))) | P14: =IF($A14="","",COUNTIFS(tblPCSInput[Call Date/Time],">="&(SETUP!$B$6),tblPCSInput[Call Date/Time],"<"&(SETUP!$B$7),tblPCSInput[Call Direction],"I",tblPCSInput[Agent ID],$A14,tblPCSInput[PCSStatus],1)) | Q14: =IF($A14="","",COUNTIFS(tblPCSInput[Call Date/Time],">="&(SETUP!$B$6),tblPCSInput[Call Date/Time],"<"&(SETUP!$B$7),tblPCSInput[Call Direction],"I",tblPCSInput[Agent ID],$A14,tblPCSInput[Question 1],"<>")) | R14: =IF($A14="","",COUNTIFS(tblPCSInput[Call Date/Time],">="&(SETUP!$B$6),tblPCSInput[Call Date/Time],"<"&(SETUP!$B$7),tblPCSInput[Call Direction],"I",tblPCSInput[Agent ID],$A14,tblPCSInput[Valid Q1],">=1")) | S14: =IFERROR(SUMIFS(tblPCSInput[Valid Q1],tblPCSInput[Call Date/Time],">="&SETUP!$B$6,tblPCSInput[Call Date/Time],"<"&SETUP!$B$7,tblPCSInput[Call Direction],"I",tblPCSInput[Agent ID],$A14)/COUNTIFS(tblPCSInput[Call Date/Time],">="&(SETUP!$B$6),tblPCSInput[Call Date/Time],"<"&(SETUP!$B$7),tblPCSInput[Call Direction],"I",tblPCSInput[Agent ID],$A14,tblPCSInput[Valid Q1],">=1"),"") | T14: =IF(S14="","",COUNTIFS(tblPCSInput[Call Date/Time],">="&(SETUP!$B$6),tblPCSInput[Call Date/Time],"<"&(SETUP!$B$7),tblPCSInput[Call Direction],"I",tblPCSInput[Agent ID],$A14,tblPCSInput[Valid Q1],"<=3",tblPCSInput[Valid Q1],">=1")) | U14: =IF(S14="","",COUNTIFS(tblPCSInput[Call Date/Time],">="&(SETUP!$B$6),tblPCSInput[Call Date/Time],"<"&(SETUP!$B$7),tblPCSInput[Call Direction],"I",tblPCSInput[Agent ID],$A14,tblPCSInput[Valid Q1],">3")) | V14: =IFERROR(Q14/P14,"") | W14: =IFERROR(R14/P14,"")
A15: =IF(ROSTER!A15="","",ROSTER!A15) -> 96500 | B15: =IF($A15="","",ROSTER!C15) -> Mejhed Asmaa | C15: =IF($A15="","",ROSTER!D15) -> Ilyasse Derrazi | D15: =IF($A15="","",ROSTER!E15) -> Anas OUAKKAD | E15: =IF($A15="","",ROSTER!F15) -> Ford Dutch | F15: =IF($A15="","",COUNTIFS(tblPCSInput[Call Date/Time],">="&(SETUP!$B$5),tblPCSInput[Call Date/Time],"<"&(SETUP!$B$5+1),tblPCSInput[Call Direction],"I",tblPCSInput[Agent ID],$A15,tblPCSInput[PCSStatus],1)) | G15: =IF($A15="","",COUNTIFS(tblPCSInput[Call Date/Time],">="&(SETUP!$B$5),tblPCSInput[Call Date/Time],"<"&(SETUP!$B$5+1),tblPCSInput[Call Direction],"I",tblPCSInput[Agent ID],$A15,tblPCSInput[Question 1],"<>")) | H15: =IF($A15="","",COUNTIFS(tblPCSInput[Call Date/Time],">="&(SETUP!$B$5),tblPCSInput[Call Date/Time],"<"&(SETUP!$B$5+1),tblPCSInput[Call Direction],"I",tblPCSInput[Agent ID],$A15,tblPCSInput[Valid Q1],">=1")) | I15: =IFERROR(SUMIFS(tblPCSInput[Valid Q1],tblPCSInput[Call Date/Time],">="&SETUP!$B$5,tblPCSInput[Call Date/Time],"<"&SETUP!$B$5+1,tblPCSInput[Call Direction],"I",tblPCSInput[Agent ID],$A15)/COUNTIFS(tblPCSInput[Call Date/Time],">="&(SETUP!$B$5),tblPCSInput[Call Date/Time],"<"&(SETUP!$B$5+1),tblPCSInput[Call Direction],"I",tblPCSInput[Agent ID],$A15,tblPCSInput[Valid Q1],">=1"),"") | J15: =IF(I15="","",COUNTIFS(tblPCSInput[Call Date/Time],">="&(SETUP!$B$5),tblPCSInput[Call Date/Time],"<"&(SETUP!$B$5+1),tblPCSInput[Call Direction],"I",tblPCSInput[Agent ID],$A15,tblPCSInput[Valid Q1],"<=3",tblPCSInput[Valid Q1],">=1")) | K15: =IF(I15="","",COUNTIFS(tblPCSInput[Call Date/Time],">="&(SETUP!$B$5),tblPCSInput[Call Date/Time],"<"&(SETUP!$B$5+1),tblPCSInput[Call Direction],"I",tblPCSInput[Agent ID],$A15,tblPCSInput[Valid Q1],">3")) | L15: =IFERROR(G15/F15,"") | M15: =IFERROR(H15/F15,"") | N15: =IF($A15="","",MAX(0,G15-H15)) | O15: =IF($A15="","",IF(H15=0,"NO VALID SURVEY",IF(H15<5,"LOW SAMPLE","OK"))) | P15: =IF($A15="","",COUNTIFS(tblPCSInput[Call Date/Time],">="&(SETUP!$B$6),tblPCSInput[Call Date/Time],"<"&(SETUP!$B$7),tblPCSInput[Call Direction],"I",tblPCSInput[Agent ID],$A15,tblPCSInput[PCSStatus],1)) | Q15: =IF($A15="","",COUNTIFS(tblPCSInput[Call Date/Time],">="&(SETUP!$B$6),tblPCSInput[Call Date/Time],"<"&(SETUP!$B$7),tblPCSInput[Call Direction],"I",tblPCSInput[Agent ID],$A15,tblPCSInput[Question 1],"<>")) | R15: =IF($A15="","",COUNTIFS(tblPCSInput[Call Date/Time],">="&(SETUP!$B$6),tblPCSInput[Call Date/Time],"<"&(SETUP!$B$7),tblPCSInput[Call Direction],"I",tblPCSInput[Agent ID],$A15,tblPCSInput[Valid Q1],">=1")) | S15: =IFERROR(SUMIFS(tblPCSInput[Valid Q1],tblPCSInput[Call Date/Time],">="&SETUP!$B$6,tblPCSInput[Call Date/Time],"<"&SETUP!$B$7,tblPCSInput[Call Direction],"I",tblPCSInput[Agent ID],$A15)/COUNTIFS(tblPCSInput[Call Date/Time],">="&(SETUP!$B$6),tblPCSInput[Call Date/Time],"<"&(SETUP!$B$7),tblPCSInput[Call Direction],"I",tblPCSInput[Agent ID],$A15,tblPCSInput[Valid Q1],">=1"),"") | T15: =IF(S15="","",COUNTIFS(tblPCSInput[Call Date/Time],">="&(SETUP!$B$6),tblPCSInput[Call Date/Time],"<"&(SETUP!$B$7),tblPCSInput[Call Direction],"I",tblPCSInput[Agent ID],$A15,tblPCSInput[Valid Q1],"<=3",tblPCSInput[Valid Q1],">=1")) | U15: =IF(S15="","",COUNTIFS(tblPCSInput[Call Date/Time],">="&(SETUP!$B$6),tblPCSInput[Call Date/Time],"<"&(SETUP!$B$7),tblPCSInput[Call Direction],"I",tblPCSInput[Agent ID],$A15,tblPCSInput[Valid Q1],">3")) | V15: =IFERROR(Q15/P15,"") | W15: =IFERROR(R15/P15,"")
A16: =IF(ROSTER!A16="","",ROSTER!A16) -> 199529 | B16: =IF($A16="","",ROSTER!C16) -> Ajermite Khalil | C16: =IF($A16="","",ROSTER!D16) -> Adil LAGRAOUI | D16: =IF($A16="","",ROSTER!E16) -> Anas OUAKKAD | E16: =IF($A16="","",ROSTER!F16) -> RSA NL | F16: =IF($A16="","",COUNTIFS(tblPCSInput[Call Date/Time],">="&(SETUP!$B$5),tblPCSInput[Call Date/Time],"<"&(SETUP!$B$5+1),tblPCSInput[Call Direction],"I",tblPCSInput[Agent ID],$A16,tblPCSInput[PCSStatus],1)) | G16: =IF($A16="","",COUNTIFS(tblPCSInput[Call Date/Time],">="&(SETUP!$B$5),tblPCSInput[Call Date/Time],"<"&(SETUP!$B$5+1),tblPCSInput[Call Direction],"I",tblPCSInput[Agent ID],$A16,tblPCSInput[Question 1],"<>")) | H16: =IF($A16="","",COUNTIFS(tblPCSInput[Call Date/Time],">="&(SETUP!$B$5),tblPCSInput[Call Date/Time],"<"&(SETUP!$B$5+1),tblPCSInput[Call Direction],"I",tblPCSInput[Agent ID],$A16,tblPCSInput[Valid Q1],">=1")) | I16: =IFERROR(SUMIFS(tblPCSInput[Valid Q1],tblPCSInput[Call Date/Time],">="&SETUP!$B$5,tblPCSInput[Call Date/Time],"<"&SETUP!$B$5+1,tblPCSInput[Call Direction],"I",tblPCSInput[Agent ID],$A16)/COUNTIFS(tblPCSInput[Call Date/Time],">="&(SETUP!$B$5),tblPCSInput[Call Date/Time],"<"&(SETUP!$B$5+1),tblPCSInput[Call Direction],"I",tblPCSInput[Agent ID],$A16,tblPCSInput[Valid Q1],">=1"),"") | J16: =IF(I16="","",COUNTIFS(tblPCSInput[Call Date/Time],">="&(SETUP!$B$5),tblPCSInput[Call Date/Time],"<"&(SETUP!$B$5+1),tblPCSInput[Call Direction],"I",tblPCSInput[Agent ID],$A16,tblPCSInput[Valid Q1],"<=3",tblPCSInput[Valid Q1],">=1")) | K16: =IF(I16="","",COUNTIFS(tblPCSInput[Call Date/Time],">="&(SETUP!$B$5),tblPCSInput[Call Date/Time],"<"&(SETUP!$B$5+1),tblPCSInput[Call Direction],"I",tblPCSInput[Agent ID],$A16,tblPCSInput[Valid Q1],">3")) | L16: =IFERROR(G16/F16,"") | M16: =IFERROR(H16/F16,"") | N16: =IF($A16="","",MAX(0,G16-H16)) | O16: =IF($A16="","",IF(H16=0,"NO VALID SURVEY",IF(H16<5,"LOW SAMPLE","OK"))) | P16: =IF($A16="","",COUNTIFS(tblPCSInput[Call Date/Time],">="&(SETUP!$B$6),tblPCSInput[Call Date/Time],"<"&(SETUP!$B$7),tblPCSInput[Call Direction],"I",tblPCSInput[Agent ID],$A16,tblPCSInput[PCSStatus],1)) | Q16: =IF($A16="","",COUNTIFS(tblPCSInput[Call Date/Time],">="&(SETUP!$B$6),tblPCSInput[Call Date/Time],"<"&(SETUP!$B$7),tblPCSInput[Call Direction],"I",tblPCSInput[Agent ID],$A16,tblPCSInput[Question 1],"<>")) | R16: =IF($A16="","",COUNTIFS(tblPCSInput[Call Date/Time],">="&(SETUP!$B$6),tblPCSInput[Call Date/Time],"<"&(SETUP!$B$7),tblPCSInput[Call Direction],"I",tblPCSInput[Agent ID],$A16,tblPCSInput[Valid Q1],">=1")) | S16: =IFERROR(SUMIFS(tblPCSInput[Valid Q1],tblPCSInput[Call Date/Time],">="&SETUP!$B$6,tblPCSInput[Call Date/Time],"<"&SETUP!$B$7,tblPCSInput[Call Direction],"I",tblPCSInput[Agent ID],$A16)/COUNTIFS(tblPCSInput[Call Date/Time],">="&(SETUP!$B$6),tblPCSInput[Call Date/Time],"<"&(SETUP!$B$7),tblPCSInput[Call Direction],"I",tblPCSInput[Agent ID],$A16,tblPCSInput[Valid Q1],">=1"),"") | T16: =IF(S16="","",COUNTIFS(tblPCSInput[Call Date/Time],">="&(SETUP!$B$6),tblPCSInput[Call Date/Time],"<"&(SETUP!$B$7),tblPCSInput[Call Direction],"I",tblPCSInput[Agent ID],$A16,tblPCSInput[Valid Q1],"<=3",tblPCSInput[Valid Q1],">=1")) | U16: =IF(S16="","",COUNTIFS(tblPCSInput[Call Date/Time],">="&(SETUP!$B$6),tblPCSInput[Call Date/Time],"<"&(SETUP!$B$7),tblPCSInput[Call Direction],"I",tblPCSInput[Agent ID],$A16,tblPCSInput[Valid Q1],">3")) | V16: =IFERROR(Q16/P16,"") | W16: =IFERROR(R16/P16,"")
... A304: =IF(ROSTER!A304="","",ROSTER!A304) | B304: =IF($A304="","",ROSTER!C304) | C304: =IF($A304="","",ROSTER!D304) | D304: =IF($A304="","",ROSTER!E304) | E304: =IF($A304="","",ROSTER!F304) | F304: =IF($A304="","",COUNTIFS(tblPCSInput[Call Date/Time],">="&(SETUP!$B$5),tblPCSInput[Call Date/Time],"<"&(SETUP!$B$5+1),tblPCSInput[Call Direction],"I",tblPCSInput[Agent ID],$A304,tblPCSInput[PCSStatus],1)) | G304: =IF($A304="","",COUNTIFS(tblPCSInput[Call Date/Time],">="&(SETUP!$B$5),tblPCSInput[Call Date/Time],"<"&(SETUP!$B$5+1),tblPCSInput[Call Direction],"I",tblPCSInput[Agent ID],$A304,tblPCSInput[Question 1],"<>")) | H304: =IF($A304="","",COUNTIFS(tblPCSInput[Call Date/Time],">="&(SETUP!$B$5),tblPCSInput[Call Date/Time],"<"&(SETUP!$B$5+1),tblPCSInput[Call Direction],"I",tblPCSInput[Agent ID],$A304,tblPCSInput[Valid Q1],">=1")) | I304: =IFERROR(SUMIFS(tblPCSInput[Valid Q1],tblPCSInput[Call Date/Time],">="&SETUP!$B$5,tblPCSInput[Call Date/Time],"<"&SETUP!$B$5+1,tblPCSInput[Call Direction],"I",tblPCSInput[Agent ID],$A304)/COUNTIFS(tblPCSInput[Call Date/Time],">="&(SETUP!$B$5),tblPCSInput[Call Date/Time],"<"&(SETUP!$B$5+1),tblPCSInput[Call Direction],"I",tblPCSInput[Agent ID],$A304,tblPCSInput[Valid Q1],">=1"),"") | J304: =IF(I304="","",COUNTIFS(tblPCSInput[Call Date/Time],">="&(SETUP!$B$5),tblPCSInput[Call Date/Time],"<"&(SETUP!$B$5+1),tblPCSInput[Call Direction],"I",tblPCSInput[Agent ID],$A304,tblPCSInput[Valid Q1],"<=3",tblPCSInput[Valid Q1],">=1")) | K304: =IF(I304="","",COUNTIFS(tblPCSInput[Call Date/Time],">="&(SETUP!$B$5),tblPCSInput[Call Date/Time],"<"&(SETUP!$B$5+1),tblPCSInput[Call Direction],"I",tblPCSInput[Agent ID],$A304,tblPCSInput[Valid Q1],">3")) | L304: =IFERROR(G304/F304,"") | M304: =IFERROR(H304/F304,"") | N304: =IF($A304="","",MAX(0,G304-H304)) | O304: =IF($A304="","",IF(H304=0,"NO VALID SURVEY",IF(H304<5,"LOW SAMPLE","OK"))) | P304: =IF($A304="","",COUNTIFS(tblPCSInput[Call Date/Time],">="&(SETUP!$B$6),tblPCSInput[Call Date/Time],"<"&(SETUP!$B$7),tblPCSInput[Call Direction],"I",tblPCSInput[Agent ID],$A304,tblPCSInput[PCSStatus],1)) | Q304: =IF($A304="","",COUNTIFS(tblPCSInput[Call Date/Time],">="&(SETUP!$B$6),tblPCSInput[Call Date/Time],"<"&(SETUP!$B$7),tblPCSInput[Call Direction],"I",tblPCSInput[Agent ID],$A304,tblPCSInput[Question 1],"<>")) | R304: =IF($A304="","",COUNTIFS(tblPCSInput[Call Date/Time],">="&(SETUP!$B$6),tblPCSInput[Call Date/Time],"<"&(SETUP!$B$7),tblPCSInput[Call Direction],"I",tblPCSInput[Agent ID],$A304,tblPCSInput[Valid Q1],">=1")) | S304: =IFERROR(SUMIFS(tblPCSInput[Valid Q1],tblPCSInput[Call Date/Time],">="&SETUP!$B$6,tblPCSInput[Call Date/Time],"<"&SETUP!$B$7,tblPCSInput[Call Direction],"I",tblPCSInput[Agent ID],$A304)/COUNTIFS(tblPCSInput[Call Date/Time],">="&(SETUP!$B$6),tblPCSInput[Call Date/Time],"<"&(SETUP!$B$7),tblPCSInput[Call Direction],"I",tblPCSInput[Agent ID],$A304,tblPCSInput[Valid Q1],">=1"),"") | T304: =IF(S304="","",COUNTIFS(tblPCSInput[Call Date/Time],">="&(SETUP!$B$6),tblPCSInput[Call Date/Time],"<"&(SETUP!$B$7),tblPCSInput[Call Direction],"I",tblPCSInput[Agent ID],$A304,tblPCSInput[Valid Q1],"<=3",tblPCSInput[Valid Q1],">=1")) | U304: =IF(S304="","",COUNTIFS(tblPCSInput[Call Date/Time],">="&(SETUP!$B$6),tblPCSInput[Call Date/Time],"<"&(SETUP!$B$7),tblPCSInput[Call Direction],"I",tblPCSInput[Agent ID],$A304,tblPCSInput[Valid Q1],">3")) | V304: =IFERROR(Q304/P304,"") | W304: =IFERROR(R304/P304,"")

Sheet LOB_SUMMARY
A1: PCS by LOB
A2: Ratios are calculated from summed counters; agent averages are never averaged together.
A4: LOB | B4: Eligible Calls Day | C4: Q1 Nonblank Day | D4: Valid Q1 Day | E4: PCS Average Day | F4: <=3 Day | G4: >3 Day | H4: PCS Participation Day | I4: Valid Response Day | J4: Eligible Calls 3H | K4: Valid Q1 3H | L4: PCS Average 3H | M4: PCS Participation 3H | N4: Valid Response 3H | O4: Sample Flag
A5: Ford Dutch | B5: =IF($A5="","",SUMIFS(tblPCSAgent[Eligible Calls Day],tblPCSAgent[LOB],$A5)) | C5: =IF($A5="","",SUMIFS(tblPCSAgent[Q1 Nonblank Day],tblPCSAgent[LOB],$A5)) | D5: =IF($A5="","",SUMIFS(tblPCSAgent[Valid Q1 Day],tblPCSAgent[LOB],$A5)) | E5: =IFERROR(SUMPRODUCT((tblPCSAgent[LOB]=$A5)*tblPCSAgent[Valid Q1 Day]*tblPCSAgent[PCS Average Day])/D5,"") | F5: =IF($A5="","",SUMIFS(tblPCSAgent[<=3 Day],tblPCSAgent[LOB],$A5)) | G5: =IF($A5="","",SUMIFS(tblPCSAgent[>3 Day],tblPCSAgent[LOB],$A5)) | H5: =IFERROR(C5/B5,"") | I5: =IFERROR(D5/B5,"") | J5: =IF($A5="","",SUMIFS(tblPCSAgent[Eligible Calls 3H],tblPCSAgent[LOB],$A5)) | K5: =IF($A5="","",SUMIFS(tblPCSAgent[Valid Q1 3H],tblPCSAgent[LOB],$A5)) | L5: =IFERROR(SUMPRODUCT((tblPCSAgent[LOB]=$A5)*tblPCSAgent[Valid Q1 3H]*tblPCSAgent[PCS Average 3H])/K5,"") | M5: =IFERROR(SUMIFS(tblPCSAgent[Q1 Nonblank 3H],tblPCSAgent[LOB],$A5)/J5,"") | N5: =IFERROR(K5/J5,"") | O5: =IF($A5="","",IF(K5=0,"NO VALID SURVEY",IF(K5<20,"LOW SAMPLE","OK")))
A6: OEM FR | B6: =IF($A6="","",SUMIFS(tblPCSAgent[Eligible Calls Day],tblPCSAgent[LOB],$A6)) | C6: =IF($A6="","",SUMIFS(tblPCSAgent[Q1 Nonblank Day],tblPCSAgent[LOB],$A6)) | D6: =IF($A6="","",SUMIFS(tblPCSAgent[Valid Q1 Day],tblPCSAgent[LOB],$A6)) | E6: =IFERROR(SUMPRODUCT((tblPCSAgent[LOB]=$A6)*tblPCSAgent[Valid Q1 Day]*tblPCSAgent[PCS Average Day])/D6,"") | F6: =IF($A6="","",SUMIFS(tblPCSAgent[<=3 Day],tblPCSAgent[LOB],$A6)) | G6: =IF($A6="","",SUMIFS(tblPCSAgent[>3 Day],tblPCSAgent[LOB],$A6)) | H6: =IFERROR(C6/B6,"") | I6: =IFERROR(D6/B6,"") | J6: =IF($A6="","",SUMIFS(tblPCSAgent[Eligible Calls 3H],tblPCSAgent[LOB],$A6)) | K6: =IF($A6="","",SUMIFS(tblPCSAgent[Valid Q1 3H],tblPCSAgent[LOB],$A6)) | L6: =IFERROR(SUMPRODUCT((tblPCSAgent[LOB]=$A6)*tblPCSAgent[Valid Q1 3H]*tblPCSAgent[PCS Average 3H])/K6,"") | M6: =IFERROR(SUMIFS(tblPCSAgent[Q1 Nonblank 3H],tblPCSAgent[LOB],$A6)/J6,"") | N6: =IFERROR(K6/J6,"") | O6: =IF($A6="","",IF(K6=0,"NO VALID SURVEY",IF(K6<20,"LOW SAMPLE","OK")))
A7: RSA FR | B7: =IF($A7="","",SUMIFS(tblPCSAgent[Eligible Calls Day],tblPCSAgent[LOB],$A7)) | C7: =IF($A7="","",SUMIFS(tblPCSAgent[Q1 Nonblank Day],tblPCSAgent[LOB],$A7)) | D7: =IF($A7="","",SUMIFS(tblPCSAgent[Valid Q1 Day],tblPCSAgent[LOB],$A7)) | E7: =IFERROR(SUMPRODUCT((tblPCSAgent[LOB]=$A7)*tblPCSAgent[Valid Q1 Day]*tblPCSAgent[PCS Average Day])/D7,"") | F7: =IF($A7="","",SUMIFS(tblPCSAgent[<=3 Day],tblPCSAgent[LOB],$A7)) | G7: =IF($A7="","",SUMIFS(tblPCSAgent[>3 Day],tblPCSAgent[LOB],$A7)) | H7: =IFERROR(C7/B7,"") | I7: =IFERROR(D7/B7,"") | J7: =IF($A7="","",SUMIFS(tblPCSAgent[Eligible Calls 3H],tblPCSAgent[LOB],$A7)) | K7: =IF($A7="","",SUMIFS(tblPCSAgent[Valid Q1 3H],tblPCSAgent[LOB],$A7)) | L7: =IFERROR(SUMPRODUCT((tblPCSAgent[LOB]=$A7)*tblPCSAgent[Valid Q1 3H]*tblPCSAgent[PCS Average 3H])/K7,"") | M7: =IFERROR(SUMIFS(tblPCSAgent[Q1 Nonblank 3H],tblPCSAgent[LOB],$A7)/J7,"") | N7: =IFERROR(K7/J7,"") | O7: =IF($A7="","",IF(K7=0,"NO VALID SURVEY",IF(K7<20,"LOW SAMPLE","OK")))
A8: RSA NL | B8: =IF($A8="","",SUMIFS(tblPCSAgent[Eligible Calls Day],tblPCSAgent[LOB],$A8)) | C8: =IF($A8="","",SUMIFS(tblPCSAgent[Q1 Nonblank Day],tblPCSAgent[LOB],$A8)) | D8: =IF($A8="","",SUMIFS(tblPCSAgent[Valid Q1 Day],tblPCSAgent[LOB],$A8)) | E8: =IFERROR(SUMPRODUCT((tblPCSAgent[LOB]=$A8)*tblPCSAgent[Valid Q1 Day]*tblPCSAgent[PCS Average Day])/D8,"") | F8: =IF($A8="","",SUMIFS(tblPCSAgent[<=3 Day],tblPCSAgent[LOB],$A8)) | G8: =IF($A8="","",SUMIFS(tblPCSAgent[>3 Day],tblPCSAgent[LOB],$A8)) | H8: =IFERROR(C8/B8,"") | I8: =IFERROR(D8/B8,"") | J8: =IF($A8="","",SUMIFS(tblPCSAgent[Eligible Calls 3H],tblPCSAgent[LOB],$A8)) | K8: =IF($A8="","",SUMIFS(tblPCSAgent[Valid Q1 3H],tblPCSAgent[LOB],$A8)) | L8: =IFERROR(SUMPRODUCT((tblPCSAgent[LOB]=$A8)*tblPCSAgent[Valid Q1 3H]*tblPCSAgent[PCS Average 3H])/K8,"") | M8: =IFERROR(SUMIFS(tblPCSAgent[Q1 Nonblank 3H],tblPCSAgent[LOB],$A8)/J8,"") | N8: =IFERROR(K8/J8,"") | O8: =IF($A8="","",IF(K8=0,"NO VALID SURVEY",IF(K8<20,"LOW SAMPLE","OK")))
A9: RSA VL | B9: =IF($A9="","",SUMIFS(tblPCSAgent[Eligible Calls Day],tblPCSAgent[LOB],$A9)) | C9: =IF($A9="","",SUMIFS(tblPCSAgent[Q1 Nonblank Day],tblPCSAgent[LOB],$A9)) | D9: =IF($A9="","",SUMIFS(tblPCSAgent[Valid Q1 Day],tblPCSAgent[LOB],$A9)) | E9: =IFERROR(SUMPRODUCT((tblPCSAgent[LOB]=$A9)*tblPCSAgent[Valid Q1 Day]*tblPCSAgent[PCS Average Day])/D9,"") | F9: =IF($A9="","",SUMIFS(tblPCSAgent[<=3 Day],tblPCSAgent[LOB],$A9)) | G9: =IF($A9="","",SUMIFS(tblPCSAgent[>3 Day],tblPCSAgent[LOB],$A9)) | H9: =IFERROR(C9/B9,"") | I9: =IFERROR(D9/B9,"") | J9: =IF($A9="","",SUMIFS(tblPCSAgent[Eligible Calls 3H],tblPCSAgent[LOB],$A9)) | K9: =IF($A9="","",SUMIFS(tblPCSAgent[Valid Q1 3H],tblPCSAgent[LOB],$A9)) | L9: =IFERROR(SUMPRODUCT((tblPCSAgent[LOB]=$A9)*tblPCSAgent[Valid Q1 3H]*tblPCSAgent[PCS Average 3H])/K9,"") | M9: =IFERROR(SUMIFS(tblPCSAgent[Q1 Nonblank 3H],tblPCSAgent[LOB],$A9)/J9,"") | N9: =IFERROR(K9/J9,"") | O9: =IF($A9="","",IF(K9=0,"NO VALID SURVEY",IF(K9<20,"LOW SAMPLE","OK")))
B10: =IF($A10="","",SUMIFS(tblPCSAgent[Eligible Calls Day],tblPCSAgent[LOB],$A10)) | C10: =IF($A10="","",SUMIFS(tblPCSAgent[Q1 Nonblank Day],tblPCSAgent[LOB],$A10)) | D10: =IF($A10="","",SUMIFS(tblPCSAgent[Valid Q1 Day],tblPCSAgent[LOB],$A10)) | E10: =IFERROR(SUMPRODUCT((tblPCSAgent[LOB]=$A10)*tblPCSAgent[Valid Q1 Day]*tblPCSAgent[PCS Average Day])/D10,"") | F10: =IF($A10="","",SUMIFS(tblPCSAgent[<=3 Day],tblPCSAgent[LOB],$A10)) | G10: =IF($A10="","",SUMIFS(tblPCSAgent[>3 Day],tblPCSAgent[LOB],$A10)) | H10: =IFERROR(C10/B10,"") | I10: =IFERROR(D10/B10,"") | J10: =IF($A10="","",SUMIFS(tblPCSAgent[Eligible Calls 3H],tblPCSAgent[LOB],$A10)) | K10: =IF($A10="","",SUMIFS(tblPCSAgent[Valid Q1 3H],tblPCSAgent[LOB],$A10)) | L10: =IFERROR(SUMPRODUCT((tblPCSAgent[LOB]=$A10)*tblPCSAgent[Valid Q1 3H]*tblPCSAgent[PCS Average 3H])/K10,"") | M10: =IFERROR(SUMIFS(tblPCSAgent[Q1 Nonblank 3H],tblPCSAgent[LOB],$A10)/J10,"") | N10: =IFERROR(K10/J10,"") | O10: =IF($A10="","",IF(K10=0,"NO VALID SURVEY",IF(K10<20,"LOW SAMPLE","OK")))
B11: =IF($A11="","",SUMIFS(tblPCSAgent[Eligible Calls Day],tblPCSAgent[LOB],$A11)) | C11: =IF($A11="","",SUMIFS(tblPCSAgent[Q1 Nonblank Day],tblPCSAgent[LOB],$A11)) | D11: =IF($A11="","",SUMIFS(tblPCSAgent[Valid Q1 Day],tblPCSAgent[LOB],$A11)) | E11: =IFERROR(SUMPRODUCT((tblPCSAgent[LOB]=$A11)*tblPCSAgent[Valid Q1 Day]*tblPCSAgent[PCS Average Day])/D11,"") | F11: =IF($A11="","",SUMIFS(tblPCSAgent[<=3 Day],tblPCSAgent[LOB],$A11)) | G11: =IF($A11="","",SUMIFS(tblPCSAgent[>3 Day],tblPCSAgent[LOB],$A11)) | H11: =IFERROR(C11/B11,"") | I11: =IFERROR(D11/B11,"") | J11: =IF($A11="","",SUMIFS(tblPCSAgent[Eligible Calls 3H],tblPCSAgent[LOB],$A11)) | K11: =IF($A11="","",SUMIFS(tblPCSAgent[Valid Q1 3H],tblPCSAgent[LOB],$A11)) | L11: =IFERROR(SUMPRODUCT((tblPCSAgent[LOB]=$A11)*tblPCSAgent[Valid Q1 3H]*tblPCSAgent[PCS Average 3H])/K11,"") | M11: =IFERROR(SUMIFS(tblPCSAgent[Q1 Nonblank 3H],tblPCSAgent[LOB],$A11)/J11,"") | N11: =IFERROR(K11/J11,"") | O11: =IF($A11="","",IF(K11=0,"NO VALID SURVEY",IF(K11<20,"LOW SAMPLE","OK")))
B12: =IF($A12="","",SUMIFS(tblPCSAgent[Eligible Calls Day],tblPCSAgent[LOB],$A12)) | C12: =IF($A12="","",SUMIFS(tblPCSAgent[Q1 Nonblank Day],tblPCSAgent[LOB],$A12)) | D12: =IF($A12="","",SUMIFS(tblPCSAgent[Valid Q1 Day],tblPCSAgent[LOB],$A12)) | E12: =IFERROR(SUMPRODUCT((tblPCSAgent[LOB]=$A12)*tblPCSAgent[Valid Q1 Day]*tblPCSAgent[PCS Average Day])/D12,"") | F12: =IF($A12="","",SUMIFS(tblPCSAgent[<=3 Day],tblPCSAgent[LOB],$A12)) | G12: =IF($A12="","",SUMIFS(tblPCSAgent[>3 Day],tblPCSAgent[LOB],$A12)) | H12: =IFERROR(C12/B12,"") | I12: =IFERROR(D12/B12,"") | J12: =IF($A12="","",SUMIFS(tblPCSAgent[Eligible Calls 3H],tblPCSAgent[LOB],$A12)) | K12: =IF($A12="","",SUMIFS(tblPCSAgent[Valid Q1 3H],tblPCSAgent[LOB],$A12)) | L12: =IFERROR(SUMPRODUCT((tblPCSAgent[LOB]=$A12)*tblPCSAgent[Valid Q1 3H]*tblPCSAgent[PCS Average 3H])/K12,"") | M12: =IFERROR(SUMIFS(tblPCSAgent[Q1 Nonblank 3H],tblPCSAgent[LOB],$A12)/J12,"") | N12: =IFERROR(K12/J12,"") | O12: =IF($A12="","",IF(K12=0,"NO VALID SURVEY",IF(K12<20,"LOW SAMPLE","OK")))
B13: =IF($A13="","",SUMIFS(tblPCSAgent[Eligible Calls Day],tblPCSAgent[LOB],$A13)) | C13: =IF($A13="","",SUMIFS(tblPCSAgent[Q1 Nonblank Day],tblPCSAgent[LOB],$A13)) | D13: =IF($A13="","",SUMIFS(tblPCSAgent[Valid Q1 Day],tblPCSAgent[LOB],$A13)) | E13: =IFERROR(SUMPRODUCT((tblPCSAgent[LOB]=$A13)*tblPCSAgent[Valid Q1 Day]*tblPCSAgent[PCS Average Day])/D13,"") | F13: =IF($A13="","",SUMIFS(tblPCSAgent[<=3 Day],tblPCSAgent[LOB],$A13)) | G13: =IF($A13="","",SUMIFS(tblPCSAgent[>3 Day],tblPCSAgent[LOB],$A13)) | H13: =IFERROR(C13/B13,"") | I13: =IFERROR(D13/B13,"") | J13: =IF($A13="","",SUMIFS(tblPCSAgent[Eligible Calls 3H],tblPCSAgent[LOB],$A13)) | K13: =IF($A13="","",SUMIFS(tblPCSAgent[Valid Q1 3H],tblPCSAgent[LOB],$A13)) | L13: =IFERROR(SUMPRODUCT((tblPCSAgent[LOB]=$A13)*tblPCSAgent[Valid Q1 3H]*tblPCSAgent[PCS Average 3H])/K13,"") | M13: =IFERROR(SUMIFS(tblPCSAgent[Q1 Nonblank 3H],tblPCSAgent[LOB],$A13)/J13,"") | N13: =IFERROR(K13/J13,"") | O13: =IF($A13="","",IF(K13=0,"NO VALID SURVEY",IF(K13<20,"LOW SAMPLE","OK")))
